Workbook

Sheet 変更履歴
A1: Ｐｈａｓｅ 外部設計工程 | BJ1: HOKUREN INTERNAL USE ONLY
A2: 画面設計書 変更履歴 | AV2: 様式No. | AZ2: F4106-0 | BD2: PAGE
A3: システム名 | H3: 統合会計システム | AV3: 作成日 | AZ3: 2025/8/29
A4: 業務名 | H4: 共計 | AV4: 更新日
A6: 機能名称 | H6: 販売共計年産繰越入力 | AV6: メニューコード
A8: 管理番号 | I8: 案件名 / 障害・問合せ件名
B10: 24058 | I10: 基幹システム再構築 会計システム外部設計

Sheet 1.遷移図
A1: Ｐｈａｓｅ 外部設計局面 | CQ1: HOKUREN INTERNAL USE ONLY
A2: 画 面 遷 移 図 | BY2: 様式No. | CF2: F4106-1 | CJ2: PAGE
A3: システム名 | J3: 統合会計システム | BY3: 作成日 | CF3: 2025/8/29
A4: 業務名 | J4: =変更履歴!H4 -> 共計 | BY4: 更新日
A6: 機能Ｎｏ． | J6: 9.3.3 | U6: 機能名称 | AD6: =変更履歴!H6 -> 販売共計年産繰越入力 | BY6: メニューコード
B9: 【画面利用条件】 | K9: ※利用可能ユーザー、利用可能組織など利用制限の有無。 利用可能とする条件を記載。
D11: 利用組織 ： | J11: 経理部、現業部門
W24: 検索 | AC24: 選択 | BL24: 承認ルート表示 | BX24: 登録、閉じる
AI27: 登録、修正 | BG27: 確認画面
AI29: キャンセル | BG29: 訂正
AC31: 申請（登録・修正・削除）、承認依頼取下、キャンセル
AC33: 削除、個別照会、承認依頼取下

Sheet 2.レイアウト（条件入力) 
A1: Ｐｈａｓｅ 外部設計局面 | CG1: HOKUREN INTERNAL USE ONLY
A2: 画面レイアウト説明書 | BP2: 様式No. | BV2: F4106-2 | CA2: PAGE
A3: システム名 | L3: 統合会計システム | BP3: 作成日 | BV3: 2025/8/29
A4: 業務名 | L4: 共計 | BP4: 更新日
A7: 画面名 | L7: 販売共計年産繰越入力
L10: 販売共計年産繰越入力 | BV10: 管理メニュー領域
D13: 条件入力
D14: 条件を入力し、販売共計繰越データを作成、照会、取消します。
D16: 検索条件
D17: 業種 | AQ17: 共計組織
D18: 収支管理品目 | AZ18: 年産 | BN18: 共計次数
D19: 繰越元共計年産
D20: 更新者 | AQ20: 更新日 | BJ20: -
D21: 伝票番号
D22: 承認状況 | N22: ☑差戻 ☑下書保存 ☑依頼中 □承認済
L47: 販売共計年産繰越入力 | BV47: 管理メニュー領域
D50: 条件入力
D51: 条件を入力し、販売共計繰越データを作成、照会、取消します。
D53: 検索条件
D55: (1 of 1) << < 1 > >>
D56: ☑ | G56: 承認状況 | L56: 更新日 | R56: 経理日 | X56: 更新者 | AK56: 繰越元 共計年産 | AP56: 繰越元収支管理品目 | BE56: 年産 | BI56: 共計 次数 | BM56: 繰越額 | BW56: 伝票番号
D58: ☑ | G58: 下書保存 | L58: YYYY/MM/DD | R58: YYYY/MM/DD | X58: ＸＸＸＸＸＸＸＸＸＸ | AL58: 2024 | AP58: 191113 小豆 | BF58: 2024 | BJ58: 01 | BO58: -1,100 | BW58: YY9999999-99
D59: □ | G59: 下書保存 | L59: YYYY/MM/DD | R59: YYYY/MM/DD | X59: ＸＸＸＸＸＸＸＸＸＸ | AL59: 2024 | AP59: XXXXXX ＸＸＸＸＸＸＸＸ | BF59: 2024 | BJ59: 01 | BO59: -1,100 | BW59: YY9999999-99
D60: □
D61: □
D62: □
D63: □
D64: □
D65: □
D66: □
D67: □
D68: □
D69: □
D70: □
D71: □
... D73: (1 of 1) << < 1 > >>
B79: 【イベント処理説明】
B80: イベント名称 | Q80: イベント処理概要 | BN80: 備考
B81: 【検索条件入力領域】
B82: 検索（業種） | Q82: 業種検索子画面をポップアップ表示する
...

Sheet 3.項目説明(条件入力)
A1: Ｐｈａｓｅ 外部設計工程 | BJ1: HOKUREN INTERNAL USE ONLY
A2: 画面項目説明書 | AV2: 様式No. | AZ2: F4106-3D | BD2: PAGE
A3: システム名 | H3: 統合会計システム | AV3: 作成日 | AZ3: 45898
A4: 業務名 | H4: 共計 | AV4: 更新日
A6: 画面名 | H6: =変更履歴!H6 -> 販売共計年産繰越入力
A8: 検索結果表示領域一覧表示順
A9: No. | D9: 項目名（ソート項目順に列挙） | AT9: 表示順
A10: 1 | D10: 承認状況 | AT10: 差戻→下書保存→依頼中→承認済
A11: 2 | D11: 更新日 | AT11: 昇順
A12: 3 | D12: 経理日 | AT12: 昇順
A13: 4 | D13: 更新者 | AT13: 昇順
A14: 5 | D14: 伝票番号 | AT14: 昇順
A16: No. | D16: 項目名 | S16: I/O | V16: 桁数 | Z16: 属性 | AD16: 符号 | AG16: 初期値 | AJ16: 前回 | AM16: 項目編集説明
V17: 入力 | X17: 表示
A18: =ROW()-17 -> 1 | D18: 【検索条件エリア】 | V18: - | X18: -
A19: =ROW()-17 -> 2 | D19: 業種 | S19: I/O | V19: 2 | X19: 2 | Z19: 文字 | AM19: ログインしたユーザーの担当する業種のみを対象として抽出する。
A20: =ROW()-17 -> 3 | D20: 業種名 | S20: O | V20: - | X20: 10 | Z20: 文字 （全角）
A21: =ROW()-17 -> 4 | D21: 共計組織 | S21: I/O | V21: 4 | X21: 4 | Z21: 数字
A22: =ROW()-17 -> 5 | D22: 共計組織名 | S22: O | V22: - | X22: 15 | Z22: 文字 （全角）
A23: =ROW()-17 -> 6 | D23: 収支管理品目 | S23: I/O | V23: 6 | X23: 6 | Z23: 文字
A24: =ROW()-17 -> 7 | D24: 収支管理品目名 | S24: O | V24: - | X24: 25 | Z24: 文字 （全角）
A25: =ROW()-17 -> 8 | D25: 年産 | S25: I/O | V25: 4 | X25: 4 | Z25: 数字
A26: =ROW()-17 -> 9 | D26: 共計次数 | S26: I/O | V26: 2 | X26: 2 | Z26: 文字
A27: =ROW()-17 -> 10 | D27: 繰越元共計年産 | S27: I/O | V27: 4 | X27: 4 | Z27: 数字
A28: =ROW()-17 -> 11 | D28: 更新者 | S28: I/O | V28: 20 | X28: 20 | Z28: 文字 （全角） | AG28: 〇 | AM28: 初期値：ログイン者の名称
A29: =ROW()-17 -> 12 | D29: 更新年月日（From） | S29: I/O | V29: 8 | X29: 10 | Z29: 数字
A30: =ROW()-17 -> 13 | D30: 更新年月日（To） | S30: I/O | V30: 8 | X30: 10 | Z30: 数字
A31: =ROW()-17 -> 14 | D31: 伝票番号 | S31: I/O | V31: 12 | X31: 12 | Z31: 文字
A32: =ROW()-17 -> 15 | D32: 承認状況 | S32: I/O | V32: - | X32: - | Z32: ﾁｪｯｸﾎﾞｯｸｽ | AG32: 〇 | AM32: 差戻、下書保存、依頼中を初期選択
A33: =ROW()-17 -> 16 | D33: 【明細表示エリア】 | V33: - | X33: -
A34: =ROW()-17 -> 17 | D34: 選択（明細） | S34: I | V34: - | X34: - | Z34: ﾗｼﾞｵﾎﾞﾀﾝ
A35: =ROW()-17 -> 18 | D35: 承認状況（明細） | S35: O | V35: - | X35: 5 | Z35: 文字 （全角）
A36: =ROW()-17 -> 19 | D36: 更新日（明細） | S36: O | V36: - | X36: 10 | Z36: 数字 | AM36: 販売共計年産繰越情報の更新日を表示する
A37: =ROW()-17 -> 20 | D37: 経理日（明細） | S37: O | V37: - | X37: 10 | Z37: 数字 | AM37: 販売共計年産繰越情報の経理日を表示する
A38: =ROW()-17 -> 21 | D38: 更新者（明細） | S38: O | V38: - | X38: 20 | Z38: 文字 （全角） | AM38: 販売共計年産繰越情報の更新者をキーに職員マスタから取得した職員氏名を表示する
A39: =ROW()-17 -> 22 | D39: 年産（明細） | S39: O | V39: - | X39: 4 | Z39: 数字
A40: =ROW()-17 -> 23 | D40: 繰越元収支管理品目（明細） | S40: O | V40: - | X40: 6 | Z40: 文字
A41: =ROW()-17 -> 24 | D41: 繰越元収支管理品目名（明細） | S41: O | V41: - | X41: 15 | Z41: 文字 （全角）
A42: =ROW()-17 -> 25 | D42: 年産（明細） | S42: O | V42: - | X42: 4 | Z42: 数字
A43: =ROW()-17 -> 26 | D43: 共計次数（明細） | S43: O | V43: - | X43: 2 | Z43: 数字 | AM43: 99編集
...

Sheet 4.項目チェック（単体）_条件入力
A1: Ｐｈａｓｅ 外部設計工程 | BJ1: HOKUREN INTERNAL USE ONLY
A2: 画面項目チェック（単体） | AV2: 様式No. | AZ2: F4106-4 | BD2: PAGE
A3: システム名 | H3: 統合会計システム | AV3: 作成日 | AZ3: 45898
A4: 業務名 | H4: =変更履歴!H4 -> 共計 | AV4: 更新日
A6: 画面名 | H6: =変更履歴!H6 -> 販売共計年産繰越入力
A8: No. | D8: 項目名 | R8: 必須 ﾁｪｯｸ | U8: 数字 ﾁｪｯｸ | X8: 文字数 ﾁｪｯｸ | AA8: 存在 ﾁｪｯｸ | AD8: ｺｰﾄﾞﾁｪｯｸ | AG8: チェック補足説明／メッセージ文言 | BD8: メッセージ コード
A9: =ROW()-8 -> 1 | D9: 業種 | AA9: ○ | AG9: ／業種はマスタに存在しません。
A10: =ROW()-8 -> 2 | D10: 共計組織 | AA10: ○ | AG10: ／共計組織はマスタに存在しません。
A11: =ROW()-8 -> 3 | D11: 収支管理品目 | AA11: ○ | AG11: ／収支管理品目コードはマスタに存在しません。
A12: =ROW()-8 -> 4 | D12: 更新日（From） | U12: ○ | AG12: 実在日でない場合、エラーとする。 ／更新日は有効な日付を入力してください。
A13: =ROW()-8 -> 5 | D13: 更新日（To） | U13: ○ | AG13: 実在日でない場合、エラーとする。 ／更新日は有効な日付を入力してください。

Sheet 5.項目チェック（関連）_条件入力 
A1: Ｐｈａｓｅ 外部設計局面 | BJ1: HOKUREN INTERNAL USE ONLY
A2: 画面項目チェック（関連） | AV2: 様式No. | AZ2: F4106-5 | BD2: PAGE
A3: システム名 | H3: 統合会計システム | AV3: 作成日 | AZ3: 45898
A4: 業務名 | H4: =変更履歴!H4 -> 共計 | AV4: 更新日
A6: 画面名 | H6: =変更履歴!H6 -> 販売共計年産繰越入力
A8: No. | D8: 関連チェック概要 | Q8: チェック詳細／メッセージ文言 | BD8: メッセージ コード
A9: =ROW()-8 -> 1 | D9: 更新日(From)と更新日(To)の検索範囲チェック | Q9: 更新日(From)、更新日(To)の両方を入力している且つ、 更新日(From)＞更新日(To)の場合はエラー ／更新日(From)は更新日(To)より過去の日付を入力してください。
A10: 2 | D10: 業種と共計組織 | Q10: 画面に入力した業種と入力者の所属する組織の組み合わせが「6．画面機能補足説明 ＜業種照会可能範囲＞」で定める業種以外の場合エラー ／業種は共計組織に応じた業種を入力してください。
A11: =ROW()-8 -> 3 | D11: 入力組織と共計組織 | Q11: 入力者の所属する組織が本所以外の場合、「6．画面機能補足説明 ＜共計組織照会可能範囲＞」で定める共計組織以外の場合エラー ／共計組織は担当の所属コードを入力してください。
A12: =ROW()-8 -> 4 | D12: 入力組織と更新者 | Q12: 「照会」ボタン押下時、入力した更新者の所属する組織が「6．画面機能補足説明 ＜共計組織照会可能範囲＞」で定める組織以外の場合エラー ／更新者は自組織に応じた更新者を入力してください。
A13: =ROW()-8 -> 5 | D13: 入力組織と収支管理品目 | Q13: 画面に入力した収支管理品目に紐づく業種と、入力者の所属する組織の組み合わせが「6．画面機能補足説明 ＜業種照会可能範囲＞」で定める業種以外の場合エラー ／収支管理品目は共計組織に応じた収支管理品目を入力してください。
A14: =ROW()-8 -> 6 | D14: 検索条件と対象データの 存在チェック | Q14: 「照会」ボタン押下時、検索条件に合致するデータが存在しない場合はエラー ／条件に該当するデータはありません。
A15: =ROW()-8 -> 7 | D15: 修正ボタンと明細未選択チェック | Q15: 「修正」ボタン押下時、明細を選択していない場合エラー ／明細を選択してください。
A16: =ROW()-8 -> 8 | D16: 修正ボタンと複数明細選択チェック | Q16: 「修正」ボタン押下時、複数明細を選択している場合エラー ／明細は１件のみ選択してください。
A17: =ROW()-8 -> 9 | D17: 修正ボタンと承認状況（依頼中）のチェック | Q17: 「修正」ボタン押下時、承認状況が「依頼中」の明細を選択している場合エラー ／依頼中の為、対象データは操作できません。
A18: =ROW()-8 -> 10 | D18: 修正ボタン承認状況（承認済）のチェック | Q18: 「修正」ボタン押下時、承認状況が「承認済」の明細を選択している場合エラー ／承認済の為、対象データは操作できません。
A19: =ROW()-8 -> 11 | D19: 削除ボタンと明細未選択のチェック | Q19: 「削除」ボタン押下時、明細を選択していない場合エラー ／明細を選択してください。
A20: =ROW()-8 -> 12 | D20: 削除ボタンと承認状況（依頼中）のチェック | Q20: 「削除」ボタン押下時、承認状況が「依頼中」の明細を1件でも選択している場合エラー ／依頼中の為、対象データは操作できません。
A21: =ROW()-8 -> 13 | D21: 削除ボタンと複数明細選択のチェック | Q21: 「削除」ボタン押下時、複数明細を選択している場合エラー ／明細は１件のみ選択してください。
A22: =ROW()-8 -> 14 | D22: 個別照会ボタンと明細未選択のチェック | Q22: 「個別照会」ボタン押下時、明細を選択していない場合エラー ／明細を選択してください。
... A30: =ROW()-8 -> 22 | D30: 承認依頼取下ボタンと入力組織のチェック | Q30: 「承認依頼取下」ボタン押下時、共計組織が入力者の所属する組織以外となる明細を1件でも選択している場合エラー ／共計組織が担当の所属コード以外となる明細は選択できません。

Sheet 2.レイアウト（入力)
A1: Ｐｈａｓｅ 外部設計局面 | CG1: HOKUREN INTERNAL USE ONLY
A2: 画面レイアウト説明書 | BP2: 様式No. | BV2: F4106-2 | CA2: PAGE
A3: システム名 | L3: 統合会計システム | BP3: 作成日 | BV3: 2025/8/29
A4: 業務名 | L4: 共計 | BP4: 更新日
A7: 画面名 | L7: =変更履歴!H6 -> 販売共計年産繰越入力
L10: 販売共計年産繰越入力 | BV10: 管理メニュー領域
D13: 条件入力 > 入力
D14: 販売共計年産繰越の情報を入力して下さい。
D16: 検索条件
D17: 業種(*) | AQ17: 共計組織(*)
D18: 収支管理品目(*) | AA18: 小豆 | AQ18: 年産(*) | BL18: 共計次数(*)
D19: 取引日 (*)
D20: 添付ファイル | O20: 0 | AQ20: 参照ＵＲＬ
D23: 繰越元情報
D24: 収支管理品目 | T24: 年産 | Y24: 共計 次数 | AD24: 内訳コード | AP24: 金額コード/金額摘要コード | BD24: 販売共計支払金 | BR24: 販売共計受入金
BD25: 繰越前残高 | BL25: 繰越額 | BR25: 繰越前残高 | BX25: 繰越額
D26: 191113 小豆 | T26: 2024 | Y26: 01 | AD26: 01 品代 | BD26: 1,000 | BR26: 2000
D27: 191113 小豆 | T27: 2024 | Y27: 01 | AD27: 01 品代 | BD27: 100 | BR27: 200
AP28: 合計 | BD28: =BD26+BD27 -> 1100 | BL28: 0 | BR28: =BR26+BR27 -> 2200
D29: 191113 小豆 | T29: 2024 | Y29: 01
D31: 繰越先情報
D32: □ | F32: 収支管理品目(*) | T32: 年産(*) | Y32: 共計 次数(*) | AD32: 内訳コード | AP32: 金額コード/金額摘要コード | BD32: 販売共計 支払金繰越額 | BQ32: 販売共計 受入金繰越額
D34: □
AP35: 合計
B41: 【イベント処理説明】
B42: イベント名称 | Q42: イベント処理概要 | BN42: 備考
B43: 検索（業種） | Q43: 業種検索子画面をポップアップ表示する
B44: 検索（共計組織） | Q44: 共計組織検索子画面をポップアップ表示する
B45: 検索（収支管理品目） | Q45: 収支管理品目検索子画面をポップアップ表示する | BN45: 共計実績のある収支管理品目のみ抽出し検索対象とする
B46: 検索（添付ファイル） | Q46: 添付ファイル／表示補助画面をポップアップ表示する。
B47: 検索（内訳コード） | Q47: 内訳コード入力／表示補助画面をポップアップ表示する。
B48: 検索（金額コード） | Q48: 金額コード入力／表示補助画面をポップアップ表示する。
B49: 検索（金額摘要コード） | Q49: 金額摘要検索子画面をポップアップ表示する
B50: 照会 | Q50: 入力した内容をチェックし、エラーの場合はエラーメッセージを表示。 エラーが無ければ、入力した条件の検索結果を一覧表示する。
B51: クリア | Q51: 検索条件入力領域を初期の状態に戻す。
B52: 表示 | Q52: 入力した内容をチェックし、エラーの場合はエラーメッセージを表示。 エラーが無ければ、業種、収支管理品目、共計組織と繰越先情報の各行の収支管理品目に入力したコードの名称を表示する。
B53: 行追加 | Q53: 明細行の追加を行う。
B54: 行削除 | Q54: 選択した明細行の削除を行う。
B55: キャンセル | Q55: 条件入力画面へ遷移する。
B56: 下書保存 | Q56: 入力した内容を単体チェックし、エラーの場合はエラーメッセージを表示。 エラーが無ければ、下書保存に更新する。
...

Sheet 3.項目説明(入力)
A1: Ｐｈａｓｅ 外部設計工程 | BJ1: HOKUREN INTERNAL USE ONLY
A2: 画面項目説明書 | AV2: 様式No. | AZ2: F4106-3D | BD2: PAGE
A3: システム名 | H3: 統合会計システム | AV3: 作成日 | AZ3: 45898
A4: 業務名 | H4: 共計 | AV4: 更新日
A6: 画面名 | H6: =変更履歴!H6 -> 販売共計年産繰越入力
A8: 検索結果表示領域一覧表示順（繰越元）
A9: No. | D9: 項目名（ソート項目順に列挙） | AT9: 表示順
A10: 1 | D10: 収支管理品目コード | AT10: 昇順
A11: 2 | D11: 年産 | AT11: 昇順
A12: 3 | D12: 共計次数 | AT12: 昇順
A13: 4 | D13: 金額コード／金額摘要コード | AT13: 昇順
A15: No. | D15: 項目名 | S15: I/O | V15: 桁数 | Z15: 属性 | AD15: 符号 | AG15: 初期値 | AJ15: 前回 | AM15: 項目編集説明
V16: 入力 | X16: 表示
A17: =ROW()-16 -> 1 | D17: 【検索条件エリア】 | V17: - | X17: -
A18: =ROW()-16 -> 2 | D18: 業種 | S18: I/O | V18: 2 | X18: 2 | Z18: 文字 | AM18: ログインしたユーザーの担当する業種のみを対象として抽出する。
A19: =ROW()-16 -> 3 | D19: 業種名 | S19: O | V19: - | X19: 10 | Z19: 文字 （全角）
A20: =ROW()-16 -> 4 | D20: 共計組織 | S20: I/O | V20: 4 | X20: 4 | Z20: 数字
A21: =ROW()-16 -> 5 | D21: 共計組織名 | S21: O | V21: - | X21: 15 | Z21: 文字 （全角）
A22: =ROW()-16 -> 6 | D22: 収支管理品目 | S22: I/O | V22: 6 | X22: 6 | Z22: 文字
A23: =ROW()-16 -> 7 | D23: 収支管理品目名 | S23: O | V23: - | X23: 15 | Z23: 文字 （全角）
A24: =ROW()-16 -> 8 | D24: 年産 | S24: I/O | V24: 4 | X24: 4 | Z24: 数字
A25: =ROW()-16 -> 9 | D25: 共計次数 | S25: I/O | V25: 2 | X25: 2 | Z25: 数字 | AM25: 99編集
A26: =ROW()-16 -> 10 | D26: 取引日 | S26: I/O | V26: 8 | X26: 10 | Z26: 数字 | AG26: 〇 | AM26: 取引日を入力する。ＶＢ期間であれば前月末日、ＶＢ期間外であれば運用管理日（当日）を設定する。
A27: =ROW()-16 -> 11 | D27: 添付ファイル | S27: O | V27: - | X27: 2 | Z27: 数字
A28: =ROW()-16 -> 12 | D28: 参照URL | S28: I/O | V28: 100 | X28: 100 | Z28: 文字
A29: =ROW()-16 -> 13 | D29: 【繰越元明細表示エリア】 | V29: - | X29: -
A30: =ROW()-16 -> 14 | D30: 収支管理品目 | S30: O | V30: - | X30: 6 | Z30: 文字
A31: =ROW()-16 -> 15 | D31: 収支管理品目名 | S31: O | V31: - | X31: 15 | Z31: 文字 （全角）
A32: =ROW()-16 -> 16 | D32: 年産 | S32: O | V32: - | X32: 4 | Z32: 数字
A33: =ROW()-16 -> 17 | D33: 共計次数 | S33: O | V33: - | X33: 2 | Z33: 数字 | AM33: 99編集
A34: =ROW()-16 -> 18 | D34: 内訳コード | S34: O | V34: - | X34: 2 | Z34: 文字
A35: =ROW()-16 -> 19 | D35: 内訳コード名 | S35: O | V35: - | X35: 10 | Z35: 文字 （全角）
A36: =ROW()-16 -> 20 | D36: 金額／金額摘要コード | S36: O | V36: - | X36: 3 | Z36: 文字 | AM36: 米穀業種の場合は金額摘要コード、それ以外の業種の場合は金額コードのリストを表示します。
A37: =ROW()-16 -> 21 | D37: 金額／金額摘要コード名 | S37: O | V37: - | X37: 10 | Z37: 文字 （全角）
A38: =ROW()-16 -> 22 | D38: 繰越前残高（販売共計支払金） | S38: O | V38: - | X38: 18 | Z38: 数字 | AD38: 〇
A39: =ROW()-16 -> 23 | D39: 繰越額（販売共計支払金） | S39: O | V39: - | X39: 18 | Z39: 数字 | AD39: 〇
A40: =ROW()-16 -> 24 | D40: 繰越前残高（販売共計受入金） | S40: O | V40: - | X40: 18 | Z40: 数字 | AD40: 〇
A41: =ROW()-16 -> 25 | D41: 繰越額（販売共計受入金） | S41: O | V41: - | X41: 18 | Z41: 数字 | AD41: 〇
A42: =ROW()-16 -> 26 | D42: 繰越前残高（合計販売共計支払金） | S42: O | V42: - | X42: 18 | Z42: 数字 | AD42: 〇
A43: =ROW()-16 -> 27 | D43: 繰越額（合計販売共計支払金） | S43: O | V43: - | X43: 18 | Z43: 数字 | AD43: 〇
...

Sheet 4.項目チェック（単体）_入力
A1: Ｐｈａｓｅ 外部設計工程 | BJ1: HOKUREN INTERNAL USE ONLY
A2: 画面項目チェック（単体） | AV2: 様式No. | AZ2: F4106-4 | BD2: PAGE
A3: システム名 | H3: 統合会計システム | AV3: 作成日 | AZ3: 45898
A4: 業務名 | H4: =変更履歴!H4 -> 共計 | AV4: 更新日
A6: 画面名 | H6: =変更履歴!H6 -> 販売共計年産繰越入力
A8: No. | D8: 項目名 | R8: 必須 ﾁｪｯｸ | U8: 数字 ﾁｪｯｸ | X8: 文字数 ﾁｪｯｸ | AA8: 存在 ﾁｪｯｸ | AD8: ｺｰﾄﾞﾁｪｯｸ | AG8: チェック補足説明／メッセージ文言 | BD8: メッセージ コード
A9: =ROW()-8 -> 1 | D9: 業種 | R9: ○ | AG9: ／業種を入力してください。
A10: =ROW()-8 -> 2 | AA10: ○ | AG10: ／業種はマスタに存在しません。
A11: =ROW()-8 -> 3 | D11: 共計組織 | R11: ○ | AG11: ／共計組織を入力してください。
A12: =ROW()-8 -> 4 | AA12: ○ | AG12: ／共計組織はマスタに存在しません。
A13: =ROW()-8 -> 5 | D13: 収支管理品目 | R13: ○ | AG13: ／収支管理品目を入力してください。
A14: =ROW()-8 -> 6 | AA14: ○ | AG14: ／収支管理品目はマスタに存在しません。
A15: =ROW()-8 -> 7 | D15: 年産 | R15: ○ | AG15: ／年産を入力してください。
A16: =ROW()-8 -> 8 | X16: ○ | AG16: ４文字である事を確認する。 ／年産は４文字で入力してください。
A17: =ROW()-8 -> 9 | D17: 共計次数 | R17: ○ | AG17: ／共計次数を入力してください。
A18: =ROW()-8 -> 10 | X18: ○ | AG18: ２文字である事を確認する。 ／共計次数は２文字で入力してください。
A19: =ROW()-8 -> 11 | D19: 取引日 | R19: ○ | AG19: ／取引日を入力してください。
A20: =ROW()-8 -> 12 | U20: ○ | AG20: 実在日でない場合、エラーとする。 ／取引日は有効な日付を入力してください。
A21: =ROW()-8 -> 13 | AD21: ○ | AG21: 取引日が未来日の場合、エラーとする。 ／取引日に未来日は入力できません。
A22: =ROW()-8 -> 14 | D22: 入力繰越額（共計支払金） | U22: ○ | AG22: ／繰越額（共計支払金）は半角数値で入力してください。
A23: =ROW()-8 -> 15 | X23: ○ | AG23: 繰越額（共計支払金に入力した値が -9,999,999,999,999 ～ 9,999,999,999,999の範囲内であることを確認する。 ／繰越額（共計支払金は-9,999,999,999,999 ～ 9,999,999,999,999の範囲内で入力してください。
A24: =ROW()-8 -> 16 | D24: 入力繰越額（共計受入金） | U24: ○ | AG24: ／繰越額（共計受入金）は半角数値で入力してください。
A25: =ROW()-8 -> 17 | X25: ○ | AG25: 繰越額（共計受入金）に入力した値が -9,999,999,999,999 ～ 9,999,999,999,999の範囲内であることを確認する。 ／繰越額（共計受入金）は-9,999,999,999,999 ～ 9,999,999,999,999の範囲内で入力してください。
A26: =ROW()-8 -> 18 | D26: 収支管理品目（繰越先） | R26: ○ | AG26: ／収支管理品目を入力してください。
A27: =ROW()-8 -> 19 | AA27: ○ | AG27: ／収支管理品目はマスタに存在しません。
A28: =ROW()-8 -> 20 | D28: 年産（繰越先） | R28: ○ | AG28: ／年産を入力してください。
A29: =ROW()-8 -> 21 | X29: ○ | AG29: ４文字である事を確認する。 ／年産は４文字で入力してください。
A30: =ROW()-8 -> 22 | D30: 共計次数（繰越先） | R30: ○ | AG30: ／共計次数を入力してください。
A31: =ROW()-8 -> 23 | X31: ○ | AG31: ２文字である事を確認する。 ／共計次数は２文字で入力してください。
A32: =ROW()-8 -> 24 | D32: 販売共計支払金繰越額 | U32: ○ | AG32: ／販売共計支払金繰越額は半角数値で入力してください。
A33: =ROW()-8 -> 25 | X33: ○ | AG33: 販売共計支払金繰越額に入力した値が -9,999,999,999,999 ～ 9,999,999,999,999の範囲内であることを確認する。 ／販売共計支払金繰越額は-9,999,999,999,999 ～ 9,999,999,999,999の範囲内で入力してください。
A34: =ROW()-8 -> 26 | D34: 販売共計受入金繰越額 | U34: ○ | AG34: ／販売共計受入金繰越額は半角数値で入力してください。
A35: =ROW()-8 -> 27 | X35: ○ | AG35: 販売共計受入金繰越額に入力した値が -9,999,999,999,999 ～ 9,999,999,999,999の範囲内であることを確認する。 ／販売共計受入金繰越額は-9,999,999,999,999 ～ 9,999,999,999,999の範囲内で入力してください。

Sheet 5.項目チェック（関連）_入力
A1: Ｐｈａｓｅ 外部設計局面 | BJ1: HOKUREN INTERNAL USE ONLY
A2: 画面項目チェック（関連） | AV2: 様式No. | AZ2: F4106-5 | BD2: PAGE
A3: システム名 | H3: 統合会計システム | AV3: 作成日 | AZ3: 45898
A4: 業務名 | H4: =変更履歴!H4 -> 共計 | AV4: 更新日
A6: 画面名 | H6: =変更履歴!H6 -> 販売共計年産繰越入力
A8: No. | D8: 関連チェック概要 | Q8: チェック詳細／メッセージ文言 | BD8: メッセージ コード
A9: =ROW()-8 -> 1 | D9: 確認画面ボタン押下時 | Q9: 繰越元の販売共計支払金繰越額の合計と繰越先の販売共計支払金繰越額を合算し、０以外の場合はエラー ／販売共計支払金の繰越額について、繰越元と繰越先の金額が合算して０となっていません。
A10: =ROW()-8 -> 2 | Q10: 繰越元の販売共計受入金繰越額の合計と繰越先の販売共計受入金繰越額を合算し、０以外の場合はエラー ／販売共計受入金の繰越額について、繰越元と繰越先の金額が合算して０となっていません。
A11: =ROW()-8 -> 3 | Q11: 繰越元の販売共計受入金繰越前残高から販売共計支払金繰越前残高を引いた額が、繰越先の販売共計支払金繰越額と販売共計受入金繰越額の合計と異なる場合、警告する。 ／繰越元と繰越先の合計が一致していませんが、よろしいですか？
A12: =ROW()-8 -> 4 | Q12: 繰越元の業種と繰越先の業種が一致しない。 ／繰越先の業種（収支管理品目）に誤りがあります。
A13: =ROW()-8 -> 5 | Q13: ＶＢ期間中に取引日が当月日付の場合、警告する。 ／取引日が入力月となっているため、入力月の経理となりますが、よろしいですか？ 前月経理とする場合は、取引日に前月末日以前を入力してください。
A14: =ROW()-8 -> 6 | D14: 照会ボタン押下時 | Q14: 業種と共計組織の組み合わせが「6．画面機能補足説明 ＜業種入力可能範囲＞」で定める業種以外の場合エラー ／業種は共計組織に応じた業種を入力してください。
A15: =ROW()-8 -> 7 | Q15: 入力した共計組織コードが「6．画面機能補足説明 ＜共計組織入力可能範囲＞」で定める共計組織以外の場合エラー ／共計組織は担当の所属コードを入力してください。
A16: =ROW()-8 -> 8 | D16: 検索条件と対象データの 存在チェック | Q16: 「照会」ボタン押下時、検索条件に合致するデータが存在しない場合はエラー ／条件に該当するデータはありません。

Sheet 2.レイアウト（確認）
A1: Ｐｈａｓｅ 外部設計局面 | CG1: HOKUREN INTERNAL USE ONLY
A2: 画面レイアウト説明書 | BP2: 様式No. | BV2: F4106-2 | CA2: PAGE
A3: システム名 | L3: 統合会計システム | BP3: 作成日 | BV3: 2025/8/29
A4: 業務名 | L4: 共計 | BP4: 更新日
A7: 画面名 | L7: =変更履歴!H6 -> 販売共計年産繰越入力
B10: 【登録・修正時】
L11: 販売共計年産繰越入力 | BV11: 管理メニュー領域
D14: 条件入力 > 入力 > 確認
D15: 販売共計年産繰越情報を確認します。
D17: 検索条件
D18: 業種 | O18: 10 雑穀 | AQ18: 共計組織 | AZ18: 4137 雑穀課
D19: 収支管理品目 | O19: 191113 | V19: 小豆 | AQ19: 年産 | AZ19: 2024 | BL19: 共計次数 | BS19: 01
D20: 取引日 | O20: 2025/03/31
D21: 添付ファイル | O21: 0 | AQ21: 参照ＵＲＬ
D23: 繰越元
D24: 収支管理品目 | T24: 年産 | Y24: 共計 次数 | AD24: 内訳コード | AQ24: 金額コード/金額摘要コード | BF24: 販売共計支払金 | BR24: 販売共計受入金
BF25: 繰越前残高 | BL25: 繰越額 | BR25: 繰越前残高 | BX25: 繰越額
D26: 191113 小豆 | T26: 2024 | Y26: 01 | AD26: 01 品代 | BF26: 1,000 | BR26: 2000
D27: 191113 小豆 | T27: 2024 | Y27: 01 | AD27: 01 品代 | BF27: 100 | BR27: 200
AQ28: 合計 | BF28: =BF26+BF27 -> 1100 | BL28: 0 | BR28: =BR26+BR27 -> 2200
D29: 191113 小豆 | T29: 2024 | Y29: 01 | AD29: 01 品代 | AQ29: 264 繰越金額（品代） | BQ29: 0 | CC29: -1,100
D31: 繰越先
D32: 収支管理品目 | T32: 年産 | Y32: 共計 次数 | AD32: 内訳コード | AQ32: 金額コード/金額摘要コード | BF32: 販売共計 支払金繰越額 | BR32: 販売共計 受入金繰越額
D34: 191113 小豆 | T34: 2025 | Y34: 01 | AD34: 01 品代 | AQ34: 264 繰越金額（品代） | BQ34: 0 | CC34: 1,100
AQ35: 合計 | BQ35: 0 | CC35: 1,100
B42: 【削除時】
L43: 販売共計年産繰越入力 | BV43: 管理メニュー領域
D46: 条件入力 > 入力 > 確認
D47: 販売共計年産繰越情報を確認します。
D49: 繰越元条件 ～ 繰越先のイメージは「登録・修正」と変わらないためイメージ割愛
B56: 【承認依頼取下時】
L57: 販売共計年産繰越入力 | BV57: 管理メニュー領域
D60: 条件入力 > 入力 > 確認
D61: 販売共計年産繰越情報を確認します。
D63: 繰越元条件 ～ 繰越先のイメージは「登録・修正」と変わらないためイメージ割愛
B72: 【イベント処理説明】
B73: イベント名称 | Q73: イベント処理概要 | BN73: 備考
B74: 訂正 | Q74: 内容入力画面へ遷移します。
B75: 申請 | Q75: 入力した内容をチェックし、エラーの場合はエラーメッセージを表示。 エラーが無ければ、入力内容で更新し、条件入力画面へ遷移します。 | BN75: 承認済の伝票を削除する場合はマイナス仕訳を起こす。
B76: キャンセル | Q76: 条件入力画面へ遷移します。
...

Sheet 3.項目説明(確認)
A1: Ｐｈａｓｅ 外部設計工程 | BJ1: HOKUREN INTERNAL USE ONLY
A2: 画面項目説明書 | AV2: 様式No. | AZ2: F4106-3D | BD2: PAGE
A3: システム名 | H3: 統合会計システム | AV3: 作成日 | AZ3: 45898
A4: 業務名 | H4: 共計 | AV4: 更新日
A6: 画面名 | H6: =変更履歴!H6 -> 販売共計年産繰越入力
A8: 検索結果表示領域一覧表示順（繰越元）
A9: No. | D9: 項目名（ソート項目順に列挙） | AT9: 表示順
A10: 1 | D10: 収支管理品目コード | AT10: 昇順
A11: 2 | D11: 年産 | AT11: 昇順
A12: 3 | D12: 共計次数 | AT12: 昇順
A13: 4 | D13: 金額コード／摘要コード | AT13: 昇順
A15: No. | D15: 項目名 | S15: I/O | V15: 桁数 | Z15: 属性 | AD15: 符号 | AG15: 初期値 | AJ15: 前回 | AM15: 項目編集説明
V16: 入力 | X16: 表示
A17: =ROW()-16 -> 1 | D17: 【検索条件エリア】 | V17: - | X17: -
A18: =ROW()-16 -> 2 | D18: 業種 | S18: O | V18: - | X18: 2 | Z18: 文字
A19: =ROW()-16 -> 3 | D19: 業種名 | S19: O | V19: - | X19: 10 | Z19: 文字 （全角）
A20: =ROW()-16 -> 4 | D20: 共計組織 | S20: O | V20: - | X20: 4 | Z20: 数字
A21: =ROW()-16 -> 5 | D21: 共計組織名 | S21: O | V21: - | X21: 15 | Z21: 文字 （全角）
A22: =ROW()-16 -> 6 | D22: 収支管理品目 | S22: O | V22: - | X22: 6 | Z22: 文字
A23: =ROW()-16 -> 7 | D23: 収支管理品目名 | S23: O | V23: - | X23: 15 | Z23: 文字 （全角）
A24: =ROW()-16 -> 8 | D24: 年産 | S24: O | V24: - | X24: 4 | Z24: 数字
A25: =ROW()-16 -> 9 | D25: 共計次数 | S25: O | V25: - | X25: 2 | Z25: 数字 | AM25: 99編集
A26: =ROW()-16 -> 10 | D26: 取引日 | S26: O | V26: - | X26: 10 | Z26: 数字
A27: =ROW()-16 -> 11 | D27: 添付ファイル | S27: O | V27: - | X27: 2 | Z27: 数字
A28: =ROW()-16 -> 12 | D28: 参照URL | S28: O | V28: - | X28: 100 | Z28: 文字
A29: =ROW()-16 -> 13 | D29: 【繰越元明細表示エリア】 | V29: - | X29: -
A30: =ROW()-16 -> 14 | D30: 収支管理品目 | S30: O | V30: - | X30: 6 | Z30: 文字
A31: =ROW()-16 -> 15 | D31: 収支管理品目名 | S31: O | V31: - | X31: 15 | Z31: 文字 （全角）
A32: =ROW()-16 -> 16 | D32: 年産 | S32: O | V32: - | X32: 4 | Z32: 数字
A33: =ROW()-16 -> 17 | D33: 共計次数 | S33: O | V33: - | X33: 2 | Z33: 数字
A34: =ROW()-16 -> 18 | D34: 内訳コード | S34: O | V34: - | X34: 2 | Z34: 文字
A35: =ROW()-16 -> 19 | D35: 内訳コード名 | S35: O | V35: - | X35: 10 | Z35: 文字 （全角）
A36: =ROW()-16 -> 20 | D36: 金額／金額摘要コード | S36: O | V36: - | X36: 3 | Z36: 文字
A37: =ROW()-16 -> 21 | D37: 金額／金額摘要コード名 | S37: O | V37: - | X37: 10 | Z37: 文字 （全角）
A38: =ROW()-16 -> 22 | D38: 繰越前残高（販売共計支払金） | S38: O | V38: - | X38: 18 | Z38: 数字 | AD38: 〇
A39: =ROW()-16 -> 23 | D39: 繰越額（販売共計支払金） | S39: O | V39: - | X39: 18 | Z39: 数字 | AD39: 〇
A40: =ROW()-16 -> 24 | D40: 繰越前残高（販売共計受入金） | S40: O | V40: - | X40: 18 | Z40: 数字 | AD40: 〇
A41: =ROW()-16 -> 25 | D41: 繰越額（販売共計受入金） | S41: O | V41: - | X41: 18 | Z41: 数字 | AD41: 〇
A42: =ROW()-16 -> 26 | D42: 繰越前残高（合計販売共計支払金） | S42: O | V42: - | X42: 18 | Z42: 数字 | AD42: 〇
A43: =ROW()-16 -> 27 | D43: 繰越額（合計販売共計支払金） | S43: O | V43: - | X43: 18 | Z43: 数字 | AD43: 〇
...

Sheet 4.項目チェック（単体）_確認
A1: Ｐｈａｓｅ 外部設計工程 | BJ1: HOKUREN INTERNAL USE ONLY
A2: 画面項目チェック（単体） | AV2: 様式No. | AZ2: F4106-4 | BD2: PAGE
A3: システム名 | H3: 統合会計システム | AV3: 作成日 | AZ3: 45898
A4: 業務名 | H4: =変更履歴!H4 -> 共計 | AV4: 更新日
A6: 画面名 | H6: =変更履歴!H6 -> 販売共計年産繰越入力
A8: No. | D8: 項目名 | R8: 必須 ﾁｪｯｸ | U8: 数字 ﾁｪｯｸ | X8: 文字数 ﾁｪｯｸ | AA8: 存在 ﾁｪｯｸ | AD8: ｺｰﾄﾞﾁｪｯｸ | AG8: チェック補足説明／メッセージ文言 | BD8: メッセージ コード
AG9: チェックなし

Sheet 5.項目チェック（関連）_確認
A1: Ｐｈａｓｅ 外部設計局面 | BJ1: HOKUREN INTERNAL USE ONLY
A2: 画面項目チェック（関連） | AV2: 様式No. | AZ2: F4106-5 | BD2: PAGE
A3: システム名 | H3: 統合会計システム | AV3: 作成日 | AZ3: 45898
A4: 業務名 | H4: =変更履歴!H4 -> 共計 | AV4: 更新日
A6: 画面名 | H6: =変更履歴!H6 -> 販売共計年産繰越入力
A8: No. | D8: 関連チェック概要 | Q8: チェック詳細／メッセージ文言 | BD8: メッセージ コード
Q9: チェックなし

Sheet 6．画面機能補足説明
A1: Ｐｈａｓｅ 外部設計工程 | BJ1: HOKUREN INTERNAL USE ONLY
A2: 画面機能補足説明 | AV2: 様式No. | AZ2: F4106-6 | BD2: PAGE
A3: システム名 | H3: 統合会計システム | AV3: 作成日 | AZ3: 45898
A4: 業務名 | H4: =変更履歴!H4 -> 共計 | AV4: 更新日
A6: 機能Ｎｏ． | H6: 9.3.4 | O6: 機能名称 | V6: =変更履歴!H6 -> 販売共計年産繰越入力
B8: 【画面機能補足説明】
C10: １．照会・入力可能範囲
C11: ＜業種照会可能範囲＞
E12: ・入力者の所属組織コードに応じて選択可能な業種を組織・業種マスタから取得し、取得できた業種のみ照会できる。
D13: 【特記事項】
E14: ・経理部は全ての業種を照会できる。
C16: ＜業種入力可能範囲＞
E17: ・入力者の所属組織コードに応じて選択可能な業種を組織・業種マスタから取得し、取得できた業種のみ入力できる。
D18: 【特記事項】
E19: ・経理部は全ての業種を入力できる。
C21: ＜共計組織 照会可能範囲＞
D22: 【入力者の所属が本所以外の場合】
E23: ・入力者の所属組織のみ照会できる。
E24: ・ただし入力者の所属組織が支所管理課の場合、支所内の担当業種を取り扱う組織も照会できる。
F25: ※支所管理課の情報は会計コードマスタ(事業所／管理組織)を元に取得する。
D26: 【入力者の所属が本所の場合】
E27: ・担当業種を取り扱う、すべての組織を照会できる。
D28: 【特記事項】
E29: ・経理部は全ての組織を照会できる。
C31: ＜共計組織 入力可能範囲＞
D32: 【入力者の所属が本所以外の場合】
E33: ・入力者の所属組織のみ入力できる。
E34: ・ただし入力者の所属組織が支所管理課の場合、支所内の担当業種を取り扱う組織も入力できる。
F35: ※支所管理課の情報は会計コードマスタ(事業所／管理組織)を元に取得する。
D36: 【入力者の所属が本所の場合】
E37: ・入力者の所属組織のみ入力できる。
D38: 【特記事項】
E39: ・経理部は全ての組織を入力できる。
