Workbook

Sheet 変更履歴
A1: Ｐｈａｓｅ 外部設計工程 | BJ1: HOKUREN INTERNAL USE ONLY
A2: 画面設計書 変更履歴 | AV2: 様式No. | AZ2: F4106-0 | BD2: PAGE
A3: システム名 | H3: 統合会計システム | AV3: 作成日 | AZ3: 2025/8/29
A4: 業務名 | H4: 共計 | AV4: 更新日
A6: 機能名称 | H6: 販売共計勘定振替作成 | AV6: メニューコード
A8: 管理番号 | I8: 案件名 / 障害・問合せ件名
B10: 24058 | I10: 基幹システム再構築 会計システム外部設計

Sheet 1.遷移図
A1: Ｐｈａｓｅ 外部設計局面 | CQ1: HOKUREN INTERNAL USE ONLY
A2: 画 面 遷 移 図 | BY2: 様式No. | CF2: F4106-1 | CJ2: PAGE
A3: システム名 | J3: 統合会計システム | BY3: 作成日 | CF3: 2025/8/29
A4: 業務名 | J4: =変更履歴!H4 -> 共計 | BY4: 更新日
A6: 機能Ｎｏ． | J6: 9.3.6 | U6: 機能名称 | AD6: =変更履歴!H6 -> 販売共計勘定振替作成 | BY6: メニューコード
B9: 【画面利用条件】 | K9: ※利用可能ユーザー、利用可能組織など利用制限の有無。 利用可能とする条件を記載。
D11: 利用組織 ： | L11: 経理部、現業部門
W21: 検索 | AB21: 選択 | AF21: 照会 | BN21: 承認ルート表示 | BX21: 登録、閉じる
AF22: クリア
AF23: 表示（コードの日本語名称表示）
AH24: 個別照会、削除、承認依頼取下
BI26: 次画面
AJ27: 登録、修正
AL30: 前画面 | BH30: 訂正
AE34: 申請、下書保存、キャンセル

Sheet 2.レイアウト（条件入力)
A1: Ｐｈａｓｅ 外部設計局面 | CG1: HOKUREN INTERNAL USE ONLY
A2: 画面レイアウト説明書 | BP2: 様式No. | BV2: F4106-2 | CA2: PAGE
A3: システム名 | L3: 統合会計システム | BP3: 作成日 | BV3: 2025/8/29
A4: 業務名 | L4: =変更履歴!H4 -> 共計 | BP4: 更新日
A7: 画面名 | L7: =変更履歴!H6 -> 販売共計勘定振替作成
B11: 【初期表示】
L12: 販売共計勘定振替作成 | BV12: 管理メニュー領域
D15: 条件入力
D16: 条件を入力し、販売共計勘定振替データを登録、照会、削除します。
D18: 検索条件
D19: 共計区分 | N19: ☑ 全道共計 □ 地区共計 □ 全国共計
D20: 業種
D21: 共計組織
D22: 収支管理品目 | BB22: 年産 | BP22: 共計次数
D23: 振替共計年度
D24: 更新者 | AQ24: 更新日 | BJ24: -
D25: 伝票番号
D26: 承認状況 | N26: ☑差戻 ☑下書保存 ☑依頼中 □承認済
L46: 販売共計勘定振替作成 | BV46: 管理メニュー領域
D49: 条件入力
D50: 条件を入力し、販売共計勘定振替データを登録、照会、削除します。
D52: 検索条件
D54: (1 of 1) << < 1 > >>
D55: ☑ | G55: 承認状況 | L55: 更新日 | S55: 経理日 | Z55: 更新者 | AK55: 業種 | AV55: 共計区分 | BB55: 事業所 | BQ55: 共計組織
D56: ☑ | G56: 下書保存 | L56: YYYY/MM/DD | S56: YYYY/MM/DD | Z56: ＸＸＸＸＸＸＸＸＸＸ | AK56: 10 雑穀 | AV56: 全道共計 | BB56: 90 本所 | BQ56: 4137 雑穀課
D57: ☑ | G57: 下書保存 | L57: YYYY/MM/DD | S57: YYYY/MM/DD | Z57: ＸＸＸＸＸＸＸＸＸＸ | AK57: 10 雑穀 | AV57: 全道共計 | BB57: 90 本所 | BQ57: 4137 雑穀課
D58: ☑ | G58: 下書保存 | L58: YYYY/MM/DD | S58: YYYY/MM/DD | Z58: ＸＸＸＸＸＸＸＸＸＸ | AK58: 10 雑穀 | AV58: 全道共計 | BB58: 90 本所 | BQ58: 4137 雑穀課
D59: ☑ | G59: 下書保存 | L59: YYYY/MM/DD | S59: YYYY/MM/DD | Z59: ＸＸＸＸＸＸＸＸＸＸ | AK59: 10 雑穀 | AV59: 全道共計 | BB59: 90 本所 | BQ59: 4137 雑穀課
D60: ☑ | G60: 下書保存 | L60: YYYY/MM/DD | S60: YYYY/MM/DD | Z60: ＸＸＸＸＸＸＸＸＸＸ | AK60: 10 雑穀 | AV60: 全道共計 | BB60: 90 本所 | BQ60: 4137 雑穀課
D61: ☑ | G61: 承認済 | L61: YYYY/MM/DD | S61: YYYY/MM/DD | Z61: ＸＸＸＸＸＸＸＸＸＸ | AK61: 10 雑穀 | AV61: 全道共計 | BB61: 90 本所 | BQ61: 4137 雑穀課
D62: □
D63: □
D64: □
D65: □
D66: □
D67: □
D68: □
D69: □
D70: □
D71: (1 of 1) << < 1 > >>
...

Sheet 3.項目説明(条件入力)
A1: Ｐｈａｓｅ 外部設計工程 | BJ1: HOKUREN INTERNAL USE ONLY
A2: 画面項目説明書 | AV2: 様式No. | AZ2: F4106-3D | BD2: PAGE
A3: システム名 | H3: 統合会計システム | AV3: 作成日 | AZ3: 45898
A4: 業務名 | H4: =変更履歴!H4 -> 共計 | AV4: 更新日
A6: 画面名 | H6: =変更履歴!H6 -> 販売共計勘定振替作成
A8: 検索結果表示領域一覧表示順
A9: No. | D9: 項目名（ソート項目順に列挙） | AT9: 表示順
A10: 1 | D10: 承認状況 | AT10: 差戻→下書保存→依頼中→承認済
A11: 2 | D11: 更新日 | AT11: 昇順
A12: 3 | D12: 経理日 | AT12: 昇順
A13: 4 | D13: 更新者 | AT13: 昇順
A14: 5 | D14: 伝票番号 | AT14: 昇順
A16: No. | D16: 項目名 | S16: I/O | V16: 桁数 | Z16: 属性 | AD16: 符号 | AG16: 初期値 | AJ16: 前回 | AM16: 項目編集説明
V17: 入力 | X17: 表示
A18: =ROW()-17 -> 1 | D18: 【検索条件エリア】 | V18: - | X18: -
A19: =ROW()-17 -> 2 | D19: 共計区分 | S19: I | V19: - | X19: - | Z19: ﾁｪｯｸﾎﾞｯｸｽ | AG19: ○ | AJ19: 〇 | AM19: 全道共計を初期選択
A20: =ROW()-17 -> 3 | D20: 業種 | S20: I | V20: 2 | X20: 2 | Z20: 文字 | AJ20: 〇 | AM20: ログインしたユーザーの担当する業種のみを対象として抽出する。
A21: =ROW()-17 -> 4 | D21: 業種名 | S21: O | V21: - | X21: 10 | Z21: 文字 （全角） | AJ21: 〇 | AM21: 業種に対する名称
A22: =ROW()-17 -> 5 | D22: 共計組織 | S22: I | V22: 4 | X22: 4 | Z22: 文字 | AJ22: 〇 | AM22: 共計組織コードを入力する
A23: =ROW()-17 -> 6 | D23: 共計組織名称 | S23: O | V23: - | X23: 15 | Z23: 文字 （全角） | AJ23: 〇 | AM23: 共計組織に対する名称を表示する
A24: =ROW()-17 -> 7 | D24: 収支管理品目 | S24: I | V24: 6 | X24: 6 | Z24: 文字 | AJ24: 〇 | AM24: 収支管理品目コードを入力する
A25: =ROW()-17 -> 8 | D25: 収支管理品目名 | S25: O | V25: - | X25: 15 | Z25: 文字 （全角） | AJ25: 〇 | AM25: 収支管理品目に対する名称を表示する
A26: =ROW()-17 -> 9 | D26: 年産 | S26: I | V26: 4 | X26: 4 | Z26: 数字 | AJ26: 〇 | AM26: 年産を入力する
A27: =ROW()-17 -> 10 | D27: 共計次数 | S27: I | V27: 2 | X27: 2 | Z27: 文字 | AJ27: 〇 | AM27: 共計次数を入力する
A28: =ROW()-17 -> 11 | D28: 振替共計年度 | S28: I | V28: 4 | X28: 4 | Z28: 数字 | AJ28: 〇 | AM28: 振替共計年度を入力する
A29: =ROW()-17 -> 12 | D29: 更新者 | S29: I/O | V29: 20 | X29: 20 | Z29: 文字 （全角） | AG29: 〇 | AJ29: 〇 | AM29: 初期値：ログイン者の名称
A30: =ROW()-17 -> 13 | D30: 更新年月日（From） | S30: I | V30: 8 | X30: 10 | Z30: 数字 | AJ30: 〇 | AM30: 更新年月日（From）を入力する
A31: =ROW()-17 -> 14 | D31: 更新年月日（To） | S31: I | V31: 8 | X31: 10 | Z31: 数字 | AJ31: 〇 | AM31: 更新年月日（To）を入力する
A32: =ROW()-17 -> 15 | D32: 伝票番号 | S32: I | V32: 12 | X32: 12 | Z32: 文字 | AM32: 伝票番号を入力する
A33: =ROW()-17 -> 16 | D33: 承認状況 | S33: I | V33: - | X33: - | Z33: ﾁｪｯｸﾎﾞｯｸｽ | AG33: ○ | AJ33: 〇 | AM33: 差戻、下書保存、依頼中を初期選択
A34: =ROW()-17 -> 17 | D34: 【明細表示エリア】 | V34: - | X34: -
A35: =ROW()-17 -> 18 | D35: 選択（明細） | S35: I | V35: - | X35: - | Z35: ﾁｪｯｸﾎﾞｯｸｽ | AG35: ○ | AM35: チェックボックス 初期値はチェックあり
A36: =ROW()-17 -> 19 | D36: 承認状況（明細） | S36: O | V36: - | X36: 5 | Z36: 文字 （全角） | AM36: 承認状況を表示する
A37: =ROW()-17 -> 20 | D37: 更新日（明細） | S37: O | V37: - | X37: 10 | Z37: 数字 | AM37: 共計勘定振替情報の更新日を表示する
A38: =ROW()-17 -> 21 | D38: 経理日（明細） | S38: O | V38: - | X38: 10 | Z38: 数字 | AM38: 共計勘定振替情報の経理日を表示する
A39: =ROW()-17 -> 22 | D39: 更新者（明細） | S39: O | V39: - | X39: 20 | Z39: 文字 （全角） | AM39: 共計勘定振替情報の更新者をキーに職員マスタから取得した職員氏名を表示する
A40: =ROW()-17 -> 23 | D40: 業種（明細） | S40: O | V40: - | X40: 13 | Z40: 文字 （全角） | AM40: 業種コード＋業種名称を表示する
A41: =ROW()-17 -> 24 | D41: 共計区分（明細） | S41: O | V41: - | X41: 4 | Z41: 文字 （全角） | AM41: 共計区分に対する名称を表示する
A42: =ROW()-17 -> 25 | D42: 事業所（明細） | S42: O | V42: - | X42: 18 | Z42: 文字 （全角） | AM42: 事業所コード＋事業所名称を表示する
A43: =ROW()-17 -> 26 | D43: 共計組織（明細） | S43: O | V43: - | X43: 20 | Z43: 文字 （全角） | AM43: 名称を表示する
...

Sheet 4.項目チェック（単体）_条件入力
A1: Ｐｈａｓｅ 外部設計工程 | BJ1: HOKUREN INTERNAL USE ONLY
A2: 画面項目チェック（単体） | AV2: 様式No. | AZ2: F4106-4 | BD2: PAGE
A3: システム名 | H3: 統合会計システム | AV3: 作成日 | AZ3: 45898
A4: 業務名 | H4: =変更履歴!H4 -> 共計 | AV4: 更新日
A6: 画面名 | H6: =変更履歴!H6 -> 販売共計勘定振替作成
A8: No. | D8: 項目名 | R8: 必須 ﾁｪｯｸ | U8: 数字 ﾁｪｯｸ | X8: 文字数 ﾁｪｯｸ | AA8: 存在 ﾁｪｯｸ | AD8: ｺｰﾄﾞﾁｪｯｸ | AG8: チェック補足説明／メッセージ文言 | BD8: メッセージ コード
A9: =ROW()-8 -> 1 | D9: 【検索条件エリア】
A10: =ROW()-8 -> 2 | D10: 業種 | AA10: ○ | AG10: ／業種はマスタに存在しません。
A11: =ROW()-8 -> 3 | D11: 共計組織 | AA11: ○ | AG11: ／共計組織はマスタに存在しません。
A12: =ROW()-8 -> 4 | D12: 収支管理品目 | AA12: ○ | AG12: ／収支管理品目はマスタに存在しません。
A13: =ROW()-8 -> 5 | D13: 年産 | X13: ○ | AG13: ４文字である事を確認する。 ／年産は４文字で入力してください。
A14: =ROW()-8 -> 6 | D14: 更新日（From） | U14: ○ | AG14: 実在日でない場合、エラーとする。 ／更新日は有効な日付を入力してください。
A15: =ROW()-8 -> 7 | D15: 更新日（To） | U15: ○ | AG15: 実在日でない場合、エラーとする。 ／更新日は有効な日付を入力してください。

Sheet 5.項目チェック（関連）_条件入力
A1: Ｐｈａｓｅ 外部設計局面 | BJ1: HOKUREN INTERNAL USE ONLY
A2: 画面項目チェック（関連） | AV2: 様式No. | AZ2: F4106-5 | BD2: PAGE
A3: システム名 | H3: 統合会計システム | AV3: 作成日 | AZ3: 45898
A4: 業務名 | H4: =変更履歴!H4 -> 共計 | AV4: 更新日
A6: 画面名 | H6: =変更履歴!H6 -> 販売共計勘定振替作成
A8: No. | D8: 関連チェック概要 | Q8: チェック詳細／メッセージ文言 | BD8: メッセージ コード
A9: =ROW()-8 -> 1 | D9: 検索条件と対象データの 存在チェック | Q9: 「照会」ボタン押下時、検索条件に合致するデータが存在しない場合はエラー ／条件に該当するデータはありません。
A10: =ROW()-8 -> 2 | D10: 業種と共計組織 | Q10: 画面に入力した業種と入力者の所属する組織の組み合わせが「6．画面機能補足説明 ＜業種照会可能範囲＞」で定める業種以外の場合エラー ／業種は共計組織に応じた業種を入力してください。
A11: =ROW()-8 -> 3 | D11: 入力組織と共計区分 | Q11: 入力者の所属する組織が支所 かつ 全道共計・全国共計を選択した場合エラー ／所属組織が支所の場合、全道共計・全国共計は選択できません。
A12: =ROW()-8 -> 4 | D12: 入力組織と共計区分 | Q12: 入力者の所属する組織が本所 かつ 地区共計を選択した場合エラー ／所属組織が本所の場合、地区共計は選択できません。
A13: =ROW()-8 -> 5 | D13: 更新日(From)と更新日(To)の検索範囲チェック | Q13: 更新日(From)、更新日(To)の両方を入力している且つ、 更新日(From)＞更新日(To)の場合はエラー ／更新日の検索範囲が不正です。
A14: =ROW()-8 -> 6 | D14: 修正ボタンと明細未選択チェック | Q14: 「修正」ボタン押下時、明細を選択していない場合エラー ／明細を選択してください。
A15: =ROW()-8 -> 7 | D15: 修正ボタンと複数明細選択チェック | Q15: 「修正」ボタン押下時、複数明細を選択している場合エラー ／明細は１件のみ選択してください。
A16: =ROW()-8 -> 8 | D16: 修正ボタンと承認状況（依頼中）のチェック | Q16: 「修正」ボタン押下時、承認状況が「依頼中」の明細を選択している場合エラー ／依頼中の為、対象データは操作できません。
A17: =ROW()-8 -> 9 | D17: 修正ボタン承認状況（承認済）のチェック | Q17: 「修正」ボタン押下時、承認状況が「承認済」の明細を選択している場合エラー ／承認済の為、対象データは操作できません。
A18: =ROW()-8 -> 10 | D18: 削除ボタンと明細未選択のチェック | Q18: 「削除」ボタン押下時、明細を選択していない場合エラー ／明細を選択してください。
A19: =ROW()-8 -> 11 | D19: 削除ボタンと承認状況（依頼中）のチェック | Q19: 「削除」ボタン押下時、承認状況が「依頼中」の明細を1件でも選択している場合エラー ／依頼中の為、対象データは操作できません。
A20: =ROW()-8 -> 12 | D20: 削除ボタンと複数明細選択のチェック | Q20: 「削除」ボタン押下時、複数明細を選択している場合エラー ／明細は１件のみ選択してください。
... A30: =ROW()-8 -> 22 | D30: 承認依頼取下ボタンと入力組織のチェック | Q30: 「承認依頼取下」ボタン押下時、共計組織が入力者の所属する組織以外となる明細を1件でも選択している場合エラー ／共計組織が担当の所属コード以外となる明細は選択できません。

Sheet 2.レイアウト（収支管理品目選択）
A1: Ｐｈａｓｅ 外部設計局面 | CG1: HOKUREN INTERNAL USE ONLY
A2: 画面レイアウト説明書 | BP2: 様式No. | BV2: F4106-2 | CA2: PAGE
A3: システム名 | L3: 統合会計システム | BP3: 作成日 | BV3: 2025/8/29
A4: 業務名 | L4: 共計 | BP4: 更新日
A7: 画面名 | L7: =変更履歴!H6 -> 販売共計勘定振替作成
L10: 販売共計勘定振替作成 | BV10: 管理メニュー領域
D13: 条件入力 > 収支管理品目選択
D14: 振替を行う収支管理品目を選択してください。
D16: 検索条件
D17: 共計区分 (*) | L17: ◎ 全道共計 〇 地区共計 〇 全国共計
D18: 業種 | W18: 雑穀
D19: 共計組織 (*) | W19: 雑穀課 | AQ19: 取引日 (*)
D20: 収支管理品目 | AQ20: 年産 (*) | BH20: 共計次数
D23: □ | G23: 収支管理品目 | BR23: 年産 | BW23: 共計次数
D24: ☑ | H24: 190609 大豆造外 | BR24: 2024 | BY24: 01 | CD24: ▲
D25: ☑ | H25: 190609 大豆造外 | BR25: 2024 | BY25: 02
D26: ☑ | H26: 190611 大豆副A | BR26: 2024 | BY26: 01
D27: ☑ | H27: 190611 大豆副A | BR27: 2024 | BY27: 01
D28: ☑ | H28: 190613 白目大豆素俵1等 | BR28: 2024 | BY28: 01
D29: ☑ | H29: 190614 白目大豆素俵2等 | BR29: 2024 | BY29: 01
D30: ☑ | H30: 191113 小豆 | BR30: 2024 | BY30: 01
D31: ☑ | H31: 191114 赤系金時 | BR31: 2024 | BY31: 01
D32: ☑ | H32: 191115 大手亡 | BR32: 2024 | BY32: 01 | CD32: ▼
B54: 【イベント処理説明】
B55: イベント名称 | Q55: イベント処理概要 | BM55: 備考
B56: 前画面 | Q56: 販売共計勘定振替作成 条件入力画面に遷移する。
B57: 次画面 | Q57: 入力した内容をチェックし、エラーの場合はエラーメッセージを表示。 エラーが無ければ、販売共計勘定振替作成 確認画面に遷移する。
B58: 照会 | Q58: 入力した内容をチェックし、エラーの場合はエラーメッセージを表示。 エラーが無ければ、入力した条件の検索結果を一覧表示する。
B59: クリア | Q59: 検索条件の入力領域を初期の状態に戻す。
B60: 表示 | Q60: 入力した内容をチェックし、エラーの場合はエラーメッセージを表示。 エラーが無ければ、業種、共計組織、収支管理品目に入力したコードの名称を表示する。
B62: 【画面制御説明】 | R62: ※画面の表示・非表示の制御、入力不可制御 などの条件を記載
B63: 項目名称 | Q63: 制御条件 | BM63: 備考
B64: カーソル（初期位置） | Q64: 業種コード入力欄とする
B65: 検索結果一覧 | Q65: 初期表示の場合は表示しないようにする。条件入力から修正で遷移した場合は、登録済の収支管理品目にチェックを入れた状態で表示する。

Sheet 3.項目説明(収支管理品目選択)
A1: Ｐｈａｓｅ 外部設計工程 | BJ1: HOKUREN INTERNAL USE ONLY
A2: 画面項目説明書 | AV2: 様式No. | AZ2: F4106-3D | BD2: PAGE
A3: システム名 | H3: 統合会計システム | AV3: 作成日 | AZ3: 45898
A4: 業務名 | H4: =変更履歴!H4 -> 共計 | AV4: 更新日
A6: 画面名 | H6: =変更履歴!H6 -> 販売共計勘定振替作成
A8: 検索結果表示領域一覧表示順
A9: No. | D9: 項目名（ソート項目順に列挙） | AT9: 表示順
A10: 1 | D10: 収支管理品目コード | AT10: 昇順
A11: 2 | D11: 年産 | AT11: 昇順
A12: 3 | D12: 共計次数 | AT12: 昇順
A14: No. | D14: 項目名 | S14: I/O | V14: 桁数 | Z14: 属性 | AD14: 符号 | AG14: 初期値 | AJ14: 前回 | AM14: 項目編集説明
V15: 入力 | X15: 表示
A16: =ROW()-15 -> 1 | D16: 共計区分 | S16: I | V16: - | X16: - | Z16: ﾗｼﾞｵﾎﾞﾀﾝ | AG16: 〇 | AM16: ラジオボタン 全道共計 地区共計 全国共計 初期値：全道共計
A17: =ROW()-15 -> 2 | D17: 業種 | S17: I | V17: 2 | X17: 2 | Z17: 文字 | AM17: ログインしたユーザーの担当する業種のみを対象として抽出する。
A18: =ROW()-15 -> 3 | D18: 業種名 | S18: O | V18: - | X18: 10 | Z18: 文字 （全角） | AM18: 業種に対する名称
A19: =ROW()-15 -> 4 | D19: 共計組織 | S19: I | V19: 4 | X19: 4 | Z19: 文字 | AM19: 共計組織コードを入力する
A20: =ROW()-15 -> 5 | D20: 共計組織名称 | S20: O | V20: - | X20: 15 | Z20: 文字 （全角） | AM20: 共計組織に対する名称
A21: =ROW()-15 -> 6 | D21: 収支管理品目 | S21: I | V21: 6 | X21: 6 | Z21: 文字 | AM21: 収支管理品目コードを入力する
A22: =ROW()-15 -> 7 | D22: 収支管理品目名 | S22: O | V22: - | X22: 15 | Z22: 文字 （全角） | AM22: 収支管理品目に対する名称
A23: =ROW()-15 -> 8 | D23: 取引日 | S23: I | V23: 8 | X23: 10 | Z23: 数字 | AG23: 〇 | AM23: 取引日を入力する。ＶＢ期間であれば前月末日、ＶＢ期間外であれば運用管理日（当日）を設定する。
A24: =ROW()-15 -> 9 | D24: 年産 | S24: I | V24: 4 | X24: 4 | Z24: 数字 | AM24: 年産を入力する
A25: =ROW()-15 -> 10 | D25: 共計次数 | S25: I | V25: 2 | X25: 2 | Z25: 文字 | AM25: 共計次数を入力する
A26: =ROW()-15 -> 11 | D26: 【明細表示エリア】 | V26: - | X26: -
A27: =ROW()-15 -> 12 | D27: 選択 | S27: I | V27: - | X27: - | Z27: ﾁｪｯｸﾎﾞｯｸｽ | AG27: 〇 | AM27: チェックボックス 初期値全行にチェックあり
A28: =ROW()-15 -> 13 | D28: 収支管理品目 | S28: O | V28: - | X28: 30 | Z28: 文字 （全角） | AM28: 収支管理品目コード＋収支管理品目コードに対する名称を表示する
A29: =ROW()-15 -> 14 | D29: 年産 | S29: O | V29: - | X29: 4 | Z29: 数字 | AM29: 年産を表示する
A30: =ROW()-15 -> 15 | D30: 共計次数 | S30: O | V30: - | X30: 2 | Z30: 文字 | AM30: 共計次数を表示する

Sheet 4.項目チェック（単体）_収支管理品目選択
A1: Ｐｈａｓｅ 外部設計工程 | BJ1: HOKUREN INTERNAL USE ONLY
A2: 画面項目チェック（単体） | AV2: 様式No. | AZ2: F4106-4 | BD2: PAGE
A3: システム名 | H3: 統合会計システム | AV3: 作成日 | AZ3: 45898
A4: 業務名 | H4: =変更履歴!H4 -> 共計 | AV4: 更新日
A6: 画面名 | H6: =変更履歴!H6 -> 販売共計勘定振替作成
A8: No. | D8: 項目名 | R8: 必須 ﾁｪｯｸ | U8: 数字 ﾁｪｯｸ | X8: 文字数 ﾁｪｯｸ | AA8: 存在 ﾁｪｯｸ | AD8: ｺｰﾄﾞﾁｪｯｸ | AG8: チェック補足説明／メッセージ文言 | BD8: メッセージ コード
A9: =ROW()-8 -> 1 | D9: 業種 | AA9: ○ | AG9: ／業種はマスタに存在しません。
A10: =ROW()-8 -> 2 | D10: 共計組織 | R10: ○ | AG10: ／共計組織を入力してください。
A11: =ROW()-8 -> 3 | AA11: ○ | AG11: ／共計組織はマスタに存在しません。
A12: =ROW()-8 -> 4 | D12: 収支管理品目 | AA12: ○ | AG12: ／収支管理品目はマスタに存在しません。
A13: =ROW()-8 -> 5 | D13: 取引日 | R13: ○ | AG13: ／取引日を入力してください。
A14: =ROW()-8 -> 6 | U14: ○ | AG14: 実在日でない場合、エラーとする。 ／取引日は有効な日付を入力してください。
A15: =ROW()-8 -> 7 | AD15: ○ | AG15: 取引日が未来日の場合、エラーとする。 ／取引日に未来日は入力できません。
A16: =ROW()-8 -> 8 | D16: 年産 | R16: ○ | AG16: ／年産を入力してください。
A17: =ROW()-8 -> 9 | X17: ○ | AG17: ４文字である事を確認する。 ／年産は４文字で入力してください。
A18: =ROW()-8 -> 10 | D18: 共計次数 | X18: ○ | AG18: ２文字である事を確認する。 ／共計次数は２文字で入力してください。

Sheet 5.項目チェック（関連)_収支管理品目選択
A1: Ｐｈａｓｅ 外部設計局面 | BJ1: HOKUREN INTERNAL USE ONLY
A2: 画面項目チェック（関連） | AV2: 様式No. | AZ2: F4106-5 | BD2: PAGE
A3: システム名 | H3: 統合会計システム | AV3: 作成日 | AZ3: 45898
A4: 業務名 | H4: =変更履歴!H4 -> 共計 | AV4: 更新日
A6: 画面名 | H6: =変更履歴!H6 -> 販売共計勘定振替作成
A8: No. | D8: 関連チェック概要 | Q8: チェック詳細／メッセージ文言 | BD8: メッセージ コード
A9: =ROW()-8 -> 1 | D9: 次画面ボタンと明細未選択チェック | Q9: 選択にチェックありの行が１行もないときエラー ／選択する収支管理品目を選択してください。
A10: =ROW()-8 -> 2 | D10: 入力組織と共計区分 | Q10: 入力者の所属する組織が支所 かつ 全道共計・全国共計を選択した場合エラー ／所属組織が支所の場合、全道共計・全国共計は選択できません。
A11: =ROW()-8 -> 3 | D11: 入力組織と共計区分 | Q11: 入力者の所属する組織が本所 かつ 地区共計を選択した場合エラー ／所属組織が本所の場合、地区共計は選択できません。
A12: =ROW()-8 -> 4 | D12: 業種と共計組織 | Q12: 「照会」「次画面」押下時、画面に入力した業種と入力者の所属する組織の組み合わせが「6．画面機能補足説明 ＜業種入力可能範囲＞」で定める業種以外の場合エラー ／業種は共計組織に応じた業種を入力してください。
A13: =ROW()-8 -> 5 | D13: 入力組織と共計組織 | Q13: 「照会」「次画面」押下時、入力した共計組織コードが「6．画面機能補足説明 ＜共計組織入力可能範囲＞」で定める共計組織以外の場合エラー ／共計組織は担当の所属コードを入力してください。
A14: =ROW()-8 -> 6 | D14: 検索条件と対象データの 存在チェック | Q14: 「照会」押下時、検索条件に合致するデータが存在しない場合はエラー ／条件に該当するデータはありません。
A15: =ROW()-8 -> 7 | D15: 取引日とVB期間の 組み合わせチェック | Q15: 「次画面」押下時、ＶＢ期間中に取引日が当月日付の場合、警告する。 ／取引日が入力月となっているため、入力月の経理となりますが、よろしいですか？ 前月経理とする場合は、取引日に前月末日以前を入力してください。

Sheet 2.レイアウト（作成)
A1: Ｐｈａｓｅ 外部設計局面 | CG1: HOKUREN INTERNAL USE ONLY
A2: 画面レイアウト説明書 | BP2: 様式No. | BV2: F4106-2 | CA2: PAGE
A3: システム名 | L3: 統合会計システム | BP3: 作成日 | BV3: 2025/8/29
A4: 業務名 | L4: =変更履歴!H4 -> 共計 | BP4: 更新日
A7: 画面名 | L7: =変更履歴!H6 -> 販売共計勘定振替作成
B12: 【登録・修正時】 | O12: ※振替情報明細非表示
L13: 販売共計勘定振替作成 | BV13: 管理メニュー領域
D16: 条件入力 > 収支管理品目選択 > 作成
D17: 内容を確認し、申請ボタンを押下してください。
D19: 基本情報
D20: 業種 | M20: 10 雑穀 | AQ20: 振替共計年度 | AZ20: 2024
D21: 事業所 | M21: 90 本所 | AQ21: 共計組織 | AZ21: 4137 雑穀課
D22: 経理日 | AQ22: 取引日 | AZ22: 2025/03/31
D23: 添付ファイル | M23: 0 | AQ23: 参照ＵＲＬ
D25: (1 of 1) << < 1 > >>
D26: No | F26: 収支管理品目 | V26: 共計区分 | AA26: 年産 | AE26: 共計 次数 | AH26: 共計受入金 | BF26: 共計支払金
AH27: 数量仮数 | AN27: 数量分子 | AT27: 金額 | BF27: 数量仮数 | BL27: 数量分子 | BR27: 金額
AD28: 総合計 | AH28: 633 | AN28: 30 | AT28: 33397390 | BF28: 53 | BR28: 1040478
D29: ◀ | CB29: ▶
D32: 伝票番号
D35: ◀ | M35: ▶
D37: 承認情報
D38: 更新情報 | Q38: 更新日時 | AD38: 所属 | BE38: 担当
D39: 更新者 | Q39: 2025/01/01 01:01:01 | AD39: 経理部 主計課 | BE39: 山田 花子
D40: 承認/差戻者 | Q40: 2025/01/01 01:01:01 | AD40: 経理部 主計課 | BE40: 田中 太郎
D41: 差戻コメント | Q41: ○○を△△に修正してください。
B48: 【登録・修正時】 | O48: ※振替情報明細表示
L49: 販売共計勘定振替作成 | BV49: 管理メニュー領域
D52: 条件入力 > 収支管理品目選択 > 作成
D53: 内容を確認し、申請ボタンを押下してください。
D55: 基本情報
D56: 業種 | M56: 10 雑穀 | AQ56: 振替共計年度 | AZ56: 2024
D57: 事業所 | M57: 90 本所 | AQ57: 共計組織 | AZ57: 4137 雑穀課
D58: 経理日 | AQ58: 取引日 | AZ58: 2025/03/31
D59: 添付ファイル | M59: 0 | AQ59: 参照ＵＲＬ
D61: (1 of 1) << < 1 > >>
D62: No | F62: 収支管理品目 | V62: 共計区分 | AA62: 年産 | AE62: 共計 次数 | AH62: 共計受入金 | BF62: 共計支払金
AH63: 数量仮数 | AN63: 数量分子 | AT63: 金額 | BF63: 数量仮数 | BL63: 数量分子 | BR63: 金額
D64: 1 | F64: 190609 大豆造外 | V64: 全道共計 | AA64: 2024 | AE64: 01 | AT64: 1000 | BF64: 17 | BR64: 1000
D65: 2 | F65: 190611 大豆副A | V65: 全道共計 | AA65: 2024 | AE65: 01 | AT65: 2000 | BR65: 2000
...

Sheet 3.項目説明(作成）
A1: Ｐｈａｓｅ 外部設計工程 | BJ1: HOKUREN INTERNAL USE ONLY
A2: 画面項目説明書 | AV2: 様式No. | AZ2: F4106-3D | BD2: PAGE
A3: システム名 | H3: 統合会計システム | AV3: 作成日 | AZ3: 45898
A4: 業務名 | H4: =変更履歴!H4 -> 共計 | AV4: 更新日
A6: 画面名 | H6: =変更履歴!H6 -> 販売共計勘定振替作成
A8: 検索結果表示領域一覧表示順
A9: No. | D9: 項目名（ソート項目順に列挙） | AT9: 表示順
A10: 1 | D10: 承認状況（差戻→下書保存→依頼中→承認済） | AT10: 昇順
A11: 2 | D11: 更新日 | AT11: 昇順
A12: 3 | D12: 経理日 | AT12: 昇順
A13: 4 | D13: 更新者 | AT13: 昇順
A14: 5 | D14: 伝票番号 | AT14: 昇順
A16: No. | D16: 項目名 | S16: I/O | V16: 桁数 | Z16: 属性 | AD16: 符号 | AG16: 初期値 | AJ16: 前回 | AM16: 項目編集説明
V17: 入力 | X17: 表示
A18: =ROW()-17 -> 1 | D18: 業種 | S18: O | V18: - | X18: 13 | Z18: 文字 （全角） | AM18: 業種コード＋業種コードに対する名称を表示する
A19: =ROW()-17 -> 2 | D19: 振替共計年度 | S19: O | V19: - | X19: 4 | Z19: 数字 | AM19: 振替共計年度を表示する
A20: =ROW()-17 -> 3 | D20: 事業所 | S20: O | V20: - | X20: 18 | Z20: 文字 （全角） | AM20: 事業所コード＋事業所コードに対する名称を表示する
A21: =ROW()-17 -> 4 | D21: 共計組織 | S21: O | V21: - | X21: 20 | Z21: 文字 （全角） | AM21: 共計組織コード＋共計組織コードに対する名称を表示する
A22: =ROW()-17 -> 5 | D22: 経理日 | S22: 0 | V22: - | X22: 10 | Z22: 数字 | AM22: 承認状況が承認済の場合、経理日を表示する。承認状況が承認済以外の場合、空白表示とする フォーマットはYYYY/MM/DDとする
A23: =ROW()-17 -> 6 | D23: 取引日 | S23: O | V23: - | X23: 10 | Z23: 数字 | AM23: 取引日を表示する。
A24: =ROW()-17 -> 7 | D24: 添付ファイル数 | S24: 0 | V24: - | X24: 2 | Z24: 数字 | AM24: 添付ファイルの数を表示する
A25: =ROW()-17 -> 8 | D25: 参照URL | S25: I/O | V25: - | X25: 200 | Z25: 文字 | AM25: 参照先のURLを表示する
A26: =ROW()-17 -> 9 | D26: 【明細表示エリア】 | V26: - | X26: - | AM26: 初期状態は折り畳み表示とする
A27: =ROW()-17 -> 10 | D27: No | S27: O | V27: - | X27: 2 | Z27: 数字 | AM27: 行番号を表示する
A28: =ROW()-17 -> 11 | D28: 収支管理品目（明細） | S28: O | V28: - | X28: 25 | Z28: 文字 （全角） | AM28: 繰越対象となる収支管理品目コード＋収支管理品目コードに対する名称を表示する
A29: =ROW()-17 -> 12 | D29: 共計区分（明細） | S29: O | V29: - | X29: 4 | Z29: 文字 （全角） | AM29: 共計区分に対する名称を表示する
A30: =ROW()-17 -> 13 | D30: 年産（明細） | S30: O | V30: - | X30: 4 | Z30: 数字 | AM30: 年産を表示する
A31: =ROW()-17 -> 14 | D31: 共計次数（明細） | S31: O | V31: - | X31: 2 | Z31: 数字 | AM31: 次数を表示する
A32: =ROW()-17 -> 15 | D32: 共計受入金 数量仮数（明細） | S32: O | V32: - | X32: 18 | Z32: 数字 | AD32: ○ | AM32: 繰越元の数量仮数を表示する
A33: =ROW()-17 -> 16 | D33: 共計受入金 数量分子（明細） | S33: O | V33: - | X33: 18,3 | Z33: 数字 | AD33: ○ | AM33: 繰越元の数量分子を表示する
A34: =ROW()-17 -> 17 | D34: 共計受入金 金額（明細） | S34: O | V34: - | X34: 18 | Z34: 数字 | AD34: ○ | AM34: 繰越元の金額を表示する
A35: =ROW()-17 -> 18 | D35: 共計支払金 数量仮数（明細） | S35: O | V35: - | X35: 18 | Z35: 数字 | AD35: ○ | AM35: 繰越先の数量仮数を表示する
A36: =ROW()-17 -> 19 | D36: 共計支払金 数量分子（明細） | S36: O | V36: - | X36: 18,3 | Z36: 数字 | AD36: ○ | AM36: 繰越先の数量分子を表示する
A37: =ROW()-17 -> 20 | D37: 共計支払金 金額（明細） | S37: O | V37: - | X37: 18 | Z37: 数字 | AD37: ○ | AM37: 繰越先の金額を表示する
A38: =ROW()-17 -> 21 | D38: 伝票番号 | S38: O | V38: - | X38: 12 | Z38: 文字 | AM38: 伝票番号を表示する
A39: =ROW()-17 -> 22 | D39: 【総合計表示エリア】 | V39: - | X39: - | AM39: 常に表示状態とする
A40: =ROW()-17 -> 23 | D40: 繰越数量仮数（総合計） | S40: O | V40: - | X40: 18 | Z40: 数字 | AD40: ○ | AM40: 明細の共計受入金 数量仮数の合計値を表示する
A41: =ROW()-17 -> 24 | D41: 繰越数量分子（総合計） | S41: O | V41: - | X41: 18,3 | Z41: 数字 | AD41: ○ | AM41: 明細の共計受入金 数量分子の合計値を表示する
A42: =ROW()-17 -> 25 | D42: 換算数量分母（総合計） | S42: O | V42: - | X42: 18 | Z42: 数字 | AD42: ○ | AM42: 明細の共計受入金 金額の合計値を表示する
A43: =ROW()-17 -> 26 | D43: 繰越品代（総合計） | S43: O | V43: - | X43: 18 | Z43: 数字 | AD43: ○ | AM43: 明細の共計支払金 数量仮数の合計値を表示する
...

Sheet 4.項目チェック（単体）_作成
A1: Ｐｈａｓｅ 外部設計工程 | BJ1: HOKUREN INTERNAL USE ONLY
A2: 画面項目チェック（単体） | AV2: 様式No. | AZ2: F4106-4 | BD2: PAGE
A3: システム名 | H3: 統合会計システム | AV3: 作成日 | AZ3: 45898
A4: 業務名 | H4: =変更履歴!H4 -> 共計 | AV4: 更新日
A6: 画面名 | H6: =変更履歴!H6 -> 販売共計勘定振替作成
A8: No. | D8: 項目名 | R8: 必須 ﾁｪｯｸ | U8: 数字 ﾁｪｯｸ | X8: 文字数 ﾁｪｯｸ | AA8: 存在 ﾁｪｯｸ | AD8: ｺｰﾄﾞﾁｪｯｸ | AG8: チェック補足説明／メッセージ文言 | BD8: メッセージ コード
AG9: チェックなし

Sheet 5.項目チェック（関連）_作成
A1: Ｐｈａｓｅ 外部設計局面 | BJ1: HOKUREN INTERNAL USE ONLY
A2: 画面項目チェック（関連） | AV2: 様式No. | AZ2: F4106-5 | BD2: PAGE
A3: システム名 | H3: 統合会計システム | AV3: 作成日 | AZ3: 45898
A4: 業務名 | H4: =変更履歴!H4 -> 共計 | AV4: 更新日
A6: 画面名 | H6: =変更履歴!H6 -> 販売共計勘定振替作成
A8: No. | D8: 関連チェック概要 | Q8: チェック詳細／メッセージ文言 | BD8: メッセージ コード
A9: 1 | D9: 申請ボタン押下時 | Q9: 共計支払金と共計受入金の金額が同額ではない場合エラー ／共計支払金の合計と共計受入金の合計が同額となっていません。

Sheet 6．画面機能補足説明
A1: Ｐｈａｓｅ 外部設計工程 | BJ1: HOKUREN INTERNAL USE ONLY
A2: 画面機能補足説明 | AV2: 様式No. | AZ2: F4106-6 | BD2: PAGE
A3: システム名 | H3: 統合会計システム | AV3: 作成日 | AZ3: 45898
A4: 業務名 | H4: =変更履歴!H4 -> 共計 | AV4: 更新日
A6: 機能Ｎｏ． | H6: 9.3.7 | O6: 機能名称 | V6: =変更履歴!H6 -> 販売共計勘定振替作成
B8: 【画面機能補足説明】
C10: １．照会・入力可能範囲
C11: ＜業種照会可能範囲＞
E12: ・入力者の所属組織コードに応じて選択可能な業種を組織・業種マスタから取得し、取得できた業種のみ照会できる。
D13: 【特記事項】
E14: ・経理部は全ての業種を照会できる。
C16: ＜業種入力可能範囲＞
E17: ・入力者の所属組織コードに応じて選択可能な業種を組織・業種マスタから取得し、取得できた業種のみ入力できる。
D18: 【特記事項】
E19: ・経理部は全ての業種を入力できる。
C21: ＜共計組織 照会可能範囲＞
D22: 【入力者の所属が本所以外の場合】
E23: ・入力者の所属組織のみ照会できる。
E24: ・ただし入力者の所属組織が支所管理課の場合、支所内の担当業種を取り扱う組織も照会できる。
F25: ※支所管理課の情報は会計コードマスタ(事業所／管理組織)を元に取得する。
D26: 【入力者の所属が本所の場合】
E27: ・担当業種を取り扱う、すべての組織を照会できる。
D28: 【特記事項】
E29: ・経理部は全ての組織を照会できる。
C31: ＜共計組織 入力可能範囲＞
D32: 【入力者の所属が本所以外の場合】
E33: ・入力者の所属組織のみ入力できる。
E34: ・ただし入力者の所属組織が支所管理課の場合、支所内の担当業種を取り扱う組織も入力できる。
F35: ※支所管理課の情報は会計コードマスタ(事業所／管理組織)を元に取得する。
D36: 【入力者の所属が本所の場合】
E37: ・入力者の所属組織のみ入力できる。
D38: 【特記事項】
E39: ・経理部は全ての組織を入力できる。
