Workbook

Sheet 変更履歴
A1: Ｐｈａｓｅ 外部設計工程 | BJ1: HOKUREN INTERNAL USE ONLY
A2: 画面設計書 変更履歴 | AV2: 様式No. | AZ2: F4106-0 | BD2: PAGE
A3: システム名 | H3: 統合会計システム | AV3: 作成日 | AZ3: 2025/8/29
A4: 業務名 | H4: 共計 | AV4: 更新日
A6: 機能名称 | H6: 購買共計勘定振替作成 | AV6: メニューコード
A8: 管理番号 | I8: 案件名 / 障害・問合せ件名
B10: 24058 | I10: 基幹システム再構築 会計システム外部設計

Sheet 1.遷移図
A1: Ｐｈａｓｅ 外部設計局面 | CQ1: HOKUREN INTERNAL USE ONLY
A2: 画 面 遷 移 図 | BY2: 様式No. | CF2: F4106-1 | CJ2: PAGE
A3: システム名 | J3: 統合会計システム | BY3: 作成日 | CF3: 2025/8/29
A4: 業務名 | J4: =変更履歴!H4 -> 共計 | BY4: 更新日
A6: 機能Ｎｏ． | J6: 9.3.5 | U6: 機能名称 | AD6: =変更履歴!H6 -> 購買共計勘定振替作成 | BY6: メニューコード
B9: 【画面利用条件】 | K9: ※利用可能ユーザー、利用可能組織など利用制限の有無。 利用可能とする条件を記載。
D11: 利用組織 ： | L11: 経理部、現業部門
AG20: 照会
U21: 検索 | AB21: 選択 | AG21: クリア | BM21: 承認ルート表示 | BY21: 登録、閉じる
AG22: 表示（コードの日本語名称表示）
AH24: 個別照会、削除、承認依頼取下
AJ27: 登録、修正 | BH27: 確認画面
AJ30: キャンセル、下書保存 | BH30: 訂正
AE34: 申請、キャンセル

Sheet 2.レイアウト（条件入力)
A1: Ｐｈａｓｅ 外部設計局面 | CG1: HOKUREN INTERNAL USE ONLY
A2: 画面レイアウト説明書 | BP2: 様式No. | BV2: F4106-2 | CA2: PAGE
A3: システム名 | L3: 統合会計システム | BP3: 作成日 | BV3: 2025/8/29
A4: 業務名 | L4: =変更履歴!H4 -> 共計 | BP4: 更新日
A7: 画面名 | L7: =変更履歴!H6 -> 購買共計勘定振替作成
B10: 【初期表示】
L11: 購買共計勘定振替作成 | BV11: 管理メニュー領域
D14: 条件入力
D15: 条件を入力し、販売共計勘定振替データを登録、照会、削除します。
D18: 検索条件
D19: 業種
D20: 振替共計年度
D21: 更新者 | AQ21: 更新日 | BJ21: -
D22: 承認状況 | N22: ☑差戻 ☑下書保存 ☑依頼中 □承認済
L42: 購買共計勘定振替作成 | BV42: 管理メニュー領域
D45: 条件入力
D46: 条件を入力し、販売共計勘定振替データを登録、照会、削除します。
D48: 検索条件
D50: (1 of 1) << < 1 > >>
D51: ☑ | G51: 承認状況 | L51: 更新日 | S51: 経理日 | Z51: 更新者 | AK51: 業種 | AV51: 事業所 | BK51: 共計組織 | BX51: 振替共計年度
D52: ☑ | G52: 下書保存 | L52: YYYY/MM/DD | S52: YYYY/MM/DD | Z52: ＸＸＸＸＸＸＸＸＸＸ | AK52: 52 農薬 | AV52: 90 本所 | BK52: 4137 農薬課 | BX52: 2024
D53: □
D54: □
D55: □
D56: □
D57: □
D58: □
D59: □
D60: □
D61: □
D62: □
D63: □
D64: □
... D67: (1 of 1) << < 1 > >>
D68: ◀ | CD68: ▶
B76: 【イベント処理説明】
B77: イベント名称 | Q77: イベント処理概要 | BN77: 備考
B78: 【検索条件入力領域】
B79: 検索（業種） | Q79: 業種検索子画面をポップアップ表示する
B80: 検索（更新者） | Q80: 職員検索子画面をポップアップ表示する
...

Sheet 3.項目説明(条件入力)
A1: Ｐｈａｓｅ 外部設計工程 | BJ1: HOKUREN INTERNAL USE ONLY
A2: 画面項目説明書 | AV2: 様式No. | AZ2: F4106-3D | BD2: PAGE
A3: システム名 | H3: 統合会計システム | AV3: 作成日 | AZ3: 45898
A4: 業務名 | H4: =変更履歴!H4 -> 共計 | AV4: 更新日
A6: 画面名 | H6: =変更履歴!H6 -> 購買共計勘定振替作成
A8: 検索結果表示領域一覧表示順
A9: No. | D9: 項目名（ソート項目順に列挙） | AT9: 表示順
A10: 1 | D10: 承認状況 | AT10: 差戻→下書保存→依頼中→承認済
A11: 2 | D11: 更新日 | AT11: 昇順
A12: 3 | D12: 経理日 | AT12: 昇順
A13: 4 | D13: 更新者 | AT13: 昇順
A14: 5
A16: No. | D16: 項目名 | S16: I/O | V16: 桁数 | Z16: 属性 | AD16: 符号 | AG16: 初期値 | AJ16: 前回 | AM16: 項目編集説明
V17: 入力 | X17: 表示
A18: =ROW()-17 -> 1 | D18: 【検索条件エリア】 | V18: - | X18: -
A19: =ROW()-17 -> 2 | D19: 業種 | S19: I | V19: 2 | X19: 2 | Z19: 文字 | AJ19: 〇 | AM19: ログインしたユーザーの担当する業種のみを対象として抽出する。
A20: =ROW()-17 -> 3 | D20: 業種名 | S20: O | V20: - | X20: 10 | Z20: 文字 （全角） | AJ20: 〇 | AM20: 業種に対する名称
A21: =ROW()-17 -> 4 | D21: 振替共計年度 | S21: I | V21: 4 | X21: 4 | Z21: 数字 | AJ21: 〇
A22: =ROW()-17 -> 5 | D22: 更新者 | S22: I/O | V22: 20 | X22: 20 | Z22: 文字 （全角） | AG22: 〇 | AJ22: 〇 | AM22: 初期値：ログイン者の名称
A23: =ROW()-17 -> 6 | D23: 更新日（From） | S23: I | V23: 8 | X23: 10 | Z23: 数字 | AJ23: 〇
A24: =ROW()-17 -> 7 | D24: 更新日（To） | S24: I | V24: 8 | X24: 10 | Z24: 数字 | AJ24: 〇
A25: =ROW()-17 -> 8 | D25: 承認状況 | S25: I | V25: - | X25: - | Z25: ﾁｪｯｸﾎﾞｯｸｽ | AG25: ○ | AJ25: 〇 | AM25: 差戻、下書保存、依頼中を初期選択
A26: =ROW()-17 -> 9 | D26: 【明細表示エリア】 | V26: - | X26: -
A27: =ROW()-17 -> 10 | D27: 選択（明細） | S27: I | V27: - | X27: - | Z27: ﾁｪｯｸﾎﾞｯｸｽ | AG27: ○ | AM27: チェックボックス 初期値はチェックなし
A28: =ROW()-17 -> 11 | D28: 承認状況（明細） | S28: O | V28: - | X28: 5 | Z28: 文字 （全角）
A29: =ROW()-17 -> 12 | D29: 更新日（明細） | S29: O | V29: - | X29: 10 | Z29: 数字 | AM29: 共計勘定振替情報の更新日を表示する
A30: =ROW()-17 -> 13 | D30: 経理日（明細） | S30: O | V30: - | X30: 10 | Z30: 数字 | AM30: 承認状況が承認済の場合、経理日を表示する。承認状況が承認済以外の場合、空白表示とする フォーマットはYYYY/MM/DDとする
A31: =ROW()-17 -> 14 | D31: 更新者（明細） | S31: O | V31: - | X31: 20 | Z31: 文字 （全角） | AM31: 共計勘定振替情報の更新者をキーに職員マスタから取得した職員氏名を表示する
A32: =ROW()-17 -> 15 | D32: 業種（明細） | S32: O | V32: - | X32: 13 | Z32: 文字 （全角） | AM32: 業種コード＋業種名
A33: =ROW()-17 -> 16 | D33: 事業所（明細） | S33: O | V33: - | X33: 20 | Z33: 文字 （全角） | AM33: 事業所コード＋事業所名
A34: =ROW()-17 -> 17 | D34: 共計組織（明細） | S34: O | V34: - | X34: 20 | Z34: 文字 （全角） | AM34: 共計組織コード ＋ 共計組織名
A35: =ROW()-17 -> 18 | D35: 振替共計年度（明細） | S35: O | V35: - | X35: 4 | Z35: 数字

Sheet 4.項目チェック（単体）_条件入力
A1: Ｐｈａｓｅ 外部設計工程 | BJ1: HOKUREN INTERNAL USE ONLY
A2: 画面項目チェック（単体） | AV2: 様式No. | AZ2: F4106-4 | BD2: PAGE
A3: システム名 | H3: 統合会計システム | AV3: 作成日 | AZ3: 45898
A4: 業務名 | H4: =変更履歴!H4 -> 共計 | AV4: 更新日
A6: 画面名 | H6: =変更履歴!H6 -> 購買共計勘定振替作成
A8: No. | D8: 項目名 | R8: 必須 ﾁｪｯｸ | U8: 数字 ﾁｪｯｸ | X8: 文字数 ﾁｪｯｸ | AA8: 存在 ﾁｪｯｸ | AD8: ｺｰﾄﾞﾁｪｯｸ | AG8: チェック補足説明／メッセージ文言 | BD8: メッセージ コード
A9: =ROW()-8 -> 1 | D9: 【検索条件エリア】
A10: =ROW()-8 -> 2 | D10: 業種 | AA10: ○ | AG10: ／業種はマスタに存在しません。
A11: =ROW()-8 -> 3 | D11: 振替共計年度 | R11: ○ | AG11: ／振替共計年度を入力してください。
A12: =ROW()-8 -> 4 | X12: ○ | AG12: ４文字である事を確認する。 ／振替共計年度は４文字で入力してください。
A13: =ROW()-8 -> 5 | D13: 更新日（From） | U13: ○ | AG13: 実在日でない場合、エラーとする。 ／更新日は有効な日付を入力してください。
A14: =ROW()-8 -> 6 | D14: 更新日（To） | U14: ○ | AG14: 実在日でない場合、エラーとする。 ／更新日は有効な日付を入力してください。

Sheet 5.項目チェック（関連）_条件入力
A1: Ｐｈａｓｅ 外部設計局面 | BJ1: HOKUREN INTERNAL USE ONLY
A2: 画面項目チェック（関連） | AV2: 様式No. | AZ2: F4106-5 | BD2: PAGE
A3: システム名 | H3: 統合会計システム | AV3: 作成日 | AZ3: 45898
A4: 業務名 | H4: =変更履歴!H4 -> 共計 | AV4: 更新日
A6: 画面名 | H6: =変更履歴!H6 -> 購買共計勘定振替作成
A8: No. | D8: 関連チェック概要 | Q8: チェック詳細／メッセージ文言 | BD8: メッセージ コード
A9: =ROW()-8 -> 1 | D9: 更新日(From)と更新日(To)の検索範囲チェック | Q9: 更新日(From)、更新日(To)の両方を入力している且つ、 更新日(From)＞更新日(To)の場合はエラー ／更新日(From)は更新日(To)より過去の日付を入力してください。
A10: 2 | D10: 業種と共計組織 | Q10: 「照会」ボタン押下時、画面に入力した業種と入力者の所属する組織の組み合わせが「6．画面機能補足説明 ＜業種照会可能範囲＞」で定める業種以外の場合エラー ／業種は共計組織に応じた業種を入力してください。
A11: =ROW()-8 -> 3 | D11: 検索条件と対象データの 存在チェック | Q11: 「照会」ボタン押下時、検索条件に合致するデータが存在しない場合はエラー ／条件に該当するデータはありません。
A12: =ROW()-8 -> 4 | D12: 修正ボタンと明細未選択チェック | Q12: 「修正」ボタン押下時、明細を選択していない場合エラー ／明細を選択してください。
A13: =ROW()-8 -> 5 | D13: 修正ボタンと複数明細選択チェック | Q13: 「修正」ボタン押下時、複数明細を選択している場合エラー ／明細は１件のみ選択してください。
A14: =ROW()-8 -> 6 | D14: 修正ボタンと承認状況（依頼中）のチェック | Q14: 「修正」ボタン押下時、承認状況が「依頼中」の明細を選択している場合エラー ／依頼中の為、対象データは操作できません。
A15: =ROW()-8 -> 7 | D15: 修正ボタン承認状況（承認済）のチェック | Q15: 「修正」ボタン押下時、承認状況が「承認済」の明細を選択している場合エラー ／承認済の為、対象データは操作できません。
A16: =ROW()-8 -> 8 | D16: 削除ボタンと明細未選択のチェック | Q16: 「削除」ボタン押下時、明細を選択していない場合エラー ／明細を選択してください。
A17: =ROW()-8 -> 9 | D17: 削除ボタンと承認状況（依頼中）のチェック | Q17: 「削除」ボタン押下時、承認状況が「依頼中」の明細を1件でも選択している場合エラー ／依頼中の為、対象データは操作できません。
A18: =ROW()-8 -> 10 | D18: 削除ボタンと複数明細選択のチェック | Q18: 「削除」ボタン押下時、複数明細を選択している場合エラー ／明細は１件のみ選択してください。
A19: =ROW()-8 -> 11 | D19: 個別照会ボタンと明細未選択のチェック | Q19: 「個別照会」ボタン押下時、明細を選択していない場合エラー ／明細を選択してください。
A20: =ROW()-8 -> 12 | D20: 個別照会ボタンと複数明細選択のチェック | Q20: 「個別照会」ボタン押下時、複数明細を選択している場合エラー ／明細は１件のみ選択してください。
A21: =ROW()-8 -> 13 | D21: 承認依頼取下ボタンと明細未選択のチェック | Q21: 「承認依頼取下」ボタン押下時、明細を選択していない場合エラー ／明細を選択してください。
A22: =ROW()-8 -> 14 | D22: 承認依頼取下ボタンと承認状況（差戻）のチェック | Q22: 「承認依頼取下」ボタン押下時、承認状況が「差戻」の明細を1件でも選択している場合エラー ／差戻の明細がある為、対象データは操作できません。
... A27: =ROW()-8 -> 19 | D27: 承認依頼取下ボタンと入力組織のチェック | Q27: 「承認依頼取下」ボタン押下時、共計組織が入力者の所属する組織以外となる明細を1件でも選択している場合エラー ／共計組織が担当の所属コード以外となる明細は選択できません。

Sheet 2.レイアウト（作成)
A1: Ｐｈａｓｅ 外部設計局面 | CG1: HOKUREN INTERNAL USE ONLY
A2: 画面レイアウト説明書 | BP2: 様式No. | BV2: F4106-2 | CA2: PAGE
A3: システム名 | L3: 統合会計システム | BP3: 作成日 | BV3: 2025/8/29
A4: 業務名 | L4: =変更履歴!H4 -> 共計 | BP4: 更新日
A7: 画面名 | L7: =変更履歴!H6 -> 購買共計勘定振替作成
B10: 【登録時】 | M10: 初期状態
L11: 購買共計勘定振替作成 | BV11: 管理メニュー領域
D14: 条件入力 > 作成
D15: 共計勘定振替情報を確認します。
D17: 基本情報
D18: 経理日 | AP18: 事業所
D19: 添付ファイル | AP19: 参照ＵＲＬ
D20: 検索条件
D21: 振替共計年度 (*) | AP21: 取引日 (*)
D22: 共計組織 (*) | AP22: 業種 (*)
D26: No | F26: 収支管理品目 | V26: 年産 | Z26: 共計受入金 | AX26: 共計支払金 | BV26: 伝票番号
Z27: 数量仮数 | AF27: 数量分子 | AL27: 金額 | AX27: 数量仮数 | BD27: 数量分子 | BJ27: 金額
V28: 総合計
D30: 承認情報
D31: 更新情報 | Q31: 更新日時 | AD31: 所属 | BE31: 担当
B37: 【照会押下後・条件入力からの修正時】
L38: 購買共計勘定振替作成 | BV38: 管理メニュー領域
D41: 条件入力 > 作成
D42: 共計勘定振替情報を確認します。
D44: 基本情報
D45: 経理日 | AP45: 事業所
D46: 添付ファイル | N46: 0 | AP46: 参照ＵＲＬ
D47: 検索条件
D48: 振替共計年度 (*) | AP48: 取引日 (*)
D49: 共計組織 (*) | W49: 農薬課 | AP49: 業種 (*) | BI49: 農薬
D52: (1 of 1) << < 1 > >>
D53: No | F53: 収支管理品目 | V53: 年産 | Z53: 共計受入金 | AX53: 共計支払金 | BV53: 伝票番号
Z54: 数量仮数 | AF54: 数量分子 | AL54: 金額 | AX54: 数量仮数 | BD54: 数量分子 | BJ54: 金額
V55: 総合計 | Z55: 53 | AL55: 1782982 | AX55: 53 | BJ55: -103939476
D58: 承認情報
D59: 更新情報 | Q59: 更新日時 | AD59: 所属 | BE59: 担当
D60: 更新者 | Q60: 2025/01/01 01:01:01 | AD60: 経理部 主計課 | BE60: 山田 花子
D61: 承認/差戻者 | Q61: 2025/01/01 01:01:01 | AD61: 経理部 主計課 | BE61: 田中 太郎
D62: 差戻コメント | Q62: ○○を△△に修正してください。
B68: 【照会押下後・条件入力からの修正時】 | AB68: ※振替情報明細表示
...

Sheet 3.項目説明(作成）
A1: Ｐｈａｓｅ 外部設計工程 | BJ1: HOKUREN INTERNAL USE ONLY
A2: 画面項目説明書 | AV2: 様式No. | AZ2: F4106-3D | BD2: PAGE
A3: システム名 | H3: 統合会計システム | AV3: 作成日 | AZ3: 45898
A4: 業務名 | H4: =変更履歴!H4 -> 共計 | AV4: 更新日
A6: 画面名 | H6: =変更履歴!H6 -> 購買共計勘定振替作成
A8: 検索結果表示領域一覧表示順
A9: No. | D9: 項目名（ソート項目順に列挙） | AT9: 表示順
A10: 1 | D10: 承認状況（差戻→下書保存→依頼中→承認済） | AT10: 昇順
A11: 2 | D11: 更新日 | AT11: 昇順
A12: 3 | D12: 経理日 | AT12: 昇順
A13: 4 | D13: 更新者 | AT13: 昇順
A14: 5
A16: No. | D16: 項目名 | S16: I/O | V16: 桁数 | Z16: 属性 | AD16: 符号 | AG16: 初期値 | AJ16: 前回 | AM16: 項目編集説明
V17: 入力 | X17: 表示
A18: =ROW()-17 -> 1 | D18: 経理日 | S18: O | V18: - | X18: 10 | Z18: 数字 | AM18: 承認状況が承認済の場合、経理日を表示する。承認状況が承認済以外の場合、空白表示とする フォーマットはYYYY/MM/DDとする
A19: =ROW()-17 -> 2 | D19: 事業所 | S19: O | V19: - | X19: 2 | Z19: 文字 | AM19: 事業所コードを表示する
A20: =ROW()-17 -> 3 | D20: 事業所名 | S20: O | V20: - | X20: 15 | Z20: 文字 （全角） | AM20: 事業所に対する名称を表示する
A21: =ROW()-17 -> 4 | D21: 添付ファイル数 | S21: O | V21: - | X21: 2 | Z21: 数字 | AM21: 添付ファイルの数を表示する
A22: =ROW()-17 -> 5 | D22: 参照URL | S22: O | V22: - | X22: 200 | Z22: 文字 | AM22: 参照先のURLを表示する
A23: =ROW()-17 -> 6 | D23: 振替共計年度 | S23: I/O | V23: 4 | X23: 4 | Z23: 数字 | AM23: 振替元の共計年度
A24: =ROW()-17 -> 7 | D24: 取引日 | S24: I/O | V24: 8 | X24: 10 | Z24: 数字 | AG24: 〇 | AM24: 取引日を入力する。ＶＢ期間であれば前月末日、ＶＢ期間外であれば運用管理日（当日）を設定する。
A25: =ROW()-17 -> 8 | D25: 共計組織 | S25: I/O | V25: 4 | X25: 4 | Z25: 文字 | AM25: 共計組織コードを入力する。 ログインユーザの所属コードに応じて絞り込みを行う。
A26: =ROW()-17 -> 9 | D26: 共計組織名 | S26: O | V26: - | X26: 15 | Z26: 文字 （全角） | AM26: 共計組織に対する名称を表示する
A27: =ROW()-17 -> 10 | D27: 業種 | S27: I/O | V27: 2 | X27: 2 | Z27: 文字 | AM27: 業種コードを設定する 入力した共計組織コードに応じて、選択可能な業種を組織・業種マスタから絞り込みを行う。 ※共計組織コードを入力していない場合は絞り込みは行わない。
A28: =ROW()-17 -> 11 | D28: 業種名 | S28: O | V28: - | X28: 10 | Z28: 文字 （全角） | AM28: 業種に対する名称を表示する
A29: =ROW()-17 -> 12 | D29: 【明細表示エリア】 | V29: - | X29: - | AM29: 初期状態は折り畳み表示とする
A30: =ROW()-17 -> 13 | D30: No | S30: O | V30: - | X30: 2 | Z30: 数字 | AM30: 行番号
A31: =ROW()-17 -> 14 | D31: 収支管理品目（明細） | S31: O | V31: - | X31: 6 | Z31: 文字 （全角） | AM31: 繰越対象となる収支管理品目コード＋収支管理品目コードに対する名称を表示する
A32: =ROW()-17 -> 15 | D32: 年産（明細） | S32: O | V32: - | X32: 4 | Z32: 数字 | AM32: 年産を表示する
A33: =ROW()-17 -> 16 | D33: 共計受入金 数量仮数（明細） | S33: O | V33: - | X33: 18 | Z33: 数字 | AD33: ○ | AM33: 繰越元の数量仮数を表示する
A34: =ROW()-17 -> 17 | D34: 共計受入金 数量分子（明細） | S34: O | V34: - | X34: 18,3 | Z34: 数字 | AD34: ○ | AM34: 繰越元の数量分子を表示する
A35: =ROW()-17 -> 18 | D35: 共計受入金 金額（明細） | S35: O | V35: - | X35: 18 | Z35: 数字 | AD35: ○ | AM35: 繰越元の金額を表示する
A36: =ROW()-17 -> 19 | D36: 共計支払金 数量仮数（明細） | S36: O | V36: - | X36: 18 | Z36: 数字 | AD36: ○ | AM36: 繰越先の数量仮数を表示する
A37: =ROW()-17 -> 20 | D37: 共計支払金 数量分子（明細） | S37: O | V37: - | X37: 18,3 | Z37: 数字 | AD37: ○ | AM37: 繰越先の数量分子を表示する
A38: =ROW()-17 -> 21 | D38: 共計支払金 金額（明細） | S38: O | V38: - | X38: 18 | Z38: 数字 | AD38: ○ | AM38: 繰越先の金額を表示する
A39: =ROW()-17 -> 22 | D39: 伝票番号 | S39: O | V39: - | X39: 12 | Z39: 文字 | AD39: ○ | AM39: 伝票番号を表示する
A40: =ROW()-17 -> 23 | D40: 【総合計表示エリア】 | V40: - | X40: - | AM40: 常に表示状態とする
A41: =ROW()-17 -> 24 | D41: 数量仮数（総合計） | S41: O | V41: - | X41: 18 | Z41: 数字 | AD41: ○ | AM41: 明細の共計受入金 数量仮数の合計値を表示する
A42: =ROW()-17 -> 25 | D42: 数量分子（総合計） | S42: O | V42: - | X42: 18,3 | Z42: 数字 | AD42: ○ | AM42: 明細の共計受入金 数量分子の合計値を表示する
A43: =ROW()-17 -> 26 | D43: 金額（総合計） | S43: O | V43: - | X43: 18 | Z43: 数字 | AD43: ○ | AM43: 明細の共計受入金 金額の合計値を表示する
...

Sheet 4.項目チェック（単体）_作成
A1: Ｐｈａｓｅ 外部設計工程 | BJ1: HOKUREN INTERNAL USE ONLY
A2: 画面項目チェック（単体） | AV2: 様式No. | AZ2: F4106-4 | BD2: PAGE
A3: システム名 | H3: 統合会計システム | AV3: 作成日 | AZ3: 45898
A4: 業務名 | H4: =変更履歴!H4 -> 共計 | AV4: 更新日
A6: 画面名 | H6: =変更履歴!H6 -> 購買共計勘定振替作成
A8: No. | D8: 項目名 | R8: 必須 ﾁｪｯｸ | U8: 数字 ﾁｪｯｸ | X8: 文字数 ﾁｪｯｸ | AA8: 存在 ﾁｪｯｸ | AD8: ｺｰﾄﾞﾁｪｯｸ | AG8: チェック補足説明／メッセージ文言 | BD8: メッセージ コード
A9: =ROW()-8 -> 1 | D9: 業種 | R9: ○ | AG9: ／業種コードを入力してください。
A10: =ROW()-8 -> 2 | AA10: ○ | AG10: ／業種はマスタに存在しません。
A11: =ROW()-8 -> 3 | D11: 振替共計年度 | R11: ○ | AG11: ／振替共計年度を入力してください。
A12: =ROW()-8 -> 4 | X12: ○ | AG12: ４文字である事を確認する。 ／振替共計年度年度は４文字で入力してください。
A13: =ROW()-8 -> 5 | D13: 取引日 | AG13: ／取引日を入力してください。
A14: =ROW()-8 -> 6 | U14: ○ | AG14: 実在日でない場合、エラーとする。 ／取引日は有効な日付を入力してください。
A15: =ROW()-8 -> 7 | AD15: ○ | AG15: 取引日が未来日の場合、エラーとする。 ／取引日に未来日は入力できません。
A16: =ROW()-8 -> 8 | D16: 共計組織 | R16: ○ | AG16: ／共計組織を入力してください。
A17: =ROW()-8 -> 9 | AA17: ○ | AG17: ／共計組織はマスタに存在しません。

Sheet 5.項目チェック（関連）_作成
A1: Ｐｈａｓｅ 外部設計局面 | BJ1: HOKUREN INTERNAL USE ONLY
A2: 画面項目チェック（関連） | AV2: 様式No. | AZ2: F4106-5 | BD2: PAGE
A3: システム名 | H3: 統合会計システム | AV3: 作成日 | AZ3: 45898
A4: 業務名 | H4: =変更履歴!H4 -> 共計 | AV4: 更新日
A6: 画面名 | H6: =変更履歴!H6 -> 購買共計勘定振替作成
A8: No. | D8: 関連チェック概要 | Q8: チェック詳細／メッセージ文言 | BD8: メッセージ コード
A9: 1 | D9: 共計支払金と共計受入金 | Q9: 「申請」押下時、共計支払金と共計受入金の金額が同額ではない場合エラー ／共計支払金の合計と共計受入金の合計が同額となっていません。
A10: 2 | D10: 業種と共計組織 | Q10: 「照会」「申請」押下時、画面に入力した業種と入力者の所属する組織の組み合わせが「6．画面機能補足説明 ＜業種入力可能範囲＞」で定める業種以外の場合エラー ／業種は共計組織に応じた業種を入力してください。
A11: 3 | D11: 入力組織と共計組織 | Q11: 「照会」「申請」押下時、入力した共計組織コードが「6．画面機能補足説明 ＜共計組織入力可能範囲＞」で定める共計組織以外の場合エラー ／共計組織は担当の所属コードを入力してください。
A12: 4 | D12: 検索条件と対象データの 存在チェック | Q12: 「照会」ボタン押下時、検索条件に合致するデータが存在しない場合はエラー ／条件に該当するデータはありません。
A13: =ROW()-8 -> 5 | D13: 取引日とVB期間の 組み合わせチェック | Q13: 「申請」押下時、ＶＢ期間中に取引日が当月日付の場合、警告する。 ／取引日が入力月となっているため、入力月の経理となりますが、よろしいですか？ 前月経理とする場合は、取引日に前月末日以前を入力してください。

Sheet 2.レイアウト（確認)
A1: Ｐｈａｓｅ 外部設計局面 | CG1: HOKUREN INTERNAL USE ONLY
A2: 画面レイアウト説明書 | BP2: 様式No. | BV2: F4106-2 | CA2: PAGE
A3: システム名 | L3: 統合会計システム | BP3: 作成日 | BV3: 2025/8/29
A4: 業務名 | L4: =変更履歴!H4 -> 共計 | BP4: 更新日
A7: 画面名 | L7: =変更履歴!H6 -> 購買共計勘定振替作成
B10: 【登録・修正時】
L11: 購買共計勘定振替作成 | BV11: 管理メニュー領域
D14: 条件入力 > 作成 > 確認
D15: 内容を確認し、申請ボタンを押下してください。
D17: 基本情報
D18: 経理日 | AP18: 事業所 | AZ18: 90 本所
D19: 添付ファイル | M19: 0 | AP19: 参照ＵＲＬ | AZ19: hhhttp//aaa
D20: 振替共計年度 | M20: 2024 | AP20: 取引日 | AZ20: 2025/03/31
D21: 共計組織 | M21: 4173 農薬課 | AP21: 業種 | AZ21: 52 農薬
D23: (1 of 1) << < 1 > >>
D24: No | F24: 収支管理品目 | V24: 年産 | Z24: 共計受入金 | AX24: 共計支払金 | BV24: 伝票番号
Z25: 数量仮数 | AF25: 数量分子 | AL25: 金額 | AX25: 数量仮数 | BD25: 数量分子 | BJ25: 金額
V26: 総合計 | Z26: 53 | AL26: 1919862 | AX26: 53 | BJ26: -112,429,197
D29: 承認情報
D30: 更新情報 | Q30: 更新日時 | AD30: 所属 | BE30: 担当
D31: 更新者 | Q31: 2025/01/01 01:01:01 | AD31: 経理部 主計課 | BE31: 山田 花子
D32: 承認/差戻者 | Q32: 2025/01/01 01:01:01 | AD32: 経理部 主計課 | BE32: 田中 太郎
D33: 差戻コメント | Q33: ○○を△△に修正してください。
B39: 【削除時】
L40: 購買共計勘定振替作成 | BV40: 管理メニュー領域
D43: 条件入力 > 確認
D44: 内容を確認し、申請ボタンを押下してください。
D46: 基本情報 ～ 承認情報のイメージは「登録・修正」と変わらないためイメージ割愛
B54: 【個別照会時】
L55: 購買共計勘定振替作成 | BV55: 管理メニュー領域
D58: 条件入力 > 確認
D59: 内容を確認し、一覧表示画面に戻る場合は「キャンセル」ボタンを押して下さい。
D61: 基本情報 ～ 承認情報のイメージは「登録・修正」と変わらないためイメージ割愛
B68: 【承認依頼取下時】
L69: 購買共計勘定振替作成 | BV69: 管理メニュー領域
D72: 条件入力 > 確認
D73: 内容を確認し、承認依頼取下ボタンを押下してください。
D75: 基本情報 ～ 承認情報のイメージは「登録・修正」と変わらないためイメージ割愛
B82: 【イベント処理説明】
B83: イベント名称 | Q83: イベント処理概要 | BN83: 備考
...

Sheet 3.項目説明(確認）
A1: Ｐｈａｓｅ 外部設計工程 | BJ1: HOKUREN INTERNAL USE ONLY
A2: 画面項目説明書 | AV2: 様式No. | AZ2: F4106-3D | BD2: PAGE
A3: システム名 | H3: 統合会計システム | AV3: 作成日 | AZ3: 45898
A4: 業務名 | H4: =変更履歴!H4 -> 共計 | AV4: 更新日
A6: 画面名 | H6: =変更履歴!H6 -> 購買共計勘定振替作成
A8: 検索結果表示領域一覧表示順
A9: No. | D9: 項目名（ソート項目順に列挙） | AT9: 表示順
A10: 1 | D10: 承認状況（差戻→下書保存→依頼中→承認済） | AT10: 昇順
A11: 2 | D11: 更新日 | AT11: 昇順
A12: 3 | D12: 経理日 | AT12: 昇順
A13: 4 | D13: 更新者 | AT13: 昇順
A14: 5
A16: No. | D16: 項目名 | S16: I/O | V16: 桁数 | Z16: 属性 | AD16: 符号 | AG16: 初期値 | AJ16: 前回 | AM16: 項目編集説明
V17: 入力 | X17: 表示
A18: =ROW()-17 -> 1 | D18: 経理日 | S18: 0 | V18: - | X18: 10 | Z18: 数字 | AM18: 承認状況が承認済の場合、経理日を表示する。承認状況が承認済以外の場合、空白表示とする フォーマットはYYYY/MM/DDとする
A19: =ROW()-17 -> 2 | D19: 事業所 | S19: O | V19: - | X19: 2 | Z19: 文字 | AM19: 事業所コードを表示する
A20: =ROW()-17 -> 3 | D20: 事業所名 | S20: O | V20: - | X20: 15 | Z20: 文字 （全角） | AM20: 事業所に対する名称を表示する
A21: =ROW()-17 -> 4 | D21: 添付ファイル数 | S21: 0 | V21: - | X21: 2 | Z21: 数字 | AM21: 添付ファイルの数を表示する
A22: =ROW()-17 -> 5 | D22: 参照URL | S22: O | V22: - | X22: 200 | Z22: 文字 | AM22: 参照先のURLを表示する
A23: =ROW()-17 -> 6 | D23: 振替共計年度 | S23: O | V23: - | X23: 4 | Z23: 数字 | AM23: 振替共計年度を表示する
A24: =ROW()-17 -> 7 | D24: 取引日 | S24: O | V24: - | X24: 10 | Z24: 数字 | AG24: 〇 | AM24: 取引日を表示する。
A25: =ROW()-17 -> 8 | D25: 共計組織 | S25: O | V25: - | X25: 4 | Z25: 文字 | AM25: 共計組織コードを表示する
A26: =ROW()-17 -> 9 | D26: 共計組織名 | S26: O | V26: - | X26: 15 | Z26: 文字 （全角） | AM26: 共計組織に対する名称を表示する
A27: =ROW()-17 -> 10 | D27: 業種 | S27: O | V27: - | X27: 2 | Z27: 文字 | AM27: 業種コード＋業種コードに対する名称を表示する
A28: =ROW()-17 -> 11 | D28: 業種名 | S28: O | V28: - | X28: 10 | Z28: 文字 （全角） | AM28: 業種に対する名称を表示する
A29: =ROW()-17 -> 12 | D29: 【明細表示エリア】 | V29: - | X29: - | AM29: 初期状態は折り畳み表示とする
A30: =ROW()-17 -> 13 | D30: No | S30: O | V30: - | X30: 2 | Z30: 数字
A31: =ROW()-17 -> 14 | D31: 収支管理品目（明細） | S31: O | V31: - | X31: 6 | Z31: 文字 （全角） | AM31: 繰越対象となる収支管理品目コード＋収支管理品目コードに対する名称を表示する
A32: =ROW()-17 -> 15 | D32: 年産（明細） | S32: O | V32: - | X32: 4 | Z32: 数字 | AM32: 年産を表示する
A33: =ROW()-17 -> 16 | D33: 共計受入金 数量仮数（明細） | S33: O | V33: - | X33: 18 | Z33: 数字 | AD33: ○ | AM33: 繰越元の数量仮数を表示する
A34: =ROW()-17 -> 17 | D34: 共計受入金 数量分子（明細） | S34: O | V34: - | X34: 18,3 | Z34: 数字 | AD34: ○ | AM34: 繰越元の数量分子を表示する
A35: =ROW()-17 -> 18 | D35: 共計受入金 金額（明細） | S35: O | V35: - | X35: 18 | Z35: 数字 | AD35: ○ | AM35: 繰越元の金額を表示する
A36: =ROW()-17 -> 19 | D36: 共計支払金 数量仮数（明細） | S36: O | V36: - | X36: 18 | Z36: 数字 | AD36: ○ | AM36: 繰越先の数量仮数を表示する
A37: =ROW()-17 -> 20 | D37: 共計支払金 数量分子（明細） | S37: O | V37: - | X37: 18,3 | Z37: 数字 | AD37: ○ | AM37: 繰越先の数量分子を表示する
A38: =ROW()-17 -> 21 | D38: 共計支払金 金額（明細） | S38: O | V38: - | X38: 18 | Z38: 数字 | AD38: ○ | AM38: 繰越先の金額を表示する
A39: =ROW()-17 -> 22 | D39: 伝票番号 | S39: O | V39: - | X39: 12 | Z39: 文字 | AD39: ○ | AM39: 伝票番号を表示する
A40: =ROW()-17 -> 23 | D40: 【総合計表示エリア】 | V40: - | X40: - | AM40: 常に表示状態とする
A41: =ROW()-17 -> 24 | D41: 数量仮数（総合計） | S41: O | V41: - | X41: 18 | Z41: 数字 | AD41: ○ | AM41: 明細の共計受入金 数量仮数の合計値を表示する
A42: =ROW()-17 -> 25 | D42: 数量分子（総合計） | S42: O | V42: - | X42: 18,3 | Z42: 数字 | AD42: ○ | AM42: 明細の共計受入金 数量分子の合計値を表示する
A43: =ROW()-17 -> 26 | D43: 金額（総合計） | S43: O | V43: - | X43: 18 | Z43: 数字 | AD43: ○ | AM43: 明細の共計受入金 金額の合計値を表示する
...

Sheet 4.項目チェック（単体）_確認
A1: Ｐｈａｓｅ 外部設計工程 | BJ1: HOKUREN INTERNAL USE ONLY
A2: 画面項目チェック（単体） | AV2: 様式No. | AZ2: F4106-4 | BD2: PAGE
A3: システム名 | H3: 統合会計システム | AV3: 作成日 | AZ3: 45898
A4: 業務名 | H4: =変更履歴!H4 -> 共計 | AV4: 更新日
A6: 画面名 | H6: =変更履歴!H6 -> 購買共計勘定振替作成
A8: No. | D8: 項目名 | R8: 必須 ﾁｪｯｸ | U8: 数字 ﾁｪｯｸ | X8: 文字数 ﾁｪｯｸ | AA8: 存在 ﾁｪｯｸ | AD8: ｺｰﾄﾞﾁｪｯｸ | AG8: チェック補足説明／メッセージ文言 | BD8: メッセージ コード
AG9: チェックなし

Sheet 5.項目チェック（関連）_確認
A1: Ｐｈａｓｅ 外部設計局面 | BJ1: HOKUREN INTERNAL USE ONLY
A2: 画面項目チェック（関連） | AV2: 様式No. | AZ2: F4106-5 | BD2: PAGE
A3: システム名 | H3: 統合会計システム | AV3: 作成日 | AZ3: 45898
A4: 業務名 | H4: =変更履歴!H4 -> 共計 | AV4: 更新日
A6: 画面名 | H6: =変更履歴!H6 -> 購買共計勘定振替作成
A8: No. | D8: 関連チェック概要 | Q8: チェック詳細／メッセージ文言 | BD8: メッセージ コード
Q9: チェックなし

Sheet 6．画面機能補足説明
A1: Ｐｈａｓｅ 外部設計工程 | BJ1: HOKUREN INTERNAL USE ONLY
A2: 画面機能補足説明 | AV2: 様式No. | AZ2: F4106-6 | BD2: PAGE
A3: システム名 | H3: 統合会計システム | AV3: 作成日 | AZ3: 45898
A4: 業務名 | H4: =変更履歴!H4 -> 共計 | AV4: 更新日
A6: 機能Ｎｏ． | H6: 9.3.7 | O6: 機能名称 | V6: =変更履歴!H6 -> 購買共計勘定振替作成
B8: 【画面機能補足説明】
C10: １．照会・入力可能範囲
C11: ＜業種照会可能範囲＞
E12: ・入力者の所属組織コードに応じて選択可能な業種を組織・業種マスタから取得し、取得できた業種のみ照会できる。
D13: 【特記事項】
E14: ・経理部は全ての業種を照会できる。
C16: ＜業種入力可能範囲＞
E17: ・入力者の所属組織コードに応じて選択可能な業種を組織・業種マスタから取得し、取得できた業種のみ入力できる。
D18: 【特記事項】
E19: ・経理部は全ての業種を入力できる。
C21: ＜共計組織 照会可能範囲＞
D22: 【入力者の所属が本所以外の場合】
E23: ・入力者の所属組織のみ照会できる。
E24: ・ただし入力者の所属組織が支所管理課の場合、支所内の担当業種を取り扱う組織も照会できる。
F25: ※支所管理課の情報は会計コードマスタ(事業所／管理組織)を元に取得する。
D26: 【入力者の所属が本所の場合】
E27: ・担当業種を取り扱う、すべての組織を照会できる。
D28: 【特記事項】
E29: ・経理部は全ての組織を照会できる。
C31: ＜共計組織 入力可能範囲＞
D32: 【入力者の所属が本所以外の場合】
E33: ・入力者の所属組織のみ入力できる。
E34: ・ただし入力者の所属組織が支所管理課の場合、支所内の担当業種を取り扱う組織も入力できる。
F35: ※支所管理課の情報は会計コードマスタ(事業所／管理組織)を元に取得する。
D36: 【入力者の所属が本所の場合】
E37: ・入力者の所属組織のみ入力できる。
D38: 【特記事項】
E39: ・経理部は全ての組織を入力できる。
