Workbook

Sheet 変更履歴
A1: Ｐｈａｓｅ 外部設計工程 | BJ1: HOKUREN INTERNAL USE ONLY
A2: 画面DesignDoc_v3_v2 変更履歴 | AV2: 様式No. | AZ2: F4106-0 | BD2: PAGE
A3: システム名 | H3: 統合会計システム | AV3: 作成日 | AZ3: 2025/8/29
A4: 業務名 | H4: 棚卸資産管理 | AV4: 更新日
A6: 機能名称 | H6: 在庫品棚卸表登録 | AV6: メニューコード
A8: 管理番号 | I8: 案件名 / 障害・問合せ件名
B10: 24058 | I10: 基幹システム再構築 会計システム外部設計

Sheet 1.遷移図 
A1: Ｐｈａｓｅ 外部設計局面 | CQ1: HOKUREN INTERNAL USE ONLY
A2: 画 面 遷 移 図 | BY2: 様式No. | CF2: F4106-1 | CJ2: PAGE
A3: システム名 | J3: 統合会計システム | BY3: 作成日 | CF3: 2025/8/29
A4: 業務名 | J4: 棚卸資産管理 | BY4: 更新日
A6: 機能Ｎｏ． | J6: 7.4.5 | U6: 機能名称 | AD6: =変更履歴!H6 -> 在庫品棚卸表登録 | BY6: メニューコード
B9: 【画面利用条件】 | K9: ※利用可能ユーザー、利用可能組織など利用制限の有無。 利用可能とする条件を記載。
D11: 利用組織 ： | L11: 本所 | R11: ： | T11: 経理課、主計課、現業部門 | AH11: 岩見沢支所 | AN11: ： | AP11: 管理担当課、現業部門 | BB11: 北見支所 | BH11: ： | BJ11: 管理担当課、現業部門 | BW11: 東京支店 | CC11: ： | CE11: 管理担当課、現業部門
L12: 函館支所 | R12: ： | T12: 管理担当課、現業部門 | AH12: 留萌支所 | AN12: ： | AP12: 管理担当課、現業部門 | BB12: 釧路支所 | BH12: ： | BJ12: 管理担当課、現業部門 | BW12: 名古屋支店 | CC12: ： | CE12: 管理担当課、現業部門
L13: 倶知安支所 | R13: ： | T13: 管理担当課、現業部門 | AH13: 旭川支所 | AN13: ： | AP13: 管理担当課、現業部門 | BB13: 中標津支所 | BH13: ： | BJ13: 管理担当課、現業部門 | BW13: 大阪支店 | CC13: ： | CE13: 管理担当課、現業部門
L14: 苫小牧支所 | R14: ： | T14: 管理担当課、現業部門 | AH14: 稚内支所 | AN14: ： | AP14: 管理担当課、現業部門 | BB14: 道央支店 | BH14: ： | BJ14: 管理担当課、現業部門 | BW14: 福岡支店 | CC14: ： | CE14: 管理担当課、現業部門
L15: 札幌支所 | R15: ： | T15: 管理担当課、現業部門 | AH15: 帯広支所 | AN15: ： | AP15: 管理担当課、現業部門 | BB15: 仙台支店 | BH15: ： | BJ15: 管理担当課、現業部門 | BW15: 東京事務所 | CC15: ： | CE15: 管理担当課、現業部門
U18: ・事業所
U19: ・業種 | AZ19: 表示(数量更新)
U20: ・受払組織 | BY20: 保存
AP24: 修正 | AT24: 棚卸結果照会画面、キャンセル | BK24: 保存、 | BT24: 参照
AC25: 照会（一覧表示） | BK25: キャンセル
AC26: クリア
S27: 検索 | W27: 選択 | AC27: 表示（コードの日本語名称表示）
AC28: ※出力(ファイル) | AY28: 照会（一覧表示） | BW28: 承認ルート表示 | CI28: 登録、
AY29: クリア | CI29: 閉じる
M30: 業務選択 | AF30: 棚卸結果入力 | BD30: 次画面 | BU30: 確認画面
AE32: キャンセル、下書保存 | BD32: 前画面 | BU32: 訂正
AS34: 下書保存
AN37: 申請（修正）、キャンセル（個別照会、承認依頼取下）
AP40: 個別照会、承認依頼取下

Sheet 2.レイアウト（在庫品棚卸表照会）
A1: Ｐｈａｓｅ 外部設計局面 | CG1: HOKUREN INTERNAL USE ONLY
A2: 画面レイアウト説明書 | BP2: 様式No. | BV2: F4106-2 | CA2: PAGE
A3: システム名 | L3: 統合会計システム | BP3: 作成日 | BV3: 2025/8/29
A4: 業務名 | L4: =変更履歴!H4 -> 棚卸資産管理 | BP4: 更新日
A7: 画面名 | L7: 在庫品棚卸表照会
B9: 【初期表示】
L10: 在庫品棚卸表照会画面 | BV10: 管理メニュー領域
D13: 在庫品棚卸表照会 >
D14: 在庫品棚卸表の登録情報を一覧表示する場合は、検索条件を入力し「照会」ボタンを押してください。
D15: 在庫品棚卸表を出力する場合は、検索条件を入力し「出力」ボタンを押してください。
D17: 検索条件
D18: 実地棚卸年月(*) | P18: 2024/09
D19: 事業所
D20: 業種
D21: 受払組織
D22: 棚卸資産種類 | P22: □販売品 □購買品 □原材料 □仕掛品 □貯蔵品
D23: 棚卸種別 | Q23: ☑一斉棚卸 ☑循環棚卸
D24: 承認状況 | P24: ☑未作成 ☑差戻 □下書保存 □依頼中 □承認済
D25: 出力対象 | P25: ◎ 在庫品棚卸表（PDF） ○ 在庫品棚卸表（CSV）
B30: 【照会後】
L31: 在庫品棚卸表照会画面 | BV31: 管理メニュー領域
D34: 在庫品棚卸表照会 >
D35: 在庫品棚卸表情報を一覧表示する場合は、検索条件を入力し「照会」ボタンを押してください。
D36: 在庫品棚卸表を出力する場合は、検索条件を入力し「出力」ボタンを押してください。
D38: 検索条件
D40: (1 of 5) << < 1 2 3 4 5 > >>
D41: ☐ | G41: 実地棚卸年月 | O41: 承認状況 | V41: 事業所 | AJ41: 業種 | AX41: 受払組織 | BQ41: 棚卸資産種類
D42: ☐ | G42: 2024/09 | O42: 未作成 | V42: 90 本所 | AJ42: 05 米穀 | AX42: 5903 旭川卸米穀デポ | BQ42: 販売品
D43: ☐ | G43: 2024/09 | O43: 差戻 | V43: 90 本所 | AJ43: 05 米穀 | AX43: 5961 三笠米穀施設 | BQ43: 販売品
D44: ☐ | G44: 2024/09 | O44: 差戻 | V44: 90 本所 | AJ44: 05 米穀 | AX44: 5984 サッポロライス炊飯工場 | BQ44: 販売品
D45: ☐ | G45: 2024/09 | O45: 差戻 | V45: 90 本所 | AJ45: 78 卸米穀 | AX45: 5622 パールライス砂川工場 | BQ45: 販売品
D46: ☐ | G46: 2024/09 | O46: 差戻 | V46: 90 本所 | AJ46: 78 卸米穀 | AX46: 5626 パールライス工場 | BQ46: 販売品
D47: ☐ | G47: 9999/99 | O47: ＫＫＫＫ | V47: XX ＫＫＫＫＫＫＫＫＫＫＫ | AJ47: XX ＫＫＫＫＫＫＫＫＫＫＫ | AX47: XXXX ＫＫＫＫＫＫＫＫＫＫＫ | BQ47: 販売品
D48: ☐ | G48: 9999/99 | O48: ＫＫＫＫ | V48: XX ＫＫＫＫＫＫＫＫＫＫＫ | AJ48: XX ＫＫＫＫＫＫＫＫＫＫＫ | AX48: XXXX ＫＫＫＫＫＫＫＫＫＫＫ | BQ48: 販売品
D49: ☐ | G49: 9999/99 | O49: ＫＫＫＫ | V49: XX ＫＫＫＫＫＫＫＫＫＫＫ | AJ49: XX ＫＫＫＫＫＫＫＫＫＫＫ | AX49: XXXX ＫＫＫＫＫＫＫＫＫＫＫ | BQ49: 販売品
D50: ☐ | G50: 9999/99 | O50: ＫＫＫＫ | V50: XX ＫＫＫＫＫＫＫＫＫＫＫ | AJ50: XX ＫＫＫＫＫＫＫＫＫＫＫ | AX50: XXXX ＫＫＫＫＫＫＫＫＫＫＫ | BQ50: 販売品
D51: ☐ | G51: 9999/99 | O51: ＫＫＫＫ | V51: XX ＫＫＫＫＫＫＫＫＫＫＫ | AJ51: XX ＫＫＫＫＫＫＫＫＫＫＫ | AX51: XXXX ＫＫＫＫＫＫＫＫＫＫＫ | BQ51: 購買品
D52: ☐ | G52: 9999/99 | O52: ＫＫＫＫ | V52: XX ＫＫＫＫＫＫＫＫＫＫＫ | AJ52: XX ＫＫＫＫＫＫＫＫＫＫＫ | AX52: XXXX ＫＫＫＫＫＫＫＫＫＫＫ | BQ52: 購買品
... D56: ☐ | G56: 9999/99 | O56: ＫＫＫＫ | V56: XX ＫＫＫＫＫＫＫＫＫＫＫ | AJ56: XX ＫＫＫＫＫＫＫＫＫＫＫ | AX56: XXXX ＫＫＫＫＫＫＫＫＫＫＫ | BQ56: 購買品
E57: ◀ | CC57: ▶
...

Sheet 3.項目説明（在庫品棚卸表照会）
A1: Ｐｈａｓｅ 外部設計工程 | BJ1: HOKUREN INTERNAL USE ONLY
A2: 画面項目説明書 | AV2: 様式No. | AZ2: F4106-3D | BD2: PAGE
A3: システム名 | H3: 統合会計システム | AV3: 作成日 | AZ3: 45898
A4: 業務名 | H4: =変更履歴!H4 -> 棚卸資産管理 | AV4: 更新日
A6: 画面名 | H6: =変更履歴!H6 -> 在庫品棚卸表登録
A8: 検索結果表示領域一覧表示順
A9: No. | D9: 項目名（ソート項目順に列挙） | AT9: 表示順
A10: 1 | D10: 承認状況 | AT10: 未作成→差戻→下書保存→依頼中→承認済
A11: 2 | D11: 事業所コード | AT11: 昇順
A12: 3 | D12: 業種コード | AT12: 昇順
A13: 4 | D13: 受払組織コード | AT13: 昇順
A14: 5 | D14: 棚卸種別 | AT14: 昇順
A17: No. | D17: 項目名 | S17: I/O | V17: 桁数 | Z17: 属性 | AD17: 符号 | AG17: 初期値 | AJ17: 前回 | AM17: 項目編集説明
V18: 入力 | X18: 表示
A19: 1 | D19: 実地棚卸年月 | S19: I | V19: 6 | X19: 7 | Z19: 数字 | AG19: ○ | AJ19: ○ | AM19: 実地棚卸年月の検索条件。 初期値：初期値：3～8月は3月、9～2月は9月を設定する。
A20: 2 | D20: 事業所コード | S20: I | V20: 2 | X20: 2 | Z20: 数字 | AJ20: ○ | AM20: 事業所コードの検索条件。 入力者の所属する組織が本所以外の場合、入力者の自事業所を固定表示する ※入力者の所属が本所の場合、絞り込みは行わない ※入力者が経理部所属の場合、絞り込みは行わない
A21: 3 | D21: 事業所名 | S21: O | V21: - | X21: 15 | Z21: 文字 （全角） | AJ21: ○ | AM21: 事業所コードによりマスタから取得した事業所名。 取得先：事業所マスタ
A22: 4 | D22: 業種コード | S22: I | V22: 2 | X22: 2 | Z22: 文字 | AJ22: ○ | AM22: 業種コードの検索条件。 入力者の所属する組織を元に、組織・業種マスタに登録のある業種に絞り込みを行う（入力者の担当業種に絞り込みを行う） ※入力者が経理部所属の場合、絞り込みは行わない
A23: 5 | D23: 業種名 | S23: O | V23: - | X23: 20 | Z23: 文字 （全角） | AJ23: ○ | AM23: 業種コードによりマスタから取得した業種名。 参照先：業種マスタ
A24: 6 | D24: 受払組織コード | S24: I | V24: 4 | X24: 4 | Z24: 数字 | AJ24: ○ | AM24: 課コード／施設コードの検索条件 入力者の所属が本所以外の場合、入力者の自組織に絞り込みを行う 入力者の所属が本所の場合、入力者の担当業種を元に、組織業種マスタより組織情報を取得し表示を行う(管理組織含む、汎用マスタで管理する） ※入力者が経理部所属の場合、絞り込みは行わない
A25: 7 | D25: 受払組織名 | S25: O | V25: - | X25: 15 | Z25: 文字 （全角） | AJ25: ○ | AM25: 受払組織コードにより課マスタ／施設マスタから取得した受払組織名。 取得先：課マスタ、施設マスタ
A26: 8 | D26: 棚卸資産種類 | S26: I | V26: - | X26: - | Z26: 文字 （全角） | AG26: ○ | AJ26: ○ | AM26: 棚卸資産種類の検索条件。 販売品／購買品／原材料／仕掛品／貯蔵品 初期値：チェック無し※ ※チェック無しの場合、すべてチェック時と同じくすべての棚卸資産種類が検索対象となる。
A27: 9 | D27: 棚卸種別 | S27: I | V27: - | X27: - | Z27: 文字 （全角） | AG27: ○ | AJ27: ○ | AM27: 棚卸種別の検索条件。 一斉棚卸／循環棚卸 初期値：一斉棚卸、循環棚卸を選択
A28: 10 | D28: 承認状況 | S28: I | V28: - | X28: - | Z28: 文字 （全角） | AG28: ○ | AJ28: ○ | AM28: 承認状況の検索条件。 未作成／差戻／下書保存／依頼中／承認済 初期値：未作成、差戻を選択
A29: 11 | D29: 出力対象 | S29: I | V29: - | X29: - | Z29: 文字 （全角） | AG29: ○ | AJ29: ○ | AM29: 出力対象の検索条件。 在庫品棚卸表（PDF）／在庫品棚卸表（CSV） 初期値：在庫品棚卸表（PDF）を選択
A30: 12 | D30: 【検索結果情報】 | S30: - | V30: - | X30: - | Z30: -
A31: 13 | D31: 実地棚卸年月 | S31: O | V31: - | X31: 7 | Z31: 数字 | AM31: 在庫品棚卸表の実地棚卸年月を表示する
A32: 14 | D32: 承認状況 | S32: O | V32: - | X32: 4 | Z32: 文字 （全角） | AM32: 在庫品棚卸表の承認状況を表示する
A33: 15 | D33: 事業所名 | S33: O | V33: - | X33: 18 | Z33: 文字 （全角） | AM33: 在庫品棚卸表の事業所名を表示する
A34: 16 | D34: 業種名 | S34: O | V34: - | X34: 23 | Z34: 文字 （全角） | AM34: 在庫品棚卸表の業種名を表示する
A35: 17 | D35: 受払組織名 | S35: O | V35: - | X35: 20 | Z35: 文字 （全角） | AM35: 在庫品棚卸表の受払組織名を表示する
A36: 18 | D36: 棚卸資産種類 | S36: O | V36: - | X36: 3 | Z36: 文字 （全角） | AM36: 在庫品棚卸表の棚卸資産種類を表示する
A37: 19 | D37: 棚卸種別 | S37: O | V37: - | X37: 4 | Z37: 文字 （全角） | AM37: 在庫品棚卸表の棚卸種別を表示する

Sheet 4.項目チェック（単体）（在庫品棚卸表照会）
A1: Ｐｈａｓｅ 外部設計工程 | BJ1: HOKUREN INTERNAL USE ONLY
A2: 画面項目チェック（単体） | AV2: 様式No. | AZ2: F4106-4 | BD2: PAGE
A3: システム名 | H3: 統合会計システム | AV3: 作成日 | AZ3: 45898
A4: 業務名 | H4: =変更履歴!H4 -> 棚卸資産管理 | AV4: 更新日
A6: 画面名 | H6: 在庫品棚卸表照会
A8: No. | D8: 項目名 | R8: 必須 ﾁｪｯｸ | U8: 数字 ﾁｪｯｸ | X8: 文字数 ﾁｪｯｸ | AA8: 存在 ﾁｪｯｸ | AD8: ｺｰﾄﾞﾁｪｯｸ | AG8: チェック補足説明／メッセージ文言 | BD8: メッセージ コード | BK8: 仮メッセージ番号
A9: 1-1 | D9: 実地棚卸年月 | R9: ○ | AG9: ／実地棚卸年月を入力してください。 | BK9: E000001
A10: 1-2 | U10: ○ | AG10: 実在しない日付の場合、エラーとする。 ／実地棚卸年月は有効な日付を入力してください。 | BK10: E000018
A11: 2-1 | D11: 事業所コード | AA11: ○ | AG11: 事業所マスタに存在しない場合、エラーとする。 ／事業所コードはマスタに存在しません。 | BK11: E000008
A12: 3-1 | D12: 業種コード | AA12: ○ | AG12: 業種マスタに存在しない場合、エラーとする。 ／業種コードはマスタに存在しません。 | BK12: E000008
A13: 4-1 | D13: 受払組織コード | AA13: ○ | AG13: 課マスタまたは施設マスタに存在しない場合、エラーとする。 ／受払組織コードはマスタに存在しません。 | BK13: E000008

Sheet 5.項目チェック（関連）（在庫品棚卸表照会）
A1: Ｐｈａｓｅ 外部設計局面 | BJ1: HOKUREN INTERNAL USE ONLY
A2: 画面項目チェック（関連） | AV2: 様式No. | AZ2: F4106-5 | BD2: PAGE
A3: システム名 | H3: 統合会計システム | AV3: 作成日 | AZ3: 45898
A4: 業務名 | H4: =変更履歴!H4 -> 棚卸資産管理 | AV4: 更新日
A6: 画面名 | H6: 在庫品棚卸表照会
A8: No. | D8: 関連チェック概要 | Q8: チェック詳細／メッセージ文言 | BD8: メッセージ コード | BK8: 仮メッセージコード
A9: =ROW()-8 -> 1 | D9: 抽出条件 | Q9: 指定した条件に該当するデータが存在しない場合、エラーとする。 ／該当データが存在しません。 | BK9: E000009
A10: =ROW()-8 -> 2 | D10: 所属と業種のチェック | Q10: 所属が取り扱う業種ではない場合、エラーとする。 ／所属で取り扱う、業種を入力してください。 | BK10: E000001
A11: =ROW()-8 -> 3 | D11: 照会、表示ボタンと業種コードのチェック | Q11: 入力した業種と入力者の所属する組織の組み合わせが組織業種マスタに存在しない場合はエラー ／業種は受払組織に応じた業種を入力してください ※入力者が経理部所属の場合、上記権限関係の関連チェックは行わない | BK11: E000025
A12: =ROW()-8 -> 4 | D12: 照会、表示ボタンと受払組織コードのチェック | Q12: 入力者の所属する組織が本所以外の場合、入力した受払組織コードが自組織ではない、または所属と受払組織の紐づけが会計コードマスタに管理されていない場合、エラーとする。 ／受払組織は担当の所属コードを入力してください。 ※入力者が経理部所属の場合、上記権限関係の関連チェックは行わない | BK12: E000025
A13: =ROW()-8 -> 5 | D13: 棚卸結果入力ボタンと明細未選択チェック | Q13: 「棚卸結果入力」ボタン押下時、明細を選択していない場合、エラーとする。 ／明細を選択してください。 | BK13: E000002
A14: =ROW()-8 -> 6 | D14: 棚卸結果入力ボタンと複数明細選択チェック | Q14: 「棚卸結果入力」ボタン押下時、複数明細を選択している場合、エラーとする。 ／明細は１件のみ選択してください。 | BK14: E000002
A15: =ROW()-8 -> 7 | D15: 棚卸結果入力ボタンと承認状況（依頼中）のチェック | Q15: 「棚卸結果入力」ボタン押下時、承認状況が「依頼中」の明細を選択している場合、エラーとする。 ／依頼中の為、対象データは操作できません。 | BK15: E000026
A16: =ROW()-8 -> 8 | D16: 棚卸結果入力ボタンと承認状況（承認済）のチェック | Q16: 「棚卸結果入力」ボタン押下時、承認状況が「承認済」の明細を選択している場合、エラーとする。 ／承認済の為、対象データは操作できません。 | BK16: E000026
A17: =ROW()-8 -> 9 | D17: 個別照会ボタンと明細未選択のチェック | Q17: 「個別照会」ボタン押下時、明細を選択していない場合、エラーとする。 ／明細を選択してください。 | BK17: E000002
A18: =ROW()-8 -> 10 | D18: 個別照会ボタンと複数明細選択のチェック | Q18: 「個別照会」ボタン押下時、複数明細を選択している場合、エラーとする。 ／明細は１件のみ選択してください。 | BK18: E000002
A19: =ROW()-8 -> 11 | D19: 承認依頼取下ボタンと明細未選択のチェック | Q19: 「承認依頼取下」ボタン押下時、明細を選択していない場合、エラーとする。 ／明細を選択してください。 | BK19: E000002
A20: =ROW()-8 -> 12 | D20: 承認依頼取下ボタンと承認状況（未作成）のチェック | Q20: 「承認依頼取下」ボタン押下時、承認状況が「未作成」の明細を1件でも選択している場合、エラーとする。 ／未作成の明細がある為、操作できません。 | BK20: E000360
... A24: =ROW()-8 -> 16 | D24: 承認依頼取下ボタンと受払組織のチェック | Q24: 「承認依頼取下」ボタン押下時、入力者の所属組織以外を選択している場合、エラーとする。 ／受払組織が担当の所属コード以外となる明細は選択できません。 | BK24: E000312
A25: =ROW()-8 -> 17 | D25: 棚卸結果入力ボタンと受払組織のチェック | Q25: 「棚卸結果入力」ボタン押下時、入力者の所属組織以外を選択している場合、エラーとする。 ／受払組織が担当の所属コード以外となる明細は選択できません。

Sheet 2.レイアウト（実地棚卸結果照会）
A1: Ｐｈａｓｅ 外部設計局面 | CG1: HOKUREN INTERNAL USE ONLY
A2: 画面レイアウト説明書 | BP2: 様式No. | BV2: F4106-2 | CA2: PAGE
A3: システム名 | L3: 統合会計システム | BP3: 作成日 | BV3: 2025/8/29
A4: 業務名 | L4: =変更履歴!H4 -> 棚卸資産管理 | BP4: 更新日
A7: 画面名 | L7: 実地棚卸結果照会
L11: 実地棚卸結果照会 | BV11: 管理メニュー領域
F14: 在庫品棚卸表照会 > 実地棚卸結果照会 >
F15: 実地棚卸結果を修正する場合は「修正」ボタンを押してください。
F17: 検索条件
F18: 実地棚卸年月 | R18: 2024/09
F19: 事業所 | R19: 90 | X19: 本所
F20: 業種 | R20: 78 | X20: 卸米穀
F21: 受払組織 | R21: 5626 | X21: パールライス工場
F22: 棚卸資産種類 | R22: 販売品
F23: 棚卸種別 | S23: 一斉棚卸
F24: 在庫品登録状態 | R24: □ 未登録 □ 依頼中 □登録済
F25: 未確認数量有無 | R25: □ 有 □ 無
BT28: ※単位・数量（上段：分子、下段：仮数）
F29: (1 of 5) << < 1 2 3 4 5 > >>
F30: 選択 | I30: 品目 | S30: 年産 | W30: 受払帳残高 | AI30: 在庫品
W31: 単位 | AA31: 数量(A) | AI31: 部門品名 | AU31: 保管場所 | BI31: 単位 | BM31: 数量(B)
F32: ◎ | I32: 227731 ななつぼし１等一般 | S32: 2024 | W32: Ｋｇ 俵 | AA32: 10 2,000 | AI32: 101-11-1 ななつ １等 一般 | AU32: 倉庫 | AY32: 12200100 ピンネ農協 | BI32: Ｋｇ 俵 | BM32: 0
BM33: 170
AI34: 101-11-1 ななつ １等 一般 | AU34: 倉庫 | AY34: 13900100 きたそらち農協 | BI34: Ｋｇ 俵 | BM34: 0
BM35: 1,105
AI36: 101-11-1 ななつ １等 一般 | AU36: 倉庫 | AY36: 11100100 東神楽農協 | BI36: Ｋｇ 俵 | BM36: 30
BM37: 85
AI38: 101-11-1 ななつ １等 一般 | AU38: 倉庫 | AY38: 12000100 東川町農協 | BI38: Ｋｇ 俵 | BM38: 30
BM39: 139
AI40: 101-11-1-962 ななつ １等 一般 （深川米穀施設） | AU40: 内部 | AY40: 962 深川米穀施設 | BI40: Ｋｇ 俵 | BM40: 13
BM41: 700
F42: ○ | I42: 227732 ななつぼし１等低蛋白 | S42: 2024 | W42: Ｋｇ 俵 | AA42: 0 334 | AI42: 101-11-3 ななつ １等 低蛋白 | AU42: 倉庫 | AY42: 12000100 東川町農協 | BI42: Ｋｇ 俵 | BM42: 0
BM43: 34
AI44: 101-11-3 ななつ １等 低蛋白 | AU44: 内部 | AY44: 962 深川米穀施設 | BI44: Ｋｇ 俵 | BM44: 0
BM45: 200
AI46: 101-11-3 ななつ １等 低蛋白 | AU46: 輸送 | AY46: 10009001 ○○通運○○支店 | BI46: Ｋｇ 俵 | BM46: 0
BM47: 100
F48: ○ | I48: 241038 ななつぼし１等仕分無 | S48: 2024 | W48: Ｋｇ 俵 | AA48: 0 205 | AI48: 101-11-99 ななつ １等 仕分無 | AU48: 倉庫 | AY48: 12800100 北石狩農協 | BI48: Ｋｇ 俵 | BM48: 0
BM49: 200
F50: ○ | I50: 242075 ななつぼし１等仕分９契約栽培 | S50: 2024 | W50: Ｋｇ 俵 | AA50: 0 68 | AI50: 101-11-9 ななつ １等 仕分９ | AU50: 倉庫 | AY50: 13900100 きたそらち農協 | BI50: Ｋｇ 俵 | BM50: 50
...

Sheet 3.項目説明（実地棚卸結果照会）
A1: Ｐｈａｓｅ 外部設計工程 | BJ1: HOKUREN INTERNAL USE ONLY
A2: 画面項目説明書 | AV2: 様式No. | AZ2: F4106-3D | BD2: PAGE
A3: システム名 | H3: 統合会計システム | AV3: 作成日 | AZ3: 45898
A4: 業務名 | H4: 棚卸資産管理 | AV4: 更新日
A6: 画面名 | H6: 実地棚卸結果照会
A8: 検索結果表示領域一覧表示順
A9: No. | D9: 項目名（ソート項目順に列挙） | AT9: 表示順
A10: =IF(ISBLANK(D10),"",ROW()-9) -> 1 | D10: 品目コード | AT10: 昇順
A11: =IF(ISBLANK(D11),"",ROW()-9) -> 2 | D11: 年産 ※棚卸資産種類が「販売品・購買品」の場合に有効 | AT11: 降順
A12: =IF(ISBLANK(D12),"",ROW()-9) -> 3 | D12: 取込順または明細行追加順（実地棚卸結果情報の在庫品明細番号） | AT12: 昇順
A13: =IF(ISBLANK(D13),"",ROW()-9)
A16: No. | D16: 項目名 | S16: I/O | V16: 桁数 | Z16: 属性 | AD16: 符号 | AG16: 初期値 | AJ16: 前回 | AM16: 項目編集説明
V17: 入力 | X17: 表示
A18: 1 | D18: 実地棚卸年月 | S18: O | V18: 6 | X18: 7 | Z18: 数字 | AJ18: ○ | AM18: 実地棚卸基準日の年月。
A19: 2 | D19: 事業所コード（事業所） | S19: O | V19: 2 | X19: 2 | Z19: 文字 | AJ19: ○ | AM19: 実地棚卸を担当する事業所コード。
A20: 3 | D20: 事業所名（事業所） | S20: O | V20: - | X20: 15 | Z20: 文字（全角） | AJ20: ○ | AM20: 実地棚卸を担当する事業所名。
A21: 4 | D21: 業種コード（業種） | S21: O | V21: 2 | X21: 2 | Z21: 文字 | AJ21: ○ | AM21: 実地棚卸を担当する業種コード。
A22: 5 | D22: 業種名（業種） | S22: O | V22: - | X22: 20 | Z22: 文字（全角） | AJ22: ○ | AM22: 実地棚卸を担当する業種名。
A23: 6 | D23: 受払組織コード（受払組織） | S23: O | V23: 4 | X23: 4 | Z23: 文字 | AJ23: ○ | AM23: 実地棚卸を担当する受払組織コード。 （課コードまたは施設コード）
A24: 7 | D24: 受払組織名（受払組織） | S24: O | V24: - | X24: 15 | Z24: 文字（全角） | AJ24: ○ | AM24: 実地棚卸を担当する受払組織名。 （課名または施設名）
A25: 8 | D25: 棚卸資産種類 | S25: O | V25: - | X25: - | Z25: 文字（全角） | AJ25: ○ | AM25: 対象品目の棚卸資産種類。
A26: 9 | D26: 棚卸種別 | S26: O | V26: - | X26: - | Z26: 文字（全角） | AJ26: ○ | AM26: 対象品目の棚卸種別。
A27: 10 | D27: 在庫品登録状態 | S27: I | V27: - | X27: - | Z27: チェックボックス | AJ27: ○ | AM27: 在庫品登録状態の検索条件。 在庫品登録状態区分（未登録/依頼中/登録済） 初期値：チェック無し※ ※チェック無しの場合、すべてチェック時と同じくすべての在庫品登録状態が検索対象となる。
A28: 11 | D28: 未確認数量有無 | S28: I | V28: - | X28: - | Z28: チェックボックス | AJ28: ○ | AM28: 未確認数量有無の検索条件。 初期値：チェック無し※ ※チェック無しの場合、すべてチェック時と同じくすべての未確認数量有無が検索対象となる。
A29: 12 | D29: 選択 | S29: I | V29: - | X29: - | Z29: ラジオ ボタン | AG29: ○ | AJ29: ○ | AM29: 初期値：検索結果一覧の1件目を選択。
A30: 13 | D30: 品目コード（品目） | S30: O | V30: - | X30: 6 | Z30: 文字（全角） | AM30: 棚卸資産受払残高の以下コード。 販売品・購買品の場合、収支管理品目コード。 原材料・仕掛品・貯蔵品の場合、科目摘要コード。
A31: 14 | D31: 品目名称（品目） | S31: O | V31: - | X31: 20 | Z31: 文字（全角） | AM31: 品目コードを元にマスタから取得。
A32: 15 | D32: 年産 | S32: O | V32: - | X32: 4 | Z32: 数字 | AM32: 棚卸資産受払残高の年産。 販売品・購買品の場合、収支管理品目の年産。 原材料・仕掛品・貯蔵品の場合、ブランク。
A33: 16 | D33: 受払帳残高 単位 | S33: O | V33: - | X33: 6 | Z33: 文字（全角） | AM33: 収支管理品目の単位。 販売品・購買品の場合、下段：収支管理品目単位区分、上段：収支管理品目入数単位区分を表示。 原材料・仕掛品・貯蔵品の場合、非表示。
A34: 17 | D34: 受払帳残高 数量(A)（分子） | S34: O | V34: - | X34: 8,3 | Z34: 数字 | AM34: 棚卸資産受払残高の数量（分子）。 販売品・購買品の場合、受払帳残高数量（分子）を表示する。
A35: 18 | D35: 受払帳残高 数量(A)（仮数） | S35: O | V35: - | X35: 8 | Z35: 数字 | AM35: 棚卸資産受払残高の数量（仮数）。 販売品・購買品の場合、受払帳残高数量（仮数）を表示する。
A36: 19 | D36: 在庫品 部門品目（部門品名） | S36: O | V36: - | X36: 20 | Z36: 文字（全角） | AM36: 実地棚卸結果情報の部門品目。 （レイアウトの部門品名の上段）
A37: 20 | D37: 在庫品 部門品目補足（部門品名） | S37: O | V37: - | X37: 20 | Z37: 文字（全角） | AM37: 実地棚卸結果情報の部門品目補足。 （レイアウトの部門品名の下段）
A38: 21 | D38: 在庫品 保管場所区分（保管場所） | S38: O | V38: - | X38: 1 | Z38: 文字（全角） | AM38: 実地棚卸結果情報の保管場所区分（内部／倉庫／輸送）
A39: 22 | D39: 在庫品 保管場所コード（保管場所） | S39: O | V39: - | X39: 8 | Z39: 文字 | AM39: 実地棚卸結果情報の以下コード。 在庫品保管場所区分が内部の場合は内部保管場所（施設コード）。 倉庫／輸送の場合は外部保管場所（取引先コード）。
A40: 23 | D40: 在庫品 保管場所名（保管場所） | S40: O | V40: - | X40: 40 | Z40: 文字（全角） | AM40: 在庫品保管場所コードを元にマスタから取得。 在庫品保管場所区分が内部の場合は施設マスタ、 倉庫／輸送の場合は取引先マスタから取得する。
A41: 24 | D41: 在庫品 単位 | S41: O | V41: - | X41: 6 | Z41: 文字（全角） | AM41: 実地棚卸結果情報の在庫品単位コードを元に、 外部コード表の「単位区分」から単位名称を取得する。 （単位（上段）：分子、単位（下段）：仮数）
... A55: 38 | D55: 未確認数量(A-B-C+D+E+F)（仮数） | S55: O | V55: - | X55: 8 | Z55: 数字 | AM55: 実地棚卸結果情報の不符合数量の数量差（仮数）。 算出式 受払帳残高数量（A)（仮数） - 在庫品数量（B)（仮数） - 売却未経理数量(C)（仮数） + 仕入未経理数量(D)（仮数） + 預り品数量(E)（仮数） + 事故品・その他数量(F)（仮数）

Sheet 4.項目チェック（単体）（実地棚卸結果照会）
A1: Ｐｈａｓｅ 外部設計工程 | BJ1: HOKUREN INTERNAL USE ONLY
A2: 画面項目チェック（単体） | AV2: 様式No. | AZ2: F4106-4 | BD2: PAGE
A3: システム名 | H3: 統合会計システム | AV3: 作成日 | AZ3: 45898
A4: 業務名 | H4: =変更履歴!H4 -> 棚卸資産管理 | AV4: 更新日
A6: 画面名 | H6: 実地棚卸結果照会
A8: No. | D8: 項目名 | R8: 必須 ﾁｪｯｸ | U8: 数字 ﾁｪｯｸ | X8: 文字数 ﾁｪｯｸ | AA8: 存在 ﾁｪｯｸ | AD8: ｺｰﾄﾞﾁｪｯｸ | AG8: チェック補足説明／メッセージ文言 | BD8: メッセージ コード
AG9: チェックなし

Sheet 5.項目チェック（関連）（実地棚卸結果照会）
A1: Ｐｈａｓｅ 外部設計局面 | BJ1: HOKUREN INTERNAL USE ONLY
A2: 画面項目チェック（関連） | AV2: 様式No. | AZ2: F4106-5 | BD2: PAGE
A3: システム名 | H3: 統合会計システム | AV3: 作成日 | AZ3: 45898
A4: 業務名 | H4: =変更履歴!H4 -> 棚卸資産管理 | AV4: 更新日
A6: 画面名 | H6: 実地棚卸結果照会
A8: No. | D8: 関連チェック概要 | Q8: チェック詳細／メッセージ文言 | BD8: メッセージ コード | BK8: 仮メッセージコード
A9: =ROW()-8 -> 1 | D9: 抽出条件 | Q9: 指定した条件に該当するデータが存在しない場合、エラーとする。 ／条件に該当するデータはありません。 | BK9: E000009
A10: =ROW()-8 -> 2 | D10: 修正ボタンと在庫品登録状態（承認済）のチェック | Q10: 「修正」ボタン押下時、在庫品棚卸表の在庫品登録状態が「承認済」の明細を選択している場合、エラーとする。 ／承認済の為、対象データは操作できません。 | BK10: E000026
A11: =ROW()-8 -> 3 | D11: 次画面ボタンと未確認数量のチェック | Q11: 「次画面」ボタン押下時、未確認数量≠0の明細が残っている場合、エラーとする。／未確認数量≠0の明細が残っている為、棚卸表の申請ができません。 | BK11: E000392
A12: =ROW()-8 -> 4 | D12: 受払帳残高.数量(A)と不符合理由（事故品・その他）のチェック | Q12: 受払帳残高.数量(A)が0で、不符合理由に「事故品・その他」を登録していない明細がある場合エラー ／受払帳残高.数量(A)が0の場合、不符合理由「事故品・その他」を入力してください。 | BK12: E000001

Sheet 2.レイアウト（実地棚卸結果入力）
A1: Ｐｈａｓｅ 外部設計局面 | CG1: HOKUREN INTERNAL USE ONLY
A2: 画面レイアウト説明書 | BP2: 様式No. | BV2: F4106-2 | CA2: PAGE
A3: システム名 | L3: 統合会計システム | BP3: 作成日 | BV3: 2025/8/29
A4: 業務名 | L4: =変更履歴!H4 -> 棚卸資産管理 | BP4: 更新日
A7: 画面名 | L7: 実地棚卸結果入力
B10: 【販売品、購買品の場合】
L11: 実地棚卸結果入力 | BV11: 管理メニュー領域
E14: 在庫品棚卸表照会 > 実地棚卸結果照会 > 実地棚卸結果入力 >
E15: 実地棚卸結果を入力した後、「棚卸結果照会画面」ボタンを押してください。
E17: 実地棚卸結果入力
E18: 実地棚卸年月 | O18: 2024/09
E19: 事業所 | O19: 90 本所 | AB19: 業種 | AL19: 05 米穀 | AY19: 受払組織 | BI19: 5626 パールライス工場
E20: 棚卸資産種類 | O20: 販売品 | AL20: 棚卸種別 | AY20: 一斉棚卸
E22: [品目] | BU22: ※単位（上段：分子、下段：仮数）
E23: 品目 | O23: 227731 ななつぼし１等一般 | AY23: 年産 | BI23: 2024
E24: 単位 | O24: Ｋｇ 俵 | AB24: 単価 | AL24: 1021
E26: [受払帳残高] | BU26: ※数量（上段：分子、下段：仮数）
E27: 金額 | N27: =AL24*AE28+AL24*(40/60) -> 2042680.7 | W27: 数量(A) | AE27: 10 | AN27: 数量(B) | AV27: 13 | BE27: 数量差(A - B) | BM27: -3
AE28: 2000 | AV28: 2200 | BM28: -200
BU29: 数量差＝売却未経理数量－仕入未経理数量－預り品数量－事故数量
E31: [在庫品] | CC31: ※単位・数量（上段：分子、下段：仮数）
E32: 選択 | H32: 部門品目 | Z32: 区分(*) | AH32: 保管場所(内部：施設) | AY32: 保管場所(輸送・倉庫：取引先)
E33: □
AY34: ピンネ農協 北海道樺戸郡新十津川町字中央６−２９
E35: □
AY36: きたそらち農協 北海道深川市2条2-30
E37: □
AY38: 東神楽農協 北海道上川郡東神楽町北1条東1丁目2-1
E39: □
AY40: 東川町農協 北海道上川郡東川町西町1丁目5-1
E41: □
AH42: 深川米穀施設
E46: 単位(*) | K46: 部門数量(*) | S46: 数量(B)
S47: 0
S48: 170
S49: 0
S50: 1105
S51: 30
S52: 85
S53: 30
...

Sheet 3.項目説明（実地棚卸結果入力）
A1: Ｐｈａｓｅ 外部設計工程 | BJ1: HOKUREN INTERNAL USE ONLY
A2: 画面項目説明書 | AV2: 様式No. | AZ2: F4106-3D | BD2: PAGE
A3: システム名 | H3: 統合会計システム | AV3: 作成日 | AZ3: 45898
A4: 業務名 | H4: 棚卸資産管理 | AV4: 更新日
A6: 画面名 | H6: 実地棚卸結果入力
A8: 検索結果表示領域一覧表示順
A9: No. | D9: 項目名（ソート項目順に列挙） | AT9: 表示順
A10: 1 | D10: 取込順または明細行追加順（実地棚卸結果情報の在庫品明細番号） | AT10: 昇順
A14: No. | D14: 項目名 | S14: I/O | V14: 桁数 | Z14: 属性 | AD14: 符号 | AG14: 初期値 | AJ14: 前回 | AM14: 項目編集説明
V15: 入力 | X15: 表示
A16: 1 | D16: 実地棚卸年月 | S16: O | V16: - | X16: 7 | Z16: 数字 | AM16: 実地棚卸基準日の年月。
A17: 2 | D17: 事業所コード（事業所） | S17: O | V17: - | X17: 2 | Z17: 文字 | AM17: 実地棚卸を担当する事業所コード。
A18: 3 | D18: 事業所名（事業所） | S18: O | V18: - | X18: 15 | Z18: 文字（全角） | AM18: 実地棚卸を担当する事業所名。
A19: 4 | D19: 業種コード（業種） | S19: O | V19: - | X19: 2 | Z19: 文字 | AM19: 実地棚卸を担当する業種コード。
A20: 5 | D20: 業種名（業種） | S20: O | V20: - | X20: 20 | Z20: 文字（全角） | AM20: 実地棚卸を担当する業種名。
A21: 6 | D21: 受払組織コード（受払組織） | S21: O | V21: - | X21: 4 | Z21: 文字 | AM21: 実地棚卸を担当する受払組織コード。 （課コードまたは施設コード）
A22: 7 | D22: 受払組織名（受払組織） | S22: O | V22: - | X22: 15 | Z22: 文字（全角） | AM22: 実地棚卸を担当する受払組織名。 （課名または施設名）
A23: 8 | D23: 棚卸資産種類 | S23: O | V23: - | X23: 3 | Z23: 文字（全角） | AM23: 対象品目の棚卸資産種類。
A24: 9 | D24: 棚卸種別 | S24: O | V24: - | X24: 4 | Z24: 文字（全角） | AM24: 対象品目の棚卸種別。
A25: 10 | D25: 品目 | S25: O | V25: - | X25: 20 | Z25: 文字（全角） | AM25: 対象品目の品目名。 販売品・購買品の場合、収支管理品目名。 原材料・仕掛品・貯蔵品の場合、棚卸資産振替入力の明細情報（部門品目＋年産・規格・型番等）
A26: 11 | D26: 年産 | S26: O | V26: - | X26: 4 | Z26: 数字 | AM26: 対象品目の年産。
A27: 12 | D27: 単位 | S27: O | V27: - | X27: 6 | Z27: 文字（全角） | AM27: 対象品目の単位区分名。 （単位（上段）：収支管理品目入数単位区分、単位（下段）：収支管理品目単位区分）
... A30: 15 | D30: 受払帳残高 数量（A）（分子） | S30: O | V30: - | X30: 8,3 | Z30: 数字 | AM30: 対象品目の受払帳残高数量（分子）。
A31: 16 | D31: 受払帳残高 数量（A）（仮数） | S31: O | V31: - | X31: 8 | Z31: 数字 | AM31: 対象品目の受払帳残高数量（仮数）。
A32: 17 | D32: 受払帳残高 数量（B）（分子） | S32: O | V32: - | X32: 8,3 | Z32: 数字 | AM32: 対象品目の在庫品の合計数量（分子）。
A33: 18 | D33: 受払帳残高 数量（B）（仮数） | S33: O | V33: - | X33: 8 | Z33: 数字 | AM33: 対象品目の在庫品の合計数量（仮数）。
A34: 19 | D34: 数量差（A - B）（分子） | S34: O | V34: - | X34: 8,3 | Z34: 数字 | AM34: 受払帳残高数量(A)（分子）－在庫品数量(B)（分子）－売却未経理等の数量（分子）の合計値を表示する。 分子の数量差0の場合、分子の数量差は非表示とする。
A35: 20 | D35: 数量差（A - B）（仮数） | S35: O | V35: - | X35: 8 | Z35: 数字 | AM35: 受払帳残高数量(A)（仮数）－在庫品数量(B)（仮数）－売却未経理等の数量（仮数）の合計値を表示する。 仮数の数量差0の場合、仮数の数量差0の表示とする。
A36: 21 | D36: 選択 | S36: I | V36: - | X36: - | Z36: チェックボックス | AM36: 初期値：チェックボックス未選択
A37: 22 | D37: 部門品目 | S37: I/O | V37: 20 | X37: 20 | Z37: 文字（全角） | AM37: 在庫品の部門品目。 （レイアウトの部門品目の上段）
A38: 23 | D38: 部門品目補足 | S38: I/O | V38: 20 | X38: 20 | Z38: 文字（全角） | AM38: 在庫品の部門品目補足。 （レイアウトの部門品目の下段）
A39: 24 | D39: 保管場所区分名 | S39: I/O | V39: 4 | X39: 4 | Z39: 文字（全角） | AM39: 在庫品の保管場所の区分値。 初期値：内部。 プルダウンリストの選択肢：内部、倉庫、輸送
A40: 25 | D40: 保管場所（施設コード） | S40: I/O | V40: 4 | X40: 4 | Z40: 文字 | AM40: 在庫品の保管場所（施設コード）
A41: 26 | D41: 保管場所（施設名） | S41: O | V41: - | X41: 10 | Z41: 文字（全角） | AM41: 保管場所（施設）入力／表示補助画面で選択した在庫品の施設略称名。
A42: 27 | D42: 保管場所（取引先コード） | S42: I/O | V42: 8 | X42: 8 | Z42: 文字 | AM42: 在庫品の保管場所（取引先コード）
A43: 28 | D43: 保管場所（取引先名） | S43: O | V43: - | X43: 40 | Z43: 文字（全角） | AM43: 保管場所（取引先）入力／表示補助画面で選択した在庫品の取引先名。
A44: 29 | D44: 保管場所（取引先住所） | S44: O | V44: - | X44: 62 | Z44: 文字（全角） | AM44: 保管場所（取引先）入力／表示補助画面で選択した在庫品の取引先住所。
A45: 30 | D45: 在庫品単位 | S45: I/O | V45: 6 | X45: 6 | Z45: 文字（全角） | AM45: 在庫品の管理単位。 初期値：未選択 プルダウンリストの選択肢：外部コード表の「単位区分」参照。 （単位（上段）：分子、単位（下段）：仮数） ※棚卸資産種類が「原材料」、「仕掛品」、「貯蔵品」の場合、テキスト入力とする。
A46: 31 | D46: 部門数量（分子） | S46: I/O | V46: 8,3 | X46: 8,3 | Z46: 数字 | AM46: 実地棚卸結果の在庫品数量（在庫品単位）（分子）
A47: 32 | D47: 部門数量（仮数） | S47: I/O | V47: 8 | X47: 8 | Z47: 数字 | AM47: 実地棚卸結果の在庫品数量（在庫品単位）（仮数）
...

Sheet 4.項目チェック（単体）（実地棚卸結果入力）
A1: Ｐｈａｓｅ 外部設計工程 | BJ1: HOKUREN INTERNAL USE ONLY
A2: 画面項目チェック（単体） | AV2: 様式No. | AZ2: F4106-4 | BD2: PAGE
A3: システム名 | H3: 統合会計システム | AV3: 作成日 | AZ3: 45898
A4: 業務名 | H4: 棚卸資産管理 | AV4: 更新日
A6: 画面名 | H6: 実地棚卸結果入力
A8: No. | D8: 項目名 | R8: 必須 ﾁｪｯｸ | U8: 数字 ﾁｪｯｸ | X8: 文字数 ﾁｪｯｸ | AA8: 存在 ﾁｪｯｸ | AD8: ｺｰﾄﾞﾁｪｯｸ | AG8: チェック補足説明／メッセージ文言 | BD8: メッセージ コード | BK8: 仮メッセージ番号
A9: 1-1 | D9: 保管場所（施設コード） | AA9: ○ | AG9: 施設マスタに存在しない場合、エラーとする ／XX行目：保管場所（施設コード）は施設マスタに存在しません。 | BK9: E000008
A10: 2-1 | D10: 保管場所（取引先コード） | AA10: ○ | AG10: 取引先マスタに存在しない場合、エラーとする ／XX行目：保管場所（取引先コード）は取引先マスタに存在しません。 | BK10: E000008
A11: 3-1 | D11: 部門数量 | R11: ○ | AG11: ／XX行目：部門数量を入力してください。 | BK11: E000045
A12: 3-2 | U12: ○ | AG12: ／XX行目：部門数量は半角数値で入力してください。 | BK12: E000048
A13: 3-3 | U13: ○ | AG13: ／XX行目：部門数量はマイナス値で入力できません。 | BK13: E000385
A14: 4-1 | D14: 不符合情報入出庫年月日 | U14: ○ | AG14: 不符合情報入出庫年月日に入力した値が実在日でない場合、エラーとする。 ／XX行目：不符合情報入出庫年月日は有効な日付を入力してください。 | BK14: E000049
A15: 5-1 | D15: 不符合情報数量 | R15: ○ | AG15: ／XX行目：不符合情報数量を入力してください。 | BK15: E000045
A16: 5-2 | U16: ○ | AG16: ／XX行目：XX行目：不符合情報数量は半角数値で入力してください。 | BK16: E000048
A17: 5-3 | U17: ○ | AG17: ／XX行目：部門数量はマイナス値で入力できません。 | BK17: E000385

Sheet 5.項目チェック（関連）（実地棚卸結果入力）
A1: Ｐｈａｓｅ 外部設計局面 | BJ1: HOKUREN INTERNAL USE ONLY
A2: 画面項目チェック（関連） | AV2: 様式No. | AZ2: F4106-5 | BD2: PAGE
A3: システム名 | H3: 統合会計システム | AV3: 作成日 | AZ3: 45898
A4: 業務名 | H4: 棚卸資産管理 | AV4: 更新日
A6: 画面名 | H6: 実地棚卸結果入力
A8: No. | D8: 関連チェック概要 | Q8: チェック詳細／メッセージ文言 | BD8: メッセージ コード | BK8: 仮メッセージコード
A9: =ROW()-8 -> 1 | D9: 保管場所区分（内部）と保管場所（未選択）のチェック | Q9: 保管場所区分が「内部」で保管場所（内部：施設）を入力していない明細がある場合、エラーとする。 ／XX行目：保管場所(内部：施設)を入力してください。 | BK9: E000045
A10: =ROW()-8 -> 2 | D10: 保管場所区分（内部）と保管場所（倉庫または輸送）のチェック | Q10: 保管場所区分が「内部」で保管場所(輸送・倉庫：取引先)を入力している明細がある場合、エラーとする。 ／XX行目：保管場所区分が内部の場合、保管場所(輸送・倉庫：取引先)は入力できません。保管場所(内部：施設)に入力してください。 | BK10: E000154
A11: =ROW()-8 -> 3 | D11: 保管場所区分（倉庫・輸送）と保管場所（未選択）のチェック | Q11: 保管場所区分が「倉庫・輸送」で保管場所(輸送・倉庫：取引先)を入力していない明細がある場合、エラーとする。 ／XX行目：保管場所(輸送・倉庫：取引先)を入力してください。 | BK11: E000045
A12: =ROW()-8 -> 4 | D12: 保管場所区分（倉庫・輸送）と保管場所（施設）のチェック | Q12: 保管場所区分が「倉庫・輸送」で保管場所(施設)を入力している明細がある場合、エラーとする。 ／XX行目：保管場所区分が倉庫・輸送の場合、保管場所(内部：施設)は入力できません。保管場所(輸送・倉庫：取引先)に入力してください。 | BK12: E000155
A13: =ROW()-8 -> 5 | D13: 保管場所区分（未選択）と保管場所（施設）のチェック | Q13: 保管場所区分が「未選択」で保管場所（内部：施設）/（輸送・倉庫：取引先）が入力されている明細がある場合、エラーとする。 ／XX行目：保管場所区分が倉庫・輸送の場合、保管場所(内部：施設)は入力できません。保管場所(輸送・倉庫：取引先)に入力してください。 | BK13: E000155
A14: =ROW()-8 -> 6 | D14: 行削除ボタンと明細未選択のチェック | Q14: 「行削除」ボタン押下時、明細を選択していない場合、エラーとする。 ／明細を選択してください。 | BK14: E000002
A15: =ROW()-8 -> 7 | D15: 受払帳残高の品目の単位と在庫品の単位の換算チェック | Q15: 在庫品の単位が収支管理品目マスタ.収支管理品目単位区分に数量換算できない場合、エラーとする。 ／入力した在庫品の単位は、受払帳残高の品目の単位に数量換算が可能な単位を設定してください。 | BK15: E000157
A16: =ROW()-8 -> 8 | D16: 棚卸資産種類(購買品・販売品)と単位（未選択）のチェック | Q16: 棚卸資産種類が「購買品」または「販売品」で、単位が「未選択」の明細がある場、エラーとする。 ／棚卸資産種類が「購買品」、「販売品」の場合、単位を選択してください。 | BK16: E000002
A17: =ROW()-8 -> 9 | D17: 不符合理由と数量の入力チェック | Q17: 不符合理由と数量のどちらか一方しか入力していない明細がある場合、エラーとする。 ／XX行目：不符合理由と数量を入力してください。 | BK17: E000045
A18: =ROW()-8 -> 10 | D18: 不符合理由（事故品・その他）と必須項目のチェック | Q18: 不符合理由が「事故品・その他」で「数量、備考」を入力していない明細がある場合、エラーとする。 ／XX行目：数量と備考を入力してください。 | BK18: E000045
A19: =ROW()-8 -> 11 | D19: 不符合理由（売却未経理）と必須項目のチェック | Q19: 不符合理由が「売却未経理」で「取引先、伝票No、入出庫年月日、数量」を入力していない明細がある場合エラー／XX行目：不符合理由が売却未経理の場合、取引先、伝票No、入出庫年月日、数量を入力してください。 | BK19: E000321
A20: =ROW()-8 -> 12 | D20: 不符合理由（仕入未経理）と必須項目のチェック | Q20: 不符合理由が「仕入未経理」で「取引先、伝票No、入出庫年月日、数量」を入力していない明細がある場合エラー／XX行目：不符合理由が仕入未経理の場合、取引先、伝票No、入出庫年月日、数量を入力してください。 | BK20: E000321
... A27: =ROW()-8 -> 19 | D27: 棚卸資産種類と在庫品単位のチェック | Q27: 棚卸資産種類が「販売品」または「購買品」で在庫品単位が「未選択」の場合、エラーとする。 ／在庫品単位を入力してください。 | BK27: E000001

Sheet 2.レイアウト（在庫品棚卸表入力）
A1: Ｐｈａｓｅ 外部設計局面 | CG1: HOKUREN INTERNAL USE ONLY
A2: 画面レイアウト説明書 | BP2: 様式No. | BV2: F4106-2 | CA2: PAGE
A3: システム名 | L3: 統合会計システム | BP3: 作成日 | BV3: 2025/8/29
A4: 業務名 | L4: =変更履歴!H4 -> 棚卸資産管理 | BP4: 更新日
A7: 画面名 | L7: 在庫品棚卸表入力
B9: 【登録時】
L10: 在庫品棚卸表入力 | BV10: 管理メニュー領域
D13: 在庫品棚卸表照会 > 実地棚卸結果照会 > 在庫品棚卸表入力 >
D14: 登録する書類情報、調査情報を入力した後、「確認画面」ボタンを押してください。
D16: 基本情報
D17: 実地棚卸年月 | P17: 2024/09
D18: 事業所 | Q18: 90 | W18: 本所
D19: 業種 | Q19: 78 | W19: 卸米穀
D20: 受払組織 | Q20: 5626 | W20: パールライス工場
D21: 棚卸資産種類 | P21: 販売品
D22: 棚卸種別 | Q22: 一斉棚卸
D24: 在庫品棚卸表
D25: 202409_本所_米穀_パールライス販売課_パールライス工場_在庫品棚卸表.pdf
D27: その他登録書類一覧
D28: ☐ | G28: 書類名称 | AE28: ファイル名
D29: ☐
D30: ☐
D31: ☐
D32: ☐
D33: ☐
D36: 調査情報 | CC36: -
D37: 実地棚卸日 | P37: 実地棚卸箇所 | AN37: 調査員名
D44: 承認情報 | CC44: +
B49: 【修正時】
L50: 在庫品棚卸表入力 | BV50: 管理メニュー領域
D53: 在庫品棚卸表照会 > 実地棚卸結果照会 > 在庫品棚卸表入力 >
D54: 登録する書類情報、調査情報を入力した後、「確認画面」ボタンを押してください。
D56: 基本情報
D57: 実地棚卸年月 | Q57: 2024/09
D58: 事業所 | Q58: 90 | T58: 本所
D59: 業種 | Q59: 78 | T59: 卸米穀
D60: 受払組織 | Q60: 5626 | T60: パールライス工場
D61: 棚卸資産種類 | P61: 販売品
D63: その他登録書類一覧
D64: ☐ | G64: 書類名称 | AE64: ファイル名
...

Sheet 3.項目説明（在庫品棚卸表入力）
A1: Ｐｈａｓｅ 外部設計工程 | BJ1: HOKUREN INTERNAL USE ONLY
A2: 画面項目説明書 | AV2: 様式No. | AZ2: F4106-3D | BD2: PAGE
A3: システム名 | H3: 統合会計システム | AV3: 作成日 | AZ3: 45898
A4: 業務名 | H4: =変更履歴!H4 -> 棚卸資産管理 | AV4: 更新日
A6: 画面名 | H6: 在庫品棚卸表入力
A8: 検索結果表示領域一覧表示順
A9: No. | D9: 項目名（ソート項目順に列挙） | AT9: 表示順
A10: 1 | D10: 一覧表示なし
A14: No. | D14: 項目名 | S14: I/O | V14: 桁数 | Z14: 属性 | AD14: 符号 | AG14: 初期値 | AJ14: 前回 | AM14: 項目編集説明
V15: 入力 | X15: 表示
A16: 1 | D16: 実地棚卸年月 | S16: O | V16: - | X16: 7 | Z16: 数字 | AG16: ○ | AJ16: ○ | AM16: 実地棚卸基準日の年月。
A17: 2 | D17: 事業所コード | S17: O | V17: - | X17: 2 | Z17: 数字 | AJ17: ○ | AM17: 実地棚卸を担当する事業所コード。
A18: 3 | D18: 事業所名 | S18: O | V18: - | X18: 15 | Z18: 文字 （全角） | AG18: ○ | AJ18: ○ | AM18: 実地棚卸を担当する事業所名。
A19: 4 | D19: 業種コード | S19: O | V19: - | X19: 2 | Z19: 文字 | AG19: ○ | AJ19: ○ | AM19: 実地棚卸を担当する業種コード。
A20: 5 | D20: 業種名 | S20: O | V20: - | X20: 20 | Z20: 文字 （全角） | AG20: ○ | AJ20: ○ | AM20: 実地棚卸を担当する業種名。
A21: 6 | D21: 受払組織コード | S21: O | V21: - | X21: 4 | Z21: 数字 | AG21: ○ | AJ21: ○ | AM21: 実地棚卸を担当する受払組織コード。 （課コードまたは施設コード）
A22: 7 | D22: 受払組織名 | S22: O | V22: - | X22: 15 | Z22: 文字 （全角） | AG22: ○ | AJ22: ○ | AM22: 実地棚卸を担当する受払組織名。 （課名または施設名）
A23: 8 | D23: 棚卸資産種類 | S23: O | V23: - | X23: 3 | Z23: 文字 （全角） | AG23: ○ | AJ23: ○ | AM23: 対象品目の棚卸資産種類。
A24: 8 | D24: 棚卸種別 | S24: O | V24: - | X24: 4 | Z24: 文字 （全角） | AG24: ○ | AJ24: ○ | AM24: 対象品目の棚卸種別。
A25: 9 | D25: 【その他登録書類一覧】 | S25: - | V25: - | X25: - | Z25: -
A26: 10 | D26: 選択(明細) | S26: I | V26: - | X26: - | Z26: チェックボックス | AM26: 初期値：チェックボックス未選択
A27: 11 | D27: 書類名称 | S27: I/O | V27: 50 | X27: 50 | Z27: 文字 （全角） | AM27: 書類名称を表示する。 初期値：以下3件の書類名称を表示 ①実地棚卸関連書類 ②保管在庫証明書 ③輸送証明書
A28: 12 | D28: ファイル名 | S28: O | V28: - | X28: 100 | Z28: 文字 （全角） | AM28: その他登録書類のファイル名を表示する。
A29: 13 | D29: 【調査情報】 | S29: - | V29: - | X29: - | Z29: -
A30: 14 | D30: 実地棚卸日 | S30: I/O | V30: 8 | X30: 8 | Z30: 数字 | AM30: 実地棚卸日を表示する。
A31: 15 | D31: 実地棚卸箇所 | S31: I/O | V31: 50 | X31: 50 | Z31: 文字 （全角） | AM31: 実地棚卸箇所を表示する。
A32: 16 | D32: 調査員名 | S32: I/O | V32: 100 | X32: 100 | Z32: 文字 （全角） | AM32: 調査員名を表示する。
A33: 17 | D33: 【承認情報】 | S33: - | V33: - | X33: - | Z33: -
A34: 18 | D34: 更新日時（更新者） | S34: O | V34: - | X34: 20 | Z34: 数字 | AM34: 更新者の更新日時を表示する。
A35: 19 | D35: 実地棚卸箇所（更新者） | S35: O | V35: - | X35: 20 | Z35: 文字(全角) | AM35: 更新者の実地棚卸箇所を表示する。
A36: 20 | D36: 担当（更新者） | S36: O | V36: - | X36: 20 | Z36: 文字(全角) | AM36: 更新者の担当を表示する。
A37: 21 | D37: 更新日時（承認/差戻者） | S37: O | V37: - | X37: 20 | Z37: 数字 | AM37: 承認/差戻者の更新日時を表示する。
A38: 22 | D38: 実地棚卸箇所（承認/差戻者） | S38: O | V38: - | X38: 20 | Z38: 文字(全角) | AM38: 承認/差戻者の実地棚卸箇所を表示する。
A39: 23 | D39: 担当（承認/差戻者） | S39: O | V39: - | X39: 20 | Z39: 文字(全角) | AM39: 承認/差戻者の担当を表示する。
A40: 24 | D40: 差戻コメント | S40: O | V40: - | X40: 42 | Z40: 文字(全角) | AM40: 差戻コメントを設定する。

Sheet 4.項目チェック（単体）（在庫品棚卸表入力）
A1: Ｐｈａｓｅ 外部設計工程 | BJ1: HOKUREN INTERNAL USE ONLY
A2: 画面項目チェック（単体） | AV2: 様式No. | AZ2: F4106-4 | BD2: PAGE
A3: システム名 | H3: 統合会計システム | AV3: 作成日 | AZ3: 45898
A4: 業務名 | H4: =変更履歴!H4 -> 棚卸資産管理 | AV4: 更新日
A6: 画面名 | H6: 在庫品棚卸表入力
A8: No. | D8: 項目名 | R8: 必須 ﾁｪｯｸ | U8: 数字 ﾁｪｯｸ | X8: 文字数 ﾁｪｯｸ | AA8: 存在 ﾁｪｯｸ | AD8: ｺｰﾄﾞﾁｪｯｸ | AG8: チェック補足説明／メッセージ文言 | BD8: メッセージ コード
AG9: チェックなし

Sheet 5.項目チェック（関連）（在庫品棚卸表入力）
A1: Ｐｈａｓｅ 外部設計局面 | BJ1: HOKUREN INTERNAL USE ONLY
A2: 画面項目チェック（関連） | AV2: 様式No. | AZ2: F4106-5 | BD2: PAGE
A3: システム名 | H3: 統合会計システム | AV3: 作成日 | AZ3: 45898
A4: 業務名 | H4: =変更履歴!H4 -> 棚卸資産管理 | AV4: 更新日
A6: 画面名 | H6: 在庫品棚卸表入力
A8: No. | D8: 関連チェック概要 | Q8: チェック詳細／メッセージ文言 | BD8: メッセージ コード | BK8: 仮メッセージコード
A9: 1 | D9: 在庫品数量の登録チェック | Q9: 「確認画面」ボタン押下時、登録対象の事業所・業種・受払組織・実地棚卸年月の棚卸資産について、在庫品数量が登録していない品目が存在する場合、エラーとする。 ／在庫品数量を登録していない品目があります。 | BK9: E000357

Sheet 2.レイアウト（在庫品棚卸表確認）
A1: Ｐｈａｓｅ 外部設計局面 | CG1: HOKUREN INTERNAL USE ONLY
A2: 画面レイアウト説明書 | BP2: 様式No. | BV2: F4106-2 | CA2: PAGE
A3: システム名 | L3: 統合会計システム | BP3: 作成日 | BV3: 2025/8/29
A4: 業務名 | L4: =変更履歴!H4 -> 棚卸資産管理 | BP4: 更新日
A7: 画面名 | L7: 在庫品棚卸表確認
B9: 【確認時】
L10: 在庫品棚卸表確認 | BV10: 管理メニュー領域
D13: 在庫品棚卸表照会 > 実地棚卸結果照会 > 在庫品棚卸表入力 > 在庫品棚卸表確認
D14: 基本情報、登録する書類情報、調査情報を確認した後、「申請」ボタンを押してください。
D16: 基本情報
D17: 実地棚卸年月 | Q17: 2024/09
D18: 事業所 | Q18: 90 | T18: 本所
D19: 業種 | Q19: 78 | T19: 卸米穀
D20: 受払組織 | Q20: 5626 | T20: パールライス工場
D21: 棚卸資産種類 | Q21: 販売品
D22: 棚卸種別 | Q22: 一斉棚卸
D24: 在庫品棚卸表
D25: 202409_本所_米穀_パールライス販売課_パールライス工場_在庫品棚卸表.pdf
D27: その他登録書類一覧
D28: 書類名称 | AB28: ファイル名
D29: 棚卸現品調査票 | AB29: 202409_棚卸現品調査票.pdf
D30: きたそらち農協_保管在庫証明書（回答用） | AB30: 202409_きたそらち農協_保管在庫証明書（回答用）.pdf
D31: 東神楽農協_保管在庫証明書（回答用） | AB31: 202409_東神楽農協_保管在庫証明書（回答用）.pdf
D32: 輸送証明書（回答用） | AB32: 202409_輸送証明書（回答用）.pdf
D33: 売上取引情報 | AB33: 202409_売上取引情報.pdf
D35: 調査情報
D36: 実地棚卸日 | P36: 実地棚卸箇所 | AN36: 調査員名
D37: 2025/04/25 | P37: パールライス工場 | AN37: 山田一郎、山田二郎、山田三郎、山田四郎、山田五郎
D38: 2025/04/25 | P38: パールライス工場 | AN38: 佐藤一郎、佐藤二郎、佐藤三郎、佐藤四郎、佐藤五郎
D39: 2025/04/25 | P39: パールライス工場 | AN39: 田中一郎、田中二郎、田中三郎、田中四郎、田中五郎
D41: 承認情報
D42: 更新情報 | M42: 更新日時 | Y42: 実地棚卸箇所 | BB42: 担当
D43: 更新者 | M43: 2025/ 1/15 12:34:56 | Y43: 経理部 主計課 | BB43: 山田 花子
D44: 承認/差戻者 | M44: 2025/ 1/16 12:34:56 | Y44: 経理部 主計課 | BB44: 田中 太郎
D45: 承認状況 | M45: 差戻
D46: 差戻コメント | M46: ○○資料を登録してください。
B52: 【個別照会時】
L53: 在庫品棚卸表確認 | BV53: 管理メニュー領域
D56: 在庫品棚卸表照会 > 実地棚卸結果照会 > 在庫品棚卸表入力 > 在庫品棚卸表確認
D57: 基本情報、登録する書類情報、調査情報を確認した後、「キャンセル」ボタンを押してください。
...

Sheet 3.項目説明（在庫品棚卸表確認）
A1: Ｐｈａｓｅ 外部設計工程 | BJ1: HOKUREN INTERNAL USE ONLY
A2: 画面項目説明書 | AV2: 様式No. | AZ2: F4106-3D | BD2: PAGE
A3: システム名 | H3: 統合会計システム | AV3: 作成日 | AZ3: 45898
A4: 業務名 | H4: =変更履歴!H4 -> 棚卸資産管理 | AV4: 更新日
A6: 画面名 | H6: 在庫品棚卸表確認
A8: 検索結果表示領域一覧表示順
A9: No. | D9: 項目名（ソート項目順に列挙） | AT9: 表示順
A10: 1 | D10: 一覧表示なし
A14: No. | D14: 項目名 | S14: I/O | V14: 桁数 | Z14: 属性 | AD14: 符号 | AG14: 初期値 | AJ14: 前回 | AM14: 項目編集説明
V15: 入力 | X15: 表示
A16: 1 | D16: 実地棚卸年月 | S16: O | V16: - | X16: 7 | Z16: 数字 | AG16: ○ | AJ16: ○ | AM16: 実地棚卸基準日の年月。
A17: 2 | D17: 事業所コード | S17: O | V17: - | X17: 2 | Z17: 数字 | AJ17: ○ | AM17: 実地棚卸を担当する事業所コード。
A18: 3 | D18: 事業所名 | S18: O | V18: - | X18: 15 | Z18: 文字 （全角） | AG18: ○ | AJ18: ○ | AM18: 実地棚卸を担当する事業所名。
A19: 4 | D19: 業種コード | S19: O | V19: - | X19: 2 | Z19: 文字 | AG19: ○ | AJ19: ○ | AM19: 実地棚卸を担当する業種コード。
A20: 5 | D20: 業種名 | S20: O | V20: - | X20: 20 | Z20: 文字 （全角） | AG20: ○ | AJ20: ○ | AM20: 実地棚卸を担当する業種名。
A21: 6 | D21: 受払組織コード | S21: O | V21: - | X21: 4 | Z21: 数字 | AG21: ○ | AJ21: ○ | AM21: 実地棚卸を担当する受払組織コード。 （課コードまたは施設コード）
A22: 7 | D22: 受払組織名 | S22: O | V22: - | X22: 15 | Z22: 文字 （全角） | AG22: ○ | AJ22: ○ | AM22: 実地棚卸を担当する受払組織名。 （課名または施設名）
A23: 8 | D23: 棚卸資産種類 | S23: O | V23: - | X23: 3 | Z23: 文字 （全角） | AG23: ○ | AJ23: ○ | AM23: 対象品目の棚卸資産種類。
A24: 9 | D24: 棚卸種別 | S24: O | V24: - | X24: 4 | Z24: 文字 （全角） | AG24: ○ | AJ24: ○ | AM24: 対象品目の棚卸資産種類。
A25: 10 | D25: 【在庫品棚卸表】 | S25: - | V25: - | X25: - | Z25: -
A26: 11 | D26: ファイル名 | S26: O | V26: - | X26: 100 | Z26: 文字 （全角） | AM26: 棚卸表のファイル名を表示する。
A27: 12 | D27: 【その他登録書類一覧】 | S27: - | V27: - | X27: - | Z27: -
A28: 13 | D28: 書類名称 | S28: O | V28: - | X28: 50 | Z28: 文字 （全角） | AM28: 書類名称を表示する。
A29: 14 | D29: ファイル名 | S29: O | V29: - | X29: 100 | Z29: 文字 （全角） | AM29: その他登録書類のファイル名を表示する。
A30: 15 | D30: 【調査情報】 | S30: - | V30: - | X30: - | Z30: -
A31: 16 | D31: 実地棚卸日 | S31: O | V31: - | X31: 8 | Z31: 数字 | AM31: 実地棚卸日を表示する。
A32: 17 | D32: 実地棚卸箇所 | S32: O | V32: - | X32: 50 | Z32: 文字 （全角） | AM32: 実地棚卸箇所を表示する。
A33: 18 | D33: 調査員名 | S33: O | V33: - | X33: 100 | Z33: 文字 （全角） | AM33: 調査員名を表示する。
A34: 19 | D34: 【承認情報】 | S34: - | V34: - | X34: - | Z34: -
A35: 20 | D35: 更新日時（更新者） | S35: O | V35: - | X35: 20 | Z35: 数字 | AM35: 更新者の更新日時を表示する。
A36: 21 | D36: 実地棚卸箇所（更新者） | S36: O | V36: - | X36: 20 | Z36: 文字(全角) | AM36: 更新者の実地棚卸箇所を表示する。
A37: 22 | D37: 担当（更新者） | S37: O | V37: - | X37: 20 | Z37: 文字(全角) | AM37: 更新者の担当を表示する。
A38: 23 | D38: 更新日時（承認/差戻者） | S38: O | V38: - | X38: 20 | Z38: 数字 | AM38: 承認/差戻者の更新日時を表示する。
A39: 24 | D39: 実地棚卸箇所（承認/差戻者） | S39: O | V39: - | X39: 20 | Z39: 文字(全角) | AM39: 承認/差戻者の実地棚卸箇所を表示する。
A40: 25 | D40: 担当（承認/差戻者） | S40: O | V40: - | X40: 20 | Z40: 文字(全角) | AM40: 承認/差戻者の担当を表示する。
A41: 26 | D41: 差戻コメント | S41: O | V41: - | X41: 42 | Z41: 文字(全角) | AM41: 差戻コメントを設定する。

Sheet 4.項目チェック（単体）（在庫品棚卸表確認）
A1: Ｐｈａｓｅ 外部設計工程 | BJ1: HOKUREN INTERNAL USE ONLY
A2: 画面項目チェック（単体） | AV2: 様式No. | AZ2: F4106-4 | BD2: PAGE
A3: システム名 | H3: 統合会計システム | AV3: 作成日 | AZ3: 45898
A4: 業務名 | H4: =変更履歴!H4 -> 棚卸資産管理 | AV4: 更新日
A6: 画面名 | H6: 在庫品棚卸表確認
A8: No. | D8: 項目名 | R8: 必須 ﾁｪｯｸ | U8: 数字 ﾁｪｯｸ | X8: 文字数 ﾁｪｯｸ | AA8: 存在 ﾁｪｯｸ | AD8: ｺｰﾄﾞﾁｪｯｸ | AG8: チェック補足説明／メッセージ文言 | BD8: メッセージ コード
AG9: チェックなし

Sheet 5.項目チェック（関連）（在庫品棚卸表確認）
A1: Ｐｈａｓｅ 外部設計局面 | BJ1: HOKUREN INTERNAL USE ONLY
A2: 画面項目チェック（関連） | AV2: 様式No. | AZ2: F4106-5 | BD2: PAGE
A3: システム名 | H3: 統合会計システム | AV3: 作成日 | AZ3: 45898
A4: 業務名 | H4: =変更履歴!H4 -> 棚卸資産管理 | AV4: 更新日
A6: 画面名 | H6: =変更履歴!H6 -> 在庫品棚卸表登録
A8: No. | D8: 関連チェック概要 | Q8: チェック詳細／メッセージ文言 | BD8: メッセージ コード
Q9: チェックなし

Sheet 6.画面機能補足説明
A1: Ｐｈａｓｅ 外部設計工程 | BJ1: HOKUREN INTERNAL USE ONLY
A2: 画面機能補足説明 | AV2: 様式No. | AZ2: F4106-6 | BD2: PAGE
A3: システム名 | H3: 統合会計システム | AV3: 作成日 | AZ3: 45898
A4: 業務名 | H4: 棚卸資産管理 | AV4: 更新日
A6: 機能Ｎｏ． | H6: 7.4.1 | O6: 機能名称 | V6: 在庫品棚卸表登録
C9: 【実地棚卸結果入力画面の項目チェック（関連）】について
E10: 実地棚卸結果入力画面の関連チェックは以下の条件時に実施する。
F12: 【棚卸資産種類が「販売品」、「購買品」の場合】
F13: 初期表示された在庫品情報の保管場所が「内部」、在庫品単位が「未選択」、
F14: 部門数量に値が入力されている場合、関連チェックを実施する。
F17: 【棚卸資産種類が「原材料」、「仕掛品」、「貯蔵品」の場合】
F18: 初期表示された在庫品情報の保管場所が「内部」、部門数量に値が入力されている場合、
F19: 関連チェックを実施する。
C21: 【在庫品棚卸表照会画面で扱う一斉棚卸データ】について
E22: 実地棚卸年月が3月と9月以外の場合、検索結果一覧には一斉棚卸のデータを表示しないが、
E23: 在庫品棚卸表（PDF・CSV）のファイル出力には一斉棚卸棚卸のデータを表示する。
C25: 【補足説明”単位・数量（上段：分子、下段：仮数）”の表示位置】について
E26: 次の補足説明は表の右端のそれぞれ表示する。
G27: ※数量・単位（上段：分子、下段：仮数）
G28: ※数量（上段：分子、下段：仮数）
G29: ※単位（上段：分子、下段：仮数）
