Workbook

Sheet 変更履歴
A1: Ｐｈａｓｅ 外部設計工程 | BJ1: HOKUREN INTERNAL USE ONLY
A2: 帳票DesignDoc_v3_v2 変更履歴 | AV2: 様式No. | AZ2: F4109-0 | BD2: PAGE
A3: システム名 | H3: 統合会計システム | AV3: 作成日 | AZ3: 2025/8/29
A4: サブシステム名 | H4: 棚卸資産管理 | AV4: 更新日
A6: 機能Ｎｏ． | H6: 7.4.3 | P6: 帳票名 | V6: 輸送証明依頼書（回答用）
A8: 管理番号 | I8: 案件名 / 障害・問合せ件名
B10: 24058 | I10: 基幹システム再構築 会計システム外部設計

Sheet 1.帳票レイアウト
A1: Ｐｈａｓｅ 外部設計工程 | EC1: HOKUREN INTERNAL USE ONLY
A2: 帳 票 レ イ ア ウ ト
A3: システム名 | L3: 統合会計システム | CR3: 様 式 № | DB3: F4109-1 | DK3: ＰＡＧＥ
A4: 業務名 | L4: 棚卸資産管理 | CR4: 作成日 | DB4: 45898 | DK4: 更新日
A6: 帳 票 名 | L6: =変更履歴!V6 -> 輸送証明依頼書（回答用）
A7: 0 | K7: 1 | U7: 2 | AE7: 3 | AO7: 4 | AY7: 5 | BI7: 6 | BS7: 7 | CC7: 8 | CM7: 9 | CW7: 0 | DG7: 1 | DQ7: 2 | EA7: 3
A8: 0 | B8: =(A8+1) -> 1 | C8: =(B8+1) -> 2 | D8: =(C8+1) -> 3 | E8: =(D8+1) -> 4 | F8: =(E8+1) -> 5 | G8: =(F8+1) -> 6 | H8: =(G8+1) -> 7 | I8: =(H8+1) -> 8 | J8: =(I8+1) -> 9 | K8: 0 | L8: =(K8+1) -> 1 | M8: =(L8+1) -> 2 | N8: =(M8+1) -> 3 | O8: =(N8+1) -> 4 | P8: =(O8+1) -> 5 | Q8: =(P8+1) -> 6 | R8: =(Q8+1) -> 7 | S8: =(R8+1) -> 8 | T8: =(S8+1) -> 9 | U8: 0 | V8: =(U8+1) -> 1 | W8: =(V8+1) -> 2 | X8: =(W8+1) -> 3 | Y8: =(X8+1) -> 4 | Z8: =(Y8+1) -> 5 | AA8: =(Z8+1) -> 6 | AB8: =(AA8+1) -> 7 | AC8: =(AB8+1) -> 8 | AD8: =(AC8+1) -> 9 | AE8: 0 | AF8: =(AE8+1) -> 1 | AG8: =(AF8+1) -> 2 | AH8: =(AG8+1) -> 3 | AI8: =(AH8+1) -> 4 | AJ8: =(AI8+1) -> 5 | AK8: =(AJ8+1) -> 6 | AL8: =(AK8+1) -> 7 | AM8: =(AL8+1) -> 8 | AN8: =(AM8+1) -> 9 | AO8: 0 | AP8: =(AO8+1) -> 1 | AQ8: =(AP8+1) -> 2 | AR8: =(AQ8+1) -> 3 | AS8: =(AR8+1) -> 4 | AT8: =(AS8+1) -> 5 | AU8: =(AT8+1) -> 6 | AV8: =(AU8+1) -> 7 | AW8: =(AV8+1) -> 8 | AX8: =(AW8+1) -> 9 | AY8: 0 | AZ8: =(AY8+1) -> 1 | BA8: =(AZ8+1) -> 2 | BB8: =(BA8+1) -> 3 | BC8: =(BB8+1) -> 4 | BD8: =(BC8+1) -> 5 | BE8: =(BD8+1) -> 6 | BF8: =(BE8+1) -> 7 | BG8: =(BF8+1) -> 8 | BH8: =(BG8+1) -> 9 | BI8: 0 | BJ8: =(BI8+1) -> 1 | BK8: =(BJ8+1) -> 2 | BL8: =(BK8+1) -> 3 | BM8: =(BL8+1) -> 4 | BN8: =(BM8+1) -> 5 | BO8: =(BN8+1) -> 6 | BP8: =(BO8+1) -> 7 | BQ8: =(BP8+1) -> 8 | BR8: =(BQ8+1) -> 9 | BS8: 0 | BT8: =(BS8+1) -> 1 | BU8: =(BT8+1) -> 2 | BV8: =(BU8+1) -> 3 | BW8: =(BV8+1) -> 4 | BX8: =(BW8+1) -> 5 | BY8: =(BX8+1) -> 6 | BZ8: =(BY8+1) -> 7 | CA8: =(BZ8+1) -> 8 | CB8: =(CA8+1) -> 9 | CC8: 0 | CD8: =(CC8+1) -> 1 | CE8: =(CD8+1) -> 2 | CF8: =(CE8+1) -> 3 | CG8: =(CF8+1) -> 4 | CH8: =(CG8+1) -> 5 | CI8: =(CH8+1) -> 6 | CJ8: =(CI8+1) -> 7 | CK8: =(CJ8+1) -> 8 | CL8: =(CK8+1) -> 9 | CM8: 0 | CN8: =(CM8+1) -> 1 | CO8: =(CN8+1) -> 2 | CP8: =(CO8+1) -> 3 | CQ8: =(CP8+1) -> 4 | CR8: =(CQ8+1) -> 5 | CS8: =(CR8+1) -> 6 | CT8: =(CS8+1) -> 7 | CU8: =(CT8+1) -> 8 | CV8: =(CU8+1) -> 9 | CW8: 0 | CX8: =(CW8+1) -> 1 | CY8: =(CX8+1) -> 2 | CZ8: =(CY8+1) -> 3 | DA8: =(CZ8+1) -> 4 | DB8: =(DA8+1) -> 5 | DC8: =(DB8+1) -> 6 | DD8: =(DC8+1) -> 7 | DE8: =(DD8+1) -> 8 | DF8: =(DE8+1) -> 9 | DG8: 0 | DH8: =(DG8+1) -> 1 | DI8: =(DH8+1) -> 2 | DJ8: =(DI8+1) -> 3 | DK8: =(DJ8+1) -> 4 | DL8: =(DK8+1) -> 5 | DM8: =(DL8+1) -> 6 | DN8: =(DM8+1) -> 7 | DO8: =(DN8+1) -> 8 | DP8: =(DO8+1) -> 9 | DQ8: 0 | DR8: =(DQ8+1) -> 1 | DS8: =(DR8+1) -> 2 | DT8: =(DS8+1) -> 3 | DU8: =(DT8+1) -> 4 | DV8: =(DU8+1) -> 5 | DW8: =(DV8+1) -> 6 | DX8: =(DW8+1) -> 7 | DY8: =(DX8+1) -> 8 | DZ8: =(DY8+1) -> 9 | EA8: 0 | EB8: =(EA8+1) -> 1 | EC8: =(EB8+1) -> 2
A9: =A8+1 -> 1
A10: =A9+1 -> 2
A11: =A10+1 -> 3
A12: =A11+1 -> 4 | D12: ホクレン農業協同組合連合会 御中
A13: =A12+1 -> 5
A14: =A13+1 -> 6
A15: =A14+1 -> 7
A16: =A15+1 -> 8 | AT16: 輸送証明書
A17: =A16+1 -> 9
A18: =A17+1 -> 10
A19: =A18+1 -> 11 | CN19: 住 | CT19: 所
A20: =A19+1 -> 12 | CN20: 代 | CP20: 表 | CR20: 者 | CT20: 名 | DV20: ㊞
A21: =A20+1 -> 13
A22: =A21+1 -> 14
A23: =A22+1 -> 15 | E23: 下記の品、Z999年 Z9月 Z9日現在貴会名義にて輸送したことを証明いたします。
A24: =A23+1 -> 16
A25: =A24+1 -> 17 | DZ25: ※単位・数量（上段：分子、下段：仮数）
A26: =A25+1 -> 18 | E26: 品名 | AM26: 単位 | AV26: 証明数量 | BM26: 備考（証明書用）
A27: =A26+1 -> 19
A28: =A27+1 -> 20 | F28: ＸＸＸＸＸＸＸＸＸＸＸＸＸＸＸＸＸＸＸＸＸＸＸＸＸ | AN28: ＸＸＸＸＸ | AX28: 9 | AY28: 9 | AZ28: , | BA28: 9 | BB28: 9 | BC28: 9 | BD28: , | BE28: 9 | BF28: 9 | BG28: 9 | BH28: , | BI28: 9 | BJ28: 9 | BK28: 9
A29: =A28+1 -> 21 | F29: ＸＸＸＸＸＸＸＸＸＸＸＸＸＸＸＸＸＸＸＸＸＸＸＸＸ | AN29: ＸＸＸＸＸ | AX29: 9 | AY29: 9 | AZ29: , | BA29: 9 | BB29: 9 | BC29: 9 | BD29: , | BE29: 9 | BF29: 9 | BG29: 9 | BH29: , | BI29: 9 | BJ29: 9 | BK29: 9
A30: =A29+1 -> 22 | F30: ＸＸＸＸＸＸＸＸＸＸＸＸＸＸＸＸＸＸＸＸＸＸＸＸＸ | AN30: ＸＸＸＸＸ | AX30: 9 | AY30: 9 | AZ30: , | BA30: 9 | BB30: 9 | BC30: 9 | BD30: , | BE30: 9 | BF30: 9 | BG30: 9 | BH30: , | BI30: 9 | BJ30: 9 | BK30: 9
A31: =A30+1 -> 23 | F31: ＸＸＸＸＸＸＸＸＸＸＸＸＸＸＸＸＸＸＸＸＸＸＸＸＸ | AN31: ＸＸＸＸＸ | AX31: 9 | AY31: 9 | AZ31: , | BA31: 9 | BB31: 9 | BC31: 9 | BD31: , | BE31: 9 | BF31: 9 | BG31: 9 | BH31: , | BI31: 9 | BJ31: 9 | BK31: 9
A32: =A31+1 -> 24 | F32: ＸＸＸＸＸＸＸＸＸＸＸＸＸＸＸＸＸＸＸＸＸＸＸＸＸ | AN32: ＸＸＸＸＸ | AX32: 9 | AY32: 9 | AZ32: , | BA32: 9 | BB32: 9 | BC32: 9 | BD32: , | BE32: 9 | BF32: 9 | BG32: 9 | BH32: , | BI32: 9 | BJ32: 9 | BK32: 9
A33: =A32+1 -> 25 | F33: ＸＸＸＸＸＸＸＸＸＸＸＸＸＸＸＸＸＸＸＸＸＸＸＸＸ | AN33: ＸＸＸＸＸ | AX33: 9 | AY33: 9 | AZ33: , | BA33: 9 | BB33: 9 | BC33: 9 | BD33: , | BE33: 9 | BF33: 9 | BG33: 9 | BH33: , | BI33: 9 | BJ33: 9 | BK33: 9
A34: =A33+1 -> 26 | F34: ＸＸＸＸＸＸＸＸＸＸＸＸＸＸＸＸＸＸＸＸＸＸＸＸＸ | AN34: ＸＸＸＸＸ | AX34: 9 | AY34: 9 | AZ34: , | BA34: 9 | BB34: 9 | BC34: 9 | BD34: , | BE34: 9 | BF34: 9 | BG34: 9 | BH34: , | BI34: 9 | BJ34: 9 | BK34: 9
A35: =A34+1 -> 27 | F35: ＸＸＸＸＸＸＸＸＸＸＸＸＸＸＸＸＸＸＸＸＸＸＸＸＸ | AN35: ＸＸＸＸＸ | AX35: 9 | AY35: 9 | AZ35: , | BA35: 9 | BB35: 9 | BC35: 9 | BD35: , | BE35: 9 | BF35: 9 | BG35: 9 | BH35: , | BI35: 9 | BJ35: 9 | BK35: 9
A36: =A35+1 -> 28 | F36: ＸＸＸＸＸＸＸＸＸＸＸＸＸＸＸＸＸＸＸＸＸＸＸＸＸ | AN36: ＸＸＸＸＸ | AX36: 9 | AY36: 9 | AZ36: , | BA36: 9 | BB36: 9 | BC36: 9 | BD36: , | BE36: 9 | BF36: 9 | BG36: 9 | BH36: , | BI36: 9 | BJ36: 9 | BK36: 9
A37: =A36+1 -> 29 | F37: ＸＸＸＸＸＸＸＸＸＸＸＸＸＸＸＸＸＸＸＸＸＸＸＸＸ | AN37: ＸＸＸＸＸ | AX37: 9 | AY37: 9 | AZ37: , | BA37: 9 | BB37: 9 | BC37: 9 | BD37: , | BE37: 9 | BF37: 9 | BG37: 9 | BH37: , | BI37: 9 | BJ37: 9 | BK37: 9
A38: =A37+1 -> 30 | F38: ＸＸＸＸＸＸＸＸＸＸＸＸＸＸＸＸＸＸＸＸＸＸＸＸＸ | AN38: ＸＸＸＸＸ | AX38: 9 | AY38: 9 | AZ38: , | BA38: 9 | BB38: 9 | BC38: 9 | BD38: , | BE38: 9 | BF38: 9 | BG38: 9 | BH38: , | BI38: 9 | BJ38: 9 | BK38: 9
A39: =A38+1 -> 31 | F39: ＸＸＸＸＸＸＸＸＸＸＸＸＸＸＸＸＸＸＸＸＸＸＸＸＸ | AN39: ＸＸＸＸＸ | AX39: 9 | AY39: 9 | AZ39: , | BA39: 9 | BB39: 9 | BC39: 9 | BD39: , | BE39: 9 | BF39: 9 | BG39: 9 | BH39: , | BI39: 9 | BJ39: 9 | BK39: 9
... A69: =A68+1 -> 61 | F69: ＸＸＸＸＸＸＸＸＸＸＸＸＸＸＸＸＸＸＸＸＸＸＸＸＸ | AN69: ＸＸＸＸＸ | AX69: 9 | AY69: 9 | AZ69: , | BA69: 9 | BB69: 9 | BC69: 9 | BD69: , | BE69: 9 | BF69: 9 | BG69: 9 | BH69: , | BI69: 9 | BJ69: 9 | BK69: 9
A70: =A69+1 -> 62
...

Sheet 1.帳票イメージ
A1: Ｐｈａｓｅ 外部設計工程 | EC1: HOKUREN INTERNAL USE ONLY
A2: 帳 票 レ イ ア ウ ト
A3: システム名 | L3: 統合会計システム | CR3: 様 式 № | DB3: F4109-1 | DK3: ＰＡＧＥ
A4: 業務名 | L4: 棚卸資産管理 | CR4: 作成日 | DB4: 45898 | DK4: 更新日
A6: 帳 票 名 | L6: =変更履歴!V6 -> 輸送証明依頼書（回答用）
A7: 0 | K7: 1 | U7: 2 | AE7: 3 | AO7: 4 | AY7: 5 | BI7: 6 | BS7: 7 | CC7: 8 | CM7: 9 | CW7: 0 | DG7: 1 | DQ7: 2 | EA7: 3
A8: 0 | B8: =(A8+1) -> 1 | C8: =(B8+1) -> 2 | D8: =(C8+1) -> 3 | E8: =(D8+1) -> 4 | F8: =(E8+1) -> 5 | G8: =(F8+1) -> 6 | H8: =(G8+1) -> 7 | I8: =(H8+1) -> 8 | J8: =(I8+1) -> 9 | K8: 0 | L8: =(K8+1) -> 1 | M8: =(L8+1) -> 2 | N8: =(M8+1) -> 3 | O8: =(N8+1) -> 4 | P8: =(O8+1) -> 5 | Q8: =(P8+1) -> 6 | R8: =(Q8+1) -> 7 | S8: =(R8+1) -> 8 | T8: =(S8+1) -> 9 | U8: 0 | V8: =(U8+1) -> 1 | W8: =(V8+1) -> 2 | X8: =(W8+1) -> 3 | Y8: =(X8+1) -> 4 | Z8: =(Y8+1) -> 5 | AA8: =(Z8+1) -> 6 | AB8: =(AA8+1) -> 7 | AC8: =(AB8+1) -> 8 | AD8: =(AC8+1) -> 9 | AE8: 0 | AF8: =(AE8+1) -> 1 | AG8: =(AF8+1) -> 2 | AH8: =(AG8+1) -> 3 | AI8: =(AH8+1) -> 4 | AJ8: =(AI8+1) -> 5 | AK8: =(AJ8+1) -> 6 | AL8: =(AK8+1) -> 7 | AM8: =(AL8+1) -> 8 | AN8: =(AM8+1) -> 9 | AO8: 0 | AP8: =(AO8+1) -> 1 | AQ8: =(AP8+1) -> 2 | AR8: =(AQ8+1) -> 3 | AS8: =(AR8+1) -> 4 | AT8: =(AS8+1) -> 5 | AU8: =(AT8+1) -> 6 | AV8: =(AU8+1) -> 7 | AW8: =(AV8+1) -> 8 | AX8: =(AW8+1) -> 9 | AY8: 0 | AZ8: =(AY8+1) -> 1 | BA8: =(AZ8+1) -> 2 | BB8: =(BA8+1) -> 3 | BC8: =(BB8+1) -> 4 | BD8: =(BC8+1) -> 5 | BE8: =(BD8+1) -> 6 | BF8: =(BE8+1) -> 7 | BG8: =(BF8+1) -> 8 | BH8: =(BG8+1) -> 9 | BI8: 0 | BJ8: =(BI8+1) -> 1 | BK8: =(BJ8+1) -> 2 | BL8: =(BK8+1) -> 3 | BM8: =(BL8+1) -> 4 | BN8: =(BM8+1) -> 5 | BO8: =(BN8+1) -> 6 | BP8: =(BO8+1) -> 7 | BQ8: =(BP8+1) -> 8 | BR8: =(BQ8+1) -> 9 | BS8: 0 | BT8: =(BS8+1) -> 1 | BU8: =(BT8+1) -> 2 | BV8: =(BU8+1) -> 3 | BW8: =(BV8+1) -> 4 | BX8: =(BW8+1) -> 5 | BY8: =(BX8+1) -> 6 | BZ8: =(BY8+1) -> 7 | CA8: =(BZ8+1) -> 8 | CB8: =(CA8+1) -> 9 | CC8: 0 | CD8: =(CC8+1) -> 1 | CE8: =(CD8+1) -> 2 | CF8: =(CE8+1) -> 3 | CG8: =(CF8+1) -> 4 | CH8: =(CG8+1) -> 5 | CI8: =(CH8+1) -> 6 | CJ8: =(CI8+1) -> 7 | CK8: =(CJ8+1) -> 8 | CL8: =(CK8+1) -> 9 | CM8: 0 | CN8: =(CM8+1) -> 1 | CO8: =(CN8+1) -> 2 | CP8: =(CO8+1) -> 3 | CQ8: =(CP8+1) -> 4 | CR8: =(CQ8+1) -> 5 | CS8: =(CR8+1) -> 6 | CT8: =(CS8+1) -> 7 | CU8: =(CT8+1) -> 8 | CV8: =(CU8+1) -> 9 | CW8: 0 | CX8: =(CW8+1) -> 1 | CY8: =(CX8+1) -> 2 | CZ8: =(CY8+1) -> 3 | DA8: =(CZ8+1) -> 4 | DB8: =(DA8+1) -> 5 | DC8: =(DB8+1) -> 6 | DD8: =(DC8+1) -> 7 | DE8: =(DD8+1) -> 8 | DF8: =(DE8+1) -> 9 | DG8: 0 | DH8: =(DG8+1) -> 1 | DI8: =(DH8+1) -> 2 | DJ8: =(DI8+1) -> 3 | DK8: =(DJ8+1) -> 4 | DL8: =(DK8+1) -> 5 | DM8: =(DL8+1) -> 6 | DN8: =(DM8+1) -> 7 | DO8: =(DN8+1) -> 8 | DP8: =(DO8+1) -> 9 | DQ8: 0 | DR8: =(DQ8+1) -> 1 | DS8: =(DR8+1) -> 2 | DT8: =(DS8+1) -> 3 | DU8: =(DT8+1) -> 4 | DV8: =(DU8+1) -> 5 | DW8: =(DV8+1) -> 6 | DX8: =(DW8+1) -> 7 | DY8: =(DX8+1) -> 8 | DZ8: =(DY8+1) -> 9 | EA8: 0 | EB8: =(EA8+1) -> 1 | EC8: =(EB8+1) -> 2
A9: =A8+1 -> 1
A10: =A9+1 -> 2
A11: =A10+1 -> 3
A12: =A11+1 -> 4 | D12: ホクレン農業協同組合連合会 御中
A13: =A12+1 -> 5
A14: =A13+1 -> 6
A15: =A14+1 -> 7
A16: =A15+1 -> 8 | AT16: 輸送証明書
A17: =A16+1 -> 9
A18: =A17+1 -> 10
A19: =A18+1 -> 11 | CN19: 住 | CT19: 所
A20: =A19+1 -> 12 | CN20: 代 | CP20: 表 | CR20: 者 | CT20: 名 | DV20: ㊞
A21: =A20+1 -> 13
A22: =A21+1 -> 14
A23: =A22+1 -> 15 | E23: 下記の品、2024年 9月30日現在貴会名義にて輸送したことを証明いたします。
A24: =A23+1 -> 16
A25: =A24+1 -> 17 | DZ25: ※単位・数量（上段：分子、下段：仮数）
A26: =A25+1 -> 18 | E26: 品名 | AM26: 単位 | AV26: 証明数量 | BM26: 備考（証明書用）
A27: =A26+1 -> 19
A28: =A27+1 -> 20 | F28: ななつ １等 一般 | AN28: KG | AV28: 0
A29: =A28+1 -> 21 | AN29: 俵 | AV29: 1105
A30: =A29+1 -> 22 | F30: ななつ １等 仕分９ | AN30: KG | AV30: 0
A31: =A30+1 -> 23 | AN31: 俵 | AV31: 68
A32: =A31+1 -> 24 | F32: 152807 玄米（倉庫）
A33: =A32+1 -> 25 | AN33: KG | AV33: 313
A34: =A33+1 -> 26
A35: =A34+1 -> 27
A36: =A35+1 -> 28
A37: =A36+1 -> 29
A38: =A37+1 -> 30
A39: =A38+1 -> 31
A40: =A39+1 -> 32
A41: =A40+1 -> 33
...

Sheet 2.条件表
A1: Ｐｈａｓｅ 外部設計工程 | BJ1: HOKUREN INTERNAL USE ONLY
A2: 帳票説明書 （作成条件表） | AV2: 様式No. | AZ2: F4109-2 | BD2: PAGE
A3: システム名 | H3: 統合会計システム | AV3: 作成日 | AZ3: 2025/8/29
A4: 業務名 | H4: 棚卸資産管理 | AV4: 更新日
A6: 機能Ｎｏ． | H6: =変更履歴!H6 -> 7.4.3 | P6: 帳票名 | Y6: =変更履歴!V6 -> 輸送証明依頼書（回答用） | AV6: データストア№ | BD6: D07040307
A8: 【帳票 用途】
B9: 外部保管品の棚卸業務にて使用する帳票
B10: 取引先（輸送会社）に対する、輸送証明書を送付してもらうための回答用の輸送証明書
A12: 作成処理 概要 | G12: 入力ファイル ： | AE12: 対象とするデータの条件 ：
H13: 実地棚卸情報 | AF13: 実地棚卸年月 = 画面で入力した実地棚卸年月
AF14: 取引先コード = 画面で入力した取引先コード
G15: 留意事項：
A20: 帳票ＩＤ
A21: 印刷箇所 | H21: □ | J21: センター印刷（ 1 部） | AE21: 印刷装置 | AM21: ■ | AO21: レーザープリンター
H22: ■ | J22: オンライン印刷（ ） | AM22: □ | AO22: インパクトプリンター
H23: □ | J23: その他 | AM23: □ | AO23: その他
J24: （ | AB24: ） | AO24: （ | BI24: ）
A25: 印刷用紙 | H25: ■ | J25: Ａ４カット紙 | AE25: 作成サイクル | AM25: 随時 | AW25: 帳票管理ｓ 保管 | BC25: 世代数
H26: □ | J26: 連続用紙 | O26: （ | R26: ｲﾝﾁx | AC26: ｲﾝﾁ | AD26: ）
H27: □ | J27: 定型用紙 | O27: （ | AD27: ） | AE27: センター印刷時 配布箇所 | BC27: 期間日数
H28: □ | J28: その他 | O28: （ | AD28: ）
A29: 印字サイズ | AE29: 処理タイプ | AM29: □ | AO29: バッチ | AS29: （ 日中 ・ 夜間 ）
P30: 桁 | AM30: ■ | AO30: オンライン画面起動
P31: 行 | AM31: □ | AO31: その他 | AS31: （ | BI31: ）
A34: ページ番号 採番条件 | H34: ■ | J34: 一連番号で採番（１から連番） | AK34: □ | AM34: ページ番号印字なし
H35: □ | J35: ページ番号採番条件あり
A38: 改ページ条件 | H38: 特になし
A42: １ページ 明細数 | G42: 21行
A44: 入力ファイルソートキー （明細印字順） | G44: 1: | I44: 事業所コード | AH44: 昇順／降順 | AJ44: 10: | BI44: 昇順／降順
G45: 2: | I45: 業種コード | AH45: 昇順／降順 | AJ45: 11: | BI45: 昇順／降順
G46: 3: | I46: 受払組織コード | AH46: 昇順／降順 | AJ46: 12: | BI46: 昇順／降順
G47: 4: | I47: 収支管理品目コード | AH47: 昇順／降順 | AJ47: 13: | BI47: 昇順／降順
G48: 5: | I48: 部門品目コード | AH48: 昇順／降順 | AJ48: 14: | BI48: 昇順／降順
G49: 6: | AH49: 昇順／降順 | AJ49: 15: | BI49: 昇順／降順
G50: 7: | AH50: 昇順／降順 | AJ50: 16: | BI50: 昇順／降順
G51: 8: | AH51: 昇順／降順 | AJ51: 17: | BI51: 昇順／降順
G52: 9: | AH52: 昇順／降順 | AJ52: 18: | BI52: 昇順／降順
A54: 合計等 印字条件 明細行の合計計算、合計行の集計計算等について記載する。

Sheet 3.項目説明
A1: Ｐｈａｓｅ 外部設計工程 | BJ1: HOKUREN INTERNAL USE ONLY
A2: 帳票説明書 （項目説明） | AV2: 様式No. | AZ2: F4109-3 | BD2: PAGE
A3: システム名 | H3: 統合会計システム | AV3: 作成日 | AZ3: 2025/8/29
A4: 業務名 | H4: 棚卸資産管理 | AV4: 更新日
A6: 機能Ｎｏ． | H6: 7.4.3 | P6: 帳票名 | Y6: =変更履歴!V6 -> 輸送証明依頼書（回答用） | AV6: データストア№ | BD6: D07040307
A8: № | D8: 項目名 | R8: 桁数 | U8: 編集パターン | AE8: 項目編集説明
A9: =ROW()-8 -> 1 | D9: 証明基準日 | R9: 11 | U9: YYYY年MM月DD日 | AE9: 依頼書作成画面で入力した証明基準日。
A10: =ROW()-8 -> 2 | D10: 品名 | R10: 26 | AE10: 実地棚卸情報.部門品目名。
A11: =ROW()-8 -> 3 | D11: 単位 | R11: 4 | AE11: 実地棚卸情報.単位。
A12: =ROW()-8 -> 4 | D12: 証明数量（仮数） | R12: 8,3 | AE12: 実地棚卸情報.在庫品数量（仮数）。
A13: =ROW()-8 -> 5 | D13: 証明数量（分子） | R13: 8,3 | AE13: 実地棚卸情報.在庫品数量（分子）。
A14: =ROW()-8 -> 6 | D14: 備考（証明書用） | R14: 100 | AE14: 依頼書作成画面で入力した備考（証明書用）。
A15: =ROW()-8 -> 7 | D15: 帳票ID | R15: 7 | AE15: 帳票のID。
