Workbook

Sheet 変更履歴
A1: Ｐｈａｓｅ 外部設計工程 | BJ1: HOKUREN INTERNAL USE ONLY
A2: 画面設計書 変更履歴 | AV2: 様式No. | AZ2: F4106-0 | BD2: PAGE
A3: システム名 | H3: 統合会計システム | AV3: 作成日 | AZ3: 2025/8/29
A4: 業務名 | H4: 共計 | AV4: 更新日
A6: 機能名称 | H6: 滞留立替金利経理計上 | AV6: メニューコード
A8: 管理番号 | I8: 案件名 / 障害・問合せ件名
B10: 24058 | I10: 基幹システム再構築 会計システム外部設計

Sheet 1.遷移図
A1: Ｐｈａｓｅ 外部設計局面 | CQ1: HOKUREN INTERNAL USE ONLY
A2: 画 面 遷 移 図 | BY2: 様式No. | CF2: F4106-1 | CJ2: PAGE
A3: システム名 | J3: 統合会計システム | BY3: 作成日 | CF3: 2025/8/29
A4: 業務名 | J4: 共計 | BY4: 更新日
A6: 機能Ｎｏ． | J6: 9.2.4 | U6: 機能名称 | AD6: =変更履歴!H6 -> 滞留立替金利経理計上 | BY6: メニューコード
B9: 【画面利用条件】 | K9: ※利用可能ユーザー、利用可能組織など利用制限の有無。 利用可能とする条件を記載。
D11: 利用組織 ： | K11: 経理部、現業部門
BA21: 品目追加
AE22: 照会 | BA22: 照会 | BJ22: 承認ルート表示 | BT22: 登録、閉じる
V23: 検索 | Z23: 選択 | AE23: クリア | BA23: クリア
AE24: 表示（コードの日本語名称表示） | BA24: 表示（コードの日本語名称表示）
AI30: 登録、修正 | BE30: 確認画面
AI32: キャンセル | BE32: 訂正
AE34: 削除、個別照会、承認依頼取下
AA36: 申請（登録・修正・削除）、承認依頼取下、キャンセル

Sheet 2.レイアウト_一覧表示
A1: Ｐｈａｓｅ 外部設計局面 | CG1: HOKUREN INTERNAL USE ONLY
A2: 画面レイアウト説明書 | BP2: 様式No. | BV2: F4106-2 | CA2: PAGE
A3: システム名 | L3: 統合会計システム | BP3: 作成日 | BV3: 2025/8/29
A4: 業務名 | L4: 共計 | BP4: 更新日
A7: 画面名 | L7: 滞留立替金利経理計上
L10: 滞留立替金利経理計上 | BU10: 管理メニュー領域
I12: 一覧表示
I13: 検索条件を入力し照会ボタンを押下してください。
I16: 検索条件
I17: 業種
I18: 共計組織 | AM18: 共計区分 | AU18: □ 全道共計 □ 地区共計 □ 全国共計
I19: 収支管理品目 | AM19: 年産 | BG19: 共計次数
I20: 更新者 | AU20: 更新日 | BL20: -
I21: 伝票番号
I22: 承認状況 | U22: ☑差戻 ☑下書保存 ☑依頼中 □承認済
L35: 滞留立替金利情報作成 | BU35: 管理メニュー領域
I37: 一覧表示
I38: 検索条件を入力し照会ボタンを押下してください。
I41: 検索条件の入力
I43: (1 of 5) << < 1 2 3 4 5 > >>
I44: □ | K44: 承認状況 | P44: 更新日 | V44: 経理日 | AB44: 更新者 | AN44: 業種 | AX44: 共計組織 | BP44: 共計区分
I45: ☑ | K45: 差戻 | P45: YYYY/MM/DD | V45: YYYY/MM/DD | AB45: ＸＸＸＸＸＸＸＸＸＸ | AN45: 10 雑穀 | AY45: 4137 農産部雑穀課 | BO45: 全道共計 | BU45: 191113
I46: □ | K46: 差戻 | P46: YYYY/MM/DD | V46: YYYY/MM/DD | AB46: ＸＸＸＸＸＸＸＸＸＸ | AN46: 10 雑穀 | AY46: 4137 農産部雑穀課 | BO46: 全道共計 | BU46: 191114
I47: □ | K47: 下書保存 | P47: YYYY/MM/DD | V47: YYYY/MM/DD | AB47: ＸＸＸＸＸＸＸＸＸＸ | AN47: XX ＸＸＸＸＸ | AY47: XXXX ＸＸＸＸＸＸＸＸＸＸ | BO47: ＸＸＸＸ | BU47: XXXXXX
I48: □ | K48: 下書保存 | P48: YYYY/MM/DD | V48: YYYY/MM/DD | AB48: ＸＸＸＸＸＸＸＸＸＸ | AN48: XX ＸＸＸＸＸ | AY48: XXXX ＸＸＸＸＸＸＸＸＸＸ | BO48: ＸＸＸＸ | BU48: XXXXXX
I49: □ | K49: 下書保存 | P49: YYYY/MM/DD | V49: YYYY/MM/DD | AB49: ＸＸＸＸＸＸＸＸＸＸ | AN49: XX ＸＸＸＸＸ | AY49: XXXX ＸＸＸＸＸＸＸＸＸＸ | BO49: ＸＸＸＸ | BU49: XXXXXX
I50: □ | K50: 下書保存 | P50: YYYY/MM/DD | V50: YYYY/MM/DD | AB50: ＸＸＸＸＸＸＸＸＸＸ | AN50: XX ＸＸＸＸＸ | AY50: XXXX ＸＸＸＸＸＸＸＸＸＸ | BO50: ＸＸＸＸ | BU50: XXXXXX
I51: □ | K51: 下書保存 | P51: YYYY/MM/DD | V51: YYYY/MM/DD | AB51: ＸＸＸＸＸＸＸＸＸＸ | AN51: XX ＸＸＸＸＸ | AY51: XXXX ＸＸＸＸＸＸＸＸＸＸ | BO51: ＸＸＸＸ | BU51: XXXXXX
I52: □ | K52: 下書保存 | P52: YYYY/MM/DD | V52: YYYY/MM/DD | AB52: ＸＸＸＸＸＸＸＸＸＸ | AN52: XX ＸＸＸＸＸ | AY52: XXXX ＸＸＸＸＸＸＸＸＸＸ | BO52: ＸＸＸＸ | BU52: XXXXXX
I53: □ | K53: 下書保存 | P53: YYYY/MM/DD | V53: YYYY/MM/DD | AB53: ＸＸＸＸＸＸＸＸＸＸ | AN53: XX ＸＸＸＸＸ | AY53: XXXX ＸＸＸＸＸＸＸＸＸＸ | BO53: ＸＸＸＸ | BU53: XXXXXX
I54: □ | K54: 下書保存 | P54: YYYY/MM/DD | V54: YYYY/MM/DD | AB54: ＸＸＸＸＸＸＸＸＸＸ | AN54: XX ＸＸＸＸＸ | AY54: XXXX ＸＸＸＸＸＸＸＸＸＸ | BO54: ＸＸＸＸ | BU54: XXXXXX
I55: □ | K55: 下書保存 | P55: YYYY/MM/DD | V55: YYYY/MM/DD | AB55: ＸＸＸＸＸＸＸＸＸＸ | AN55: XX ＸＸＸＸＸ | AY55: XXXX ＸＸＸＸＸＸＸＸＸＸ | BO55: ＸＸＸＸ | BU55: XXXXXX
I56: □ | K56: 下書保存 | P56: YYYY/MM/DD | V56: YYYY/MM/DD | AB56: ＸＸＸＸＸＸＸＸＸＸ | AN56: XX ＸＸＸＸＸ | AY56: XXXX ＸＸＸＸＸＸＸＸＸＸ | BO56: ＸＸＸＸ | BU56: XXXXXX
... I59: □ | K59: 下書保存 | P59: YYYY/MM/DD | V59: YYYY/MM/DD | AB59: ＸＸＸＸＸＸＸＸＸＸ | AN59: XX ＸＸＸＸＸ | AY59: XXXX ＸＸＸＸＸＸＸＸＸＸ | BO59: ＸＸＸＸ | BU59: XXXXXX
I60: (1 of 5) << < 1 2 3 4 5 > >>
I61: ◀
I64: (1 of 5) << < 1 2 3 4 5 > >>
I65: □ | K65: 計上対象収支管理品目 | AG65: 年産 | AJ65: 共計次数 | AO65: 伝票番号
I66: ☑ | L66: 191113 小豆 | AG66: 2024 | AJ66: 01 | AP66: XXXXXXXXXXXX
I67: □ | L67: 191114 赤系金時 | AG67: 2024 | AJ67: 01 | AP67: XXXXXXXXXXXX
...

Sheet 3.項目説明_一覧表示
A1: Ｐｈａｓｅ 外部設計工程 | BJ1: HOKUREN INTERNAL USE ONLY
A2: 画面項目説明書 | AV2: 様式No. | AZ2: F4106-3D | BD2: PAGE
A3: システム名 | H3: 統合会計システム | AV3: 作成日 | AZ3: 45898
A4: 業務名 | H4: 共計 | AV4: 更新日
A6: 画面名 | H6: =変更履歴!H6 -> 滞留立替金利経理計上
A8: 検索結果表示領域一覧表示順
A9: No. | D9: 項目名（ソート項目順に列挙） | AT9: 表示順
A10: 1 | D10: 承認状況 | AT10: 差戻→下書保存→依頼中→承認済
A11: 2 | D11: 更新日 | AT11: 昇順
A12: 3 | D12: 経理日 | AT12: 昇順
A13: 4 | D13: 更新者 | AT13: 昇順
A14: 5 | D14: 伝票番号 | AT14: 昇順
A16: No. | D16: 項目名 | S16: I/O | V16: 桁数 | Z16: 属性 | AD16: 符号 | AG16: 初期値 | AJ16: 前回 | AM16: 項目編集説明
V17: 入力 | X17: 表示
A18: =ROW()-17 -> 1 | D18: 【検索条件エリア】 | V18: - | X18: -
A19: =ROW()-17 -> 2 | D19: 業種 | S19: I/O | V19: 2 | X19: 2 | Z19: 文字 | AJ19: 〇 | AM19: ログインしたユーザーの担当する業種のみを対象として抽出する。
A20: =ROW()-17 -> 3 | D20: 業種名 | S20: O | V20: - | X20: 10 | Z20: 文字 （全角） | AJ20: 〇 | AM20: 業種に対する名称を表示する
A21: =ROW()-17 -> 4 | D21: 共計組織 | S21: I/O | V21: 4 | X21: 4 | Z21: 文字 | AJ21: 〇 | AM21: 共計組織コードを入力する
A22: =ROW()-17 -> 5 | D22: 共計組織名 | S22: O | V22: - | X22: 15 | Z22: 文字 （全角） | AJ22: 〇 | AM22: 共計組織に対する名称を取得する
A23: =ROW()-17 -> 6 | D23: 共計区分 | S23: I/O | V23: - | X23: - | Z23: ﾁｪｯｸﾎﾞｯｸｽ | AG23: 〇 | AJ23: 〇 | AM23: チェックボックス 全道共計、地区共計、全国共計 初期値：全道共計
A24: =ROW()-17 -> 7 | D24: 収支管理品目 | S24: I/O | V24: 6 | X24: 6 | Z24: 文字 | AJ24: 〇 | AM24: 収支管理品目コードを入力する。 計上先収支管理品目を検索する。
A25: =ROW()-17 -> 8 | D25: 収支管理品目名 | S25: O | V25: - | X25: 20 | Z25: 文字 （全角） | AJ25: 〇 | AM25: 収支管理品目に対する名称を表示する
A26: =ROW()-17 -> 9 | D26: 年産 | S26: I/O | V26: 4 | X26: 4 | Z26: 数字 | AJ26: 〇 | AM26: 年産を入力する
A27: =ROW()-17 -> 10 | D27: 共計次数 | S27: I/O | V27: 2 | X27: 2 | Z27: 数字 | AJ27: 〇 | AM27: 共計次数を入力する
A28: =ROW()-17 -> 11 | D28: 更新者 | S28: I/O | V28: 20 | X28: 20 | Z28: 文字 （全角） | AG28: 〇 | AJ28: 〇 | AM28: 初期値：ログイン者の名称
A29: =ROW()-17 -> 12 | D29: 更新日（From） | S29: I/O | V29: 8 | X29: 10 | Z29: 数字 | AJ29: 〇 | AM29: 更新日の開始値を入力する
A30: =ROW()-17 -> 13 | D30: 更新日（To） | S30: I/O | V30: 8 | X30: 10 | Z30: 数字 | AJ30: 〇 | AM30: 更新日の終了値を入力する
A31: =ROW()-17 -> 14 | D31: 伝票番号 | S31: I/O | V31: 12 | X31: 12 | Z31: 文字 | AJ31: 〇 | AM31: 伝票番号を入力する
A32: =ROW()-17 -> 15 | D32: 承認状況 | S32: I/O | V32: 1 | X32: - | Z32: ﾁｪｯｸﾎﾞｯｸｽ | AG32: 〇 | AJ32: 〇 | AM32: 差戻、下書保存、依頼中を初期選択
A33: =ROW()-17 -> 16 | D33: 【明細表示エリア】 | V33: - | X33: -
A34: =ROW()-17 -> 17 | D34: 選択（明細） | S34: I | V34: - | X34: - | Z34: ﾁｪｯｸﾎﾞｯｸｽ | AM34: 初期値チェックなし
A35: =ROW()-17 -> 18 | D35: 承認状況（明細） | S35: O | V35: - | X35: 5 | Z35: 文字 （全角） | AM35: 承認状況を表示する
A36: =ROW()-17 -> 19 | D36: 更新日（明細） | S36: O | V36: - | X36: 10 | Z36: 数字 | AM36: 滞留立替金利計算結果情報の更新日を表示する
A37: =ROW()-17 -> 20 | D37: 経理日（明細） | S37: O | V37: - | X37: 10 | Z37: 数字 | AM37: 滞留立替金利計算結果情報の経理日を表示する
A38: =ROW()-17 -> 21 | D38: 更新者（明細） | S38: O | V38: - | X38: 20 | Z38: 文字 （全角） | AM38: 滞留立替金利計算結果情報の更新者をキーに職員マスタから取得した職員氏名を表示する
A39: =ROW()-17 -> 22 | D39: 業種（明細） | S39: O | V39: - | X39: 2 | Z39: 文字 | AM39: 滞留立替金利計算結果情報の業種を表示する
A40: =ROW()-17 -> 23 | D40: 業種名（明細） | S40: O | V40: - | X40: 15 | Z40: 文字 （全角） | AM40: 業種に対する名称を表示する
A41: =ROW()-17 -> 24 | D41: 共計組織（明細） | S41: O | V41: - | X41: 4 | Z41: 文字 | AM41: 滞留立替金利計算結果情報の共計組織を表示する
A42: =ROW()-17 -> 25 | D42: 共計組織名（明細） | S42: O | V42: - | X42: 15 | Z42: 文字 （全角） | AM42: 共計組織に対する名称を表示する
A43: =ROW()-17 -> 26 | D43: 共計区分（明細） | S43: O | V43: - | X43: 4 | Z43: 文字 （全角） | AM43: 滞留立替金利計算結果情報の共計区分に対する名称を表示する
...

Sheet 4.項目チェック（単体）_一覧表示
A1: Ｐｈａｓｅ 外部設計工程 | BJ1: HOKUREN INTERNAL USE ONLY
A2: 画面項目チェック（単体） | AV2: 様式No. | AZ2: F4106-4 | BD2: PAGE
A3: システム名 | H3: 統合会計システム | AV3: 作成日 | AZ3: 45898
A4: 業務名 | H4: 共計 | AV4: 更新日
A6: 画面名 | H6: =変更履歴!H6 -> 滞留立替金利経理計上
A8: No. | D8: 項目名 | R8: 必須 ﾁｪｯｸ | U8: 数字 ﾁｪｯｸ | X8: 文字数 ﾁｪｯｸ | AA8: 存在 ﾁｪｯｸ | AD8: ｺｰﾄﾞﾁｪｯｸ | AG8: チェック補足説明／メッセージ文言 | BD8: メッセージ コード | BK8: 仮メッセージ番号
A9: =ROW()-8 -> 1 | D9: 業種 | AA9: ○ | AG9: 業種マスタに存在しない場合エラー ／業種はマスタに存在しません。 | BK9: E000008
A10: =ROW()-8 -> 2 | D10: 共計組織 | AA10: ○ | AG10: 共計組織検索で参照するマスタに存在しない場合エラー ／共計組織はマスタに存在しません。 | BK10: E000008
A11: =ROW()-8 -> 3 | D11: 収支管理品目 | AA11: ○ | AG11: ／収支管理品目コードはマスタに存在しません。 | BK11: E000008
A12: =ROW()-8 -> 4 | D12: 年産 | X12: ○ | AG12: ４文字である事を確認する。 ／年産は４文字で入力してください。 | BK12: E000012
A13: =ROW()-8 -> 5 | D13: 共計次数 | X13: ○ | AG13: ２文字である事を確認する。 ／共計次数は２文字で入力してください。 | BK13: E000012
A14: =ROW()-8 -> 6 | D14: 更新日（From） | U14: ○ | AG14: 実在日でない場合、エラーとする。 ／更新日は有効な日付を入力してください。 | BK14: E000018
A15: =ROW()-8 -> 7 | D15: 更新日（To） | U15: ○ | AG15: 実在日でない場合、エラーとする。 ／更新日は有効な日付を入力してください。 | BK15: E000018

Sheet 5.項目チェック（関連）_一覧表示
A1: Ｐｈａｓｅ 外部設計局面 | BJ1: HOKUREN INTERNAL USE ONLY
A2: 画面項目チェック（関連） | AV2: 様式No. | AZ2: F4106-5 | BD2: PAGE
A3: システム名 | H3: 統合会計システム | AV3: 作成日 | AZ3: 45898
A4: 業務名 | H4: 共計 | AV4: 更新日
A6: 画面名 | H6: =変更履歴!H6 -> 滞留立替金利経理計上
A8: No. | D8: 関連チェック概要 | Q8: チェック詳細／メッセージ文言 | BD8: メッセージ コード
A9: =ROW()-8 -> 1 | D9: 更新日(From)と更新日(To)の検索範囲チェック | Q9: 更新日(From)、更新日(To)の両方を入力している且つ、 更新日(From)＞更新日(To)の場合はエラー ／更新日(From)は更新日(To)より過去の日付を入力してください。
A10: 2 | D10: 業種と共計組織 | Q10: 画面に入力した業種と入力者の所属する組織の組み合わせが「6．画面機能補足説明 ＜業種照会可能範囲＞」で定める業種以外の場合エラー ／業種は共計組織に応じた業種を入力してください。
A11: =ROW()-8 -> 3 | D11: 入力組織と共計組織 | Q11: 入力者の所属する組織が本所以外の場合、「6．画面機能補足説明 ＜共計組織照会可能範囲＞」で定める共計組織以外の場合エラー ／共計組織は担当の所属コードを入力してください。
A12: =ROW()-8 -> 4 | D12: 入力組織と更新者 | Q12: 「照会」ボタン押下時、入力した更新者の所属する組織が「6．画面機能補足説明 ＜共計組織照会可能範囲＞」で定める組織以外の場合エラー ／更新者は自組織に応じた更新者を入力してください。
A13: =ROW()-8 -> 5 | D13: 入力組織と収支管理品目 | Q13: 画面に入力した収支管理品目に紐づく業種と、入力者の所属する組織の組み合わせが「6．画面機能補足説明 ＜業種照会可能範囲＞」で定める業種以外の場合エラー ／収支管理品目は共計組織に応じた収支管理品目を入力してください。
A14: =ROW()-8 -> 6 | D14: 検索条件と対象データの 存在チェック | Q14: 「照会」ボタン押下時、検索条件に合致するデータが存在しない場合はエラー ／条件に該当するデータはありません。
A15: =ROW()-8 -> 7 | D15: 修正ボタンと明細未選択チェック | Q15: 「修正」ボタン押下時、明細を選択していない場合エラー ／明細を選択してください。
A16: =ROW()-8 -> 8 | D16: 修正ボタンと複数明細選択チェック | Q16: 「修正」ボタン押下時、複数明細を選択している場合エラー ／明細は１件のみ選択してください。
A17: =ROW()-8 -> 9 | D17: 修正ボタンと承認状況（依頼中）のチェック | Q17: 「修正」ボタン押下時、承認状況が「依頼中」の明細を選択している場合エラー ／依頼中の為、対象データは操作できません。
A18: =ROW()-8 -> 10 | D18: 修正ボタン承認状況（承認済）のチェック | Q18: 「修正」ボタン押下時、承認状況が「承認済」の明細を選択している場合エラー ／承認済の為、対象データは操作できません。
A19: =ROW()-8 -> 11 | D19: 削除ボタンと明細未選択のチェック | Q19: 「削除」ボタン押下時、明細を選択していない場合エラー ／明細を選択してください。
A20: =ROW()-8 -> 12 | D20: 削除ボタンと承認状況（依頼中）のチェック | Q20: 「削除」ボタン押下時、承認状況が「依頼中」の明細を1件でも選択している場合エラー ／依頼中の為、対象データは操作できません。
A21: =ROW()-8 -> 13 | D21: 削除ボタンと複数明細選択のチェック | Q21: 「削除」ボタン押下時、複数明細を選択している場合エラー ／明細は１件のみ選択してください。
A22: =ROW()-8 -> 14 | D22: 個別照会ボタンと明細未選択のチェック | Q22: 「個別照会」ボタン押下時、明細を選択していない場合エラー ／明細を選択してください。
... A30: =ROW()-8 -> 22 | D30: 承認依頼取下ボタンと入力組織のチェック | Q30: 「承認依頼取下」ボタン押下時、共計組織が担当の所属コード以外となる明細を1件でも選択している場合エラー ／共計組織が担当の所属コード以外となる明細は選択できません。

Sheet 2.レイアウト_作成
A1: Ｐｈａｓｅ 外部設計局面 | CG1: HOKUREN INTERNAL USE ONLY
A2: 画面レイアウト説明書 | BP2: 様式No. | BV2: F4106-2 | CA2: PAGE
A3: システム名 | L3: 統合会計システム | BP3: 作成日 | BV3: 2025/8/29
A4: 業務名 | L4: 共計 | BP4: 更新日
A7: 画面名 | L7: 滞留立替金利経理計上
D9: 【登録時】 | M9: ※初期表示
M10: 滞留立替金利経理計上 | BU10: 管理メニュー領域
H12: 一覧表示 | M12: ＞ | O12: 作成
H13: 検索条件を入力し、照会ボタンを押下して対象を検索してください。 検索結果より滞留立替金利情報を確認し、確認画面ボタンを押下してください。
H16: 基本情報
H17: 伝票番号 | AP17: 取引日 (*)
H18: 添付ファイル数 | AP18: 参照ＵＲＬ
H19: 検索条件
H20: 業種 (*) | AP20: 共計組織 (*)
H21: 共計区分 | R21: ◎ 全道共計 〇 地区共計 〇 全国共計 | AP21: 金利計算基準日 (*)
H22: 年産 (*)
H23: 収支管理品目 (*) | AP23: 共計次数 (*)
H24: 複数品目の発生金利を一つの指定品目に一括して金利計上する場合は、品目追加ボタンを押してください。
H27: 滞留立替金利情報
H28: 計上年月日 | U28: 滞留金利 | AY28: 立替金利
H29: 総金利
H30: 既計上金利
H31: 今回計上金利
H34: 承認情報
H35: 更新情報 | U35: 更新日時 | AH35: 所属 | BH35: 担当
E43: ※品目追加ボタン１回押下時
M44: 滞留立替金利経理計上 | BU44: 管理メニュー領域
H46: 一覧表示 | M46: ＞ | O46: 作成
H47: 検索条件を入力し、照会ボタンを押下して対象を検索してください。 検索結果より滞留立替金利情報を確認し、確認画面ボタンを押下してください。
H50: 基本情報
H51: 伝票番号 | AP51: 取引日 (*)
H52: 添付ファイル数 | AP52: 参照ＵＲＬ
H53: 検索条件
H54: 業種 (*) | AP54: 共計組織 (*)
H55: 共計区分 | R55: ◎ 全道共計 〇 地区共計 〇 全国共計 | AP55: 金利計算基準日 (*)
H56: 年産 (*)
H57: 収支管理品目 (*) | AP57: 共計次数 (*)
H58: 収支管理品目２ | AP58: 共計次数２
H59: 複数品目の発生金利を一つの指定品目に一括して金利計上する場合は、品目追加ボタンをおしてください。
H62: 滞留立替金利情報
...

Sheet 3.項目説明_作成
A1: Ｐｈａｓｅ 外部設計工程 | BJ1: HOKUREN INTERNAL USE ONLY
A2: 画面項目説明書 | AV2: 様式No. | AZ2: F4106-3D | BD2: PAGE
A3: システム名 | H3: 統合会計システム | AV3: 作成日 | AZ3: 45898
A4: 業務名 | H4: 共計 | AV4: 更新日
A6: 画面名 | H6: =変更履歴!H6 -> 滞留立替金利経理計上
A8: 検索結果表示領域一覧表示順
A9: No. | D9: 項目名（ソート項目順に列挙） | AT9: 表示順
A10: 1 | D10: 計上年月日
A13: No. | D13: 項目名 | S13: I/O | V13: 桁数 | Z13: 属性 | AD13: 符号 | AG13: 初期値 | AJ13: 前回 | AM13: 項目編集説明
V14: 入力 | X14: 表示
A15: =ROW()-14 -> 1 | D15: 【基本情報エリア】 | V15: - | X15: -
A16: =ROW()-14 -> 2 | D16: 伝票番号 | S16: O | V16: - | X16: 12 | Z16: 文字
A17: =ROW()-14 -> 3 | D17: 取引日 | S17: I/O | V17: 8 | X17: 10 | Z17: 数字 | AG17: 〇 | AM17: 取引日を入力する。ＶＢ期間であれば前月末日、ＶＢ期間外であれば運用管理日（当日）を設定する。
A18: =ROW()-14 -> 4 | D18: 添付ファイル | S18: O | V18: - | X18: 2 | Z18: 数字
A19: =ROW()-14 -> 5 | D19: 参照ＵＲＬ | S19: I/O | V19: 200 | X19: 200 | Z19: 文字
A20: =ROW()-14 -> 6 | D20: 【検索条件エリア】 | V20: - | X20: -
A21: =ROW()-14 -> 7 | D21: 業種 | S21: I/O | V21: 2 | X21: 2 | Z21: 文字 | AM21: 滞留立替金利計算結果情報の業種を入力する
A22: =ROW()-14 -> 8 | D22: 業種名 | S22: O | V22: - | X22: 10 | Z22: 文字 （全角） | AM22: 業種に対する名称を表示する
A23: =ROW()-14 -> 9 | D23: 共計組織 | S23: I/O | V23: 4 | X23: 4 | Z23: 文字 | AM23: 滞留立替金利計算結果情報の共計組織を入力する
A24: =ROW()-14 -> 10 | D24: 共計組織名 | S24: O | V24: - | X24: 15 | Z24: 文字 （全角） | AM24: 共計組織に対する名称を表示する
A25: =ROW()-14 -> 11 | D25: 共計区分 | S25: I/O | V25: - | X25: - | Z25: ﾗｼﾞｵボタン | AG25: 〇 | AM25: ラジオボタン 全道共計 地区共計 全国共計 初期値：全道共計
A26: =ROW()-14 -> 12 | D26: 金利計算基準日 | S26: I/O | V26: 8 | X26: 10 | Z26: 数字 | AM26: 金利計算基準日を入力する。
A27: =ROW()-14 -> 13 | D27: 収支管理品目 | S27: I/O | V27: 6 | X27: 6 | Z27: 文字 | AM27: 収支管理品目コードを入力する
A28: =ROW()-14 -> 14 | D28: 収支管理品目名 | S28: O | V28: - | X28: 20 | Z28: 文字 （全角） | AM28: 収支管理品目に対する名称を表示する
A29: =ROW()-14 -> 15 | D29: 年産 | S29: I/O | V29: 4 | X29: 4 | Z29: 数字 | AM29: 年産を入力する
A30: =ROW()-14 -> 16 | D30: 共計次数 | S30: I/O | V30: 2 | X30: 2 | Z30: 数字 | AM30: 共計次数を入力する
A31: =ROW()-14 -> 17 | D31: 収支管理品目２ | S31: I/O | V31: 6 | X31: 6 | Z31: 文字 | AM31: 収支管理品目コードを入力する
A32: =ROW()-14 -> 18 | D32: 収支管理品目名２ | S32: O | V32: - | X32: 20 | Z32: 文字 （全角） | AM32: 収支管理品目２に対する名称を表示する
A33: =ROW()-14 -> 19 | D33: 共計次数２ | S33: I/O | V33: 2 | X33: 2 | Z33: 数字 | AM33: 共計次数を入力する
A34: =ROW()-14 -> 20 | D34: 収支管理品目３ | S34: I/O | V34: 6 | X34: 6 | Z34: 文字 | AM34: 収支管理品目コードを入力する
A35: =ROW()-14 -> 21 | D35: 収支管理品目名３ | S35: O | V35: - | X35: 20 | Z35: 文字 （全角） | AM35: 収支管理品目３に対する名称を表示する
A36: =ROW()-14 -> 22 | D36: 共計次数３ | S36: I/O | V36: 2 | X36: 2 | Z36: 数字 | AM36: 共計次数を入力する
A37: =ROW()-14 -> 23 | D37: 【明細エリア】 | V37: - | X37: -
A38: =ROW()-14 -> 24 | D38: 計上年月日（明細） | S38: O | V38: - | X38: 10 | Z38: 数字 | AM38: 滞留立替金利計算結果情報の計上年月日をYYYY/MM/DD形式で表示する
A39: =ROW()-14 -> 25 | D39: 滞留金利（明細） | S39: O | V39: - | X39: 18 | Z39: 数字 | AD39: ○ | AM39: 滞留立替金利計算結果情報の滞留金利をカンマ編集して表示する
A40: =ROW()-14 -> 26 | D40: 立替金利（明細） | S40: O | V40: - | X40: 18 | Z40: 数字 | AD40: ○ | AM40: 滞留立替金利計算結果情報の立替金利をカンマ編集して表示する
A41: =ROW()-14 -> 27 | D41: 滞留金利（総金利） | S41: O | V41: - | X41: 18 | Z41: 数字 | AD41: ○ | AM41: 一覧上に表示されている滞留金利の合計をカンマ編集して表示する
A42: =ROW()-14 -> 28 | D42: 立替金利（総金利） | S42: O | V42: - | X42: 18 | Z42: 数字 | AD42: ○ | AM42: 一覧上に表示されている立替金利の合計をカンマ編集して表示する
A43: =ROW()-14 -> 29 | D43: 滞留金利（既計上金利） | S43: O | V43: - | X43: 18 | Z43: 数字 | AD43: ○ | AM43: 既計上分の滞留金利の合計をカンマ編集して表示する
A44: =ROW()-14 -> 30 | D44: 立替金利（既計上金利） | S44: O | V44: - | X44: 18 | Z44: 数字 | AD44: ○ | AM44: 既計上分の立替金利の合計をカンマ編集して表示する
...

Sheet 4.項目チェック（単体）_作成
A1: Ｐｈａｓｅ 外部設計工程 | BJ1: HOKUREN INTERNAL USE ONLY
A2: 画面項目チェック（単体） | AV2: 様式No. | AZ2: F4106-4 | BD2: PAGE
A3: システム名 | H3: 統合会計システム | AV3: 作成日 | AZ3: 45898
A4: 業務名 | H4: 共計 | AV4: 更新日
A6: 画面名 | H6: =変更履歴!H6 -> 滞留立替金利経理計上
A8: No. | D8: 項目名 | R8: 必須 ﾁｪｯｸ | U8: 数字 ﾁｪｯｸ | X8: 文字数 ﾁｪｯｸ | AA8: 存在 ﾁｪｯｸ | AD8: ｺｰﾄﾞﾁｪｯｸ | AG8: チェック補足説明／メッセージ文言 | BD8: メッセージ コード | BK8: 仮メッセージ番号
A9: =ROW()-8 -> 1 | D9: 取引日 | R9: ○ | AG9: ／取引日を入力してください。 | BK9: E000001
A10: =ROW()-8 -> 2 | U10: ○ | AG10: 実在日でない場合、エラーとする。 ／取引日は有効な日付を入力してください。 | BK10: E000018
A11: =ROW()-8 -> 3 | AD11: ○ | AG11: 取引日が未来日の場合、エラーとする。 ／取引日に未来日は入力できません。 | BK11: E000032
A12: =ROW()-8 -> 4 | D12: 業種 | R12: ○ | AG12: ／業種コードを入力してください。 | BK12: E000001
A13: =ROW()-8 -> 5 | AA13: ○ | AG13: ／業種はマスタに存在しません。 | BK13: E000008
A14: =ROW()-8 -> 6 | D14: 共計組織 | R14: ○ | AG14: ／共計組織を入力してください。 | BK14: E000001
A15: =ROW()-8 -> 7 | AA15: ○ | AG15: ／共計組織はマスタに存在しません。 | BK15: E000008
A16: =ROW()-8 -> 8 | D16: 金利計算基準日 | R16: ○ | AG16: ／金利計算基準日を入力してください。 | BK16: E000001
A17: =ROW()-8 -> 9 | U17: ○ | AG17: 実在日でない場合、エラーとする。 ／金利計算基準日は有効な日付を入力してください。 | BK17: E000018
A18: =ROW()-8 -> 10 | D18: 収支管理品目 | R18: ○ | AG18: ／収支管理品目を入力してください。 | BK18: E000001
A19: =ROW()-8 -> 11 | AA19: ○ | AG19: ／収支管理品目コードはマスタに存在しません。 | BK19: E000008
A20: =ROW()-8 -> 12 | D20: 年産 | R20: 〇 | AG20: ／年産を入力してください。 | BK20: E000001
A21: =ROW()-8 -> 13 | X21: ○ | AG21: ４文字である事を確認する。 ／年産は４文字で入力してください。 | BK21: E000012
A22: =ROW()-8 -> 14 | D22: 共計次数 | R22: 〇 | AG22: ／共計次数を入力してください。 | BK22: E000001
A23: =ROW()-8 -> 15 | X23: ○ | AG23: ２文字である事を確認する。 ／共計次数は２文字で入力してください。 | BK23: E000012
A24: =ROW()-8 -> 16 | D24: 収支管理品目２ | AA24: ○ | AG24: ／収支管理品目コードはマスタに存在しません。 | BK24: E000008
A25: =ROW()-8 -> 17 | D25: 共計次数２ | X25: ○ | AG25: ２文字である事を確認する。 ／共計次数は２文字で入力してください。 | BK25: E000012
A26: =ROW()-8 -> 18 | D26: 収支管理品目３ | AA26: ○ | AG26: ／収支管理品目コードはマスタに存在しません。 | BK26: E000008
A27: =ROW()-8 -> 19 | D27: 共計次数３ | X27: ○ | AG27: ２文字である事を確認する。 ／共計次数は２文字で入力してください。 | BK27: E000012

Sheet 5.項目チェック（関連）_作成
A1: Ｐｈａｓｅ 外部設計局面 | BJ1: HOKUREN INTERNAL USE ONLY
A2: 画面項目チェック（関連） | AV2: 様式No. | AZ2: F4106-5 | BD2: PAGE
A3: システム名 | H3: 統合会計システム | AV3: 作成日 | AZ3: 45898
A4: 業務名 | H4: 共計 | AV4: 更新日
A6: 画面名 | H6: =変更履歴!H6 -> 滞留立替金利経理計上
A8: No. | D8: 関連チェック概要 | Q8: チェック詳細／メッセージ文言 | BD8: メッセージ コード
A9: 1 | D9: 収支管理品目２・共計次数２ | Q9: いずれかを入力かつ、収支管理品目２・共計次数２全て入力されていない場合、エラー ／収支管理品目２・共計次数２はすべて入力してください。
A10: 2 | D10: 収支管理品目３・共計次数３ | Q10: いずれかを入力かつ、収支管理品目３・共計次数３全て入力されていない場合、エラー ／収支管理品目３・共計次数３はすべて入力してください。
A11: 3 | D11: 取引日とVB期間の 組み合わせチェック | Q11: ＶＢ期間中に取引日が当月日付の場合、警告する。 ／取引日が入力月となっているため、入力月の経理となりますが、よろしいですか？ 前月経理とする場合は、取引日に前月末日以前を入力してください。
A12: 4 | D12: 検索条件と対象データの 存在チェック | Q12: 「照会」ボタン押下時、検索条件に合致するデータが存在しない場合はエラー ／条件に該当するデータはありません。
A13: 5 | D13: 業種と共計組織 | Q13: 入力した業種と入力者の所属する組織の組み合わせが「6．画面機能補足説明 ＜業種入力可能範囲＞」で定める業種以外の場合エラー ／業種は共計組織に応じた業種を入力してください。
A14: 6 | D14: 入力組織と共計組織 | Q14: 入力した共計組織コードが「6．画面機能補足説明 ＜共計組織入力可能範囲＞」で定める共計組織以外の場合エラー ／共計組織は担当の所属コードを入力してください。
A15: 7 | D15: 入力組織と共計区分 | Q15: 入力者の所属する組織が支所 かつ 全道共計・全国共計を選択した場合エラー ／所属組織が支所の場合、全道共計・全国共計は選択できません。
A16: 8 | D16: 入力組織と共計区分 | Q16: 入力者の所属する組織が本所 かつ 地区共計を選択した場合エラー ／所属組織が本所の場合、地区共計は選択できません。
A17: 9 | D17: 計上対象収支管理品目 | Q17: 対象の収支管理品目が２つ以上 かつ 計上対象収支管理品目未選択の場合エラー ／計上対象収支管理品目を選択してください。

Sheet 2.レイアウト_確認
A1: Ｐｈａｓｅ 外部設計局面 | CG1: HOKUREN INTERNAL USE ONLY
A2: 画面レイアウト説明書 | BP2: 様式No. | BV2: F4106-2 | CA2: PAGE
A3: システム名 | L3: 統合会計システム | BP3: 作成日 | BV3: 2025/8/29
A4: 業務名 | L4: 共計 | BP4: 更新日
A7: 画面名 | L7: 滞留立替金利経理計上
D9: 【登録・修正時】
M10: 滞留立替金利経理計上 | BU10: 管理メニュー領域
H12: 一覧表示 | M12: ＞ | O12: 作成 | S12: ＞ | U12: 確認
H13: 内容を確認し、申請ボタンを押下してください。
H15: 基本情報
H16: 伝票番号 | S16: YY9999999-99 | AP16: 取引日 | BA16: 2025/03/31
H17: 添付ファイル数 | S17: 3 | AP17: 参照ＵＲＬ | BA17: hhhttp//aaa
H18: 業種 | S18: 10 雑穀 | AP18: 共計組織 | BA18: 4137 農産部雑穀課
H19: 共計区分 | S19: 全道共計 | AP19: 金利計算基準日 | BA19: 2025/03/31
H20: 年産 | S20: 2024
H21: 収支管理品目 | S21: 191113 小豆 | AP21: 共計次数 | BA21: 01
H22: 収支管理品目２ | S22: 191114 赤系金時 | AP22: 共計次数２ | BA22: 01
H23: 収支管理品目３ | AP23: 共計次数３
H26: 滞留立替金利情報
H27: 計上年月日 | U27: 滞留金利 | AY27: 立替金利
I28: 2024/10/31 | V28: 1000
I29: 2024/11/30 | V29: 2000
I30: 2024/12/31 | V30: 1500
I31: 2024/01/10 | V31: 1200
I32: 2025/01/31 | V32: 1000 | AZ32: 390
I33: 2025/02/28 | V33: 270
I34: 2025/03/31 | V34: 2300
H35: 総金利 | V35: =U36+V37 -> 9270 | AZ35: =BA36+AZ37 -> 390
H36: 既計上金利 | U36: 0 | BA36: 0
H37: 今回計上金利 | V37: =SUM(V28:V34) -> 9270 | AZ37: =SUM(AZ28:AZ34) -> 390
H38: 計上対象収支管理品目 | W38: 191113 小豆 2024 01
H40: 承認情報
H41: 更新情報 | U41: 更新日時 | AH41: 所属 | BH41: 担当
H42: 更新者 | U42: 2025/01/01 01:01:01 | AH42: 経理部 主計課 | BH42: 山田 花子
H43: 承認/差戻者 | U43: 2025/01/01 01:01:01 | AH43: 経理部 主計課 | BH43: 田中 太郎
H44: 差戻コメント | U44: ○○を△△に修正してください。
D50: 【削除時】
M51: 滞留立替金利経理計上 | BU51: 管理メニュー領域
H53: 一覧表示 | M53: ＞ | O53: 確認
H54: 内容を確認し、申請ボタンを押下してください。
...

Sheet 3.項目説明_確認
A1: Ｐｈａｓｅ 外部設計工程 | BJ1: HOKUREN INTERNAL USE ONLY
A2: 画面項目説明書 | AV2: 様式No. | AZ2: F4106-3D | BD2: PAGE
A3: システム名 | H3: 統合会計システム | AV3: 作成日 | AZ3: 45898
A4: 業務名 | H4: 共計 | AV4: 更新日
A6: 画面名 | H6: =変更履歴!H6 -> 滞留立替金利経理計上
A8: 検索結果表示領域一覧表示順
A9: No. | D9: 項目名（ソート項目順に列挙） | AT9: 表示順
A10: 1 | D10: 計上年月日
A13: No. | D13: 項目名 | S13: I/O | V13: 桁数 | Z13: 属性 | AD13: 符号 | AG13: 初期値 | AJ13: 前回 | AM13: 項目編集説明
V14: 入力 | X14: 表示
A15: =ROW()-14 -> 1 | D15: 【基本情報エリア】 | V15: - | X15: -
A16: =ROW()-14 -> 2 | D16: 伝票番号 | S16: O | V16: - | X16: 12 | Z16: 文字
A17: =ROW()-14 -> 3 | D17: 取引日 | S17: O | V17: - | X17: 10 | Z17: 数字 | AM17: 取引日を表示する。
A18: =ROW()-14 -> 4 | D18: 添付ファイル | S18: O | V18: - | X18: 2 | Z18: 数字
A19: =ROW()-14 -> 5 | D19: 参照ＵＲＬ | S19: O | V19: - | X19: 200 | Z19: 文字
A20: =ROW()-14 -> 6 | D20: 業種 | S20: O | V20: - | X20: 2 | Z20: 文字 （全角） | AM20: 滞留立替金利計算結果情報の業種を表示する
A21: =ROW()-14 -> 7 | D21: 業種名 | S21: O | V21: - | X21: 10 | Z21: 文字 （全角） | AM21: 業種に対する名称を表示する
A22: =ROW()-14 -> 8 | D22: 共計組織 | S22: O | V22: - | X22: 4 | Z22: 文字 | AM22: 滞留立替金利計算結果情報の共計組織を表示する
A23: =ROW()-14 -> 9 | D23: 共計組織名 | S23: O | V23: - | X23: 15 | Z23: 文字 （全角） | AM23: 共計組織に対する名称を表示する
A24: =ROW()-14 -> 10 | D24: 共計区分 | S24: O | V24: - | X24: 4 | Z24: 文字 （全角） | AM24: 滞留立替金利計算結果情報の共計区分に対する名称を表示する
A25: =ROW()-14 -> 11 | D25: 金利計算基準日 | S25: O | V25: - | X25: 10 | Z25: 数字 | AM25: 金利計算基準日を表示する。
A26: =ROW()-14 -> 12 | D26: 収支管理品目 | S26: O | V26: - | X26: 6 | Z26: 文字 | AM26: 収支管理品目コードを表示する
A27: =ROW()-14 -> 13 | D27: 収支管理品目名 | S27: O | V27: - | X27: 20 | Z27: 文字 （全角） | AM27: 収支管理品目に対する名称を表示する
A28: =ROW()-14 -> 14 | D28: 年産 | S28: O | V28: - | X28: 4 | Z28: 数字 | AM28: 年産を表示する
A29: =ROW()-14 -> 15 | D29: 共計次数 | S29: O | V29: - | X29: 2 | Z29: 数字 | AM29: 共計次数を表示する
A30: =ROW()-14 -> 16 | D30: 収支管理品目２ | S30: O | V30: - | X30: 6 | Z30: 文字 | AM30: 収支管理品目コードを表示する
A31: =ROW()-14 -> 17 | D31: 収支管理品目名２ | S31: O | V31: - | X31: 20 | Z31: 文字 （全角） | AM31: 収支管理品目２に対する名称を表示する
... A35: =ROW()-14 -> 21 | D35: 共計次数３ | S35: O | V35: - | X35: 2 | Z35: 数字 | AM35: 共計次数を表示する
A36: =ROW()-14 -> 22 | D36: 【明細エリア】 | V36: - | X36: -
A37: =ROW()-14 -> 23 | D37: 計上年月日（明細） | S37: O | V37: - | X37: 10 | Z37: 数字 | AM37: 滞留立替金利計算結果情報の計上年月日をYYYY/MM/DD形式で表示する
A38: =ROW()-14 -> 24 | D38: 滞留金利（明細） | S38: O | V38: - | X38: 18 | Z38: 数字 | AD38: 〇 | AM38: 滞留立替金利計算結果情報の滞留金利をカンマ編集して表示する
A39: =ROW()-14 -> 25 | D39: 立替金利（明細） | S39: O | V39: - | X39: 18 | Z39: 数字 | AD39: 〇 | AM39: 滞留立替金利計算結果情報の立替金利をカンマ編集して表示する
A40: =ROW()-14 -> 26 | D40: 滞留金利（総金利） | S40: O | V40: - | X40: 18 | Z40: 数字 | AD40: 〇 | AM40: 一覧上に表示されている滞留金利の合計をカンマ編集して表示する
A41: =ROW()-14 -> 27 | D41: 立替金利（総金利） | S41: O | V41: - | X41: 18 | Z41: 数字 | AD41: 〇 | AM41: 一覧上に表示されている立替金利の合計をカンマ編集して表示する
A42: =ROW()-14 -> 28 | D42: 滞留金利（既計上金利） | S42: O | V42: - | X42: 18 | Z42: 数字 | AD42: 〇 | AM42: 既計上分の滞留金利の合計をカンマ編集して表示する
A43: =ROW()-14 -> 29 | D43: 立替金利（既計上金利） | S43: O | V43: - | X43: 18 | Z43: 数字 | AD43: 〇 | AM43: 既計上分の立替金利の合計をカンマ編集して表示する
A44: =ROW()-14 -> 30 | D44: 滞留金利（今回計上金利） | S44: O | V44: - | X44: 18 | Z44: 数字 | AD44: 〇 | AM44: 滞留金利（総金利）－ 滞留金利（既計上金利）をカンマ編集して表示する
A45: =ROW()-14 -> 31 | D45: 立替金利（今回計上金利） | S45: O | V45: - | X45: 18 | Z45: 数字 | AD45: 〇 | AM45: 立替金利（総金利）－ 立替金利（既計上金利）をカンマ編集して表示する
A46: =ROW()-14 -> 32 | D46: 【プルダウンリスト項目】 | V46: - | X46: -
A47: =ROW()-14 -> 33 | D47: 計上対象収支管理品目 | S47: O | V47: - | X47: 6 | Z47: 文字 | AM47: 一覧画面で選択した明細の収支管理品目コードを表示する
...

Sheet 4.項目チェック（単体）_確認
A1: Ｐｈａｓｅ 外部設計工程 | BJ1: HOKUREN INTERNAL USE ONLY
A2: 画面項目チェック（単体） | AV2: 様式No. | AZ2: F4106-4 | BD2: PAGE
A3: システム名 | H3: 統合会計システム | AV3: 作成日 | AZ3: 45898
A4: 業務名 | H4: 共計 | AV4: 更新日
A6: 画面名 | H6: =変更履歴!H6 -> 滞留立替金利経理計上
A8: No. | D8: 項目名 | R8: 必須 ﾁｪｯｸ | U8: 数字 ﾁｪｯｸ | X8: 文字数 ﾁｪｯｸ | AA8: 存在 ﾁｪｯｸ | AD8: ｺｰﾄﾞﾁｪｯｸ | AG8: チェック補足説明／メッセージ文言 | BD8: メッセージ コード
AG9: チェック項目なし

Sheet 5.項目チェック（関連）_確認
A1: Ｐｈａｓｅ 外部設計局面 | BJ1: HOKUREN INTERNAL USE ONLY
A2: 画面項目チェック（関連） | AV2: 様式No. | AZ2: F4106-5 | BD2: PAGE
A3: システム名 | H3: 統合会計システム | AV3: 作成日 | AZ3: 45898
A4: 業務名 | H4: 共計 | AV4: 更新日
A6: 画面名 | H6: =変更履歴!H6 -> 滞留立替金利経理計上
A8: No. | D8: 関連チェック概要 | Q8: チェック詳細／メッセージ文言 | BD8: メッセージ コード
Q9: チェックなし

Sheet 6．画面機能補足説明
A1: Ｐｈａｓｅ 外部設計工程 | BJ1: HOKUREN INTERNAL USE ONLY
A2: 画面機能補足説明 | AV2: 様式No. | AZ2: F4106-6 | BD2: PAGE
A3: システム名 | H3: 統合会計システム | AV3: 作成日 | AZ3: 45898
A4: 業務名 | H4: 共計 | AV4: 更新日
A6: 機能Ｎｏ． | H6: 9.2.5 | O6: 機能名称 | V6: =変更履歴!H6 -> 滞留立替金利経理計上
B8: 【画面機能補足説明】
C10: １．照会・入力可能範囲
C11: ＜業種照会可能範囲＞
E12: ・入力者の所属組織コードに応じて選択可能な業種を組織・業種マスタから取得し、取得できた業種のみ照会できる。
D13: 【特記事項】
E14: ・経理部は全ての業種を照会できる。
C16: ＜業種入力可能範囲＞
E17: ・入力者の所属組織コードに応じて選択可能な業種を組織・業種マスタから取得し、取得できた業種のみ入力できる。
D18: 【特記事項】
E19: ・経理部は全ての業種を入力できる。
C21: ＜共計組織 照会可能範囲＞
D22: 【入力者の所属が本所以外の場合】
E23: ・入力者の所属組織のみ照会できる。
E24: ・ただし入力者の所属組織が支所管理課の場合、支所内の担当業種を取り扱う組織も照会できる。
F25: ※支所管理課の情報は会計コードマスタ(事業所／管理組織)を元に取得する。
D26: 【入力者の所属が本所の場合】
E27: ・担当業種を取り扱う、すべての組織を照会できる。
D28: 【特記事項】
E29: ・経理部は全ての組織を照会できる。
C31: ＜共計組織 入力可能範囲＞
D32: 【入力者の所属が本所以外の場合】
E33: ・入力者の所属組織のみ入力できる。
E34: ・ただし入力者の所属組織が支所管理課の場合、支所内の担当業種を取り扱う組織も入力できる。
F35: ※支所管理課の情報は会計コードマスタ(事業所／管理組織)を元に取得する。
D36: 【入力者の所属が本所の場合】
E37: ・入力者の所属組織のみ入力できる。
D38: 【特記事項】
E39: ・経理部は全ての組織を入力できる。
