Workbook

Sheet 変更履歴
A1: Ｐｈａｓｅ 外部設計工程 | BJ1: HOKUREN INTERNAL USE ONLY
A2: 画面設計書 変更履歴 | AV2: 様式No. | AZ2: F4106-0 | BD2: PAGE
A3: システム名 | H3: 統合会計システム | AV3: 作成日 | AZ3: 2025/8/29
A4: 業務名 | H4: 共計 | AV4: 更新日
A6: 機能名称 | H6: 滞留立替金利計算書作成 | AV6: メニューコード
A8: 管理番号 | I8: 案件名 / 障害・問合せ件名
B10: 24058 | I10: 基幹システム再構築 会計システム外部設計

Sheet 1.遷移図
A1: Ｐｈａｓｅ 外部設計局面 | CQ1: HOKUREN INTERNAL USE ONLY
A2: 画 面 遷 移 図 | BY2: 様式No. | CF2: F4106-1 | CJ2: PAGE
A3: システム名 | J3: 統合会計システム | BY3: 作成日 | CF3: 2025/8/29
A4: 業務名 | J4: =変更履歴!H4 -> 共計 | BY4: 更新日
A6: 機能Ｎｏ． | J6: 9.2.2 | U6: 機能名称 | AD6: =変更履歴!H6 -> 滞留立替金利計算書作成 | BY6: メニューコード
B9: 【画面利用条件】 | K9: ※利用可能ユーザー、利用可能組織など利用制限の有無。 利用可能とする条件を記載。
D11: 利用組織 ： | K11: 経理部、現業部門

Sheet 2.レイアウト（作成_初期状態）
A1: Ｐｈａｓｅ 外部設計局面 | CG1: HOKUREN INTERNAL USE ONLY
A2: 画面レイアウト説明書 | BP2: 様式No. | BV2: F4106-2 | CA2: PAGE
A3: システム名 | L3: 統合会計システム | BP3: 作成日 | BV3: 2025/8/29
A4: 業務名 | L4: =変更履歴!H4 -> 共計 | BP4: 更新日
A7: 画面名 | L7: =変更履歴!H6 -> 滞留立替金利計算書作成
C10: ※初期表示
L11: 滞留立替金利計算書作成 | BV11: 管理メニュー領域
D15: 滞留立替金利計算書作成
D17: 出力条件を入力し、「CSV出力」ボタンまたは「印刷」ボタンを押してください。
D19: 検索条件
D20: 業種(*)
D21: 共計区分(*) | N21: □ 全道共計 □ 地区共計 □ 全国共計
D22: 共計組織 | AS22: 対象年月日 | BI22: -
D23: 年産
D24: 収支管理品目 | AS24: 共計次数
M25: 複数品目を指定して金利計算書を出力する場合は、品目追加ボタンを押してください。
C43: ※品目追加ボタン１回押下時
L44: 滞留立替金利計算書作成 | BV44: 管理メニュー領域
D48: 滞留立替金利計算書作成
D50: 出力条件を入力し、「CSV出力」ボタンまたは「印刷」ボタンを押してください。
D52: 検索条件
D53: 業種(*)
D54: 共計区分 | N54: □ 全道共計 □ 地区共計 □ 全国共計
D55: 共計組織 | AS55: 対象年月日 | BI55: -
D56: 年産
D57: 収支管理品目 | AS57: 共計次数
D58: 収支管理品目２ | AS58: 共計次数２
M59: 複数品目を指定して金利計算書を出力する場合は、品目追加ボタンを押してください。
C78: ※品目追加ボタン２回押下時
L79: 滞留立替金利計算書作成 | BV79: 管理メニュー領域
D83: 滞留立替金利計算書作成
D85: 出力条件を入力し、「CSV出力」ボタンまたは「印刷」ボタンを押してください。
D87: 検索条件
D88: 業種(*)
D89: 共計区分 | N89: □ 全道共計 □ 地区共計 □ 全国共計
D90: 共計組織 | AS90: 対象年月日 | BI90: -
D91: 年産
D92: 収支管理品目 | AS92: 共計次数
D93: 収支管理品目２ | AS93: 共計次数２
D94: 収支管理品目３ | AS94: 共計次数３
...

Sheet 3.項目説明
A1: Ｐｈａｓｅ 外部設計工程 | BJ1: HOKUREN INTERNAL USE ONLY
A2: 画面項目説明書 | AV2: 様式No. | AZ2: F4106-3D | BD2: PAGE
A3: システム名 | H3: 統合会計システム | AV3: 作成日 | AZ3: 45898
A4: 業務名 | H4: =変更履歴!H4 -> 共計 | AV4: 更新日
A6: 画面名 | H6: =変更履歴!H6 -> 滞留立替金利計算書作成
A8: 検索結果表示領域一覧表示順
A9: No. | D9: 項目名（ソート項目順に列挙） | AT9: 表示順
D10: 無し
A14: No. | D14: 項目名 | S14: I/O | V14: 桁数 | Z14: 属性 | AD14: 符号 | AG14: 初期値 | AJ14: 前回 | AM14: 項目編集説明
V15: 入力 | X15: 表示
A16: =ROW()-15 -> 1 | D16: 業種 | S16: I/O | V16: 2 | X16: 2 | Z16: 文字 | AM16: ログインしたユーザーの担当する業種のみを対象として抽出する。
A17: =ROW()-15 -> 2 | D17: 業種名 | S17: O | V17: - | X17: 10 | Z17: 文字 （全角） | AJ17: 〇
A18: =ROW()-15 -> 3 | D18: 共計区分 | S18: I/O | V18: 1 | X18: 5 | Z18: ﾁｪｯｸﾎﾞｯｸｽ | AM18: チェックボックス 全道共計、地区共計、全国共計 初期値なし
A19: =ROW()-15 -> 4 | D19: 共計組織 | S19: I/O | V19: 4 | X19: 4 | Z19: 文字 | AJ19: 〇 | AM19: 共計組織コードを入力する
A20: =ROW()-15 -> 5 | D20: 共計組織名 | S20: O | V20: - | X20: 15 | Z20: 文字 （全角） | AJ20: 〇 | AM20: 共計組織に対する名称を取得する
A21: =ROW()-15 -> 6 | D21: 収支管理品目 | S21: I/O | V21: 6 | X21: 6 | Z21: 文字 | AJ21: 〇 | AM21: 収支管理品目コードを入力する。 計上先収支管理品目を検索する。
A22: =ROW()-15 -> 7 | D22: 収支管理品目名 | S22: O | V22: - | X22: 25 | Z22: 文字 （全角） | AJ22: 〇 | AM22: 収支管理品目に対する名称を表示する
A23: =ROW()-15 -> 8 | D23: 年産 | S23: I/O | V23: 4 | X23: 4 | Z23: 数字 | AJ23: 〇 | AM23: 年産を入力する
A24: =ROW()-15 -> 9 | D24: 共計次数 | S24: I/O | V24: 2 | X24: 2 | Z24: 数字 | AJ24: 〇 | AM24: 共計次数を入力する
A25: =ROW()-15 -> 10 | D25: 収支管理品目２ | S25: I/O | V25: 6 | X25: 6 | Z25: 文字 | AJ25: 〇 | AM25: 収支管理品目コードを入力する。 計上先収支管理品目を検索する。
A26: =ROW()-15 -> 11 | D26: 収支管理品目名２ | S26: O | V26: - | X26: 25 | Z26: 文字 （全角） | AJ26: 〇 | AM26: 収支管理品目に対する名称を表示する
A27: =ROW()-15 -> 12 | D27: 共計次数２ | S27: I/O | V27: 2 | X27: 2 | Z27: 数字 | AJ27: 〇 | AM27: 共計次数を入力する
A28: =ROW()-15 -> 13 | D28: 収支管理品目３ | S28: I/O | V28: 6 | X28: 6 | Z28: 文字 | AJ28: 〇 | AM28: 収支管理品目コードを入力する。 計上先収支管理品目を検索する。
A29: =ROW()-15 -> 14 | D29: 収支管理品目名３ | S29: O | V29: - | X29: 25 | Z29: 文字 （全角） | AJ29: 〇 | AM29: 収支管理品目に対する名称を表示する
A30: =ROW()-15 -> 15 | D30: 共計次数３ | S30: I/O | V30: 2 | X30: 2 | Z30: 数字 | AJ30: 〇 | AM30: 共計次数を入力する
... A32: =ROW()-15 -> 17 | D32: 対象年月日（To） | S32: I/O | V32: 8 | X32: 10 | Z32: 数字 | AJ32: 〇 | AM32: 対象年月日の終了値を入力する。（空欄不可）

Sheet 4.項目チェック（単体）
A1: Ｐｈａｓｅ 外部設計工程 | BJ1: HOKUREN INTERNAL USE ONLY
A2: 画面項目チェック（単体） | AV2: 様式No. | AZ2: F4106-4 | BD2: PAGE
A3: システム名 | H3: 統合会計システム | AV3: 作成日 | AZ3: 45898
A4: 業務名 | H4: =変更履歴!H4 -> 共計 | AV4: 更新日
A6: 画面名 | H6: =変更履歴!H6 -> 滞留立替金利計算書作成
A8: No. | D8: 項目名 | R8: 必須 ﾁｪｯｸ | U8: 数字 ﾁｪｯｸ | X8: 文字数 ﾁｪｯｸ | AA8: 存在 ﾁｪｯｸ | AD8: ｺｰﾄﾞﾁｪｯｸ | AG8: チェック補足説明／メッセージ文言 | BD8: メッセージ コード | BK8: 仮メッセージ番号
A9: =ROW()-8 -> 1 | D9: 業種 | R9: ○ | AG9: ／業種を入力してください。 | BK9: E000001
A10: =ROW()-8 -> 2 | AA10: ○ | AG10: 業種マスタに存在しない場合エラー ／業種はマスタに存在しません。 | BK10: E000008
A11: =ROW()-8 -> 3 | D11: 共計組織 | AA11: ○ | AG11: 共計組織検索で参照するマスタに存在しない場合エラー ／共計組織はマスタに存在しません。 | BK11: E000008
A12: =ROW()-8 -> 4 | D12: 収支管理品目 | AA12: ○ | AG12: 収支管理品目マスタに存在しない場合エラー ／収支管理品目コードはマスタに存在しません。 | BK12: E000008
A13: =ROW()-8 -> 5 | D13: 年産 | X13: ○ | AG13: ４文字である事を確認する。 ／年産は４文字で入力してください。 | BK13: E000012
A14: =ROW()-8 -> 6 | D14: 共計次数 | X14: ○ | AG14: ２文字である事を確認する。 ／共計次数は２文字で入力してください。 | BK14: E000012
A15: =ROW()-8 -> 7 | D15: 収支管理品目２ | AA15: ○ | AG15: 収支管理品目マスタに存在しない場合エラー ／収支管理品目コードはマスタに存在しません。 | BK15: E000008
A16: =ROW()-8 -> 8 | D16: 共計次数２ | X16: ○ | AG16: ２文字である事を確認する。 ／共計次数は２文字で入力してください。 | BK16: E000012
A17: =ROW()-8 -> 9 | D17: 収支管理品目３ | AA17: ○ | AG17: 収支管理品目マスタに存在しない場合エラー ／収支管理品目コードはマスタに存在しません。 | BK17: E000008
A18: =ROW()-8 -> 10 | D18: 共計次数３ | X18: ○ | AG18: ２文字である事を確認する。 ／共計次数は２文字で入力してください。 | BK18: E000012
A19: =ROW()-8 -> 11 | D19: 対象年月日（From） | U19: ○ | AG19: 実在日でない場合、エラーとする。 ／対象年月日は有効な日付を入力してください。 | BK19: E000018
A20: =ROW()-8 -> 12 | D20: 対象年月日（To） | R20: ○ | AG20: ／対象年月日（To）を入力してください。 | BK20: E000001
A21: =ROW()-8 -> 13 | U21: ○ | AG21: 実在日でない場合、エラーとする。 ／対象年月日は有効な日付を入力してください。 | BK21: E000018

Sheet 5.項目チェック（関連）
A1: Ｐｈａｓｅ 外部設計局面 | BJ1: HOKUREN INTERNAL USE ONLY
A2: 画面項目チェック（関連） | AV2: 様式No. | AZ2: F4106-5 | BD2: PAGE
A3: システム名 | H3: 統合会計システム | AV3: 作成日 | AZ3: 45898
A4: 業務名 | H4: =変更履歴!H4 -> 共計 | AV4: 更新日
A6: 画面名 | H6: =変更履歴!H6 -> 滞留立替金利計算書作成
A8: No. | D8: 関連チェック概要 | Q8: チェック詳細／メッセージ文言 | BD8: メッセージ コード
A9: 1 | D9: 対象年月(From)と対象年月(To)の検索範囲チェック | Q9: 対象年月(From)、対象年月(To)の両方を入力している且つ、 対象年月(From)＞対象年月(To)の場合はエラー ／対象年月の検索範囲が不正です。
A10: 2 | D10: 入力組織と共計区分 | Q10: 入力者の所属する組織が本所以外の場合、全道共計・全国共計を選択した場合エラー ／所属組織が支所の場合、全道共計・全国共計は選択できません。
A11: 3 | D11: 収支管理品目 金利 | Q11: 収支管理品目を複数入力した場合、適用される利率の種類が混在している場合エラー ／共計適用金利マスタの金利管理・金利分類・金利連番が異なる収支管理品目は入力できません。
A12: 4 | D12: 業種と共計組織 | Q12: 画面に入力した業種と入力者の所属する組織の組み合わせが「6．画面機能補足説明 ＜業種照会可能範囲＞」で定める業種以外の場合エラー ／業種は共計組織に応じた業種を入力してください。
A13: 5 | D13: 入力組織と共計組織 | Q13: 入力した共計組織コードが「6．画面機能補足説明 ＜共計組織照会可能範囲＞」で定める共計組織以外の場合エラー ／共計組織は担当の所属コードを入力してください。
A14: 6 | D14: 入力組織と収支管理品目 | Q14: 画面に入力した収支管理品目に紐づく業種と、入力者の所属する組織の組み合わせが「6．画面機能補足説明 ＜業種照会可能範囲＞」で定める業種以外の場合エラー ／収支管理品目は共計組織に応じた収支管理品目を入力してください。
A15: =ROW()-8 -> 7 | D15: 検索条件と対象データの 存在チェック | Q15: 「CSV出力」「印刷」ボタン押下時、検索条件に合致するデータが存在しない場合はエラー ／条件に該当するデータはありません。

Sheet 6．画面機能補足説明
A1: Ｐｈａｓｅ 外部設計工程 | BJ1: HOKUREN INTERNAL USE ONLY
A2: 画面機能補足説明 | AV2: 様式No. | AZ2: F4106-6 | BD2: PAGE
A3: システム名 | H3: 統合会計システム | AV3: 作成日 | AZ3: 45898
A4: 業務名 | H4: =変更履歴!H4 -> 共計 | AV4: 更新日
A6: 機能Ｎｏ． | H6: 9.2.2 | O6: 機能名称 | V6: =変更履歴!H6 -> 滞留立替金利計算書作成
B8: 【画面機能補足説明】
C10: １．照会可能範囲
C11: ＜業種照会可能範囲＞
E12: ・入力者の所属組織コードに応じて選択可能な業種を組織・業種マスタから取得し、取得できた業種のみ照会できる。
D13: 【特記事項】
E14: ・経理部は全ての業種を照会できる。
C16: ＜共計組織 照会可能範囲＞
D17: 【入力者の所属が本所以外の場合】
E18: ・入力者の所属組織のみ照会できる。
E19: ・ただし入力者の所属組織が支所管理課の場合、支所内の担当業種を取り扱う組織も照会できる。
F20: ※支所管理課の情報は会計コードマスタ(事業所／管理組織)を元に取得する。
D21: 【入力者の所属が本所の場合】
E22: ・担当業種を取り扱う、すべての組織を照会できる。
D23: 【特記事項】
E24: ・経理部は全ての組織を照会できる。
