Workbook

Sheet 変更履歴
A1: Ｐｈａｓｅ 外部設計工程 | BJ1: HOKUREN INTERNAL USE ONLY
A2: 画面設計書 変更履歴 | AV2: 様式No. | AZ2: F4106-0 | BD2: PAGE
A3: システム名 | H3: 統合会計システム | AV3: 作成日 | AZ3: 2025/8/29
A4: 業務名 | H4: 共計 | AV4: 更新日
A6: 機能名称 | H6: 滞留立替金利補正入力 | AV6: メニューコード
A8: 管理番号 | I8: 案件名 / 障害・問合せ件名
B10: 24058 | I10: 基幹システム再構築 会計システム外部設計

Sheet 1.遷移図
A1: Ｐｈａｓｅ 外部設計局面 | CQ1: HOKUREN INTERNAL USE ONLY
A2: 画 面 遷 移 図 | BY2: 様式No. | CF2: F4106-1 | CJ2: PAGE
A3: システム名 | J3: 統合会計システム | BY3: 作成日 | CF3: 2025/8/29
A4: 業務名 | J4: =変更履歴!H4 -> 共計 | BY4: 更新日
A6: 機能Ｎｏ． | J6: 9.2.3 | U6: 機能名称 | AD6: =変更履歴!H6 -> 滞留立替金利補正入力 | BY6: メニューコード
B9: 【画面利用条件】 | K9: ※利用可能ユーザー、利用可能組織など利用制限の有無。 利用可能とする条件を記載。
D11: 利用組織 ： | K11: 経理部、現業部門
Y22: 検索 | AC22: 選択 | BE22: 承認ルート表示 | BO22: 登録、閉じる
AF24: 照会
AF25: クリア
AF26: 表示（コードの日本語名称表示）
P30: メニュー選択 | AJ30: 登録、修正 | BB30: 確認画面
AK32: キャンセル | BB32: 訂正
AH34: 下書保存
AD36: 個別照会、削除、承認依頼取下
BH39: 申請、キャンセル

Sheet 2.レイアウト（検索)
A1: Ｐｈａｓｅ 外部設計局面 | CG1: HOKUREN INTERNAL USE ONLY
A2: 画面レイアウト説明書 | BP2: 様式No. | BV2: F4106-2 | CA2: PAGE
A3: システム名 | L3: 統合会計システム | BP3: 作成日 | BV3: 2025/8/29
A4: 業務名 | L4: =変更履歴!H4 -> 共計 | BP4: 更新日
A7: 画面名 | L7: =変更履歴!H6 -> 滞留立替金利補正入力
L10: 滞留立替金利補正入力 | BV10: 管理メニュー領域
D13: 検索
D14: 滞留立替金利の補正が必要な収支管理品目を選択し、補正入力を行います。
D16: 検索条件
D17: 業種 | AI17: 共計区分 | AQ17: □ 全道共計 □ 地区共計 □ 全国共計
D18: 共計組織 | AI18: 収支管理品目
D19: 年産 | AI19: 共計次数 | BE19: 対象年月 | BT19: -
D20: 更新者 | AI20: 更新日 | AZ20: -
D21: 伝票番号
D22: 承認状況 | M22: ☑差戻 ☑下書保存 ☑依頼中 □承認済
D25: (1 of 5) << < 1 2 3 4 5 > >>
D26: 選択 | H26: 承認状況 | P26: 業種 | AA26: 共計区分 | AG26: 共計組織 | AT26: 収支管理品目 | BO26: 年産 | BS26: 共計次数 | BY26: 対象年月
D27: ◎ | H27: 差戻 | P27: 10 雑穀 | AB27: 全道共計 | AH27: 4137 雑穀課 | AU27: 191113 小豆 | BO27: 2024 | BS27: 01 | BY27: 2025/01
D28: 〇 | H28: 下書保存 | P28: 10 雑穀 | AB28: 全道共計 | AH28: 4137 雑穀課 | AU28: 191114 赤系金時 | BO28: 2024 | BS28: 01 | BY28: 2025/01
D29: 〇 | H29: 下書保存 | P29: 10 雑穀 | AB29: 全道共計 | AH29: 4137 雑穀課 | AU29: 191115 大手亡 | BO29: 2024 | BS29: 01 | BY29: 2025/01
D30: 〇 | H30: 下書保存 | P30: XX ＸＸＸＸＸ | AB30: 全道共計 | AH30: XXXX ＸＸＸ | AU30: XXXXXX ＸＸＸＸＸＸＸＸＸ０ | BO30: 2024 | BS30: 01 | BY30: 2025/01
D31: 〇 | H31: 下書保存 | P31: XX ＸＸＸＸＸ | AB31: 全道共計 | AH31: XXXX ＸＸＸ | AU31: XXXXXX ＸＸＸＸＸＸＸＸＸ０ | BO31: 2024 | BS31: 01 | BY31: 2025/01
D32: 〇 | H32: 下書保存 | P32: XX ＸＸＸＸＸ | AB32: 全道共計 | AH32: XXXX ＸＸＸ | AU32: XXXXXX ＸＸＸＸＸＸＸＸＸ０ | BO32: 2024 | BS32: 01 | BY32: 2025/01
D33: 〇 | H33: 下書保存 | P33: XX ＸＸＸＸＸ | AB33: 全道共計 | AH33: XXXX ＸＸＸ | AU33: XXXXXX ＸＸＸＸＸＸＸＸＸ０ | BO33: 2024 | BS33: 01 | BY33: 2025/01
D34: 〇 | H34: 下書保存 | P34: XX ＸＸＸＸＸ | AB34: 全道共計 | AH34: XXXX ＸＸＸ | AU34: XXXXXX ＸＸＸＸＸＸＸＸＸ０ | BO34: 2024 | BS34: 01 | BY34: 2025/01
D35: 〇 | H35: 下書保存 | P35: XX ＸＸＸＸＸ | AB35: 全道共計 | AH35: XXXX ＸＸＸ | AU35: XXXXXX ＸＸＸＸＸＸＸＸＸ０ | BO35: 2024 | BS35: 01 | BY35: 2025/01
D36: 〇 | H36: 下書保存 | P36: XX ＸＸＸＸＸ | AB36: 全道共計 | AH36: XXXX ＸＸＸ | AU36: XXXXXX ＸＸＸＸＸＸＸＸＸ０ | BO36: 2024 | BS36: 01 | BY36: 2025/01
D37: 〇 | H37: 下書保存 | P37: XX ＸＸＸＸＸ | AB37: 全道共計 | AH37: XXXX ＸＸＸ | AU37: XXXXXX ＸＸＸＸＸＸＸＸＸ０ | BO37: 2024 | BS37: 01 | BY37: 2025/01
D38: 〇 | H38: 下書保存 | P38: XX ＸＸＸＸＸ | AB38: 全道共計 | AH38: XXXX ＸＸＸ | AU38: XXXXXX ＸＸＸＸＸＸＸＸＸ０ | BO38: 2024 | BS38: 01 | BY38: 2025/01
... D41: 〇 | H41: 下書保存 | P41: XX ＸＸＸＸＸ | AB41: 全道共計 | AH41: XXXX ＸＸＸ | AU41: XXXXXX ＸＸＸＸＸＸＸＸＸ０ | BO41: 2024 | BS41: 01 | BY41: 2025/01
D42: (1 of 5) << < 1 2 3 4 5 > >>
B48: 【イベント処理説明】
B49: イベント名称 | Q49: イベント処理概要 | BN49: 備考
B50: 【検索条件入力領域】
B51: 検索（業種） | Q51: 業種検索子画面をポップアップ表示する
B52: 検索（共計組織） | Q52: 共計組織検索子画面をポップアップ表示する
B53: 検索（収支管理品目） | Q53: 収支管理品目検索子画面をポップアップ表示する
B54: 検索（更新者） | Q54: 職員検索子画面をポップアップ表示する
B55: 登録 | Q55: 滞留立替金利補正入力画面へ遷移します。
B56: 照会 | Q56: 入力した内容をチェックし、エラーの場合はエラーメッセージを表示。 エラーが無ければ、入力した条件の検索結果を一覧表示します。
...

Sheet 3.項目説明(検索）
A1: Ｐｈａｓｅ 外部設計工程 | BJ1: HOKUREN INTERNAL USE ONLY
A2: 画面項目説明書 | AV2: 様式No. | AZ2: F4106-3D | BD2: PAGE
A3: システム名 | H3: 統合会計システム | AV3: 作成日 | AZ3: 45898
A4: 業務名 | H4: =変更履歴!H4 -> 共計 | AV4: 更新日
A6: 画面名 | H6: =変更履歴!H6 -> 滞留立替金利補正入力
A8: 検索結果表示領域一覧表示順
A9: No. | D9: 項目名（ソート項目順に列挙） | AT9: 表示順
A10: 1 | D10: 承認状況（差戻→下書保存→依頼中→承認済） | AT10: 昇順
A11: 2 | D11: 伝票番号 | AT11: 昇順
A13: No. | D13: 項目名 | S13: I/O | V13: 桁数 | Z13: 属性 | AD13: 符号 | AG13: 初期値 | AJ13: 前回 | AM13: 項目編集説明
V14: 入力 | X14: 表示
A15: =ROW()-14 -> 1 | D15: 【検索条件エリア】 | V15: - | X15: -
A16: =ROW()-14 -> 2 | D16: 業種 | S16: I/O | V16: 2 | X16: 2 | Z16: 文字 | AJ16: 〇 | AM16: ログインしたユーザーの担当する業種のみを対象として抽出する。
A17: =ROW()-14 -> 3 | D17: 業種名 | S17: O | V17: - | X17: 10 | Z17: 文字 （全角） | AJ17: 〇
A18: =ROW()-14 -> 4 | D18: 共計区分 | S18: I/O | V18: - | X18: - | Z18: ﾁｪｯｸﾎﾞｯｸｽ | AG18: 〇 | AJ18: 〇 | AM18: チェックボックス 全道共計 地区共計 全国共計 初期値なし
A19: =ROW()-14 -> 5 | D19: 共計組織 | S19: I/O | V19: 4 | X19: 4 | Z19: 文字 | AJ19: 〇
A20: =ROW()-14 -> 6 | D20: 共計組織名 | S20: O | V20: - | X20: 15 | Z20: 文字 （全角） | AJ20: 〇
A21: =ROW()-14 -> 7 | D21: 収支管理品目 | S21: I/O | V21: 6 | X21: 6 | Z21: 文字 | AJ21: 〇
A22: =ROW()-14 -> 8 | D22: 収支管理品目名 | S22: O | V22: - | X22: 25 | Z22: 文字 （全角） | AJ22: 〇
A23: =ROW()-14 -> 9 | D23: 年産 | S23: I/O | V23: 4 | X23: 4 | Z23: 数字 | AJ23: 〇
A24: =ROW()-14 -> 10 | D24: 共計次数 | S24: I/O | V24: 2 | X24: 2 | Z24: 数字 | AJ24: 〇
A25: =ROW()-14 -> 11 | D25: 対象年月（From） | S25: I/O | V25: 6 | X25: 7 | Z25: 数字 | AJ25: 〇
A26: =ROW()-14 -> 12 | D26: 対象年月（To） | S26: I/O | V26: 6 | X26: 7 | Z26: 数字 | AJ26: 〇
A27: =ROW()-14 -> 13 | D27: 更新者 | S27: I/O | V27: 20 | X27: 20 | Z27: 文字 （全角） | AG27: 〇 | AJ27: 〇 | AM27: 初期値：ログイン者の名称
A28: =ROW()-14 -> 14 | D28: 更新年月日（From） | S28: I/O | V28: 8 | X28: 10 | Z28: 数字 | AJ28: 〇
A29: =ROW()-14 -> 15 | D29: 更新年月日（To） | S29: I/O | V29: 8 | X29: 10 | Z29: 数字 | AJ29: 〇
A30: =ROW()-14 -> 16 | D30: 伝票番号 | S30: I/O | V30: 12 | X30: 12 | Z30: 文字 | AJ30: 〇
A31: =ROW()-14 -> 17 | D31: 承認状況 | S31: I/O | V31: - | X31: - | Z31: ﾁｪｯｸﾎﾞｯｸｽ | AG31: 〇 | AJ31: 〇 | AM31: 差戻、下書保存、依頼中を初期選択
A32: =ROW()-14 -> 18 | D32: 【明細表示エリア】 | V32: - | X32: -
A33: =ROW()-14 -> 19 | D33: 選択（明細） | S33: I | V33: - | X33: - | Z33: ﾗｼﾞｵﾎﾞﾀﾝ
A34: =ROW()-14 -> 20 | D34: 承認状況（明細） | S34: O | V34: - | X34: 5 | Z34: 文字 （全角）
A35: =ROW()-14 -> 21 | D35: 業種（明細） | S35: O | V35: - | X35: 2 | Z35: 文字
A36: =ROW()-14 -> 22 | D36: 業種名（明細） | S36: O | V36: - | X36: 10 | Z36: 文字 （全角）
A37: =ROW()-14 -> 23 | D37: 共計区分（明細） | S37: O | V37: - | X37: 4 | Z37: 文字 （全角） | AM37: 共計区分名称
A38: =ROW()-14 -> 24 | D38: 共計組織（明細） | S38: O | V38: - | X38: 4 | Z38: 文字
A39: =ROW()-14 -> 25 | D39: 共計組織名（明細） | S39: O | V39: - | X39: 15 | Z39: 文字 （全角）
A40: =ROW()-14 -> 26 | D40: 収支管理品目（明細） | S40: O | V40: - | X40: 6 | Z40: 文字
A41: =ROW()-14 -> 27 | D41: 収支管理品目名（明細） | S41: O | V41: - | X41: 25 | Z41: 文字 （全角）
A42: =ROW()-14 -> 28 | D42: 年産（明細） | S42: O | V42: - | X42: 4 | Z42: 数字
A43: =ROW()-14 -> 29 | D43: 共計次数（明細） | S43: O | V43: - | X43: 2 | Z43: 数字
...

Sheet 4.項目チェック（単体）_検索
A1: Ｐｈａｓｅ 外部設計工程 | BJ1: HOKUREN INTERNAL USE ONLY
A2: 画面項目チェック（単体） | AV2: 様式No. | AZ2: F4106-4 | BD2: PAGE
A3: システム名 | H3: 統合会計システム | AV3: 作成日 | AZ3: 45898
A4: 業務名 | H4: =変更履歴!H4 -> 共計 | AV4: 更新日
A6: 画面名 | H6: =変更履歴!H6 -> 滞留立替金利補正入力
A8: No. | D8: 項目名 | R8: 必須 ﾁｪｯｸ | U8: 数字 ﾁｪｯｸ | X8: 文字数 ﾁｪｯｸ | AA8: 存在 ﾁｪｯｸ | AD8: ｺｰﾄﾞﾁｪｯｸ | AG8: チェック補足説明／メッセージ文言 | BD8: メッセージ コード | BK8: 仮メッセージ番号
A9: =ROW()-8 -> 1 | D9: 業種 | AA9: ○ | AG9: ／業種はマスタに存在しません。 | BK9: E000008
A10: =ROW()-8 -> 2 | D10: 共計組織 | AA10: ○ | AG10: ／共計組織はマスタに存在しません。 | BK10: E000008
A11: =ROW()-8 -> 3 | D11: 収支管理品目 | AA11: ○ | AG11: ／収支管理品目はマスタに存在しません。 | BK11: E000008
A12: =ROW()-8 -> 4 | D12: 年産 | X12: ○ | AG12: ４文字である事を確認する。 ／年産は４文字で入力してください。 | BK12: E000012
A13: =ROW()-8 -> 5 | D13: 共計次数 | X13: ○ | AG13: ２文字である事を確認する。 ／共計次数は２文字で入力してください。 | BK13: E000012
A14: =ROW()-8 -> 6 | D14: 対象年月（From） | U14: ○ | AG14: 実在日でない場合、エラーとする。 ／対象年月に誤りがあります。（実在日ではありません） | BK14: E000019
A15: =ROW()-8 -> 7 | D15: 対象年月（To） | U15: ○ | AG15: 実在日でない場合、エラーとする。 ／対象年月に誤りがあります。（実在日ではありません） | BK15: E000019
A16: =ROW()-8 -> 8 | D16: 更新日（From） | U16: ○ | AG16: 実在日でない場合、エラーとする。 ／更新日は有効な日付を入力してください。 | BK16: E000018
A17: =ROW()-8 -> 9 | D17: 更新日（To） | U17: ○ | AG17: 実在日でない場合、エラーとする。 ／更新日は有効な日付を入力してください。 | BK17: E000018

Sheet 5.項目チェック（関連）_検索
A1: Ｐｈａｓｅ 外部設計局面 | BJ1: HOKUREN INTERNAL USE ONLY
A2: 画面項目チェック（関連） | AV2: 様式No. | AZ2: F4106-5 | BD2: PAGE
A3: システム名 | H3: 統合会計システム | AV3: 作成日 | AZ3: 45898
A4: 業務名 | H4: =変更履歴!H4 -> 共計 | AV4: 更新日
A6: 画面名 | H6: =変更履歴!H6 -> 滞留立替金利補正入力
A8: No. | D8: 関連チェック概要 | Q8: チェック詳細／メッセージ文言 | BD8: メッセージ コード
A9: =ROW()-8 -> 1 | D9: 対象年月(From)と対象年月(To)の検索範囲チェック | Q9: 対象年月(From)、対象年月(To)の両方を入力している且つ、 対象年月(From)＞対象年月(To)の場合はエラー ／対象年月(From)は対象年月(To)より過去の日付を入力してください。
A10: =ROW()-8 -> 2 | D10: 更新日(From)と更新日(To)の検索範囲チェック | Q10: 更新日(From)、更新日(To)の両方を入力している且つ、 更新日(From)＞更新日(To)の場合はエラー ／更新日(From)は更新日(To)より過去の日付を入力してください。
A11: =ROW()-8 -> 3 | D11: 入力組織と共計区分 | Q11: 入力者の所属する組織が本所以外の場合、全道共計・全国共計を選択した場合エラー ／所属組織が支所の場合、全道共計・全国共計は選択できません。
A12: =ROW()-8 -> 4 | D12: 業種と共計組織 | Q12: 画面に入力した業種と入力者の所属する組織の組み合わせが「6．画面機能補足説明 ＜業種照会可能範囲＞」で定める業種以外の場合エラー ／業種は共計組織に応じた業種を入力してください。
A13: =ROW()-8 -> 5 | D13: 入力組織と共計組織 | Q13: 入力者の所属する組織が本所以外の場合、「6．画面機能補足説明 ＜共計組織照会可能範囲＞」で定める共計組織以外の場合エラー ／共計組織は担当の所属コードを入力してください。
A14: =ROW()-8 -> 6 | D14: 入力組織と更新者 | Q14: 「照会」ボタン押下時、入力した更新者の所属する組織が「6．画面機能補足説明 ＜共計組織照会可能範囲＞」で定める組織以外の場合エラー ／更新者は自組織に応じた更新者を入力してください。
A15: =ROW()-8 -> 7 | D15: 入力組織と収支管理品目 | Q15: 画面に入力した収支管理品目に紐づく業種と、入力者の所属する組織の組み合わせが「6．画面機能補足説明 ＜業種照会可能範囲＞」で定める業種以外の場合エラー ／収支管理品目は共計組織に応じた収支管理品目を入力してください。
A16: =ROW()-8 -> 8 | D16: 検索条件と対象データの 存在チェック | Q16: 「照会」ボタン押下時、検索条件に合致するデータが存在しない場合はエラー ／条件に該当するデータはありません。
A17: =ROW()-8 -> 9 | D17: 修正ボタンと明細未選択チェック | Q17: 「修正」ボタン押下時、明細を選択していない場合エラー ／明細を選択してください。
A18: =ROW()-8 -> 10 | D18: 修正ボタンと複数明細選択チェック | Q18: 「修正」ボタン押下時、複数明細を選択している場合エラー ／明細は１件のみ選択してください。
A19: =ROW()-8 -> 11 | D19: 修正ボタンと承認状況（依頼中）のチェック | Q19: 「修正」ボタン押下時、承認状況が「依頼中」の明細を選択している場合エラー ／依頼中の為、対象データは操作できません。
A20: =ROW()-8 -> 12 | D20: 修正ボタン承認状況（承認済）のチェック | Q20: 「修正」ボタン押下時、承認状況が「承認済」の明細を選択している場合エラー ／承認済の為、対象データは操作できません。
... A32: =ROW()-8 -> 24 | D32: 承認依頼取下ボタンと入力組織のチェック | Q32: 「承認依頼取下」ボタン押下時、共計組織が入力者の所属する組織以外となる明細を1件でも選択している場合エラー ／共計組織が担当の所属コード以外となる明細は選択できません。

Sheet 2.レイアウト（入力)
A1: Ｐｈａｓｅ 外部設計局面 | CG1: HOKUREN INTERNAL USE ONLY
A2: 画面レイアウト説明書 | BP2: 様式No. | BV2: F4106-2 | CA2: PAGE
A3: システム名 | L3: 統合会計システム | BP3: 作成日 | BV3: 2025/8/29
A4: 業務名 | L4: =変更履歴!H4 -> 共計 | BP4: 更新日
A7: 画面名 | L7: =変更履歴!H6 -> 滞留立替金利補正入力
L10: 滞留立替金利補正入力 | BV10: 管理メニュー領域
D13: 検索 > 入力
D14: 滞留立替金利の補正金額を登録します。
D16: 基本情報
D17: 業種 (*) | AE17: 共計区分(*) | BG17: 共計組織 (*)
D18: 収支管理品目(*) | AE18: 年産 (*) | BG18: 共計次数 (*)
D19: 対象年月(*) | AE19: 添付ファイル数 | AN19: 0 | BG19: 参照ＵＲＬ
D22: 日 | H22: 入金補正金額 | T22: 支払補正金額 | AF22: 入金額 | AR22: 支払額 | BD22: 補正後入金額 | BQ22: 補正後支払額
D23: 1
D24: 2
D25: 3
D26: 4
D27: 5
D28: 6
D29: 7
D30: 8
D31: 9
D32: 10
D33: 11
D34: 12
... D53: 31
D54: 計 | I54: =SUM(I23:R53) -> 0 | U54: =SUM(U23:AD53) -> 0 | AG54: =SUM(AG23:AP53) -> 0 | AS54: =SUM(AS23:BB53) -> 0
D57: 承認情報
D58: 更新情報 | Q58: 更新日時 | AD58: 所属 | BD58: 担当
L67: 滞留立替金利補正入力 | BV67: 管理メニュー領域
D70: 検索 > 修正
D71: 滞留立替金利の補正金額を修正します。
D73: 基本情報
D74: 業種 | L74: 10 | O74: 雑穀 | AE74: 共計区分 | AM74: 全道共計 | BG74: 共計組織 | BO74: 4137 | BS74: 雑穀課
D75: 収支管理品目 | L75: 191113 | R75: 小豆 | AE75: 年産 | AN75: 2024 | BG75: 共計次数 | BO75: 01
D76: 対象年月 | L76: 2025/01 | AE76: 添付ファイル数 | AN76: 0 | BG76: 参照ＵＲＬ
D79: 日 | H79: 入金補正金額 | T79: 支払補正金額 | AF79: 入金額 | AR79: 支払額 | BD79: 補正後入金額 | BQ79: 補正後支払額
D80: 1 | I80: 100 | U80: 300 | AG80: 180000000 | AS80: 300000 | BE80: =I80+AG80 -> 180000100 | BR80: =U80+AS80 -> 300300
D81: 2 | AG81: 60000000 | AS81: 160000
D82: 3 | I82: 300 | AG82: 60000000 | AS82: 70000 | BE82: =I82+AG82 -> 60000300
...

Sheet 3.項目説明(入力）
A1: Ｐｈａｓｅ 外部設計工程 | BJ1: HOKUREN INTERNAL USE ONLY
A2: 画面項目説明書 | AV2: 様式No. | AZ2: F4106-3D | BD2: PAGE
A3: システム名 | H3: 統合会計システム | AV3: 作成日 | AZ3: 45898
A4: 業務名 | H4: =変更履歴!H4 -> 共計 | AV4: 更新日
A6: 画面名 | H6: =変更履歴!H6 -> 滞留立替金利補正入力
A8: 検索結果表示領域一覧表示順
A9: No. | D9: 項目名（ソート項目順に列挙） | AT9: 表示順
A10: 1 | D10: 日
A13: No. | D13: 項目名 | S13: I/O | V13: 桁数 | Z13: 属性 | AD13: 符号 | AG13: 初期値 | AJ13: 前回 | AM13: 項目編集説明
V14: 入力 | X14: 表示
A15: =ROW()-14 -> 1 | D15: 【基本情報エリア】 | V15: - | X15: -
A16: =ROW()-14 -> 2 | D16: 業種 | S16: I/O | V16: 2 | X16: 2 | Z16: 文字 | AM16: ログインしたユーザーの担当する業種のみを対象として抽出する。
A17: =ROW()-14 -> 3 | D17: 業種名 | S17: O | V17: - | X17: 10 | Z17: 文字 （全角）
A18: =ROW()-14 -> 4 | D18: 共計区分 | S18: I/O | V18: - | X18: - | Z18: 文字 （全角） | AG18: 〇 | AM18: 入力：プルダウンリスト ログインしたユーザーの所属に応じて以下の内容を設定する。 本所の場合： 「全道共計」（初期値）「全国共計」 支所の場合： 「地区共計」（初期値）
A19: =ROW()-14 -> 5 | D19: 共計組織 | S19: I/O | V19: 4 | X19: 4 | Z19: 文字
A20: =ROW()-14 -> 6 | D20: 共計組織名 | S20: O | V20: - | X20: 15 | Z20: 文字 （全角）
A21: =ROW()-14 -> 7 | D21: 収支管理品目 | S21: I/O | V21: 6 | X21: 6 | Z21: 文字
A22: =ROW()-14 -> 8 | D22: 収支管理品目名 | S22: O | V22: - | X22: 25 | Z22: 全角
A23: =ROW()-14 -> 9 | D23: 年産 | S23: I/O | V23: 4 | X23: 4 | Z23: 数字
A24: =ROW()-14 -> 10 | D24: 共計次数 | S24: I/O | V24: 2 | X24: 2 | Z24: 数字
A25: =ROW()-14 -> 11 | D25: 対象年月 | S25: I/O | V25: 6 | X25: 7 | Z25: 数字
A26: =ROW()-14 -> 12 | D26: 添付ファイル | S26: O | V26: - | X26: 2 | Z26: 数字
A27: =ROW()-14 -> 13 | D27: 参照ＵＲＬ | S27: I/O | V27: 200 | X27: 200 | Z27: 文字
A28: =ROW()-14 -> 14 | D28: 【明細エリア】 | V28: - | X28: -
A29: =ROW()-14 -> 15 | D29: 日（明細） | S29: O | V29: - | X29: 2 | Z29: 数字 | AM29: １から対象年月の末日までの日付をセットする。
A30: =ROW()-14 -> 16 | D30: 入金補正金額（明細） | S30: I/O | V30: 14 | X30: 18 | Z30: 数字 | AD30: 〇 | AM30: 修正、照会画面の場合、登録済みの入金補正金額を表示する。
A31: =ROW()-14 -> 17 | D31: 支払補正金額（明細） | S31: I/O | V31: 14 | X31: 18 | Z31: 数字 | AD31: 〇 | AM31: 修正、照会画面の場合、登録済みの支払補正金額を表示する。
A32: =ROW()-14 -> 18 | D32: 入金額（明細） | S32: O | V32: - | X32: 18 | Z32: 数字 | AD32: 〇 | AM32: 滞留立替金利計算結果情報の入金額をカンマ編集して表示する。
A33: =ROW()-14 -> 19 | D33: 支払額（明細） | S33: O | V33: - | X33: 18 | Z33: 数字 | AD33: 〇 | AM33: 滞留立替金利計算結果情報の支払額をカンマ編集して表示する。
A34: =ROW()-14 -> 20 | D34: 補正後入金額（明細） | S34: O | V34: - | X34: 18 | Z34: 数字 | AD34: 〇 | AM34: 入金補正金額（明細）＋入金額（明細）をカンマ編集して表示する。
A35: =ROW()-14 -> 21 | D35: 補正後支払額（明細） | S35: O | V35: - | X35: 18 | Z35: 数字 | AD35: 〇 | AM35: 支払補正金額（明細）＋支払額（明細）をカンマ編集して表示する。
A36: =ROW()-14 -> 22 | D36: 入金補正金額（合計） | S36: O | V36: - | X36: 18 | Z36: 数字 | AD36: 〇 | AM36: 明細の入金補正金額の合計値をカンマ編集して表示する。
A37: =ROW()-14 -> 23 | D37: 支払補正金額（合計） | S37: O | V37: - | X37: 18 | Z37: 数字 | AD37: 〇 | AM37: 明細の支払補正金額の合計値をカンマ編集して表示する。
A38: =ROW()-14 -> 24 | D38: 入金額（合計） | S38: O | V38: - | X38: 18 | Z38: 数字 | AD38: 〇 | AM38: 明細の入金額の合計値をカンマ編集して表示する。
A39: =ROW()-14 -> 25 | D39: 支払額（合計） | S39: O | V39: - | X39: 18 | Z39: 数字 | AD39: 〇 | AM39: 明細の支払額の合計値をカンマ編集して表示する。
A40: =ROW()-14 -> 26 | D40: 【承認情報エリア】 | V40: - | X40: -
A41: =ROW()-14 -> 27 | D41: 更新者（更新日時） | S41: O | V41: - | X41: 19 | Z41: 数字 | AM41: 更新者-日時を表示する。
A42: =ROW()-14 -> 28 | D42: 更新者（所属） | S42: O | V42: - | X42: 15 | Z42: 文字 （全角） | AM42: 更新者-所属を表示する。
A43: =ROW()-14 -> 29 | D43: 更新者（担当者） | S43: O | V43: - | X43: 20 | Z43: 文字 （全角） | AM43: 更新者-担当者を表示する。
A44: =ROW()-14 -> 30 | D44: 承認/差戻（更新日時） | S44: O | V44: - | X44: 19 | Z44: 数字 | AM44: 承認/差戻者-日時を表示する。
...

Sheet 4.項目チェック（単体）_入力
A1: Ｐｈａｓｅ 外部設計工程 | BJ1: HOKUREN INTERNAL USE ONLY
A2: 画面項目チェック（単体） | AV2: 様式No. | AZ2: F4106-4 | BD2: PAGE
A3: システム名 | H3: 統合会計システム | AV3: 作成日 | AZ3: 45898
A4: 業務名 | H4: =変更履歴!H4 -> 共計 | AV4: 更新日
A6: 画面名 | H6: =変更履歴!H6 -> 滞留立替金利補正入力
A8: No. | D8: 項目名 | R8: 必須 ﾁｪｯｸ | U8: 数字 ﾁｪｯｸ | X8: 文字数 ﾁｪｯｸ | AA8: 存在 ﾁｪｯｸ | AD8: ｺｰﾄﾞﾁｪｯｸ | AG8: チェック補足説明／メッセージ文言 | BD8: メッセージ コード | BK8: 仮メッセージ番号
A9: =ROW()-8 -> 1 | D9: 業種 | R9: ○ | AG9: ／業種コードを入力してください。 | BK9: E000001
A10: =ROW()-8 -> 2 | AA10: ○ | AG10: ／業種はマスタに存在しません。 | BK10: E000008
A11: =ROW()-8 -> 3 | D11: 共計組織 | R11: ○ | AG11: ／共計組織を入力してください。 | BK11: E000001
A12: =ROW()-8 -> 4 | AA12: ○ | AG12: ／共計組織はマスタに存在しません。 | BK12: E000008
A13: =ROW()-8 -> 5 | D13: 収支管理品目 | R13: ○ | AG13: ／収支管理品目を入力してください。 | BK13: E000001
A14: =ROW()-8 -> 6 | AA14: ○ | AG14: ／収支管理品目はマスタに存在しません。 | BK14: E000008
A15: =ROW()-8 -> 7 | D15: 年産 | R15: ○ | AG15: ／年産を入力してください。 | BK15: E000001
A16: =ROW()-8 -> 8 | X16: ○ | AG16: ４文字である事を確認する。 ／年産は４文字で入力してください。 | BK16: E000012
A17: =ROW()-8 -> 9 | D17: 共計次数 | R17: ○ | AG17: ／共計次数を入力してください。 | BK17: E000001
A18: =ROW()-8 -> 10 | X18: ○ | AG18: ２文字である事を確認する。 ／共計次数は２文字で入力してください。 | BK18: E000012
A19: =ROW()-8 -> 11 | D19: 対象年月 | R19: ○ | AG19: ／対象年月を入力してください。 | BK19: E000001
A20: =ROW()-8 -> 12 | U20: ○ | AG20: 実在日でない場合、エラーとする。 ／対象年月に誤りがあります。（実在日ではありません） | BK20: E000019
A21: =ROW()-8 -> 13 | D21: 入金補正金額 | U21: ○ | AG21: ／入金補正額は半角数値で入力してください。 | BK21: E000014
A22: =ROW()-8 -> 14 | X22: ○ | AG22: 入金補正金額に入力した値が -9,999,999,999,999 ～ 9,999,999,999,999の範囲内であることを確認する。 ／入金補正金額は-9,999,999,999,999 ～ 9,999,999,999,999の範囲内で入力してください。 | BK22: E000023
A23: =ROW()-8 -> 15 | D23: 支払補正金額 | U23: ○ | AG23: ／支払補正額は半角数値で入力してください。 | BK23: E000014
A24: =ROW()-8 -> 16 | X24: ○ | AG24: 支払補正金額に入力した値が -9,999,999,999,999 ～ 9,999,999,999,999の範囲内であることを確認する。 ／支払補正金額は-9,999,999,999,999 ～ 9,999,999,999,999の範囲内で入力してください。 | BK24: E000023

Sheet 5.項目チェック（関連）_入力
A1: Ｐｈａｓｅ 外部設計局面 | BJ1: HOKUREN INTERNAL USE ONLY
A2: 画面項目チェック（関連） | AV2: 様式No. | AZ2: F4106-5 | BD2: PAGE
A3: システム名 | H3: 統合会計システム | AV3: 作成日 | AZ3: 45898
A4: 業務名 | H4: =変更履歴!H4 -> 共計 | AV4: 更新日
A6: 画面名 | H6: =変更履歴!H6 -> 滞留立替金利補正入力
A8: No. | D8: 関連チェック概要 | Q8: チェック詳細／メッセージ文言 | BD8: メッセージ コード
A9: =ROW()-8 -> 1 | D9: 対象年月 | Q9: 「確認画面」押下時、対象年月に締処理済の年月が入力されている場合、エラー ／締処理済の日付で滞留立替金利補正入力をすることはできません。
A10: =ROW()-8 -> 2 | D10: 対象年月日、入金補正額 、支払補正額 | Q10: 「確認画面」押下時、存在しない日付の行に補正額が入力されている場合、エラー ／日付は有効な日付を入力してください。
A11: =ROW()-8 -> 3 | D11: 入金補正額、支払補正額 | Q11: 「確認画面」押下時、入金補正額または支払補正額が1件も入力されていない場合、エラー ／入金補正金額、支払補正金額を入力してください。
A12: =ROW()-8 -> 4 | D12: 入力組織と共計区分 | Q12: 「照会」、「確認画面」押下時、入力者の所属する組織が支所 かつ 全道共計・全国共計を選択した場合エラー ／所属組織が支所の場合、全道共計・全国共計は選択できません。
A13: =ROW()-8 -> 5 | D13: 入力組織と共計区分 | Q13: 「照会」、「確認画面」押下時、入力者の所属する組織が本所 かつ 地区共計を選択した場合エラー ／所属組織が本所の場合、地区共計は選択できません。
A14: =ROW()-8 -> 6 | D14: 業種と共計組織 | Q14: 「照会」、「確認画面」押下時、入力した業種と入力者の所属する組織の組み合わせが「6．画面機能補足説明 ＜業種入力可能範囲＞」で定める共計組織以外の場合エラー ／業種は共計組織に応じた業種を入力してください。
A15: =ROW()-8 -> 7 | D15: 入力組織と共計組織 | Q15: 「照会」、「確認画面」押下時、入力した共計組織コードが「6．画面機能補足説明 ＜共計組織入力可能範囲＞」で定める共計組織以外の場合エラー ／共計組織は担当の所属コードを入力してください。
A16: =ROW()-8 -> 8 | D16: 検索条件と対象データの 存在チェック | Q16: 「照会」ボタン押下時、検索条件に合致するデータが存在しない場合はエラー ／条件に該当するデータはありません。

Sheet 2.レイアウト（確認)
A1: Ｐｈａｓｅ 外部設計局面 | CG1: HOKUREN INTERNAL USE ONLY
A2: 画面レイアウト説明書 | BP2: 様式No. | BV2: F4106-2 | CA2: PAGE
A3: システム名 | L3: 統合会計システム | BP3: 作成日 | BV3: 2025/8/29
A4: 業務名 | L4: =変更履歴!H4 -> 共計 | BP4: 更新日
A7: 画面名 | L7: =変更履歴!H6 -> 滞留立替金利補正入力
B9: 【照会時】
L11: 滞留立替金利補正入力 | BV11: 管理メニュー領域
D14: 検索 | G14: > | H14: 確認
D15: 滞留立替金利の補正金額を確認します。
D17: 基本情報
D18: 業種 | K18: 10 雑穀 | AE18: 共計区分 | AM18: 全道共計 | BE18: 共計組織 | BL18: 4137 雑穀課
D19: 収支管理品目 | K19: 191113 小豆 | AE19: 年産 | AN19: 2024 | BE19: 共計次数 | BL19: 01
D20: 対象年月 | K20: 2025/01 | AE20: 添付ファイル数 | AN20: 0 | BE20: 参照ＵＲＬ
D22: 日 | H22: 入金補正金額 | T22: 支払補正金額 | AF22: 入金額 | AR22: 支払額 | BD22: 補正後入金額 | BQ22: 補正後支払額
D23: 1 | I23: 100 | U23: 300 | AG23: 180000000 | AS23: 300000 | BE23: =I23+AG23 -> 180000100 | BR23: =U23+AS23 -> 300300
D24: 2 | AG24: 60000000 | AS24: 160000
D25: 3 | I25: 300 | AG25: 60000000 | AS25: 70000 | BE25: =I25+AG25 -> 60000300
D26: 4 | U26: 400 | AG26: 60000000 | AS26: 170000 | BR26: =U26+AS26 -> 170400
D27: 5 | I27: -1,000 | U27: -2,000 | AG27: 40000000 | AS27: 20000 | BE27: =I27+AG27 -> 39999000 | BR27: =U27+AS27 -> 18000
D28: 6 | AG28: 40000000 | AS28: 110000
D29: 7 | AG29: 50000000 | AS29: 170000
D30: 8
D31: 9
D32: 10
D33: 11
D34: 12
D35: 13
D36: 14
D37: 15
D38: 16
D39: 17
D40: 18
D41: 19
... D53: 31
D54: 計 | I54: -600 | U54: -1300 | AG54: =SUM(AG23:AP53) -> 490000000 | AS54: =SUM(AS23:BB53) -> 1000000
D56: 承認情報
D57: 更新情報 | Q57: 更新日時 | AD57: 所属 | BD57: 担当
B66: 【削除時】
L68: 滞留立替金利補正入力 | BV68: 管理メニュー領域
D71: 検索 | G71: > | H71: 確認
...

Sheet 3.項目説明(確認）
A1: Ｐｈａｓｅ 外部設計工程 | BJ1: HOKUREN INTERNAL USE ONLY
A2: 画面項目説明書 | AV2: 様式No. | AZ2: F4106-3D | BD2: PAGE
A3: システム名 | H3: 統合会計システム | AV3: 作成日 | AZ3: 45898
A4: 業務名 | H4: =変更履歴!H4 -> 共計 | AV4: 更新日
A6: 画面名 | H6: =変更履歴!H6 -> 滞留立替金利補正入力
A8: 検索結果表示領域一覧表示順
A9: No. | D9: 項目名（ソート項目順に列挙） | AT9: 表示順
A10: 1
A11: 2
A14: No. | D14: 項目名 | S14: I/O | V14: 桁数 | Z14: 属性 | AD14: 符号 | AG14: 初期値 | AJ14: 前回 | AM14: 項目編集説明
V15: 入力 | X15: 表示
A16: =ROW()-15 -> 1 | D16: 【基本情報エリア】 | V16: - | X16: -
A17: =ROW()-15 -> 2 | D17: 業種 | S17: O | V17: - | X17: 2 | Z17: 文字
A18: =ROW()-15 -> 3 | D18: 業種名 | S18: O | V18: - | X18: 10 | Z18: 文字 （全角） | AM18: 業種に対する名称を表示する
A19: =ROW()-15 -> 4 | D19: 共計区分 | S19: O | V19: - | X19: 4 | Z19: 文字 （全角）
A20: =ROW()-15 -> 5 | D20: 共計組織 | S20: O | V20: - | X20: 4 | Z20: 文字
A21: =ROW()-15 -> 6 | D21: 共計組織名 | S21: O | V21: - | X21: 15 | Z21: 文字 （全角） | AM21: 共計組織に対する名称を表示する
A22: =ROW()-15 -> 7 | D22: 収支管理品目 | S22: O | V22: - | X22: 6 | Z22: 文字
A23: =ROW()-15 -> 8 | D23: 収支管理品目名 | S23: O | V23: - | X23: 25 | Z23: 文字 （全角） | AM23: 収支管理品目に対する名称を表示する
A24: =ROW()-15 -> 9 | D24: 年産 | S24: O | V24: - | X24: 4 | Z24: 数字
A25: =ROW()-15 -> 10 | D25: 共計次数 | S25: O | V25: - | X25: 2 | Z25: 数字
A26: =ROW()-15 -> 11 | D26: 対象年月 | S26: O | V26: - | X26: 7 | Z26: 数字 | AM26: 滞留立替金利補正入力の対象年月をYYYY/MM形式で表示する。
A27: =ROW()-15 -> 12 | D27: 添付ファイル | S27: O | V27: - | X27: 2 | Z27: 数字
A28: =ROW()-15 -> 13 | D28: 参照ＵＲＬ | S28: O | V28: - | X28: 200 | Z28: 文字
A29: =ROW()-15 -> 14 | D29: 【明細エリア】 | V29: - | X29: -
A30: =ROW()-15 -> 15 | D30: 日（明細） | S30: O | V30: - | X30: 2 | Z30: 数字 | AM30: １から対象年月の末日までの日付をセットする。
A31: =ROW()-15 -> 16 | D31: 入金補正金額（明細） | S31: O | V31: - | X31: 18 | Z31: 数字 | AD31: 〇 | AM31: 入力画面で入力した入金補正金額をカンマ編集して表示する。
A32: =ROW()-15 -> 17 | D32: 支払補正金額（明細） | S32: O | V32: - | X32: 18 | Z32: 数字 | AD32: 〇 | AM32: 入力画面で入力した支払補正金額をカンマ編集して表示する。
A33: =ROW()-15 -> 18 | D33: 入金額（明細） | S33: O | V33: - | X33: 18 | Z33: 数字 | AD33: 〇 | AM33: 滞留立替金利計算結果情報の入金額をカンマ編集して表示する。
A34: =ROW()-15 -> 19 | D34: 支払額（明細） | S34: O | V34: - | X34: 18 | Z34: 数字 | AD34: 〇 | AM34: 滞留立替金利計算結果情報の支払額をカンマ編集して表示する。
A35: =ROW()-15 -> 20 | D35: 補正後入金額（明細） | S35: O | V35: - | X35: 18 | Z35: 数字 | AD35: 〇 | AM35: 入金補正金額（明細）＋入金額（明細）をカンマ編集して表示する。
A36: =ROW()-15 -> 21 | D36: 補正後支払額（明細） | S36: O | V36: - | X36: 18 | Z36: 数字 | AD36: 〇 | AM36: 支払補正金額（明細）＋支払額（明細）をカンマ編集して表示する。
A37: =ROW()-15 -> 22 | D37: 入金補正金額（合計） | S37: O | V37: - | X37: 18 | Z37: 数字 | AD37: 〇 | AM37: 明細の入金補正金額の合計値をカンマ編集して表示する。
A38: =ROW()-15 -> 23 | D38: 支払補正金額（合計） | S38: O | V38: - | X38: 18 | Z38: 数字 | AD38: 〇 | AM38: 明細の支払補正金額の合計値をカンマ編集して表示する。
A39: =ROW()-15 -> 24 | D39: 入金額（合計） | S39: O | V39: - | X39: 18 | Z39: 数字 | AD39: 〇 | AM39: 明細の入金額の合計値をカンマ編集して表示する。
A40: =ROW()-15 -> 25 | D40: 支払額（合計） | S40: O | V40: - | X40: 18 | Z40: 数字 | AD40: 〇 | AM40: 明細の支払額の合計値をカンマ編集して表示する。
A41: =ROW()-15 -> 26 | D41: 【承認情報エリア】 | V41: - | X41: -
A42: =ROW()-15 -> 27 | D42: 更新者（更新日時） | S42: O | V42: - | X42: 19 | Z42: 数字 | AM42: 更新者-日時を表示する。
A43: =ROW()-15 -> 28 | D43: 更新者（所属） | S43: O | V43: - | X43: 15 | Z43: 文字 （全角） | AM43: 更新者-所属を表示する。
A44: =ROW()-15 -> 29 | D44: 更新者（担当者） | S44: O | V44: - | X44: 20 | Z44: 文字 （全角） | AM44: 更新者-担当者を表示する。
...

Sheet 4.項目チェック（単体）_確認
A1: Ｐｈａｓｅ 外部設計工程 | BJ1: HOKUREN INTERNAL USE ONLY
A2: 画面項目チェック（単体） | AV2: 様式No. | AZ2: F4106-4 | BD2: PAGE
A3: システム名 | H3: 統合会計システム | AV3: 作成日 | AZ3: 45898
A4: 業務名 | H4: =変更履歴!H4 -> 共計 | AV4: 更新日
A6: 画面名 | H6: =変更履歴!H6 -> 滞留立替金利補正入力
A8: No. | D8: 項目名 | R8: 必須 ﾁｪｯｸ | U8: 数字 ﾁｪｯｸ | X8: 文字数 ﾁｪｯｸ | AA8: 存在 ﾁｪｯｸ | AD8: ｺｰﾄﾞﾁｪｯｸ | AG8: チェック補足説明／メッセージ文言 | BD8: メッセージ コード
AG9: チェックなし

Sheet 5.項目チェック（関連）_確認
A1: Ｐｈａｓｅ 外部設計局面 | BJ1: HOKUREN INTERNAL USE ONLY
A2: 画面項目チェック（関連） | AV2: 様式No. | AZ2: F4106-5 | BD2: PAGE
A3: システム名 | H3: 統合会計システム | AV3: 作成日 | AZ3: 45898
A4: 業務名 | H4: =変更履歴!H4 -> 共計 | AV4: 更新日
A6: 画面名 | H6: =変更履歴!H6 -> 滞留立替金利補正入力
A8: No. | D8: 関連チェック概要 | Q8: チェック詳細／メッセージ文言 | BD8: メッセージ コード
Q9: チェックなし

Sheet 6．画面機能補足説明
A1: Ｐｈａｓｅ 外部設計工程 | BJ1: HOKUREN INTERNAL USE ONLY
A2: 画面機能補足説明 | AV2: 様式No. | AZ2: F4106-6 | BD2: PAGE
A3: システム名 | H3: 統合会計システム | AV3: 作成日 | AZ3: 45898
A4: 業務名 | H4: =変更履歴!H4 -> 共計 | AV4: 更新日
A6: 機能Ｎｏ． | H6: 9.2.3 | O6: 機能名称 | V6: =変更履歴!H6 -> 滞留立替金利補正入力
B8: 【画面機能補足説明】
C10: １．照会・入力可能範囲
C11: ＜業種照会可能範囲＞
E12: ・入力者の所属組織コードに応じて選択可能な業種を組織・業種マスタから取得し、取得できた業種のみ照会できる。
D13: 【特記事項】
E14: ・経理部は全ての業種を照会できる。
C16: ＜業種入力可能範囲＞
E17: ・入力者の所属組織コードに応じて選択可能な業種を組織・業種マスタから取得し、取得できた業種のみ入力できる。
D18: 【特記事項】
E19: ・経理部は全ての業種を入力できる。
C21: ＜共計組織 照会可能範囲＞
D22: 【入力者の所属が本所以外の場合】
E23: ・入力者の所属組織のみ照会できる。
E24: ・ただし入力者の所属組織が支所管理課の場合、支所内の担当業種を取り扱う組織も照会できる。
F25: ※支所管理課の情報は会計コードマスタ(事業所／管理組織)を元に取得する。
D26: 【入力者の所属が本所の場合】
E27: ・担当業種を取り扱う、すべての組織を照会できる。
D28: 【特記事項】
E29: ・経理部は全ての組織を照会できる。
C31: ＜共計組織 入力可能範囲＞
D32: 【入力者の所属が本所以外の場合】
E33: ・入力者の所属組織のみ入力できる。
E34: ・ただし入力者の所属組織が支所管理課の場合、支所内の担当業種を取り扱う組織も入力できる。
F35: ※支所管理課の情報は会計コードマスタ(事業所／管理組織)を元に取得する。
D36: 【入力者の所属が本所の場合】
E37: ・入力者の所属組織のみ入力できる。
D38: 【特記事項】
E39: ・経理部は全ての組織を入力できる。
