Workbook
Name 【債権】最新データ辞書: #REF!
Name 項目辞書: #REF!

Sheet 表紙
F46: ProActive
B48: 変更履歴
B50: 項番 | C50: 変更発生日 | D50: 変更者 | E50: 変更箇所 | F50: 変更内容
B51: 1 | C51: 45898 | D51: SCSK井上 | F51: 新規作成
B52: 2
B53: 3
B54: 4
B55: 5
B56: 6
B57: 7
B58: 8
B59: 9
B60: 10
B61: 11
B62: 12
B63: 13
... B80: 30

Sheet 業務機能概要
A1: ドキュメント名 | L1: サブシステム | S1: 業務機能名 | AL1: 作成者 | AQ1: =表紙!D51 -> SCSK井上 | AV1: 更新者
A2: 業務機能概要書 | G2: 業務機能概要 | L2: 債務管理サブシステム | S2: 一括支払予定修正 | AL2: 作成日付 | AQ2: =表紙!C51 -> 45898 | AV2: 更新日付
B4: ※本資料では「1取引」という言葉を「部門システムやスクラッチ開発機能にて取引計上された単位」という意味で使用する。
C5: ProActiveC4上では「１取引＝１支払依頼伝票」とする。
B6: 【目的・役割】
C7: ・ | D7: ホクレン様の業務では、支払予定情報を変更する際、複数の取引の支払予定情報をまとめて変更することがある。
D8: ProActiveC4の標準機能では1取引ごとでしか支払予定修正を行うことができない。
D9: そのため一括支払予定修正機能にて複数の取引の支払予定情報をまとめて変更できるようにする。
C11: ・ | D11: 支払予定情報の不正な変更や誤った変更の検知が必要である。
D12: 一括支払予定修正機能にて、「変更済みのみ出力」や「振込先口座を変更した支払予定情報のみ出力」を可能とする。
D13: これにより、不正な変更や誤った変更の検知を可能とする。さらに一括支払予定修正機能自体が、支払予定情報の不正な変更へのけん制となる。
B16: 【利用者】
C17: ・ | D17: 経理課
B20: 【利用頻度】
C21: ・ | D21: 随時
B24: 【対象要件定義書】
C25: ・ | D25: 要件定義書(一括支払予定修正).xls
B28: 【処理概要】
C29: １) | D29: 支払予定修正対象データの抽出
D30: 検索条件を入力し検索を行うことで支払予定情報の抽出を可能とする。
D31: ・ | E31: 一括支払予定修正対象一覧照会画面の【検索条件】に入力された内容に一致する支払予定情報を抽出する。
E32: （「データアクセス要領シート」の「①一括支払予定修正対象一覧照会画面」の「１．検索ボタン押下時」参照）
D34: ・ | E34: 一括支払予定修正対象一覧照会画面の【検索条件】には以下のチェックボックスを配置する。
E35: チェックを入れた場合、以下の条件で支払予定情報を抽出する。
E36: 画面項目 | U36: 抽出条件
E37: ファクタリング確定済の支払予定は振替元支払先を対象とする | U37: 標準機能の動作と同様
E38: 全額決済済みも表示する | U38: 標準機能の動作と同様
E39: 変更済みのみ対象 | U39: チェックを入れた場合、すでに支払予定情報の変更を行った支払予定情報のみを抽出の対象とする。
E40: 振込先口座変更済みのみ出力 | U40: チェックを入れた場合、すでに振込先の口座情報の変更を行った支払予定情報のみを抽出の対象とする。
C55: ２) | D55: 支払予定情報データの一覧取得
D56: 支払予定情報の一覧を取得する。変更後の口座、支払予定日付、支払方法の確認を可能とする。
D57: 取得する項目は「項目概要シート」の「①一括支払予定修正対象一覧照会画面」の【検索結果一覧】を参照。
D60: ・ | E60: 一覧を取得し【検索結果一覧】表示時、全額決済済みの明細がある場合はその明細の選択チェックボックスは非活性とする。（チェックボックスはチェック無）
D63: ・ | E63: 一覧を取得し【検索結果一覧】表示時、各明細行の選択チェックボックスはチェック有とする。
E64: ユーザによるチェック有無の変更を可能とする。
D66: ・ | E66: 一覧取得後、一括支払予定修正対象一覧照会画面の【検索結果一覧】のボタンについて
E67: 抽出された支払予定情報の件数によって、以下の通り制御を行う。
F69: 抽出件数=0件の場合
G70: 「全選択」ボタン、「全解除」ボタン、「支払予定修正」ボタンは使用不可とする。
F72: 抽出件数≧1件で、選択チェックボックスにチェックが入っている明細行が0件の場合
...

Sheet 画面遷移図
A1: ドキュメント名 | L1: サブシステム | S1: 業務機能名 | AJ1: 作成者 | AO1: =表紙!D51 -> SCSK井上 | AT1: 更新者
A2: 業務機能概要書 | G2: 画面遷移図 | L2: =業務機能概要!L2 -> 債務管理サブシステム | S2: =業務機能概要!S2 -> 一括支払予定修正 | AJ2: 作成日付 | AO2: =表紙!C51 -> 45898 | AT2: 更新日付
B4: 【メニュー起動時の画面遷移】

Sheet 画面レイアウト (一括支払予定修正対象一覧照会画面）
A1: ドキュメント名 | AH1: サブシステム | AY1: 業務機能名 | DF1: 作成者 | DV1: =表紙!D51 -> SCSK井上 | EL1: 更新者
A2: 業務機能概要書 | R2: 画面レイアウト | AH2: =業務機能概要!L2 -> 債務管理サブシステム | AY2: =業務機能概要!S2 -> 一括支払予定修正 | DF2: 作成日付 | DV2: =表紙!C51 -> 45898 | EL2: 更新日付
A3: 画面名 | J3: 一括支払予定修正対象一覧照会画面 | HS3: 画面№ | IB3: ①
B4: 0 | H4: 40 | R4: 110 | AB4: 180 | AL4: 250 | AV4: 320 | BF4: 390 | BP4: 460 | BZ4: 530 | CJ4: 600 | CT4: 670 | DD4: 740 | DN4: 810 | DX4: 880 | EH4: 950 | HD4: 999 | HG4: ＜補足説明＞
A5: 0
A6: 5
A7: 20
A8: 35
A9: 50
A10: 65
A11: 80
A12: 95
A13: 110
A14: 125
A15: 140
A16: 155
... A47: 620
HH83: 「支払予定修正」ボタン押下時に
HH84: 一括支払予定修正理由修正画面に
HH85: 遷移する。

Sheet 画面レイアウト (一括支払予定修正理由修正画面）
A1: ドキュメント名 | AH1: サブシステム | AX1: 業務機能名 | DF1: 作成者 | DV1: =表紙!D51 -> SCSK井上 | EL1: 更新者
A2: 業務機能概要書 | R2: 画面レイアウト | AH2: =業務機能概要!L2 -> 債務管理サブシステム | AX2: =業務機能概要!S2 -> 一括支払予定修正 | DF2: 作成日付 | DV2: =表紙!C51 -> 45898 | EL2: 更新日付
A3: 画面名 | J3: 一括支払予定修正理由修正画面 | HS3: 画面№ | IB3: ②
B4: 0 | H4: 40 | R4: 110 | AB4: 180 | AL4: 250 | AV4: 320 | BF4: 390 | BP4: 460 | BZ4: 530 | CJ4: 600 | CT4: 670 | DD4: 740 | DN4: 810 | DX4: 880 | EH4: 950 | HD4: 999 | HG4: ＜補足説明＞
A5: 0
A6: 5
A7: 20
A8: 35
A9: 50
A10: 65
A11: 80
A12: 95
A13: 110
A14: 125
A15: 140
A16: 155
... A33: 410
A34: 425 | HH34: 修正ボタン押下時に
A35: 440 | HH35: 一括支払予定修正画面
A36: 455 | HH36: に遷移する。
A37: 470
A38: 485
A39: 500
A40: 515
A41: 530
A42: 545
A43: 560
A44: 575
A45: 590
A46: 605
A47: 620

Sheet 画面レイアウト (一括支払予定修正画面）
A1: ドキュメント名 | AH1: サブシステム | AX1: 業務機能名 | DF1: 作成者 | DV1: =表紙!D51 -> SCSK井上 | EL1: 更新者
A2: 業務機能概要書 | R2: 画面レイアウト | AH2: =業務機能概要!L2 -> 債務管理サブシステム | AX2: =業務機能概要!S2 -> 一括支払予定修正 | DF2: 作成日付 | DV2: =表紙!C51 -> 45898 | EL2: 更新日付
A3: 画面名 | J3: 一括支払予定修正画面 | HS3: 画面№ | IB3: ③
B4: 0 | H4: 40 | R4: 110 | AB4: 180 | AL4: 250 | AV4: 320 | BF4: 390 | BP4: 460 | BZ4: 530 | CJ4: 600 | CT4: 670 | DD4: 740 | DN4: 810 | DX4: 880 | EH4: 950 | HD4: 999 | HG4: ＜補足説明＞
A5: 0
A6: 5
A7: 20
A8: 35
A9: 50
A10: 65
A11: 80
A12: 95 | HH12: 確定ボタン押下時に
A13: 110 | HH13: 一括支払予定修正理由修正画面に
A14: 125 | HH14: 遷移する。
A15: 140
A16: 155
A17: 170
A18: 185
A19: 200
A20: 215
A21: 230
A22: 245
A23: 260
A24: 275
A25: 290
A26: 305
... A47: 620

Sheet 項目概要
A1: ドキュメント名 | O1: サブシステム | W1: 業務機能名 | AR1: 作成者 | AW1: =表紙!D51 -> SCSK井上 | BB1: 更新者 | BW1: ○ | BX1: IN | BY1: 文字列
A2: 業務機能概要書 | G2: 項目概要 | O2: =業務機能概要!L2 -> 債務管理サブシステム | W2: =業務機能概要!S2 -> 一括支払予定修正 | AR2: 作成日付 | AW2: =表紙!C51 -> 45898 | BB2: 更新日付 | BW2: － | BX2: OUT | BY2: 数値
BX3: IN/OUT | BY3: 半英数
A4: 【画面項目説明】 | BY4: 半カナ
BY5: コード
B6: [①一括支払予定修正対象一覧照会画面] | BY6: 日付
B7: № | C7: ラベル | M7: 項目名 | W7: I/O | Y7: 必須 | AA7: 型 | AC7: 桁数 | AE7: ソート | AG7: 初期表示 | AM7: 備考 | BY7: 時間
B8: 【検索条件】 | BY8: －
B9: 1 | C9: 支払部門 | M9: 支払部門コード | W9: IN | Y9: － | AA9: コード | AC9: 10 | AE9: ー | AG9: ー | AM9: 支払予定情報の検索条件として支払部門コードを指定
M10: 支払部門ズームボタン | W10: IN | Y10: － | AA10: － | AC10: ー | AE10: ー | AG10: ー
M11: 支払部門名 | W11: OUT | Y11: － | AA11: 文字列 | AC11: 40 | AE11: ー | AG11: ー | AM11: 支払部門コードに紐づく、組織体系.部門名
B12: 2 | C12: 債務計上部門 | M12: 債務計上部門コード | W12: IN | Y12: － | AA12: コード | AC12: 10 | AE12: ー | AG12: ー | AM12: 支払予定情報の検索条件として債務計上部門コードを指定
M13: 債務計上部門ズームボタン | W13: IN | Y13: － | AA13: － | AC13: ー | AE13: ー | AG13: ー
M14: 債務計上部門名 | W14: OUT | Y14: － | AA14: 文字列 | AC14: 40 | AE14: ー | AG14: ー | AM14: 債務計上部門コードに紐づく、組織体系.部門名
B15: 3 | C15: プロジェクト | M15: プロジェクトコード | W15: IN | Y15: － | AA15: コード | AC15: 20 | AE15: ー | AG15: ー | AM15: 支払予定情報の検索条件としてプロジェクトコードを指定
M16: プロジェクトコードズームボタン | W16: IN | Y16: － | AA16: － | AC16: ー | AE16: ー | AG16: ー
M17: プロジェクト名 | W17: OUT | Y17: － | AA17: 文字列 | AC17: 30 | AE17: ー | AG17: ー | AM17: プロジェクトコードに紐づく、プロジェクト.プロジェクト名
B18: 4 | C18: 名寄部門 | M18: 名寄部門コード | W18: IN | Y18: － | AA18: コード | AC18: 10 | AE18: ー | AG18: ー | AM18: 支払予定情報の検索条件として名寄部門コードを指定
M19: 名寄部門ズームボタン | W19: IN | Y19: － | AA19: － | AC19: ー | AE19: ー | AG19: ー
M20: 名寄部門名 | W20: OUT | Y20: － | AA20: 文字列 | AC20: 40 | AE20: ー | AG20: ー | AM20: 名寄部門コードに紐づく、組織体系.部門名
B21: 5 | C21: 支払締日付 | M21: 支払締日付FROM | W21: IN | Y21: － | AA21: 日付 | AC21: 8 | AE21: ー | AG21: ー | AM21: 支払予定情報の検索条件として支払締日付（FROM）を指定
M22: 支払締日付TO | W22: IN | Y22: － | AA22: 日付 | AC22: 8 | AE22: ー | AG22: ー | AM22: 支払予定情報の検索条件として支払締日付（TO）を指定
B23: 6 | C23: 支払予定日付 | M23: 支払予定日付FROM | W23: IN | Y23: － | AA23: 日付 | AC23: 8 | AE23: ー | AM23: 支払予定情報の検索条件として支払予定日付（FROM）を指定
M24: 支払予定日付TO | W24: IN | Y24: ○ | AA24: 日付 | AC24: 8 | AE24: ー | AG24: システム日付の2営業日後 | AM24: 支払予定情報の検索条件として支払予定日付（TO）を指定。営業日マスタから、当日の2営業日後を取得し初期値として設定。
B25: 7 | C25: 支払先 | M25: 支払先コード | W25: IN | Y25: － | AA25: コード | AC25: 15 | AE25: ー | AG25: ー | AM25: 支払予定情報の検索条件として支払先コードを指定
M26: 支払先ズームボタン | W26: IN | Y26: － | AA26: － | AC26: ー | AE26: ー | AG26: ー
M27: 支払先名 | W27: OUT | Y27: － | AA27: 文字列 | AC27: 50 | AE27: ー | AG27: ー | AM27: 支払先コードに紐づく、取引先.取引先名１＋取引先名２
B28: 8 | C28: 支払締区分 | M28: 支払締区分 | W28: IN | Y28: ○ | AA28: － | AC28: ー | AE28: ー | AG28: 「１：すべて」 | AM28: 「１：すべて」「２：定時支払のみ」「３：随時支払のみ」
B29: 9 | C29: 支払通知書番号 | M29: 支払通知書番号 | W29: IN | Y29: － | AA29: 文字列 | AC29: 12 | AE29: ー | AG29: ー | AM29: 支払予定情報の検索条件として支払通知書を指定
B30: 10 | C30: 確証番号 | M30: 確証番号 | W30: IN | Y30: － | AA30: 文字列 | AC30: 20 | AE30: ー | AG30: ー | AM30: 支払予定情報の検索条件として確証番号を指定
B31: 11 | C31: 金額判定 | M31: 金額判定FROM | W31: IN | Y31: － | AA31: 数値 | AC31: 13 | AE31: ー | AG31: ー | AM31: 支払予定情報の検索条件として取引金額（FROM）を指定
M32: 金額判定TO | W32: IN | Y32: － | AA32: 数値 | AC32: 13 | AE32: ー | AG32: ー | AM32: 支払予定情報の検索条件として取引金額（TO）を指定
B33: 12 | C33: 支払手段 | M33: 支払手段 | W33: IN | Y33: － | AA33: － | AC33: ー | AE33: ー | AG33: ー | AM33: 支払予定情報の検索条件として支払手段をプルダウンから選択。
B34: 13 | C34: 支払方法 | M34: 支払方法 | W34: IN | Y34: － | AA34: － | AC34: ー | AE34: ー | AG34: ー | AM34: 支払予定情報の検索条件として支払方法をプルダウンから選択。支払手段の選択内容からプルダウンの選択項目は変動。
B35: 14 | C35: 振込先金融機関 | M35: 金融機関コード | W35: IN | Y35: － | AA35: コード | AC35: 4 | AE35: ー | AG35: ー | AM35: 支払予定情報の検索条件として振込先金融機関コードを指定
M36: 金融機関ズームボタン | W36: IN | Y36: － | AA36: － | AC36: ー | AE36: ー | AG36: ー
M37: 金融機関名 | W37: OUT | Y37: － | AA37: 文字列 | AC37: 50 | AE37: ー | AG37: ー | AM37: 金融機関コードに紐づく、金融機関.金融機関名
B38: 15 | C38: 振込先店舗 | M38: 店舗コード | W38: IN | Y38: － | AA38: コード | AC38: 3 | AE38: ー | AG38: ー | AM38: 支払予定情報の検索条件として振込先金融機関の店舗コードを設定
M39: 店舗ズームボタン | W39: IN | Y39: － | AA39: － | AC39: ー | AE39: ー | AG39: ー
M40: 店舗名 | W40: OUT | Y40: － | AA40: 文字列 | AC40: 30 | AE40: ー | AG40: ー | AM40: 店舗コードに紐づく、店舗.店舗名
...

Sheet イベント概要
A1: ドキュメント名 | P1: サブシステム | V1: 業務機能名 | AN1: 作成者 | AS1: =表紙!D51 -> SCSK井上 | AX1: 更新者
A2: 業務機能概要書 | G2: イベント概要 | P2: =業務機能概要!L2 -> 債務管理サブシステム | V2: =業務機能概要!S2 -> 一括支払予定修正 | AN2: 作成日付 | AS2: =表紙!C51 -> 45898 | AX2: 更新日付
A4: 【画面イベント処理】
B6: [①一括支払予定修正対象一覧照会画面] | EX6: 注１）初期表示は全ての
B7: № | C7: イベント名 | N7: 処理説明 | EX7: データを処理対象とする
B8: =IF(C8="","",MAX(B$7:B7)+1) -> 1 | C8: 初期処理 | N8: ■ | O8: メニューから起動した場合
B9: =IF(C9="","",MAX(B$7:B8)+1) | O9: １．【検索条件】の初期値設定を行う。（項目概要シート参照）
B10: =IF(C10="","",MAX(B$7:B9)+1) | O10: ２．【検索結果一覧】は0件とする。
B11: =IF(C11="","",MAX(B$7:B10)+1) | O11: ３．【合計金額】の初期値設定を行う。（項目概要シート参照）
B13: =IF(C13="","",MAX(B$7:B11)+1) | N13: ■ | O13: 一括支払予定修正理由修正画面から遷移した場合
B14: =IF(C14="","",MAX(B$7:B12)+1) | O14: １．「検索ボタン」イベントを実行し、再度検索結果を取得する。【検索結果一覧】に設定する。（検索条件は当初の検索条件を適用）
B15: =IF(C15="","",MAX(B$7:B13)+1) | O15: ２．１．の結果から【合計金額】を再度設定する。
B16: =IF(C16="","",MAX(B$7:B15)+1)
B17: =IF(C17="","",MAX(B$7:B16)+1)
B18: =IF(C18="","",MAX(B$7:B17)+1)
B19: =IF(C19="","",MAX(B$7:B18)+1) -> 2 | C19: 支払部門ズームボタン | N19: １．計上部門ズームを起動する。
B20: =IF(C20="","",MAX(B$7:B19)+1) | O20: 計上部門ズーム画面には下記項目を引き渡す。
B21: =IF(C21="","",MAX(B$7:B20)+1) | P21: ・ | Q21: 部門基準日 | X21: ： | Y21: 遷移元画面で入力された支払予定日付FROM
B22: =IF(C22="","",MAX(B$7:B21)+1) | P22: ・ | Q22: 計上部門コード | X22: ： | Y22: 遷移元画面で入力された支払部門コード
B23: =IF(C23="","",MAX(B$7:B22)+1) | P23: ・ | Q23: 計上部門名(カナ) | X23: ： | Y23: 未設定
B24: =IF(C24="","",MAX(B$7:B23)+1) | P24: ・ | Q24: 廃止部門取得 | X24: ： | Y24: チェックなし（廃止部門は取得しない） | AJ24: ※変更不可とする
B25: =IF(C25="","",MAX(B$7:B24)+1) | P25: ・ | Q25: 廃止部門取得日付 | X25: ： | Y25: 未設定
B26: =IF(C26="","",MAX(B$7:B25)+1) | N26: ２．計上部門ズーム画面で選択した値により、遷移元画面の以下の項目を設定する。
B27: =IF(C27="","",MAX(B$7:B26)+1) | P27: ・ | Q27: 支払部門コード
B28: =IF(C28="","",MAX(B$7:B27)+1) | P28: ・ | Q28: 支払部門名
B29: =IF(C29="","",MAX(B$7:B28)+1)
B30: =IF(C30="","",MAX(B$7:B29)+1) -> 3 | C30: 債務計上部門ズームボタン | N30: １．計上部門ズームを起動する。
B31: =IF(C31="","",MAX(B$7:B30)+1) | O31: 計上部門ズーム画面には下記項目を引き渡す。
B32: =IF(C32="","",MAX(B$7:B31)+1) | P32: ・ | Q32: 部門基準日 | X32: ： | Y32: 遷移元画面で入力された支払予定日付FROM
B33: =IF(C33="","",MAX(B$7:B32)+1) | P33: ・ | Q33: 計上部門コード | X33: ： | Y33: 遷移元画面で入力された債務計上部門コード
B34: =IF(C34="","",MAX(B$7:B33)+1) | P34: ・ | Q34: 計上部門名(カナ) | X34: ： | Y34: 未設定
B35: =IF(C35="","",MAX(B$7:B34)+1) | P35: ・ | Q35: 廃止部門取得 | X35: ： | Y35: チェックなし（廃止部門は取得しない） | AJ35: ※変更不可とする
B36: =IF(C36="","",MAX(B$7:B35)+1) | P36: ・ | Q36: 廃止部門取得日付 | X36: ： | Y36: 未設定
B37: =IF(C37="","",MAX(B$7:B36)+1) | N37: ２．計上部門ズーム画面で選択した値により、遷移元画面の以下の項目を設定する。
B38: =IF(C38="","",MAX(B$7:B37)+1) | P38: ・ | Q38: 債務計上部門コード
B39: =IF(C39="","",MAX(B$7:B38)+1) | P39: ・ | Q39: 債務計上部門名
B40: =IF(C40="","",MAX(B$7:B39)+1)
B52: =IF(C52="","",MAX(B$7:B40)+1) -> 4 | C52: プロジェクトコードズームボタン | N52: １．プロジェクトコードズームを起動する。
B53: =IF(C53="","",MAX(B$7:B52)+1) | O53: プロジェクトコードズーム画面には下記項目を引き渡す。
B54: =IF(C54="","",MAX(B$7:B53)+1) | P54: ・ | Q54: プロジェクトコード | X54: ： | Y54: 遷移元画面で入力されたプロジェクトコード
...

Sheet チェック仕様
A1: ドキュメント名 | J1: サブシステム | Q1: 業務機能名 | AH1: 作成者 | AM1: =表紙!D51 -> SCSK井上 | AR1: 更新者
A2: 業務機能概要書 | F2: チェック仕様 | J2: =業務機能概要!L2 -> 債務管理サブシステム | Q2: =業務機能概要!S2 -> 一括支払予定修正 | AH2: 作成日付 | AM2: =表紙!C51 -> 45898 | AR2: 更新日付
A4: 【チェック処理】
B6: ①一括支払予定修正対象一覧照会画面
B7: １．検索ボタン押下時
B8: № | C8: 項目名 | J8: 条件必須 | M8: 存在 | P8: 範囲 | S8: 関連 | V8: その他 | Y8: 内容
B9: =IF(C9="","",MAX(B$8:B8)+1) -> 1 | C9: ー | W9: 〇 | Y9: 取得対象のデータ件数が0件の場合
B10: =IF(C10="","",MAX(B$8:B9)+1) | Z10: エラーメッセージ：「該当データがありません。」（AE15_MTI00000）
B11: =IF(C11="","",MAX(B$8:B10)+1)
B12: =IF(C12="","",MAX(B$8:B11)+1) -> 2 | C12: ー | W12: 〇 | Y12: 取得したデータ件数が制限件数を超えた場合
B13: =IF(C13="","",MAX(B$8:B12)+1) | Z13: エラーメッセージ：「処理対象のデータが件数の制限値{0}を超えたため、処理はキャンセルされました。
B14: =IF(C14="","",MAX(B$8:B13)+1) | AE14: 処理条件を見直して再度実行してください。」（AE91_MTI00000）
B16: ２．支払予定修正ボタン
B17: № | C17: 項目名 | J17: 条件必須 | M17: 存在 | P17: 範囲 | S17: 関連 | V17: その他 | Y17: 内容
B18: =IF(C18="","",MAX(B$17:B17)+1) -> 1 | C18: ー | W18: 〇 | Y18: 選択チェックボックスがONになっている明細について、更新日時が変更されている場合
B19: =IF(C19="","",MAX(B$17:B18)+1) | Z19: エラーメッセージ：「該当するデータは既に更新されています。」（AE16_MTI00002）
B20: =IF(C20="","",MAX(B$17:B19)+1)
B22: ②一括支払予定修正理由修正画面
B23: １．時間指定実行ボタン
B24: № | C24: 項目名 | J24: 条件必須 | M24: 存在 | P24: 範囲 | S24: 関連 | V24: その他 | Y24: 内容
B25: =IF(C25="","",MAX(B$24:B24)+1) -> 1 | C25: 支払部門 | N25: 〇 | Y25: 支払部門が組織体系に未登録または廃止されている場合
B26: =IF(C26="","",MAX(B$17:B25)+1) | Z26: エラーメッセージ：「修正情報.支払部門:支払部門は、組織体系に未登録または廃止されています。」
B27: =IF(C27="","",MAX(B$17:B26)+1) | AE27: （AE00_AAP00036）
B49: ③一括支払予定修正画面
B50: １．確定ボタン
B51: № | C51: 項目名 | J51: 条件必須 | M51: 存在 | P51: 範囲 | S51: 関連 | V51: その他 | Y51: 内容
B52: =IF(C52="","",MAX(B$51:B51)+1) -> 1 | C52: 手形期日 | Q52: 〇 | Y52: 手形期日<振出日付の場合
B53: =IF(C53="","",MAX(B$24:B52)+1) | Z53: エラーメッセージ：「修正情報.手形期日:手形期日は、振出日付よりも過去の日付にすることは出来ません。」 | BE53: AE05_AAP00011
B54: =IF(C54="","",MAX(B$24:B53)+1)
B55: =IF(C55="","",MAX(B$24:B54)+1) -> 2 | C55: 出金口座 | N55: 〇 | Y55: 出金口座が自社口座マスタに未登録または使用不可となっている場合
B56: =IF(C56="","",MAX(B$24:B55)+1) | Z56: エラーメッセージ：「修正情報.出金口座:出金口座は、自社口座マスタに未登録または使用不可となっています。」 | BE56: AE00_AAP00026
B57: =IF(C57="","",MAX(B$24:B56)+1)
B58: =IF(C58="","",MAX(B$24:B57)+1) -> 3 | C58: 金融機関 | N58: 〇 | Y58: 金融機関が金融機関マスタに未登録または使用不可となっている場合
B59: =IF(C59="","",MAX(B$24:B58)+1) | Z59: エラーメッセージ：「修正情報.金融機関:金融機関は、金融機関マスタに未登録または廃止されています。」 | BE59: AE00_AAP00015
B60: =IF(C60="","",MAX(B$24:B59)+1)
B61: =IF(C61="","",MAX(B$24:B60)+1) -> 4 | C61: 店舗 | N61: 〇 | Y61: 店舗が店舗マスタに未登録または使用不可となっている場合
B62: =IF(C62="","",MAX(B$24:B61)+1) | Z62: エラーメッセージ：「修正情報.店舗:店舗は、店舗マスタに未登録または廃止されています。」 | BE62: AE00_AAP00016
B63: =IF(C63="","",MAX(B$24:B62)+1)
B64: =IF(C64="","",MAX(B$24:B63)+1) -> 5 | C64: 振出日付 | K64: 〇 | Y64: 支払方法コードに紐づく、支払方法.支払手段区分が「3:手形支払」であり、かつ、振出日付がブランクの場合
B65: =IF(C65="","",MAX(B$24:B64)+1) | Z65: エラーメッセージ：「修正情報.振出日付:必須項目です。」 | BE65: AE11_MTI00000
...

Sheet ⇒

Sheet データアクセス要領
A1: ドキュメント名 | L1: サブシステム | S1: 業務機能名 | AJ1: 作成者 | AO1: =表紙!D51 -> SCSK井上 | AT1: 更新者
A2: 業務機能概要書 | G2: データアクセス要領 | L2: =業務機能概要!L2 -> 債務管理サブシステム | S2: =業務機能概要!S2 -> 一括支払予定修正 | AJ2: 作成日付 | AO2: =表紙!C51 -> 45898 | AT2: 更新日付
A4: 【編集要領】
B6: ①一括支払予定修正対象一覧照会画面
C7: 変更済みのみ対象 | I7: 振込先口座変更済みのみ出力 | V7: 検索時のSQL
D8: チェック無し | K8: チェック無し | S8: １．２．の結果をUNIONで結合して出力する。
D9: チェックあり | K9: チェック無し | S9: ２．の結果を出力する。
D10: チェック無し | K10: チェックあり | S10: ３．の結果を出力する。
D11: チェックあり | K11: チェックあり | S11: ２．の結果を出力する。
B15: １． | C15: 検索ボタン押下時①（支払予定変更なしデータのみ取得）
D17: ■抽出エンティティ
D18: № | E18: エンティティ名
D19: 1 | E19: 支払予定テーブル
D20: 2 | E20: 支払通知書テーブル
D21: 3 | E21: 債務テーブル
D22: 4 | E22: 支払伝票テーブル
D23: 5 | E23: プロジェクトテーブル
D24: 6 | E24: 取引先テーブル
D25: 7 | E25: 金融機関テーブル
D26: 8 | E26: 店舗テーブル
D27: 9 | E27: 自社口座テーブル
D28: 10 | E28: 組織体系テーブル
D29: 11 | E29: 支払決済条件テーブル
... D31: 13 | E31: 支払手形依頼テーブル
D33: ■抽出項目
D34: № | E34: 項目名
D35: 1 | E35: 支払通知書．支払締日付 | V35: 22 | W35: 組織体系（債務計上部門用）．部門表示コード
D36: 2 | E36: 支払通知書．支払通知書番号 | V36: 23 | W36: 組織体系（債務計上部門用）．部門名（略）
D37: 3 | E37: 債務．仕訳プロジェクトコード | V37: 24 | W37: 支払決済条件．支払決済条件コード
D38: 4 | E38: プロジェクト．プロジェクト名 | V38: 25 | W38: 支払決済条件．支払決済条件名（略）
D39: 5 | E39: 組織体系（支払部門用）．部門表示コード | V39: 26 | W39: 支払通知書．支払金額
D40: 6 | E40: 組織体系（支払部門用）．部門名（略） | V40: 27 | W40: 支払通知書．支払決済金額
D41: 7 | E41: 支払予定．支払先コード | V41: 28 | W41: 支払通知書．支払金額-支払通知書．支払決済金額
D42: 8 | E42: 取引先．取引先名（略） | V42: 29 | W42: 支払通知書．支払通知書状況区分
D43: 9 | E43: 支払予定．支払予定日付 | V43: 30 | W43: 支払予定．更新日時
D44: 10 | E44: 支払予定．支払予定コード | V44: 31 | W44: 支払予定．更新者
D45: 11 | E45: 支払方法．支払方法名 | V45: 32 | W45: ユーザ．ユーザ名（姓）+ユーザ．ユーザ名（名）
D46: 12 | E46: 支払予定．振込金融機関コード | V46: 33 | W46: 支払手形依頼．手形振出日付
... D53: 19 | E53: 店舗（出金口座）．店舗名 | V53: 40 | W53: 支払予定．振込先口座名義人（カナ）
D54: 20 | E54: 支払予定．自社口座コード
...

Sheet 補足
A1: ドキュメント名 | L1: サブシステム | R1: 業務機能名 | AM1: 作成者 | AR1: =表紙!D51 -> SCSK井上 | AW1: 更新者
A2: 業務機能概要書 | G2: 補足説明 | L2: =業務機能概要!L2 -> 債務管理サブシステム | R2: =業務機能概要!S2 -> 一括支払予定修正 | AM2: 作成日付 | AR2: =表紙!C51 -> 45898 | AW2: 更新日付
B4: ①一括支払予定対象一覧照会画面のCSV出力
B5: 検索結果一覧部のグリッドをCSV形式で出力するイメージ
C7: テキストエディタで開いた場合（横に長いため分けて添付）
C68: Excelで開いた場合（横に長いため分けて添付）
B132: ②一括支払予定修正対象一覧照会画面の検索結果について
E134: 例１（ホクレン様想定） | X134: 一括支払予定修正対象一覧照会画面
F135: 支払通知書（支払案内書）
G136: 支払先A
G137: 9/20支払
G138: 振込
G139: 自社口座X
G140: 振込先口座Y
H141: 支払依頼伝票１（取引） | U141: → | X141: 支払先A、9/20支払、振込、、自社口座X、振込先口座Y、プロジェクト（業種A）、債務計上部門AA、50,000円
I142: 明細１ | L142: プロジェクト（業種A）
L143: 債務計上部門AA
L144: 50,000
E149: 例２（随時支払 複数明細）
F150: 支払通知書（支払案内書）
G151: 支払先A
G152: 9/20支払
G153: 振込
G154: 自社口座X
G155: 振込先口座Y
H156: 支払依頼伝票１（取引） | U156: → | X156: 支払先A、9/20支払、振込、、自社口座X、振込先口座Y、プロジェクト（業種B）、債務計上部門BB、90,000円
I157: 明細１ | L157: プロジェクト（業種B）
L158: 債務計上部門BB
L159: 40,000
I160: 明細２ | L160: プロジェクト（業種C）
L161: 債務計上部門CC
L162: 50,000
E167: 例３ （定時支払）
F169: 支払通知書（支払案内書）
G170: 支払先A
G171: 9/20支払
G172: 振込
G173: 自社口座X
G174: 振込先口座Y
H175: 支払依頼伝票１（取引） | U175: → | X175: 支払先A、9/20支払、振込、、自社口座X、振込先口座Y、プロジェクト（業種D）、債務計上部門DD、70,000円
...
