Workbook
Name 【債権】最新データ辞書: #REF!
Name ステータスリスト: #REF!
Name 形式: #REF!
Name 項目辞書: #REF!
Name 項目辞書: #REF!
Name 重要度リスト: #REF!
Name 媒体: #REF!
Name 分類リスト: #REF!
Name 連携方法: #REF!

Sheet 表紙
F46: ProActive
B48: 変更履歴
B50: 項番 | C50: 変更発生日 | D50: 変更者 | E50: 変更箇所 | F50: 変更内容
B51: 1 | C51: 45898 | D51: SCSK位田 | F51: 新規作成
B52: 2
B53: 3
B54: 4
B55: 5
B56: 6
B57: 7
B58: 8
B59: 9
B60: 10
B61: 11
B62: 12
B63: 13
... B80: 30

Sheet 業務機能概要
A1: ドキュメント名 | L1: サブシステム | Q1: 業務機能名 | AJ1: 作成者 | AO1: =表紙!D51 -> SCSK位田 | AT1: 更新者
A2: 業務機能概要書 | G2: 業務機能概要 | L2: 業務共通 | Q2: 取引先マスタ自動取込 | AJ2: 作成日付 | AO2: =表紙!C51 -> 45898 | AT2: 更新日付
B4: 【目的・役割】
C5: ・ | D5: ホクレン様のシステムでは、伝票入力は部門システムやスクラッチ開発する機能で実施し、また、マスタ情報の管理も共通マスタや会計マスタのマスタ管理システムで実施する。
D6: このため、ProActiveC4では、仕訳、支払などの業務データや組織、勘定科目、取引先などのマスタ情報を外部のシステムから取込む必要がある。
D7: マスタデータは夜間処理にて、スクラッチ開発するマスタ（ProActiveC4外のシステム）の情報と同期をとる必要がある。
B10: 【利用者】
C11: ・ | D11: バッチ実行
B14: 【利用頻度】
C15: ・ | D15: 日次 | H15: ※ | I15: 取引先マスタを新規登録してすぐに、スクラッチで伝票入力することがあるため、日中連動も実施する。
B18: 【対象要件定義書】
C19: ・ | D19: 要件定義書(他システムとのデータ連動)
B22: 【処理概要】
C23: １) | D23: ファイルによってデータ連動される取引先、支払先（決済条件含む）の情報をProActiveC4標準の「取引先マスタ取込データ」の処理を使用してProActiveC4に取込む。
D24: バッチファイルで定義された取込ディレクトリに配置されている連動データ（取込用のCSVファイル）の情報を取得する。
D25: ※ | E25: 取引先は支払先ではない取引相手（仕訳上、科目の内訳情報として使用される取引相手先）と定義する
D26: ※ | E26: 取引先、支払先はそれぞれ別の連動データとして別ファイルで作成される想定
F27: 取引先取込ファイル | O27: ： | P27: TORISK_YYYYMMDDHHMMSSmmm.csv
F28: 支払先取込ファイル | O28: ： | P28: SHHARSK_YYYYMMDDHHMMSSmmm.csv
C31: ２) | D31: 1)で取得した取込ファイルをINPUTとして、取引先マスタ外部データ取込をバッチ実行する。（オンライン機能「取引先マスタ外部データ取込」の動作を踏襲する。）
D32: ※標準の取引先マスタ外部データ取込はオンライン処理可能なままとする
D34: 2-1. | F34: 取引先マスタ自動取込バッチ
F35: 標準機能の取引先外部データ取込をバッチダイレクトで実行する。（※取込対象を取引先として実行する）
D37: 2-2. | F37: 支払先マスタ自動取込バッチ
F38: 標準機能の取引先外部データ取込をバッチダイレクトで実行する。（※取込対象を支払先として実行する）
C40: 3) | D40: バッチ実行される取引先マスタ外部データ取込は、ProActiveC4外のタスク管理用のミドルウェア（以下、タスクスケジューラ）から実行する想定とする。
D41: 正常終了、対象データがない場合は、「異常なし」のステータスをタスクスケジューラに返却する。
D42: エラー終了の場合は、「エラーあり」のステータスをタスクスケジューラに返却する。
D45: [実行情報]
D46: No | F46: パラメータ | O46: 内容
D47: 1 | F47: ※イベント概要参照
D50: [終了情報]
D51: 戻り値 | F51: 内容 | O51: 内容
D52: 0 | F52: 正常終了
D53: 1 | F53: 異常終了 | O53: 業務エラー/システムエラー発生時 | AJ53: ※「補足1 取込結果判定」シート参照
B56: 【共通要件】
D57: 共通要件内容 | J57: 対応内容（標準準拠の場合、記載省略）
D58: セキュリティ | J58: 部門制限、本人制限の機能性は実装しない。
D59: 承認WF | J59: 対応なし。承認WFの利用は不可とする。
D60: 組織変更 | J60: 対応なし。当機能は仕訳に関係しないため、組織変更を考慮しない。
...

Sheet 画面遷移図
A1: ドキュメント名 | L1: サブシステム | Q1: 業務機能名 | AJ1: 作成者 | AO1: =表紙!D51 -> SCSK位田 | AT1: 更新者 | AY1: SCSK相坂
A2: 業務機能概要書 | G2: 画面遷移図 | L2: =業務機能概要!L2 -> 業務共通 | Q2: =業務機能概要!Q2 -> 取引先マスタ自動取込 | AJ2: 作成日付 | AO2: =表紙!C51 -> 45898 | AT2: 更新日付 | AY2: 44103
B4: 【メニュー起動時の画面遷移】

Sheet 画面レイアウト
A1: ドキュメント名 | AH1: サブシステム | AX1: 業務機能名 | DF1: 作成者 | DV1: =表紙!D51 -> SCSK位田 | EL1: 更新者
A2: 業務機能概要書 | R2: 画面レイアウト | AH2: =業務機能概要!L2 -> 業務共通 | AX2: =業務機能概要!Q2 -> 取引先マスタ自動取込 | DF2: 作成日付 | DV2: =表紙!C51 -> 45898 | EL2: 更新日付
A3: 画面名 | FD3: 画面№ | FM3: ①
B4: 0 | H4: 40 | R4: 110 | AB4: 180 | AL4: 250 | AV4: 320 | BF4: 390 | BP4: 460 | BZ4: 530 | CJ4: 600 | CT4: 670 | DD4: 740 | DN4: 810 | DX4: 880 | EH4: 950 | EO4: 999 | ER4: ＜補足説明＞
A5: 0
A6: 5
A7: 20
A8: 35
A9: 50
A10: 65
A11: 80
A12: 95
A13: 110
A14: 125
A15: 140
A16: 155
... A47: 620
A57: 画面名 | J57: 自動消込確定情報登録画面 | FD57: 画面№ | FM57: ②
B58: 0 | H58: 40 | R58: 110 | AB58: 180 | AL58: 250 | AV58: 320 | BF58: 390 | BP58: 460 | BZ58: 530 | CJ58: 600 | CT58: 670 | DD58: 740 | DN58: 810 | DX58: 880 | EH58: 950 | EO58: 999 | ER58: ＜補足説明＞
A59: 0
A60: 5
A61: 20
A62: 35
A63: 50
A64: 65
A65: 80
A66: 95
A67: 110
A68: 125
A69: 140
A70: 155
... A101: 620
A111: 画面名 | FD111: 画面№ | FM111: ①
B112: 0 | H112: 40 | R112: 110 | AB112: 180 | AL112: 250 | AV112: 320 | BF112: 390 | BP112: 460 | BZ112: 530 | CJ112: 600 | CT112: 670 | DD112: 740 | DN112: 810 | DX112: 880 | EH112: 950 | EO112: 999 | ER112: ＜補足説明＞
A113: 0
A114: 5
A115: 20
A116: 35
A117: 50
A118: 65
...

Sheet 項目概要
A1: ドキュメント名 | L1: サブシステム | Q1: 業務機能名 | AJ1: 作成者 | AO1: =表紙!D51 -> SCSK位田 | AT1: 更新者 | BE1: ○ | BF1: IN | BG1: 文字列
A2: 業務機能概要書 | G2: 項目概要 | L2: =業務機能概要!L2 -> 業務共通 | Q2: =業務機能概要!Q2 -> 取引先マスタ自動取込 | AJ2: 作成日付 | AO2: =表紙!C51 -> 45898 | AT2: 更新日付 | BE2: － | BF2: OUT | BG2: 数値
BF3: IN/OUT | BG3: 半英数
A4: 【画面項目説明】 | BG4: 半カナ
BG5: コード
B6: [①自動消込確定情報登録画面] | AQ6: ※追加及び変更項目のみ記載 | BG6: 日付
B7: № | C7: ラベル | J7: 項目名 | Q7: I/O | S7: 必須 | U7: 型 | W7: 桁数 | Y7: ソート | AA7: 初期表示 | AE7: 備考 | BG7: －
B8: 【ヘッダ部】
B9: 1 | C9: 一覧を最大化 | J9: 一覧を最大化ボタン | Q9: IN | S9: － | U9: － | W9: － | Y9: ー | AA9: ー
B10: 2 | Q10: IN | S10: ○ | U10: 日付 | W10: 8 | Y10: ー | AA10: システム日付
B11: 3 | Q11: OUT | S11: － | U11: コード | W11: 12 | Y11: ー | AA11: ー
B12: 4 | Q12: IN | S12: ○ | U12: コード | W12: 10 | Y12: ー | AA12: ー
Q13: IN | S13: － | U13: － | W13: ー | Y13: ー | AA13: ー
Q14: OUT | S14: － | U14: 文字列 | W14: 20 | Y14: ー | AA14: ー
B15: 5 | Q15: IN | S15: ○ | U15: コード | W15: 15 | Y15: ー | AA15: ー
Q16: IN | S16: － | U16: － | W16: ー | Y16: ー | AA16: ー
Q17: OUT | S17: － | U17: 文字列 | W17: 20 | Y17: ー | AA17: ー
B18: 6 | Q18: IN | S18: ○ | U18: － | W18: ー | Y18: ー
B20: 7 | Q20: IN | S20: ○ | U20: 数値 | W20: 13 | Y20: ー | AA20: ー
B21: 【】
B22: 1
B25: 2
B28: 3
B30: 4
B31: 5
B32: 【】 | AE32: ※ソート順は画面レイアウトシートの補足説明欄参照。
B33: 1
B34: 2
B35: 2
B36: 3
B37: 2
B38: 3
B39: 4
B40: 5
B41: 6
B42: 7
B43: 8
B44: 9
... B52: 16
B53: 【フッタ部】
...

Sheet イベント概要
A1: ドキュメント名 | L1: サブシステム | Q1: 業務機能名 | AJ1: 作成者 | AO1: =表紙!D51 -> SCSK位田 | AT1: 更新者
A2: 業務機能概要書 | G2: イベント概要 | L2: =業務機能概要!L2 -> 業務共通 | Q2: =業務機能概要!Q2 -> 取引先マスタ自動取込 | AJ2: 作成日付 | AO2: =表紙!C51 -> 45898 | AT2: 更新日付
A4: 【画面イベント処理】
EV5: 注１）初期表示は全ての
B6: № | C6: イベント名 | J6: 処理説明 | EV6: データを処理対象とする
B7: =IF(C7="","",MAX(B$6:B6)+1) -> 1 | C7: 取引先マスタ自動取込バッチイベント | J7: 1. | K7: バッチファイルで定義されたディレクトリに配置された取込用のCSVファイルをINPUTとし、
B8: =IF(C8="","",MAX(B$6:B7)+1) | K8: ProActiveC4標準機能の取引先外部データ取込を実行する。（※取込対象は取引先として実行する）
K9: ＜パラメータ＞
K10: ・ | L10: 会社コード | T10: ： | U10: バッチ実行用のxmlで指定された会社コード
K11: ・ | L11: 取込対象 | T11: ： | U11: 取引先
K12: ・ | L12: 取引先取込CSVファイル | T12: ： | U12: バッチファイルのパラメータにて指定されたファイル
B13: =IF(C13="","",MAX(B$6:B8)+1)
B14: =IF(C14="","",MAX(B$6:B13)+1) | K14: 取込用のCSVファイルが取得できなかった場合は、処理を中断する。バッチ実行結果はエラーとする。
K15: 取得できた場合は、後続の処理を継続する。
K16: ※ | L16: 上記のファイル取得、エラーハンドリングはバッチファイルで実施する（アプリケーションでの考慮は不要）
K17: ※ | L17: 取込用CSVのファイルサイズが0byteの場合は、正常として処理終了する。（バッチファイルにてファイルを正常処理フォルダへ移動する）
J19: ２．実行結果をバッチジョブ情報に反映する。
K20: ■ | L20: 取込対象ファイルが存在しなかった場合
M21: 今回のデータ連動では、連動対象データが存在しない場合は0byteファイルが連動され、バッチファイルにて処理対象外とするため
M22: ProActiveのプログラムでデータが存在しない場合のハンドリングは不要となる。
K24: ■ | L24: 上記以外の場合
M25: 標準仕様に準じる
B26: =IF(C26="","",MAX(B$6:B14)+1)
B27: =IF(C27="","",MAX(B$6:B15)+1) | J27: ３．実行結果をバッチジョブ情報に反映する。
B28: =IF(C28="","",MAX(B$6:B26)+1) | K28: ■ | L28: 業務エラー（マスタの存在チェックエラーなど）の場合 | AK28: ※ | AL28: ProActiveC4標準の仕様では、業務エラーがあった場合
B29: =IF(C29="","",MAX(B$6:B28)+1) | L29: ※エラー内容に１つでもNULL以外のメッセージが設定されていた場合 | AL29: 「正常終了」となるが、エラー対処が必要となるため、
B30: =IF(C30="","",MAX(B$6:B29)+1) | M30: 進行状況 | Q30: ： | R30: エラー | AL30: 処理結果は「エラー」とする
B31: =IF(C31="","",MAX(B$6:B30)+1) | M31: 機能 | Q31: ： | R31: 取引先取込処理実行バッチ
M32: メッセージ内容 | Q32: ： | R32: 「取込データにエラーが存在しています。取引先外部取込履歴一覧照会より、取引先外部取込チェックリストを出力して内容をご確認ください。」 | BD32: AE99_CMCST02
B33: =IF(C33="","",MAX(B$6:B31)+1) | K33: ■ | L33: 上記以外の場合
B34: =IF(C34="","",MAX(B$6:B33)+1) | M34: 標準仕様に準じる
J36: ４．バッチ実行結果の終了情報を返却する。
K37: ■ | L37: 正常終了できた場合
M38: 「0:正常終了」
K39: ■ | L39: エラーが発生した場合（※ProActiveC4標準機能の取引先外部データ取込でエラーが発生した場合は当ケースに該当する）
M40: 「1:異常終了」
J42: ５．取込処理後、取込用のCSVファイルは処理済用ファイルのディレクトリに移動する
K43: ※ | L43: アプリケーションではなくバッチファイルでファイル移動する
K44: ※ | L44: 正常用、エラー用のディレクトリを作成して処理結果によって移動先ディレクトリを分岐させる
B49: 2 | C49: 支払先マスタ自動取込バッチイベント | J49: 1. | K49: バッチファイルで定義されたディレクトリに配置された取込用のCSVファイルをINPUTとし、
...

Sheet チェック仕様
A1: ドキュメント名 | L1: サブシステム | Q1: 業務機能名 | AJ1: 作成者 | AO1: =表紙!D51 -> SCSK位田 | AT1: 更新者
A2: 業務機能概要書 | G2: チェック仕様 | L2: =業務機能概要!L2 -> 業務共通 | Q2: =業務機能概要!Q2 -> 取引先マスタ自動取込 | AJ2: 作成日付 | AO2: =表紙!C51 -> 45898 | AT2: 更新日付
A4: 【チェック処理】
B6: １．初期処理時
B7: № | C7: 項目名 | L7: 条件必須 | O7: 存在 | R7: 範囲 | U7: 関連 | X7: その他 | AA7: 内容
B8: =IF(C8="","",MAX(B7:B$7)+1) -> 1 | C8: － | X8: ○
B9: =IF(C9="","",MAX(B$7:B8)+1)
B10: =IF(C10="","",MAX(B$7:B9)+1)
B11: =IF(C11="","",MAX(B$7:B10)+1)
B13: ２．検索ボタン押下時
B14: № | C14: 項目名 | L14: 条件必須 | O14: 存在 | R14: 範囲 | U14: 関連 | X14: その他 | AA14: 内容
B15: =IF(C15="","",MAX(B$14:B14)+1)
B16: =IF(C16="","",MAX(B$14:B15)+1)
B17: =IF(C17="","",MAX(B$14:B16)+1)
B18: =IF(C18="","",MAX(B$14:B17)+1)
B19: =IF(C19="","",MAX(B$14:B18)+1)
B20: =IF(C20="","",MAX(B$14:B19)+1)
B21: =IF(C21="","",MAX(B$14:B20)+1)
B22: =IF(C22="","",MAX(B$14:B21)+1)
B23: =IF(C23="","",MAX(B$14:B22)+1)
B24: =IF(C24="","",MAX(B$14:B23)+1)
B25: =IF(C25="","",MAX(B$14:B24)+1)
B26: =IF(C26="","",MAX(B$14:B25)+1)
... B31: =IF(C31="","",MAX(B$14:B30)+1)
B33: ３．データ取込ボタン
B34: № | C34: 項目名 | L34: 条件必須 | O34: 存在 | R34: 範囲 | U34: 関連 | X34: その他 | AA34: 内容
B35: =IF(C35="","",MAX(B$34:B34)+1)
B36: =IF(C36="","",MAX(B$34:B35)+1)
B37: =IF(C37="","",MAX(B$34:B36)+1)
B38: =IF(C38="","",MAX(B$34:B37)+1)
B39: =IF(C39="","",MAX(B$34:B38)+1)
B40: =IF(C40="","",MAX(B$34:B39)+1)
B41: =IF(C41="","",MAX(B$34:B40)+1)
B42: =IF(C42="","",MAX(B$34:B41)+1)
B43: =IF(C43="","",MAX(B$34:B42)+1)
B44: =IF(C44="","",MAX(B$34:B40)+1)
B45: =IF(C45="","",MAX(B$34:B44)+1)
B46: =IF(C46="","",MAX(B$34:B45)+1)
B47: 4
B48: =IF(C48="","",MAX(B$34:B47)+1)
...

Sheet 出力CSV定義
A1: ドキュメント名 | E1: サブシステム | G1: 業務機能名 | P1: 作成者 | R1: =表紙!D51 -> SCSK位田 | T1: 更新者
A2: 業務機能概要書 | C2: 出力CSV定義 | E2: =業務機能概要!L2 -> 業務共通 | G2: =業務機能概要!Q2 -> 取引先マスタ自動取込 | P2: 作成日 | R2: =表紙!C51 -> 45898 | T2: 更新日
A4: データ名 | I4: ヘッダ行 | K4: あり | M4: なし | N4: ダブルクォーテーション | Q4: あり | S4: なし | X4: 文字列
A5: ﾌｧｲﾙ形式・ﾚｺｰﾄﾞ長 | D5: 固定長（ | G5: Byte） | I5: 可変長（区切り文字［ ，(カンマ) ］） | M5: バイナリデータ | P5: その他（ ） | X5: 半英数
A6: 文字コード | D6: UNI（Win系） | F6: EBCDIC(K) | I6: その他（UTF-8） | M6: 改行コード | O6: LF(UNIX系) | Q6: CRLF(Win系) | T6: なし | X6: 半カナ
A7: 全角(2byte)文字項目 | D7: あり | F7: なし | M7: 数値編集 | O7: 左詰め | Q7: 右詰め［ゼロ埋め］ | T7: 右詰め［スペース埋め］ | X7: コード
A8: 特記事項 | C8: 出力順：起票日付、仕訳伝票番号、仕訳自動作成フラグ、仕訳伝票行番号 | J8: ※「"」が含まれる項目は「""」に変換する。 | X8: 数値
A9: No. | B9: 項目名 | E9: 必須 | F9: 型 | G9: 桁数 | H9: 開始位置 | I9: 備考 | X9: 日付
H10: /列 | X10: 時間
A11: 1 | F11: 日付 | G11: 8 | H11: A | X11: 年月
A12: 2 | F12: 半英数 | G12: 12 | H12: B | X12: 区分
A13: 3 | F13: コード | G13: 10 | H13: C | X13: フラグ
A14: 4 | F14: 文字列 | G14: 40 | H14: D | X14: -
A15: 5
A16: 6
A17: 7
A18: 8
A19: 9
A20: 10
A21: 11
A22: 12
A23: 13
A24: 14
A25: 15

Sheet 出力CSVサンプル

Sheet 取込フォーマット定義（一般支払先）
A1: ドキュメント名 | E1: サブシステム | G1: 業務機能名 | P1: 作成者 | R1: SCSK位田 | T1: 更新者
A2: 業務機能概要書 | C2: 取込フォーマット定義 | E2: 業務共通 | G2: 取引先マスタ自動取込 | P2: 作成日 | R2: =表紙!C51 -> 45898 | T2: 更新日
A4: データ名 | C4: 支払先外部データ取込フォーマット | I4: ヘッダ行 | K4: あり | M4: なし | N4: ダブルクォーテーション | Q4: あり | S4: なし | X4: 文字列
A5: ﾌｧｲﾙ形式・ﾚｺｰﾄﾞ長 | D5: 固定長（ | G5: Byte） | I5: 可変長（区切り文字［ ，(カンマ) ］） | M5: バイナリデータ | P5: その他（ ） | X5: 半英数
A6: 文字コード | D6: UNI（Win系） | F6: EBCDIC(K) | I6: その他（ UTF-8） | M6: 改行コード | O6: LF(UNIX系) | Q6: CRLF(Win系) | T6: なし | X6: 半カナ
A7: 全角(2byte)文字項目 | D7: あり | F7: なし | M7: 数値編集 | O7: 左詰め | Q7: 右詰め［ゼロ埋め］ | T7: 右詰め［スペース埋め］ | X7: コード
A8: 特記事項 | C8: 取込ファイルには、取込項目のタイトル行が必要となる | X8: 数値
A9: No. | B9: 項目名 | E9: 必須 | F9: 型 | G9: 桁数 | H9: 開始位置 | I9: 項目説明 | O9: 設定値 | X9: 日付
H10: /列 | X10: 時間
A11: 1 | B11: 編集区分 | E11: 〇 | F11: 区分 | G11: 1 | H11: =SUBSTITUTE(SUBSTITUTE(ADDRESS(1,A11),"$1",""),"$","") -> A | I11: 新規追加データの場合は「1:新規」、 | O11: 左記のとおり設定 | X11: 年月
I12: 既存データの修正および削除（使用不可フラグを１に更新）の場合は「２:修正」
I13: 既存支払先に対して、決済条件を追加する際も「２：修正」を使用する | X13: 区分
A14: =MAX(A$11:A11)+1 -> 2 | B14: 新規変更区分名称 | F14: 文字列 | G14: 4 | H14: =SUBSTITUTE(SUBSTITUTE(ADDRESS(1,A14),"$1",""),"$","") -> B | I14: 空白 | O14: 設定なし | X14: フラグ
A15: =MAX(A$11:A14)+1 -> 3 | B15: 取引先区分コード | E15: 〇 | F15: コード | G15: 2 | H15: =SUBSTITUTE(SUBSTITUTE(ADDRESS(1,A15),"$1",""),"$","") -> C | I15: 「00:初期導入」 | O15: 「00:初期導入」（固定値） | X15: -
A16: =MAX(A$11:A15)+1 -> 4 | B16: 取引先区分名 | F16: 文字列 | G16: 20 | H16: =SUBSTITUTE(SUBSTITUTE(ADDRESS(1,A16),"$1",""),"$","") -> D | I16: 空白 | O16: 設定なし
A17: =MAX(A$11:A16)+1 -> 5 | B17: 取引先コード | E17: △ | F17: コード | G17: 15 | H17: =SUBSTITUTE(SUBSTITUTE(ADDRESS(1,A17),"$1",""),"$","") -> E | I17: 支払先を一意に特定するコード | O17: 一般支払先のコード（9桁）
A18: =MAX(A$11:A17)+1 -> 6 | B18: 社内取引部門表示コード | E18: △ | F18: コード | G18: 15 | H18: =SUBSTITUTE(SUBSTITUTE(ADDRESS(1,A18),"$1",""),"$","") -> F | I18: 空白 | O18: 設定なし
A19: =MAX(A$11:A18)+1 -> 7 | B19: 社内取引部門名（略） | F19: 文字列 | G19: 20 | H19: =SUBSTITUTE(SUBSTITUTE(ADDRESS(1,A19),"$1",""),"$","") -> G | I19: 空白 | O19: 設定なし
A20: =MAX(A$11:A19)+1 -> 8 | B20: 適格請求書発行事業者登録番号 | F20: 文字列 | G20: 14 | H20: =SUBSTITUTE(SUBSTITUTE(ADDRESS(1,A20),"$1",""),"$","") -> H | I20: 空白 | O20: 設定なし
A21: =MAX(A$11:A20)+1 -> 9 | B21: 企業コード | E21: △ | F21: コード | G21: 15 | H21: =SUBSTITUTE(SUBSTITUTE(ADDRESS(1,A21),"$1",""),"$","") -> I | I21: 空白 | O21: 設定なし
A22: =MAX(A$11:A21)+1 -> 10 | B22: 企業名（略） | F22: 文字列 | G22: 20 | H22: =SUBSTITUTE(SUBSTITUTE(ADDRESS(1,A22),"$1",""),"$","") -> J | I22: 空白 | O22: 設定なし
A23: =MAX(A$11:A22)+1 -> 11 | B23: 得意先フラグ | F23: フラグ | G23: 1 | H23: =SUBSTITUTE(SUBSTITUTE(ADDRESS(1,A23),"$1",""),"$","") -> K | I23: 「0:得意先として使用しない」 | O23: ０（固定値）
A24: =MAX(A$11:A23)+1 -> 12 | B24: 需要家フラグ | F24: フラグ | G24: 1 | H24: =SUBSTITUTE(SUBSTITUTE(ADDRESS(1,A24),"$1",""),"$","") -> L | I24: 「0:需要家として使用しない」 | O24: ０（固定値）
A25: =MAX(A$11:A24)+1 -> 13 | B25: 出荷先フラグ | F25: フラグ | G25: 1 | H25: =SUBSTITUTE(SUBSTITUTE(ADDRESS(1,A25),"$1",""),"$","") -> M | I25: 「0:出荷先として使用しない」 | O25: ０（固定値）
A26: =MAX(A$11:A25)+1 -> 14 | B26: 仕入先フラグ | F26: フラグ | G26: 1 | H26: =SUBSTITUTE(SUBSTITUTE(ADDRESS(1,A26),"$1",""),"$","") -> N | I26: 「0:仕入先として使用しない」 | O26: ０（固定値）
A27: =MAX(A$11:A26)+1 -> 15 | B27: 入荷元フラグ | F27: フラグ | G27: 1 | H27: =SUBSTITUTE(SUBSTITUTE(ADDRESS(1,A27),"$1",""),"$","") -> O | I27: 「0:入荷元として使用しない」 | O27: ０（固定値）
A28: =MAX(A$11:A27)+1 -> 16 | B28: 請求先フラグ | F28: フラグ | G28: 1 | H28: =SUBSTITUTE(SUBSTITUTE(ADDRESS(1,A28),"$1",""),"$","") -> P | I28: 「0:請求先として使用しない」 | O28: ０（固定値）
A29: =MAX(A$11:A28)+1 -> 17 | B29: 支払先フラグ | F29: フラグ | G29: 1 | H29: =SUBSTITUTE(SUBSTITUTE(ADDRESS(1,A29),"$1",""),"$","") -> Q | I29: 「1:支払先として使用する」 | O29: １（固定値）
A30: =MAX(A$11:A29)+1 -> 18 | B30: 諸口取引先フラグ | F30: フラグ | G30: 1 | H30: =SUBSTITUTE(SUBSTITUTE(ADDRESS(1,A30),"$1",""),"$","") -> R | I30: 「0:取引先」 | O30: 0 | P30: ※諸口支払先の場合は１
A31: =MAX(A$11:A30)+1 -> 19 | B31: 取引先名１ | E31: 〇 | F31: 文字列 | G31: 50 | H31: =SUBSTITUTE(SUBSTITUTE(ADDRESS(1,A31),"$1",""),"$","") -> S | I31: 取引先の名称 | O31: 名称住所マスタ.取引先名（漢字）の先頭50桁(25文字) | T31: ※取引先名：全角50文字(法人30文字、店舗20文字) | X31: ※連動元システムでは常に全角で情報を保持
A32: =MAX(A$11:A31)+1 -> 20 | B32: 取引先名２ | F32: 文字列 | G32: 50 | H32: =SUBSTITUTE(SUBSTITUTE(ADDRESS(1,A32),"$1",""),"$","") -> T | I32: 取引先の名称 | O32: 名称住所マスタ.取引先名（漢字）の51～100桁(25文字)
A33: =MAX(A$11:A32)+1 -> 21 | B33: 取引先名（略） | E33: 〇 | F33: 文字列 | G33: 20 | H33: =SUBSTITUTE(SUBSTITUTE(ADDRESS(1,A33),"$1",""),"$","") -> U | I33: 取引先の略称 | O33: 名称住所マスタ.取引先略称名（漢字）の先頭20桁(10文字) | T33: ※取引先名（略）：全角25文字（法人13文字、店舗12文字） | X33: ※連動元システムでは常に全角で情報を保持
A34: =MAX(A$11:A33)+1 -> 22 | B34: 取引先名（カナ） | E34: 〇 | F34: 半カナ | G34: 40 | H34: =SUBSTITUTE(SUBSTITUTE(ADDRESS(1,A34),"$1",""),"$","") -> V | I34: 取引先のカナ名称 | O34: 名称住所マスタ.取引先略称名（カナ）の先頭40桁 | T34: ※カナ略称：半角50文字（法人26文字、店舗24文字）
A35: =MAX(A$11:A34)+1 -> 23 | B35: 取引先名（英字） | F35: 半英数 | G35: 40 | H35: =SUBSTITUTE(SUBSTITUTE(ADDRESS(1,A35),"$1",""),"$","") -> W | I35: 空白 | O35: 設定なし
A36: =MAX(A$11:A35)+1 -> 24 | B36: 休日パターンコード | F36: コード | G36: 5 | H36: =SUBSTITUTE(SUBSTITUTE(ADDRESS(1,A36),"$1",""),"$","") -> X | I36: 空白 | O36: 設定なし
A37: =MAX(A$11:A36)+1 -> 25 | B37: 休日パターン名 | F37: 文字列 | G37: 40 | H37: =SUBSTITUTE(SUBSTITUTE(ADDRESS(1,A37),"$1",""),"$","") -> Y | I37: 空白 | O37: 設定なし
A38: =MAX(A$11:A37)+1 -> 26 | B38: 国コード | F38: コード | G38: 3 | H38: =SUBSTITUTE(SUBSTITUTE(ADDRESS(1,A38),"$1",""),"$","") -> Z | I38: 空白 | O38: 設定なし
A39: =MAX(A$11:A38)+1 -> 27 | B39: 国名称 | F39: 文字列 | G39: 20 | H39: =SUBSTITUTE(SUBSTITUTE(ADDRESS(1,A39),"$1",""),"$","") -> AA | I39: 空白 | O39: 設定なし
A40: =MAX(A$11:A39)+1 -> 28 | B40: 取引先地域分類値コード | F40: コード | G40: 4 | H40: =SUBSTITUTE(SUBSTITUTE(ADDRESS(1,A40),"$1",""),"$","") -> AB | I40: 空白 | O40: 設定なし
A41: =MAX(A$11:A40)+1 -> 29 | B41: 取引先地域分類値 | F41: 文字列 | G41: 20 | H41: =SUBSTITUTE(SUBSTITUTE(ADDRESS(1,A41),"$1",""),"$","") -> AC | I41: 空白 | O41: 設定なし
...

Sheet 取込フォーマット定義（支払先） bk
A1: ドキュメント名 | E1: サブシステム | G1: 業務機能名 | P1: 作成者 | R1: =表紙!D51 -> SCSK位田 | T1: 更新者
A2: 業務機能概要書 | C2: 取込フォーマット定義 | E2: =業務機能概要!L2 -> 業務共通 | G2: =業務機能概要!Q2 -> 取引先マスタ自動取込 | P2: 作成日 | R2: =表紙!C51 -> 45898 | T2: 更新日
A4: データ名 | C4: 支払先外部データ取込フォーマット | I4: ヘッダ行 | K4: あり | M4: なし | N4: ダブルクォーテーション | Q4: あり | S4: なし | X4: 文字列
A5: ﾌｧｲﾙ形式・ﾚｺｰﾄﾞ長 | D5: 固定長（ | G5: Byte） | I5: 可変長（区切り文字［ ，(カンマ) ］） | M5: バイナリデータ | P5: その他（ ） | X5: 半英数
A6: 文字コード | D6: UNI（Win系） | F6: EBCDIC(K) | I6: その他（ UTF-8） | M6: 改行コード | O6: LF(UNIX系) | Q6: CRLF(Win系) | T6: なし | X6: 半カナ
A7: 全角(2byte)文字項目 | D7: あり | F7: なし | M7: 数値編集 | O7: 左詰め | Q7: 右詰め［ゼロ埋め］ | T7: 右詰め［スペース埋め］ | X7: コード
A8: 特記事項 | C8: 取込ファイルには、取込項目のタイトル行が必要となる | X8: 数値
A9: No. | B9: 項目名 | E9: 必須 | F9: 型 | G9: 桁数 | H9: 開始位置 | I9: 備考 | X9: 日付
H10: /列 | X10: 時間
A11: 1 | B11: 編集区分 | E11: 〇 | F11: 区分 | G11: 1 | H11: =SUBSTITUTE(SUBSTITUTE(ADDRESS(1,A11),"$1",""),"$","") -> A | I11: 新規追加データの場合は「1:新規」、既存データの修正および削除（使用不可フラグを１に更新）の場合は「２:修正」 ※連動元システム側でセットする | X11: 年月
A12: =MAX(A$11:A11)+1 -> 2 | B12: 新規変更区分名称 | F12: 文字列 | G12: 4 | H12: =SUBSTITUTE(SUBSTITUTE(ADDRESS(1,A12),"$1",""),"$","") -> B | I12: 空白 | X12: 区分
A13: =MAX(A$11:A12)+1 -> 3 | B13: 取引先区分コード | E13: 〇 | F13: コード | G13: 2 | H13: =SUBSTITUTE(SUBSTITUTE(ADDRESS(1,A13),"$1",""),"$","") -> C | I13: 「00:初期導入」 | X13: フラグ
A14: =MAX(A$11:A13)+1 -> 4 | B14: 取引先区分名 | F14: 文字列 | G14: 20 | H14: =SUBSTITUTE(SUBSTITUTE(ADDRESS(1,A14),"$1",""),"$","") -> D | I14: 空白 | X14: -
A15: =MAX(A$11:A14)+1 -> 5 | B15: 取引先コード | E15: △ | F15: コード | G15: 15 | H15: =SUBSTITUTE(SUBSTITUTE(ADDRESS(1,A15),"$1",""),"$","") -> E | I15: 名称住所マスタ（AN910）．取引先コード ※名称住所マスタ（AN910）．取引先枝番コードも連結？支払先を一意に特定する番号としたい。 | X15: ★連動元のテーブル情報が決定後に設定値を設計する
A16: =MAX(A$11:A15)+1 -> 6 | B16: 社内取引部門表示コード | E16: △ | F16: コード | G16: 15 | H16: =SUBSTITUTE(SUBSTITUTE(ADDRESS(1,A16),"$1",""),"$","") -> F | I16: 空白
A17: =MAX(A$11:A16)+1 -> 7 | B17: 社内取引部門名（略） | F17: 文字列 | G17: 20 | H17: =SUBSTITUTE(SUBSTITUTE(ADDRESS(1,A17),"$1",""),"$","") -> G | I17: 空白
A18: =MAX(A$11:A17)+1 -> 8 | B18: 適格請求書発行事業者登録番号 | F18: 文字列 | G18: 14 | H18: =SUBSTITUTE(SUBSTITUTE(ADDRESS(1,A18),"$1",""),"$","") -> H | I18: 空白
A19: =MAX(A$11:A18)+1 -> 9 | B19: 企業コード | E19: △ | F19: コード | G19: 15 | H19: =SUBSTITUTE(SUBSTITUTE(ADDRESS(1,A19),"$1",""),"$","") -> I | I19: 空白
A20: =MAX(A$11:A19)+1 -> 10 | B20: 企業名（略） | F20: 文字列 | G20: 20 | H20: =SUBSTITUTE(SUBSTITUTE(ADDRESS(1,A20),"$1",""),"$","") -> J | I20: 空白
A21: =MAX(A$11:A20)+1 -> 11 | B21: 得意先フラグ | F21: フラグ | G21: 1 | H21: =SUBSTITUTE(SUBSTITUTE(ADDRESS(1,A21),"$1",""),"$","") -> K | I21: 「0:得意先として使用しない」
A22: =MAX(A$11:A21)+1 -> 12 | B22: 需要家フラグ | F22: フラグ | G22: 1 | H22: =SUBSTITUTE(SUBSTITUTE(ADDRESS(1,A22),"$1",""),"$","") -> L | I22: 「0:需要家として使用しない」
A23: =MAX(A$11:A22)+1 -> 13 | B23: 出荷先フラグ | F23: フラグ | G23: 1 | H23: =SUBSTITUTE(SUBSTITUTE(ADDRESS(1,A23),"$1",""),"$","") -> M | I23: 「0:出荷先として使用しない」
A24: =MAX(A$11:A23)+1 -> 14 | B24: 仕入先フラグ | F24: フラグ | G24: 1 | H24: =SUBSTITUTE(SUBSTITUTE(ADDRESS(1,A24),"$1",""),"$","") -> N | I24: 「0:仕入先として使用しない」
A25: =MAX(A$11:A24)+1 -> 15 | B25: 入荷元フラグ | F25: フラグ | G25: 1 | H25: =SUBSTITUTE(SUBSTITUTE(ADDRESS(1,A25),"$1",""),"$","") -> O | I25: 「0:入荷元として使用しない」
A26: =MAX(A$11:A25)+1 -> 16 | B26: 請求先フラグ | F26: フラグ | G26: 1 | H26: =SUBSTITUTE(SUBSTITUTE(ADDRESS(1,A26),"$1",""),"$","") -> P | I26: 「0:請求先として使用しない」
A27: =MAX(A$11:A26)+1 -> 17 | B27: 支払先フラグ | F27: フラグ | G27: 1 | H27: =SUBSTITUTE(SUBSTITUTE(ADDRESS(1,A27),"$1",""),"$","") -> Q | I27: 「1:支払先として使用する」
A28: =MAX(A$11:A27)+1 -> 18 | B28: 諸口取引先フラグ | F28: フラグ | G28: 1 | H28: =SUBSTITUTE(SUBSTITUTE(ADDRESS(1,A28),"$1",""),"$","") -> R | I28: 「0:取引先」
A29: =MAX(A$11:A28)+1 -> 19 | B29: 取引先名１ | E29: 〇 | F29: 文字列 | G29: 50 | H29: =SUBSTITUTE(SUBSTITUTE(ADDRESS(1,A29),"$1",""),"$","") -> S | I29: 名称住所マスタ（AN910）．取引先略称名（漢字） | X29: ★連動元のテーブル情報が決定後に設定値を設計する
A30: =MAX(A$11:A29)+1 -> 20 | B30: 取引先名２ | F30: 文字列 | G30: 50 | H30: =SUBSTITUTE(SUBSTITUTE(ADDRESS(1,A30),"$1",""),"$","") -> T | I30: 空白
A31: =MAX(A$11:A30)+1 -> 21 | B31: 取引先名（略） | E31: 〇 | F31: 文字列 | G31: 20 | H31: =SUBSTITUTE(SUBSTITUTE(ADDRESS(1,A31),"$1",""),"$","") -> U | I31: 名称住所マスタ（AN910）．取引先略称名（漢字） ※20byteに省略する必要あり | X31: ★連動元のテーブル情報が決定後に設定値を設計する
A32: =MAX(A$11:A31)+1 -> 22 | B32: 取引先名（カナ） | E32: 〇 | F32: 半カナ | G32: 40 | H32: =SUBSTITUTE(SUBSTITUTE(ADDRESS(1,A32),"$1",""),"$","") -> V | I32: 名称住所マスタ（AN910）．取引先略称名（カナ） | X32: ★連動元のテーブル情報が決定後に設定値を設計する
A33: =MAX(A$11:A32)+1 -> 23 | B33: 取引先名（英字） | F33: 半英数 | G33: 40 | H33: =SUBSTITUTE(SUBSTITUTE(ADDRESS(1,A33),"$1",""),"$","") -> W | I33: 空白
A34: =MAX(A$11:A33)+1 -> 24 | B34: 休日パターンコード | F34: コード | G34: 5 | H34: =SUBSTITUTE(SUBSTITUTE(ADDRESS(1,A34),"$1",""),"$","") -> X | I34: 空白
A35: =MAX(A$11:A34)+1 -> 25 | B35: 休日パターン名 | F35: 文字列 | G35: 40 | H35: =SUBSTITUTE(SUBSTITUTE(ADDRESS(1,A35),"$1",""),"$","") -> Y | I35: 空白
A36: =MAX(A$11:A35)+1 -> 26 | B36: 国コード | F36: コード | G36: 3 | H36: =SUBSTITUTE(SUBSTITUTE(ADDRESS(1,A36),"$1",""),"$","") -> Z | I36: 空白
A37: =MAX(A$11:A36)+1 -> 27 | B37: 国名称 | F37: 文字列 | G37: 20 | H37: =SUBSTITUTE(SUBSTITUTE(ADDRESS(1,A37),"$1",""),"$","") -> AA | I37: 空白
A38: =MAX(A$11:A37)+1 -> 28 | B38: 取引先地域分類値コード | F38: コード | G38: 4 | H38: =SUBSTITUTE(SUBSTITUTE(ADDRESS(1,A38),"$1",""),"$","") -> AB | I38: 空白
A39: =MAX(A$11:A38)+1 -> 29 | B39: 取引先地域分類値 | F39: 文字列 | G39: 20 | H39: =SUBSTITUTE(SUBSTITUTE(ADDRESS(1,A39),"$1",""),"$","") -> AC | I39: 空白
A40: =MAX(A$11:A39)+1 -> 30 | B40: 郵便番号 | F40: 半英数 | G40: 8 | H40: =SUBSTITUTE(SUBSTITUTE(ADDRESS(1,A40),"$1",""),"$","") -> AD | I40: 空白
A41: =MAX(A$11:A40)+1 -> 31 | B41: 住所１ | F41: 文字列 | G41: 100 | H41: =SUBSTITUTE(SUBSTITUTE(ADDRESS(1,A41),"$1",""),"$","") -> AE | I41: 空白
...

Sheet 取込フォーマット定義（職員）※支払先
A1: ドキュメント名 | E1: サブシステム | G1: 業務機能名 | P1: 作成者 | R1: SCSK位田 | T1: 更新者
A2: 業務機能概要書 | C2: 取込フォーマット定義 | E2: 業務共通 | G2: 取引先マスタ自動取込 | P2: 作成日 | R2: =表紙!C51 -> 45898 | T2: 更新日
A4: データ名 | C4: 支払先外部データ取込フォーマット | I4: ヘッダ行 | K4: あり | M4: なし | N4: ダブルクォーテーション | Q4: あり | S4: なし | X4: 文字列
A5: ﾌｧｲﾙ形式・ﾚｺｰﾄﾞ長 | D5: 固定長（ | G5: Byte） | I5: 可変長（区切り文字［ ，(カンマ) ］） | M5: バイナリデータ | P5: その他（ ） | X5: 半英数
A6: 文字コード | D6: UNI（Win系） | F6: EBCDIC(K) | I6: その他（ UTF-8） | M6: 改行コード | O6: LF(UNIX系) | Q6: CRLF(Win系) | T6: なし | X6: 半カナ
A7: 全角(2byte)文字項目 | D7: あり | F7: なし | M7: 数値編集 | O7: 左詰め | Q7: 右詰め［ゼロ埋め］ | T7: 右詰め［スペース埋め］ | X7: コード
A8: 特記事項 | C8: 取込ファイルには、取込項目のタイトル行が必要となる | X8: 数値
A9: No. | B9: 項目名 | E9: 必須 | F9: 型 | G9: 桁数 | H9: 開始位置 | I9: 項目説明 | O9: 設定値 | X9: 日付
H10: /列 | X10: 時間
A11: 1 | B11: 編集区分 | E11: 〇 | F11: 区分 | G11: 1 | H11: =SUBSTITUTE(SUBSTITUTE(ADDRESS(1,A11),"$1",""),"$","") -> A | I11: 新規追加データの場合は「1:新規」、 | O11: 左記のとおり設定 | X11: 年月
I12: 既存データの修正および削除（使用不可フラグを１に更新）の場合は「２:修正」
I13: 既存支払先に対して、決済条件を追加する際も「２：修正」を使用する | X13: 区分
A14: =MAX(A$11:A11)+1 -> 2 | B14: 新規変更区分名称 | F14: 文字列 | G14: 4 | H14: =SUBSTITUTE(SUBSTITUTE(ADDRESS(1,A14),"$1",""),"$","") -> B | I14: 空白 | O14: 設定なし | X14: 区分
A15: =MAX(A$11:A14)+1 -> 3 | B15: 取引先区分コード | E15: 〇 | F15: コード | G15: 2 | H15: =SUBSTITUTE(SUBSTITUTE(ADDRESS(1,A15),"$1",""),"$","") -> C | I15: 「00:初期導入」 | O15: 「00:初期導入」（固定値） | X15: フラグ
A16: =MAX(A$11:A15)+1 -> 4 | B16: 取引先区分名 | F16: 文字列 | G16: 20 | H16: =SUBSTITUTE(SUBSTITUTE(ADDRESS(1,A16),"$1",""),"$","") -> D | I16: 空白 | O16: 設定なし | X16: -
A17: =MAX(A$11:A16)+1 -> 5 | B17: 取引先コード | E17: △ | F17: コード | G17: 15 | H17: =SUBSTITUTE(SUBSTITUTE(ADDRESS(1,A17),"$1",""),"$","") -> E | I17: 支払先を一意に特定するコード | O17: 職員コード
A18: =MAX(A$11:A17)+1 -> 6 | B18: 社内取引部門表示コード | E18: △ | F18: コード | G18: 15 | H18: =SUBSTITUTE(SUBSTITUTE(ADDRESS(1,A18),"$1",""),"$","") -> F | I18: 空白 | O18: 設定なし
A19: =MAX(A$11:A18)+1 -> 7 | B19: 社内取引部門名（略） | F19: 文字列 | G19: 20 | H19: =SUBSTITUTE(SUBSTITUTE(ADDRESS(1,A19),"$1",""),"$","") -> G | I19: 空白 | O19: 設定なし
A20: =MAX(A$11:A19)+1 -> 8 | B20: 適格請求書発行事業者登録番号 | F20: 文字列 | G20: 14 | H20: =SUBSTITUTE(SUBSTITUTE(ADDRESS(1,A20),"$1",""),"$","") -> H | I20: 空白 | O20: 設定なし
A21: =MAX(A$11:A20)+1 -> 9 | B21: 企業コード | E21: △ | F21: コード | G21: 15 | H21: =SUBSTITUTE(SUBSTITUTE(ADDRESS(1,A21),"$1",""),"$","") -> I | I21: 空白 | O21: 設定なし
A22: =MAX(A$11:A21)+1 -> 10 | B22: 企業名（略） | F22: 文字列 | G22: 20 | H22: =SUBSTITUTE(SUBSTITUTE(ADDRESS(1,A22),"$1",""),"$","") -> J | I22: 空白 | O22: 設定なし
A23: =MAX(A$11:A22)+1 -> 11 | B23: 得意先フラグ | F23: フラグ | G23: 1 | H23: =SUBSTITUTE(SUBSTITUTE(ADDRESS(1,A23),"$1",""),"$","") -> K | I23: 「0:得意先として使用しない」 | O23: ０（固定値）
A24: =MAX(A$11:A23)+1 -> 12 | B24: 需要家フラグ | F24: フラグ | G24: 1 | H24: =SUBSTITUTE(SUBSTITUTE(ADDRESS(1,A24),"$1",""),"$","") -> L | I24: 「0:需要家として使用しない」 | O24: ０（固定値）
A25: =MAX(A$11:A24)+1 -> 13 | B25: 出荷先フラグ | F25: フラグ | G25: 1 | H25: =SUBSTITUTE(SUBSTITUTE(ADDRESS(1,A25),"$1",""),"$","") -> M | I25: 「0:出荷先として使用しない」 | O25: ０（固定値）
A26: =MAX(A$11:A25)+1 -> 14 | B26: 仕入先フラグ | F26: フラグ | G26: 1 | H26: =SUBSTITUTE(SUBSTITUTE(ADDRESS(1,A26),"$1",""),"$","") -> N | I26: 「0:仕入先として使用しない」 | O26: ０（固定値）
A27: =MAX(A$11:A26)+1 -> 15 | B27: 入荷元フラグ | F27: フラグ | G27: 1 | H27: =SUBSTITUTE(SUBSTITUTE(ADDRESS(1,A27),"$1",""),"$","") -> O | I27: 「0:入荷元として使用しない」 | O27: ０（固定値）
A28: =MAX(A$11:A27)+1 -> 16 | B28: 請求先フラグ | F28: フラグ | G28: 1 | H28: =SUBSTITUTE(SUBSTITUTE(ADDRESS(1,A28),"$1",""),"$","") -> P | I28: 「0:請求先として使用しない」 | O28: ０（固定値）
A29: =MAX(A$11:A28)+1 -> 17 | B29: 支払先フラグ | F29: フラグ | G29: 1 | H29: =SUBSTITUTE(SUBSTITUTE(ADDRESS(1,A29),"$1",""),"$","") -> Q | I29: 「1:支払先として使用する」 | O29: １（固定値）
A30: =MAX(A$11:A29)+1 -> 18 | B30: 諸口取引先フラグ | F30: フラグ | G30: 1 | H30: =SUBSTITUTE(SUBSTITUTE(ADDRESS(1,A30),"$1",""),"$","") -> R | I30: 「0:取引先」 | O30: 0
A31: =MAX(A$11:A30)+1 -> 19 | B31: 取引先名１ | E31: 〇 | F31: 文字列 | G31: 50 | H31: =SUBSTITUTE(SUBSTITUTE(ADDRESS(1,A31),"$1",""),"$","") -> S | I31: 取引先の名称 | O31: 名称住所マスタ.取引先名（漢字）の先頭50桁(25文字) | T31: ※取引先名：全角50文字(法人30文字、店舗20文字) | X31: ※連動元システムでは常に全角で情報を保持
A32: =MAX(A$11:A31)+1 -> 20 | B32: 取引先名２ | F32: 文字列 | G32: 50 | H32: =SUBSTITUTE(SUBSTITUTE(ADDRESS(1,A32),"$1",""),"$","") -> T | I32: 空白 | O32: 名称住所マスタ.取引先名（漢字）の51～100桁(25文字)
A33: =MAX(A$11:A32)+1 -> 21 | B33: 取引先名（略） | E33: 〇 | F33: 文字列 | G33: 20 | H33: =SUBSTITUTE(SUBSTITUTE(ADDRESS(1,A33),"$1",""),"$","") -> U | I33: 取引先の略称 | O33: 名称住所マスタ.取引先略称名（漢字）の先頭20桁(10文字) | T33: ※取引先名（略）：全角25文字（法人13文字、店舗12文字） | X33: ※連動元システムでは常に全角で情報を保持
A34: =MAX(A$11:A33)+1 -> 22 | B34: 取引先名（カナ） | E34: 〇 | F34: 半カナ | G34: 40 | H34: =SUBSTITUTE(SUBSTITUTE(ADDRESS(1,A34),"$1",""),"$","") -> V | I34: 取引先のカナ名称 | O34: 名称住所マスタ.取引先略称名（カナ）の先頭40桁 | T34: ※カナ略称：半角50文字（法人26文字、店舗24文字）
A35: =MAX(A$11:A34)+1 -> 23 | B35: 取引先名（英字） | F35: 半英数 | G35: 40 | H35: =SUBSTITUTE(SUBSTITUTE(ADDRESS(1,A35),"$1",""),"$","") -> W | I35: 空白 | O35: 設定なし
A36: =MAX(A$11:A35)+1 -> 24 | B36: 休日パターンコード | F36: コード | G36: 5 | H36: =SUBSTITUTE(SUBSTITUTE(ADDRESS(1,A36),"$1",""),"$","") -> X | I36: 空白 | O36: 設定なし
A37: =MAX(A$11:A36)+1 -> 25 | B37: 休日パターン名 | F37: 文字列 | G37: 40 | H37: =SUBSTITUTE(SUBSTITUTE(ADDRESS(1,A37),"$1",""),"$","") -> Y | I37: 空白 | O37: 設定なし
A38: =MAX(A$11:A37)+1 -> 26 | B38: 国コード | F38: コード | G38: 3 | H38: =SUBSTITUTE(SUBSTITUTE(ADDRESS(1,A38),"$1",""),"$","") -> Z | I38: 空白 | O38: 設定なし
A39: =MAX(A$11:A38)+1 -> 27 | B39: 国名称 | F39: 文字列 | G39: 20 | H39: =SUBSTITUTE(SUBSTITUTE(ADDRESS(1,A39),"$1",""),"$","") -> AA | I39: 空白 | O39: 設定なし
A40: =MAX(A$11:A39)+1 -> 28 | B40: 取引先地域分類値コード | F40: コード | G40: 4 | H40: =SUBSTITUTE(SUBSTITUTE(ADDRESS(1,A40),"$1",""),"$","") -> AB | I40: 空白 | O40: 設定なし
A41: =MAX(A$11:A40)+1 -> 29 | B41: 取引先地域分類値 | F41: 文字列 | G41: 20 | H41: =SUBSTITUTE(SUBSTITUTE(ADDRESS(1,A41),"$1",""),"$","") -> AC | I41: 空白 | O41: 設定なし
...

Sheet 取込フォーマット定義（取引先）
A1: ドキュメント名 | E1: サブシステム | G1: 業務機能名 | P1: 作成者 | R1: =表紙!D51 -> SCSK位田 | T1: 更新者
A2: 業務機能概要書 | C2: 取込フォーマット定義 | E2: =業務機能概要!L2 -> 業務共通 | G2: =業務機能概要!Q2 -> 取引先マスタ自動取込 | P2: 作成日 | R2: =表紙!C51 -> 45898 | T2: 更新日
A4: データ名 | C4: 取引先外部データ取込フォーマット | I4: ヘッダ行 | K4: あり | M4: なし | N4: ダブルクォーテーション | Q4: あり | S4: なし | X4: 文字列
A5: ﾌｧｲﾙ形式・ﾚｺｰﾄﾞ長 | D5: 固定長（ | G5: Byte） | I5: 可変長（区切り文字［ ，(カンマ) ］） | M5: バイナリデータ | P5: その他（ ） | X5: 半英数
A6: 文字コード | D6: UNI（Win系） | F6: EBCDIC(K) | I6: その他（ UTF-8） | M6: 改行コード | O6: LF(UNIX系) | Q6: CRLF(Win系) | T6: なし | X6: 半カナ
A7: 全角(2byte)文字項目 | D7: あり | F7: なし | M7: 数値編集 | O7: 左詰め | Q7: 右詰め［ゼロ埋め］ | T7: 右詰め［スペース埋め］ | X7: コード
A8: 特記事項 | C8: 取込ファイルには、取込項目のタイトル行が必要となる | X8: 数値
A9: No. | B9: 項目名 | E9: 必須 | F9: 型 | G9: 桁数 | H9: 開始位置 | I9: 備考 | X9: 日付
H10: /列 | X10: 時間
A11: 1 | B11: 編集区分 | E11: 〇 | F11: 区分 | G11: 1 | H11: =SUBSTITUTE(SUBSTITUTE(ADDRESS(1,A11),"$1",""),"$","") -> A | I11: 新規追加データの場合は「1:新規」、 | O11: 左記のとおり設定 | X11: 年月
I12: 既存データの修正および削除（使用不可フラグを１に更新）の場合は「２:修正」 | X12: 区分
X13: フラグ
A14: =MAX(A$11:A11)+1 -> 2 | B14: 新規変更区分名称 | F14: 文字列 | G14: 4 | H14: =SUBSTITUTE(SUBSTITUTE(ADDRESS(1,A14),"$1",""),"$","") -> B | I14: 空白 | O14: 設定なし | X14: -
A15: =MAX(A$11:A14)+1 -> 3 | B15: 取引先区分コード | E15: 〇 | F15: コード | G15: 2 | H15: =SUBSTITUTE(SUBSTITUTE(ADDRESS(1,A15),"$1",""),"$","") -> C | I15: 「00:初期導入」 | O15: 「00:初期導入」（固定値）
A16: =MAX(A$11:A15)+1 -> 4 | B16: 取引先区分名 | F16: 文字列 | G16: 20 | H16: =SUBSTITUTE(SUBSTITUTE(ADDRESS(1,A16),"$1",""),"$","") -> D | I16: 空白 | O16: 設定なし
A17: =MAX(A$11:A16)+1 -> 5 | B17: 取引先コード | E17: △ | F17: コード | G17: 15 | H17: =SUBSTITUTE(SUBSTITUTE(ADDRESS(1,A17),"$1",""),"$","") -> E | I17: 取引先を一意に特定するコード | O17: 取引先コード（9桁）
A18: =MAX(A$11:A17)+1 -> 6 | B18: 社内取引部門表示コード | E18: △ | F18: コード | G18: 15 | H18: =SUBSTITUTE(SUBSTITUTE(ADDRESS(1,A18),"$1",""),"$","") -> F | I18: 空白 | O18: 設定なし
A19: =MAX(A$11:A18)+1 -> 7 | B19: 社内取引部門名（略） | F19: 文字列 | G19: 20 | H19: =SUBSTITUTE(SUBSTITUTE(ADDRESS(1,A19),"$1",""),"$","") -> G | I19: 空白 | O19: 設定なし
A20: =MAX(A$11:A19)+1 -> 8 | B20: 適格請求書発行事業者登録番号 | F20: 文字列 | G20: 14 | H20: =SUBSTITUTE(SUBSTITUTE(ADDRESS(1,A20),"$1",""),"$","") -> H | I20: 空白 | O20: 設定なし
A21: =MAX(A$11:A20)+1 -> 9 | B21: 企業コード | E21: △ | F21: コード | G21: 15 | H21: =SUBSTITUTE(SUBSTITUTE(ADDRESS(1,A21),"$1",""),"$","") -> I | I21: 空白 | O21: 設定なし
A22: =MAX(A$11:A21)+1 -> 10 | B22: 企業名（略） | F22: 文字列 | G22: 20 | H22: =SUBSTITUTE(SUBSTITUTE(ADDRESS(1,A22),"$1",""),"$","") -> J | I22: 空白 | O22: 設定なし
A23: =MAX(A$11:A22)+1 -> 11 | B23: 得意先フラグ | F23: フラグ | G23: 1 | H23: =SUBSTITUTE(SUBSTITUTE(ADDRESS(1,A23),"$1",""),"$","") -> K | I23: 「0:得意先として使用しない」 | O23: ０（固定値）
A24: =MAX(A$11:A23)+1 -> 12 | B24: 需要家フラグ | F24: フラグ | G24: 1 | H24: =SUBSTITUTE(SUBSTITUTE(ADDRESS(1,A24),"$1",""),"$","") -> L | I24: 「0:需要家として使用しない」 | O24: ０（固定値）
A25: =MAX(A$11:A24)+1 -> 13 | B25: 出荷先フラグ | F25: フラグ | G25: 1 | H25: =SUBSTITUTE(SUBSTITUTE(ADDRESS(1,A25),"$1",""),"$","") -> M | I25: 「0:出荷先として使用しない」 | O25: ０（固定値）
A26: =MAX(A$11:A25)+1 -> 14 | B26: 仕入先フラグ | F26: フラグ | G26: 1 | H26: =SUBSTITUTE(SUBSTITUTE(ADDRESS(1,A26),"$1",""),"$","") -> N | I26: 「0:仕入先として使用しない」 | O26: ０（固定値）
A27: =MAX(A$11:A26)+1 -> 15 | B27: 入荷元フラグ | F27: フラグ | G27: 1 | H27: =SUBSTITUTE(SUBSTITUTE(ADDRESS(1,A27),"$1",""),"$","") -> O | I27: 「0:入荷元として使用しない」 | O27: ０（固定値）
A28: =MAX(A$11:A27)+1 -> 16 | B28: 請求先フラグ | F28: フラグ | G28: 1 | H28: =SUBSTITUTE(SUBSTITUTE(ADDRESS(1,A28),"$1",""),"$","") -> P | I28: 「0:請求先として使用しない」 | O28: ０（固定値）
A29: =MAX(A$11:A28)+1 -> 17 | B29: 支払先フラグ | F29: フラグ | G29: 1 | H29: =SUBSTITUTE(SUBSTITUTE(ADDRESS(1,A29),"$1",""),"$","") -> Q | I29: 「0:支払先として使用しない」 | O29: ０（固定値）
A30: =MAX(A$11:A29)+1 -> 18 | B30: 諸口取引先フラグ | F30: フラグ | G30: 1 | H30: =SUBSTITUTE(SUBSTITUTE(ADDRESS(1,A30),"$1",""),"$","") -> R | I30: 「0:取引先」 | O30: 0
A31: =MAX(A$11:A30)+1 -> 19 | B31: 取引先名１ | E31: 〇 | F31: 文字列 | G31: 50 | H31: =SUBSTITUTE(SUBSTITUTE(ADDRESS(1,A31),"$1",""),"$","") -> S | I31: 取引先の名称 | O31: 名称住所マスタ.取引先名（漢字）の先頭50桁(25文字) | T31: ※取引先名：全角50文字(法人30文字、店舗20文字) | X31: ※連動元システムでは常に全角で情報を保持
A32: =MAX(A$11:A31)+1 -> 20 | B32: 取引先名２ | F32: 文字列 | G32: 50 | H32: =SUBSTITUTE(SUBSTITUTE(ADDRESS(1,A32),"$1",""),"$","") -> T | I32: 空白 | O32: 名称住所マスタ.取引先名（漢字）の51～100桁(25文字)
A33: =MAX(A$11:A32)+1 -> 21 | B33: 取引先名（略） | E33: 〇 | F33: 文字列 | G33: 20 | H33: =SUBSTITUTE(SUBSTITUTE(ADDRESS(1,A33),"$1",""),"$","") -> U | I33: 取引先の略称 | O33: 名称住所マスタ.取引先略称名（漢字）の先頭20桁(10文字) | T33: ※取引先名（略）：全角25文字（法人13文字、店舗12文字） | X33: ※連動元システムでは常に全角で情報を保持
A34: =MAX(A$11:A33)+1 -> 22 | B34: 取引先名（カナ） | E34: 〇 | F34: 半カナ | G34: 40 | H34: =SUBSTITUTE(SUBSTITUTE(ADDRESS(1,A34),"$1",""),"$","") -> V | I34: 取引先のカナ名称 | O34: 名称住所マスタ.取引先略称名（カナ）の先頭40桁 | T34: ※カナ略称：半角50文字（法人26文字、店舗24文字）
A35: =MAX(A$11:A34)+1 -> 23 | B35: 取引先名（英字） | F35: 半英数 | G35: 40 | H35: =SUBSTITUTE(SUBSTITUTE(ADDRESS(1,A35),"$1",""),"$","") -> W | I35: 空白 | O35: 設定なし
A36: =MAX(A$11:A35)+1 -> 24 | B36: 休日パターンコード | F36: コード | G36: 5 | H36: =SUBSTITUTE(SUBSTITUTE(ADDRESS(1,A36),"$1",""),"$","") -> X | I36: 空白 | O36: 設定なし
A37: =MAX(A$11:A36)+1 -> 25 | B37: 休日パターン名 | F37: 文字列 | G37: 40 | H37: =SUBSTITUTE(SUBSTITUTE(ADDRESS(1,A37),"$1",""),"$","") -> Y | I37: 空白 | O37: 設定なし
A38: =MAX(A$11:A37)+1 -> 26 | B38: 国コード | F38: コード | G38: 3 | H38: =SUBSTITUTE(SUBSTITUTE(ADDRESS(1,A38),"$1",""),"$","") -> Z | I38: 空白 | O38: 設定なし
A39: =MAX(A$11:A38)+1 -> 27 | B39: 国名称 | F39: 文字列 | G39: 20 | H39: =SUBSTITUTE(SUBSTITUTE(ADDRESS(1,A39),"$1",""),"$","") -> AA | I39: 空白 | O39: 設定なし
A40: =MAX(A$11:A39)+1 -> 28 | B40: 取引先地域分類値コード | F40: コード | G40: 4 | H40: =SUBSTITUTE(SUBSTITUTE(ADDRESS(1,A40),"$1",""),"$","") -> AB | I40: 空白 | O40: 設定なし
A41: =MAX(A$11:A40)+1 -> 29 | B41: 取引先地域分類値 | F41: 文字列 | G41: 20 | H41: =SUBSTITUTE(SUBSTITUTE(ADDRESS(1,A41),"$1",""),"$","") -> AC | I41: 空白 | O41: 設定なし
...

Sheet 取込データサンプル（支払先）
A1: 編集区分 | B1: 新規変更区分名称 | C1: 取引先区分コード | D1: 取引先区分名 | E1: 取引先コード | F1: 社内取引部門表示コード | G1: 社内取引部門名（略） | H1: 適格請求書発行事業者登録番号 | I1: 企業コード | J1: 企業名（略） | K1: 得意先フラグ | L1: 需要家フラグ | M1: 出荷先フラグ | N1: 仕入先フラグ | O1: 入荷元フラグ | P1: 請求先フラグ | Q1: 支払先フラグ | R1: 諸口取引先フラグ | S1: 取引先名１ | T1: 取引先名２ | U1: 取引先名（略） | V1: 取引先名（カナ） | W1: 取引先名（英字） | X1: 休日パターンコード | Y1: 休日パターン名 | Z1: 国コード | AA1: 国名称 | AB1: 取引先地域分類値コード | AC1: 取引先地域分類値 | AD1: 郵便番号 | AE1: 住所１ | AF1: 住所２ | AG1: 住所３ | AH1: ＴＥＬ | AI1: ＦＡＸ | AJ1: 取引開始日付 | AK1: 取引終了日付 | AL1: 備考 | AM1: 分類値コード１ | AN1: 分類値１ | AO1: 分類値コード２ | AP1: 分類値２ | AQ1: 分類値コード３ | AR1: 分類値３ | AS1: 分類値コード４ | AT1: 分類値４ | AU1: 分類値コード５ | AV1: 分類値５ | AW1: 分類値コード６ | AX1: 分類値６ | AY1: 分類値コード７ | AZ1: 分類値７ | BA1: 分類値コード８ | BB1: 分類値８ | BC1: 分類値コード９ | BD1: 分類値９ | BE1: 分類値コード１０ | BF1: 分類値１０ | BG1: 使用不可フラグ | BH1: 取引先所在地区分 | BI1: 取引先所在地区分名 | BJ1: 国内取引フラグ | BK1: 外為取引フラグ | BL1: 通貨コード | BM1: 消費税端数計算区分 | BN1: 消費税計算単位区分 | BO1: 取引金額端数処理区分 | BP1: 承認申請状況区分名 | BQ1: 承認申請番号 | BR1: 承認申請日付 | BS1: 承認申請者名 | BT1: 承認申請部門名（略） | BU1: 登録者名 | BV1: 登録日時 | BW1: 更新者名 | BX1: 更新日時 | BY1: 得意先担当者コード | BZ1: 得意先担当者名 | CA1: 得意先担当部門表示コード | CB1: 得意先担当部門名（略） | CC1: 得意先先方担当者名 | CD1: 得意先先方担当者ＭＡＩＬ | CE1: 得意先先方担当者ＴＥＬ | CF1: 得意先分類値コード１ | CG1: 得意先分類値１ | CH1: 得意先分類値コード２ | CI1: 得意先分類値２ | CJ1: 得意先分類値コード３ | CK1: 得意先分類値３ | CL1: 得意先分類値コード４ | CM1: 得意先分類値４ | CN1: 得意先分類値コード５ | CO1: 得意先分類値５ | CP1: 得意先備考 | CQ1: 得意先ランク分類値コード | CR1: 得意先ランク分類値 | CS1: 得意先インコタームズ１ | CT1: 得意先インコタームズ２ | CU1: 売上消費税区分 | CV1: 売上消費税計算区分 | CW1: 得意先貿易輸送手段区分 | CX1: 得意先貿易輸送手段区分名 | CY1: 検収リードタイム | CZ1: 請求案内伝票値引表示フラグ | DA1: 納品書金額表示フラグ | DB1: 輸送手段コード１ | DC1: 輸送手段名１ | DD1: 輸送手段コード２ | DE1: 輸送手段名２ | DF1: 倉庫コード１ | DG1: 倉庫名（略）１ | DH1: 倉庫１配送リードタイム（輸送１） | DI1: 倉庫１配送リードタイム（輸送２） | DJ1: 倉庫コード２ | DK1: 倉庫名（略）２ | DL1: 倉庫２配送リードタイム（輸送１） | DM1: 倉庫２配送リードタイム（輸送２） | DN1: 倉庫コード３ | DO1: 倉庫名（略）３ | DP1: 倉庫３配送リードタイム（輸送１） | DQ1: 倉庫３配送リードタイム（輸送２） | DR1: 倉庫コード４ | DS1: 倉庫名（略）４ | DT1: 倉庫４配送リードタイム（輸送１） | DU1: 倉庫４配送リードタイム（輸送２） | DV1: 倉庫コード５ | DW1: 倉庫名（略）５ | DX1: 倉庫５配送リードタイム（輸送１） | DY1: 倉庫５配送リードタイム（輸送２） | DZ1: 仕入先担当者コード | EA1: 仕入先担当者名 | EB1: 仕入先担当部門表示コード | EC1: 仕入先担当部門名（略） | ED1: 仕入先先方担当者名 | EE1: 仕入先先方担当者ＭＡＩＬ | EF1: 仕入先先方担当者ＴＥＬ | EG1: 仕入先分類値コード１ | EH1: 仕入先分類値１ | EI1: 仕入先分類値コード２ | EJ1: 仕入先分類値２ | EK1: 仕入先分類値コード３ | EL1: 仕入先分類値３ | EM1: 仕入先分類値コード４ | EN1: 仕入先分類値４ | EO1: 仕入先分類値コード５ | EP1: 仕入先分類値５ | EQ1: 仕入先備考 | ER1: 仕入先ランク分類値コード | ES1: 仕入先ランク分類値 | ET1: 仕入先インコタームズ１ | EU1: 仕入先インコタームズ２ | EV1: 仕入消費税区分 | EW1: 仕入消費税計算区分 | EX1: 仕入先貿易輸送手段区分 | EY1: 仕入先貿易輸送手段区分名 | EZ1: 下請事業者フラグ | FA1: 支払通知書出力内容 | FB1: 預り源泉対象初期値フラグ | FC1: 預り源泉税端数計算区分 | FD1: 支払消費税差額計算フラグ | FE1: 取込支払消費税差額計算フラグ | FF1: 共通支払先フラグ | FG1: 支払書内容確認コメント | FH1: 支払決済条件行番号 | FI1: 支払決済条件コード | FJ1: 支払決済条件名 | FK1: 支払決済条件名（略） | FL1: 取引形態区分 | FM1: 支払締区分 | FN1: 支払締名寄フラグ | FO1: 名寄部門表示コード | FP1: 名寄部門名（略） | FQ1: 名寄部門基準日付 | FR1: 支払通知書書式区分 | FS1: 支払通知書品目内訳表示フラグ | FT1: 支払基準金額 | FU1: 支払決済条件使用不可フラグ | FV1: 分割条件（未満） | FW1: 分割率（未満） | FX1: 端数桁数（未満） | FY1: 端数区分（未満） | FZ1: 分割基準金額（未満） | GA1: 支払方法コード（未満１） | GB1: 支払方法名（未満１） | GC1: 休日考慮区分（未満１） | GD1: 出金口座コード（未満１） | GE1: 出金口座名（未満１） | GF1: 支払方法コード（未満２） | GG1: 支払方法名（未満２） | GH1: 休日考慮区分（未満２） | GI1: 出金口座コード（未満２） | GJ1: 出金口座名（未満２） | GK1: 分割条件（以上） | GL1: 分割率（以上） | GM1: 端数桁数（以上） | GN1: 端数区分（以上） | GO1: 分割基準金額（以上） | GP1: 支払方法コード（以上１） | GQ1: 支払方法名（以上１） | GR1: 休日考慮区分（以上１） | GS1: 出金口座コード（以上１） | GT1: 出金口座名（以上１） | GU1: 支払方法コード（以上２） | GV1: 支払方法名（以上２） | GW1: 休日考慮区分（以上２） | GX1: 出金口座コード（以上２） | GY1: 出金口座名（以上２） | GZ1: 振込先金融機関コード | HA1: 振込先金融機関名 | HB1: 振込先金融機関店舗コード | HC1: 振込先金融機関店舗名 | HD1: 振込先銀行口座種別区分 | HE1: 振込先銀行口座番号 | HF1: 振込先銀行口座名義人名 | HG1: 振込先銀行口座名義人名（カナ） | HH1: 先方負担振込手数料フラグ | HI1: 振込先郵便口座番号 | HJ1: 振込先郵便口座名義人名 | HK1: 振込先郵便口座名義人名（カナ） | HL1: 手形支払サイト | HM1: 支払手形期日指定月数 | HN1: 支払手形期日指定日 | HO1: 支払手形休日区分 | HP1: 手形種類コード | HQ1: 手形種類名 | HR1: 期日振込サイト | HS1: 期日指定月数 | HT1: 期日指定日 | HU1: 休日区分 | HV1: 外国送金種類区分 | HW1: 外国送金受取方法区分 | HX1: 外国送金先方負担手数料フラグ | HY1: 外国送金目的（英字） | HZ1: 外国送金メッセージ（英字） | IA1: 外国送金受取人名（英字） | IB1: 外国送金受取人住所（英字） | IC1: 外国送金受取人口座番号 | ID1: 外国送金支払先銀行名（英字） | IE1: 外国送金支払先銀行支店名（英字） | IF1: 外国送金支払先銀行住所（英字） | IG1: コルレス先経由銀行名（英字） | IH1: コルレス先経由銀行支店名（英字） | II1: コルレス先経由銀行住所（英字） | IJ1: 非コルレス先経由銀行名（英字） | IK1: 非コルレス先経由銀行支店名（英字） | IL1: 非コルレス先経由銀行住所（英字） | IM1: 支払締日 | IN1: 期日サイクル区分（未満１） | IO1: 期日指定月数（未満１） | IP1: 期日指定支払日（未満１） | IQ1: 期日指定日数（未満１） | IR1: 期日サイクル区分（未満２） | IS1: 期日指定月数（未満２） | IT1: 期日指定支払日（未満２） | IU1: 期日指定日数（未満２） | IV1: 期日サイクル区分（以上１） | IW1: 期日指定月数（以上１） | IX1: 期日指定支払日（以上１） | IY1: 期日指定日数（以上１） | IZ1: 期日サイクル区分（以上２） | JA1: 期日指定月数（以上２） | JB1: 期日指定支払日（以上２） | JC1: 期日指定日数（以上２）
A2: 1 | C2: 0 | D2: 初期導入 | E2: 100120001 | H2: 10000000000001 | K2: 0 | L2: 0 | M2: 0 | N2: 0 | O2: 0 | P2: 0 | Q2: 0 | R2: 0 | S2: 新函館農協 本店 | U2: 新函館農協 本店 | V2: ｼﾝﾊｺﾀﾞﾃﾉｳｷｮｳ | BG2: 0 | BH2: 0 | BI2: 国内 | BJ2: 1 | BK2: 0 | BM2: 3 | BN2: 1 | BO2: 3 | BP2: － | BU2: 住商 二郎 | BV2: 2.0230712e+16 | BW2: 住商 一郎 | BX2: 2.0240415e+16 | CZ2: 0 | DA2: 0 | EZ2: 0 | FB2: 0 | FC2: 1 | FD2: 1 | FE2: 0 | FF2: 0
A3: 1 | C3: 0 | D3: 初期導入 | E3: 100120002 | H3: 10000000000002 | K3: 0 | L3: 0 | M3: 0 | N3: 0 | O3: 0 | P3: 1 | Q3: 1 | R3: 0 | S3: 新函館農協 米穀畑作課 | U3: 新函館農協 米穀畑 | V3: ｼﾝﾊｺﾀﾞﾃﾉｳｷｮｳ | AM3: 2 | AN3: グループ間取引 | BG3: 0 | BH3: 0 | BI3: 国内 | BJ3: 1 | BK3: 0 | BM3: 3 | BN3: 1 | BO3: 3 | BP3: － | BU3: 住商 二郎 | BV3: 2.0230712e+16 | BW3: 住商 一郎 | BX3: 2.0240802e+16 | CZ3: 0 | DA3: 0 | EZ3: 0 | FB3: 0 | FC3: 1 | FD3: 1 | FE3: 1 | FF3: 0 | FG3: 送付後、1カ月以内にご連絡がない場合は、内容を確認済みとさせていただきます。 | FH3: 1 | FI3: 1 | FJ3: 翌月末支払 | FK3: 翌月末支払 | FL3: 1 | FM3: 2 | FN3: 0 | FR3: 2 | FS3: 0 | FT3: 0 | FU3: 0 | FV3: 1 | GA3: S02 | GB3: 振込-ＦＢ | GC3: 1 | GZ3: 19 | HA3: 北海道銀行 | HB3: 101 | HC3: 本店 | HD3: 1 | HE3: 3334444 | HF3: 新函館農協 米穀畑 | HG3: ｼﾝﾊｺﾀﾞﾃﾉｳｷﾖｳ | HH3: 0 | IM3: 0 | IN3: 1 | IO3: 1 | IP3: 99
A4: 1 | C4: 0 | D4: 初期導入 | E4: 100120002 | H4: 10000000000002 | K4: 0 | L4: 0 | M4: 0 | N4: 0 | O4: 0 | P4: 1 | Q4: 1 | R4: 0 | S4: 新函館農協 米穀畑作課 | U4: 新函館農協 米穀畑 | V4: ｼﾝﾊｺﾀﾞﾃﾉｳｷｮｳ | AM4: 2 | AN4: グループ間取引 | BG4: 0 | BH4: 0 | BI4: 国内 | BJ4: 1 | BK4: 0 | BM4: 3 | BN4: 1 | BO4: 3 | BP4: － | BU4: 住商 二郎 | BV4: 2.0230712e+16 | BW4: 住商 一郎 | BX4: 2.0240802e+16 | CZ4: 0 | DA4: 0 | EZ4: 0 | FB4: 0 | FC4: 1 | FD4: 1 | FE4: 1 | FF4: 0 | FG4: 送付後、1カ月以内にご連絡がない場合は、内容を確認済みとさせていただきます。 | FH4: 2 | FI4: 2 | FJ4: 翌月末-引落 | FK4: 翌月末-引落 | FL4: 1 | FM4: 2 | FN4: 0 | FR4: 2 | FS4: 0 | FT4: 0 | FU4: 0 | FV4: 1 | GA4: S06 | GB4: 引落 | GC4: 1 | GD4: 00190001 | GE4: 北海道銀行 本店 | IM4: 0 | IN4: 1 | IO4: 1 | IP4: 99
A5: 1 | C5: 0 | D5: 初期導入 | E5: 100120002 | H5: 10000000000002 | K5: 0 | L5: 0 | M5: 0 | N5: 0 | O5: 0 | P5: 1 | Q5: 1 | R5: 0 | S5: 新函館農協 米穀畑作課 | U5: 新函館農協 米穀畑 | V5: ｼﾝﾊｺﾀﾞﾃﾉｳｷｮｳ | AM5: 2 | AN5: グループ間取引 | BG5: 0 | BH5: 0 | BI5: 国内 | BJ5: 1 | BK5: 0 | BM5: 3 | BN5: 1 | BO5: 3 | BP5: － | BU5: 住商 二郎 | BV5: 2.0230712e+16 | BW5: 住商 一郎 | BX5: 2.0240802e+16 | CZ5: 0 | DA5: 0 | EZ5: 0 | FB5: 0 | FC5: 1 | FD5: 1 | FE5: 1 | FF5: 0 | FG5: 送付後、1カ月以内にご連絡がない場合は、内容を確認済みとさせていただきます。 | FH5: 3 | FI5: 3 | FJ5: 一括決済用 | FK5: 一括決済用_手形 | FL5: 1 | FM5: 2 | FN5: 0 | FR5: 2 | FS5: 0 | FT5: 0 | FU5: 0 | FV5: 1 | GA5: S07 | GB5: 支払手形 | GC5: 1 | HL5: 20 | HM5: 1 | HN5: 20 | HO5: 1 | HP5: ST005 | HQ5: 支払手形_一括決済 | IM5: 0 | IN5: 1 | IO5: 1 | IP5: 99
A6: 1 | C6: 0 | D6: 初期導入 | E6: 100120002 | H6: 10000000000002 | K6: 0 | L6: 0 | M6: 0 | N6: 0 | O6: 0 | P6: 1 | Q6: 1 | R6: 0 | S6: 新函館農協 米穀畑作課 | U6: 新函館農協 米穀畑 | V6: ｼﾝﾊｺﾀﾞﾃﾉｳｷｮｳ | AM6: 2 | AN6: グループ間取引 | BG6: 0 | BH6: 0 | BI6: 国内 | BJ6: 1 | BK6: 0 | BM6: 3 | BN6: 1 | BO6: 3 | BP6: － | BU6: 住商 二郎 | BV6: 2.0230712e+16 | BW6: 住商 一郎 | BX6: 2.0240802e+16 | CZ6: 0 | DA6: 0 | EZ6: 0 | FB6: 0 | FC6: 1 | FD6: 1 | FE6: 1 | FF6: 0 | FG6: 送付後、1カ月以内にご連絡がない場合は、内容を確認済みとさせていただきます。 | FH6: 4 | FI6: 4 | FJ6: 翌月末支払い定時 | FK6: 翌月末定時 | FL6: 1 | FM6: 1 | FN6: 1 | FR6: 2 | FS6: 0 | FT6: 0 | FU6: 0 | FV6: 1 | GA6: S02 | GB6: 振込-ＦＢ | GC6: 1 | GZ6: 18 | HA6: 北洋銀行 | HB6: 28 | HC6: 本店 | HD6: 1 | HE6: 2222555 | HF6: 新函館農協定時 | HG6: ｼﾝﾊｺﾀﾞﾃﾉｳｷﾖｳﾃｲｼﾞ | HH6: 0 | IM6: 99 | IN6: 1 | IO6: 1 | IP6: 99
A7: 1 | C7: 0 | D7: 初期導入 | E7: 100120002 | H7: 10000000000002 | K7: 0 | L7: 0 | M7: 0 | N7: 0 | O7: 0 | P7: 1 | Q7: 1 | R7: 0 | S7: 新函館農協 米穀畑作課 | U7: 新函館農協 米穀畑 | V7: ｼﾝﾊｺﾀﾞﾃﾉｳｷｮｳ | AM7: 2 | AN7: グループ間取引 | BG7: 0 | BH7: 0 | BI7: 国内 | BJ7: 1 | BK7: 0 | BM7: 3 | BN7: 1 | BO7: 3 | BP7: － | BU7: 住商 二郎 | BV7: 2.0230712e+16 | BW7: 住商 一郎 | BX7: 2.0240802e+16 | CZ7: 0 | DA7: 0 | EZ7: 0 | FB7: 0 | FC7: 1 | FD7: 1 | FE7: 1 | FF7: 0 | FG7: 送付後、1カ月以内にご連絡がない場合は、内容を確認済みとさせていただきます。 | FH7: 5 | FI7: 5 | FJ7: 一括決済_振込 | FK7: 一括決済_振込 | FL7: 1 | FM7: 2 | FN7: 0 | FR7: 2 | FS7: 0 | FT7: 0 | FU7: 0 | FV7: 1 | GA7: S02 | GB7: 振込-ＦＢ | GC7: 1 | GD7: 00190004 | GE7: 北海道銀行ｲｯｶﾂｹｯｻｲ | GZ7: 19 | HA7: 北海道銀行 | HB7: 101 | HC7: 本店 | HD7: 1 | HE7: 7777777 | HF7: 口座名義人新函館 | HG7: ｼﾝﾊｺﾀﾞﾃﾞ | HH7: 0 | IM7: 0 | IN7: 1 | IO7: 1 | IP7: 20
A8: 1 | C8: 0 | D8: 初期導入 | E8: 100120002 | H8: 10000000000002 | K8: 0 | L8: 0 | M8: 0 | N8: 0 | O8: 0 | P8: 1 | Q8: 1 | R8: 0 | S8: 新函館農協 米穀畑作課 | U8: 新函館農協 米穀畑 | V8: ｼﾝﾊｺﾀﾞﾃﾉｳｷｮｳ | AM8: 2 | AN8: グループ間取引 | BG8: 0 | BH8: 0 | BI8: 国内 | BJ8: 1 | BK8: 0 | BM8: 3 | BN8: 1 | BO8: 3 | BP8: － | BU8: 住商 二郎 | BV8: 2.0230712e+16 | BW8: 住商 一郎 | BX8: 2.0240802e+16 | CZ8: 0 | DA8: 0 | EZ8: 0 | FB8: 0 | FC8: 1 | FD8: 1 | FE8: 1 | FF8: 0 | FG8: 送付後、1カ月以内にご連絡がない場合は、内容を確認済みとさせていただきます。 | FH8: 6 | FI8: 6 | FJ8: 納付書支払 | FK8: 納付書支払 | FL8: 1 | FM8: 2 | FN8: 0 | FR8: 3 | FS8: 0 | FT8: 0 | FU8: 0 | FV8: 1 | GA8: S04 | GB8: 振込-総合 | GC8: 1 | GZ8: 19 | HA8: 北海道銀行 | HB8: 104 | HC8: 南一条支店 | HD8: 1 | HE8: 6667777 | HF8: ホクレン | HG8: ﾎｸﾚﾝ | HH8: 0 | IM8: 0 | IN8: 1 | IO8: 1 | IP8: 99
A9: 1 | C9: 0 | D9: 初期導入 | E9: 108000000 | H9: 10000000000003 | K9: 0 | L9: 0 | M9: 0 | N9: 0 | O9: 0 | P9: 0 | Q9: 1 | R9: 0 | S9: 北海道銀行 | U9: 北海道銀行 | V9: ﾎｯｶｲﾄﾞｳｷﾞﾝｺｳ | BG9: 0 | BH9: 0 | BI9: 国内 | BJ9: 1 | BK9: 0 | BM9: 3 | BN9: 1 | BO9: 3 | BP9: － | BU9: 住商 一郎 | BV9: 2.0230906e+16 | BW9: 住商 一郎 | BX9: 2.0240415e+16 | CZ9: 0 | DA9: 0 | EZ9: 0 | FB9: 0 | FC9: 1 | FD9: 1 | FE9: 0 | FF9: 0 | FG9: 送付後、1カ月以内にご連絡がない場合は内容を確認済みとさせていただきます。 | FH9: 1 | FI9: 1 | FJ9: 末締め翌月末支払 | FK9: 末締め翌月末支払 | FL9: 1 | FM9: 2 | FN9: 0 | FR9: 3 | FS9: 0 | FT9: 0 | FU9: 0 | FV9: 1 | GA9: S04 | GB9: 振込-総合 | GC9: 1 | GZ9: 1 | HA9: みずほ | HB9: 1 | HC9: 丸の内 | HD9: 2 | HE9: 7654321 | HF9: ホッカイドウギンコウ | HG9: ﾎﾂｶｲﾄﾞｳｷﾞﾝｺｳ | HH9: 0 | IM9: 0 | IN9: 1 | IO9: 1 | IP9: 99
A10: 1 | C10: 0 | D10: 初期導入 | E10: 1082521003 | H10: 10000000000004 | K10: 0 | L10: 0 | M10: 0 | N10: 0 | O10: 0 | P10: 1 | Q10: 1 | R10: 0 | S10: ㈱ホクレン商事 営業部 | U10: ホクレン商事 営業部 | V10: ﾎｸﾚﾝ | AM10: 2 | AN10: グループ間取引 | BG10: 0 | BH10: 0 | BI10: 国内 | BJ10: 1 | BK10: 0 | BM10: 3 | BN10: 1 | BO10: 3 | BP10: － | BU10: 住商 二郎 | BV10: 2.0230712e+16 | BW10: 住商 一郎 | BX10: 2.0240807e+16 | CZ10: 0 | DA10: 0 | EZ10: 0 | FB10: 0 | FC10: 1 | FD10: 1 | FE10: 1 | FF10: 0 | FG10: 送付後、1カ月以内にご連絡がない場合は内容を確認済みとさせていただきます。 | FH10: 1 | FI10: 1 | FJ10: 随時支払 FB振込 | FK10: 随時支払 FB振込 | FL10: 1 | FM10: 2 | FN10: 0 | FR10: 3 | FS10: 0 | FT10: 0 | FU10: 0 | FV10: 1 | GA10: S02 | GB10: 振込-ＦＢ | GC10: 1 | GZ10: 1 | HA10: みずほ | HB10: 2 | HC10: 築地 | HD10: 2 | HE10: 1234567 | HF10: ホクレン商事 | HG10: ﾎｸﾚﾝｼﾖｳｼﾞ | HH10: 0 | IM10: 0 | IN10: 2 | IQ10: 10
A11: 1 | C11: 0 | D11: 初期導入 | E11: 1082521003 | H11: 10000000000004 | K11: 0 | L11: 0 | M11: 0 | N11: 0 | O11: 0 | P11: 1 | Q11: 1 | R11: 0 | S11: ㈱ホクレン商事 営業部 | U11: ホクレン商事 営業部 | V11: ﾎｸﾚﾝ | AM11: 2 | AN11: グループ間取引 | BG11: 0 | BH11: 0 | BI11: 国内 | BJ11: 1 | BK11: 0 | BM11: 3 | BN11: 1 | BO11: 3 | BP11: － | BU11: 住商 二郎 | BV11: 2.0230712e+16 | BW11: 住商 一郎 | BX11: 2.0240807e+16 | CZ11: 0 | DA11: 0 | EZ11: 0 | FB11: 0 | FC11: 1 | FD11: 1 | FE11: 1 | FF11: 0 | FG11: 送付後、1カ月以内にご連絡がない場合は内容を確認済みとさせていただきます。 | FH11: 2 | FI11: 2 | FJ11: 随時支払 引落 | FK11: 随時支払 引落 | FL11: 1 | FM11: 2 | FN11: 0 | FR11: 3 | FS11: 0 | FT11: 0 | FU11: 0 | FV11: 1 | GA11: S06 | GB11: 引落 | GC11: 1 | IM11: 0 | IN11: 2 | IQ11: 10
A12: 1 | C12: 0 | D12: 初期導入 | E12: 1082521003 | H12: 10000000000004 | K12: 0 | L12: 0 | M12: 0 | N12: 0 | O12: 0 | P12: 1 | Q12: 1 | R12: 0 | S12: ㈱ホクレン商事 営業部 | U12: ホクレン商事 営業部 | V12: ﾎｸﾚﾝ | AM12: 2 | AN12: グループ間取引 | BG12: 0 | BH12: 0 | BI12: 国内 | BJ12: 1 | BK12: 0 | BM12: 3 | BN12: 1 | BO12: 3 | BP12: － | BU12: 住商 二郎 | BV12: 2.0230712e+16 | BW12: 住商 一郎 | BX12: 2.0240807e+16 | CZ12: 0 | DA12: 0 | EZ12: 0 | FB12: 0 | FC12: 1 | FD12: 1 | FE12: 1 | FF12: 0 | FG12: 送付後、1カ月以内にご連絡がない場合は内容を確認済みとさせていただきます。 | FH12: 3 | FI12: 3 | FJ12: 随時支払 納付書 | FK12: 随時支払 納付書 | FL12: 1 | FM12: 2 | FN12: 0 | FR12: 3 | FS12: 0 | FT12: 0 | FU12: 0 | FV12: 1 | GA12: S04 | GB12: 振込-総合 | GC12: 1 | GZ12: 1 | HA12: みずほ | HB12: 1 | HC12: 丸の内 | HD12: 2 | HE12: 2345678 | HF12: ホクレンショウジ | HG12: ﾎｸﾚﾝｼﾖｳｼﾞ | HH12: 0 | IM12: 0 | IN12: 2 | IQ12: 10
A13: 1 | C13: 0 | D13: 初期導入 | E13: 1082521003 | H13: 10000000000004 | K13: 0 | L13: 0 | M13: 0 | N13: 0 | O13: 0 | P13: 1 | Q13: 1 | R13: 0 | S13: ㈱ホクレン商事 営業部 | U13: ホクレン商事 営業部 | V13: ﾎｸﾚﾝ | AM13: 2 | AN13: グループ間取引 | BG13: 0 | BH13: 0 | BI13: 国内 | BJ13: 1 | BK13: 0 | BM13: 3 | BN13: 1 | BO13: 3 | BP13: － | BU13: 住商 二郎 | BV13: 2.0230712e+16 | BW13: 住商 一郎 | BX13: 2.0240807e+16 | CZ13: 0 | DA13: 0 | EZ13: 0 | FB13: 0 | FC13: 1 | FD13: 1 | FE13: 1 | FF13: 0 | FG13: 送付後、1カ月以内にご連絡がない場合は内容を確認済みとさせていただきます。 | FH13: 4 | FI13: 4 | FJ13: 一括決済_手形 | FK13: 一括決済_手形 | FL13: 1 | FM13: 2 | FN13: 0 | FR13: 1 | FS13: 0 | FT13: 0 | FU13: 0 | FV13: 1 | GA13: S07 | GB13: 支払手形 | GC13: 1 | HL13: 60 | HM13: 2 | HN13: 30 | HO13: 1 | HP13: ST005 | HQ13: 支払手形_一括決済 | IM13: 0 | IN13: 1 | IO13: 2 | IP13: 99
A14: 1 | C14: 0 | D14: 初期導入 | E14: 108400001 | H14: 10000000000005 | K14: 0 | L14: 0 | M14: 0 | N14: 0 | O14: 0 | P14: 1 | Q14: 1 | R14: 0 | S14: 全国農業協同組合連合会 本所 | U14: 全農連 本所 | V14: ｾﾞﾝﾉｳﾘﾝ | BG14: 0 | BH14: 0 | BI14: 国内 | BJ14: 1 | BK14: 0 | BM14: 3 | BN14: 1 | BO14: 3 | BP14: － | BU14: 住商 二郎 | BV14: 2.0230712e+16 | BW14: 住商 一郎 | BX14: 2.0240628e+16 | CZ14: 0 | DA14: 0 | EZ14: 0 | FB14: 0 | FC14: 1 | FD14: 1 | FE14: 1 | FF14: 0 | FG14: 送付後、1カ月以内にご連絡がない場合は内容を確認済みとさせていただきます。 | FH14: 1 | FI14: 1 | FJ14: 翌月末支払-北洋銀行 | FK14: 翌月末支払-北洋銀行 | FL14: 1 | FM14: 2 | FN14: 0 | FR14: 2 | FS14: 0 | FT14: 0 | FU14: 0 | FV14: 1 | GA14: S02 | GB14: 振込-ＦＢ | GC14: 1 | GZ14: 18 | HA14: 北洋銀行 | HB14: 28 | HC14: 本店 | HD14: 1 | HE14: 2229999 | HF14: 全農連 北洋銀行 | HG14: ｾﾞﾝﾉｳﾚﾝﾎｸﾖｳｷﾞﾝｺｳ | HH14: 0 | IM14: 0 | IN14: 1 | IO14: 1 | IP14: 99
A15: 1 | C15: 0 | D15: 初期導入 | E15: 108400001 | H15: 10000000000005 | K15: 0 | L15: 0 | M15: 0 | N15: 0 | O15: 0 | P15: 1 | Q15: 1 | R15: 0 | S15: 全国農業協同組合連合会 本所 | U15: 全農連 本所 | V15: ｾﾞﾝﾉｳﾘﾝ | BG15: 0 | BH15: 0 | BI15: 国内 | BJ15: 1 | BK15: 0 | BM15: 3 | BN15: 1 | BO15: 3 | BP15: － | BU15: 住商 二郎 | BV15: 2.0230712e+16 | BW15: 住商 一郎 | BX15: 2.0240628e+16 | CZ15: 0 | DA15: 0 | EZ15: 0 | FB15: 0 | FC15: 1 | FD15: 1 | FE15: 1 | FF15: 0 | FG15: 送付後、1カ月以内にご連絡がない場合は内容を確認済みとさせていただきます。 | FH15: 2 | FI15: 2 | FJ15: 納付書支払 | FK15: 納付書支払 | FL15: 1 | FM15: 2 | FN15: 0 | FR15: 3 | FS15: 0 | FT15: 0 | FU15: 0 | FV15: 1 | GA15: S04 | GB15: 振込-総合 | GC15: 1 | GZ15: 20 | HA15: 北海道信金 | HB15: 113 | HC15: 大通南支店 | HD15: 1 | HE15: 9998888 | HF15: 全農連 | HG15: ｾﾞﾝﾉｳﾚﾝ | HH15: 0 | IM15: 0 | IN15: 1 | IO15: 1 | IP15: 99
A16: 1 | C16: 0 | D16: 初期導入 | E16: 108400002 | H16: 10000000000006 | K16: 0 | L16: 0 | M16: 0 | N16: 0 | O16: 0 | P16: 0 | Q16: 1 | R16: 0 | S16: JA新函館 | U16: JA新函館 | V16: JA | BG16: 0 | BH16: 0 | BI16: 国内 | BJ16: 1 | BK16: 0 | BM16: 3 | BN16: 1 | BO16: 3 | BP16: － | BU16: 住商 一郎 | BV16: 2.0230713e+16 | BW16: 住商 一郎 | BX16: 2.0240807e+16 | CZ16: 0 | DA16: 0 | EZ16: 0 | FB16: 0 | FC16: 1 | FD16: 1 | FE16: 0 | FF16: 0 | FH16: 1 | FI16: 1 | FJ16: 翌月末支払随時 | FK16: 翌月末支払随時 | FL16: 1 | FM16: 2 | FN16: 0 | FR16: 3 | FS16: 0 | FT16: 0 | FU16: 0 | FV16: 1 | GA16: S02 | GB16: 振込-ＦＢ | GC16: 1 | GZ16: 18 | HA16: 北洋銀行 | HB16: 485 | HC16: 札幌市役所支店 | HD16: 1 | HE16: 6543333 | HF16: JA新函館 | HG16: ｼﾞｴｲｴｲｼﾝﾊｺﾀﾞﾃ | HH16: 0 | IM16: 0 | IN16: 1 | IO16: 1 | IP16: 99
A17: 1 | C17: 0 | D17: 初期導入 | E17: 108400002 | H17: 10000000000006 | K17: 0 | L17: 0 | M17: 0 | N17: 0 | O17: 0 | P17: 0 | Q17: 1 | R17: 0 | S17: JA新函館 | U17: JA新函館 | V17: JA | BG17: 0 | BH17: 0 | BI17: 国内 | BJ17: 1 | BK17: 0 | BM17: 3 | BN17: 1 | BO17: 3 | BP17: － | BU17: 住商 一郎 | BV17: 2.0230713e+16 | BW17: 住商 一郎 | BX17: 2.0240807e+16 | CZ17: 0 | DA17: 0 | EZ17: 0 | FB17: 0 | FC17: 1 | FD17: 1 | FE17: 0 | FF17: 0 | FH17: 2 | FI17: 2 | FJ17: 納付書支払 | FK17: 納付書支払 | FL17: 1 | FM17: 2 | FN17: 0 | FR17: 3 | FS17: 0 | FT17: 0 | FU17: 0 | FV17: 1 | GA17: S04 | GB17: 振込-総合 | GC17: 1 | GZ17: 18 | HA17: 北洋銀行 | HB17: 28 | HC17: 本店 | HD17: 1 | HE17: 7777776 | HF17: JA新函館 | HG17: ｼﾞｴｲｴｲｼﾝﾊｺﾀﾞﾃ | HH17: 0 | IM17: 0 | IN17: 1 | IO17: 1 | IP17: 99
A18: 1 | C18: 0 | D18: 初期導入 | E18: 108400002 | H18: 10000000000006 | K18: 0 | L18: 0 | M18: 0 | N18: 0 | O18: 0 | P18: 0 | Q18: 1 | R18: 0 | S18: JA新函館 | U18: JA新函館 | V18: JA | BG18: 0 | BH18: 0 | BI18: 国内 | BJ18: 1 | BK18: 0 | BM18: 3 | BN18: 1 | BO18: 3 | BP18: － | BU18: 住商 一郎 | BV18: 2.0230713e+16 | BW18: 住商 一郎 | BX18: 2.0240807e+16 | CZ18: 0 | DA18: 0 | EZ18: 0 | FB18: 0 | FC18: 1 | FD18: 1 | FE18: 0 | FF18: 0 | FH18: 3 | FI18: 3 | FJ18: 仕入金額を前渡金で充当 | FK18: 前渡金にて充当 | FL18: 1 | FM18: 2 | FN18: 0 | FR18: 3 | FS18: 0 | FT18: 0 | FU18: 0 | FV18: 1 | GA18: ZZ | GB18: 振込-その他 | GC18: 1 | GD18: 00300001 | GE18: 前渡金充当 本所用 | GZ18: 19 | HA18: 北海道銀行 | HB18: 101 | HC18: 本店 | HD18: 1 | HE18: 2224444 | HF18: JA新函館 | HG18: ｼﾞｴｲｴｲｼﾝﾊｺﾀﾞﾃ | HH18: 0 | IM18: 0 | IN18: 1 | IO18: 1 | IP18: 99
A19: 1 | C19: 0 | D19: 初期導入 | E19: 108400002 | H19: 10000000000006 | K19: 0 | L19: 0 | M19: 0 | N19: 0 | O19: 0 | P19: 0 | Q19: 1 | R19: 0 | S19: JA新函館 | U19: JA新函館 | V19: JA | BG19: 0 | BH19: 0 | BI19: 国内 | BJ19: 1 | BK19: 0 | BM19: 3 | BN19: 1 | BO19: 3 | BP19: － | BU19: 住商 一郎 | BV19: 2.0230713e+16 | BW19: 住商 一郎 | BX19: 2.0240807e+16 | CZ19: 0 | DA19: 0 | EZ19: 0 | FB19: 0 | FC19: 1 | FD19: 1 | FE19: 0 | FF19: 0 | FH19: 4 | FI19: 4 | FJ19: 一括決済_手形 | FK19: 一括決済_手形 | FL19: 1 | FM19: 2 | FN19: 0 | FR19: 1 | FS19: 0 | FT19: 0 | FU19: 0 | FV19: 1 | GA19: S07 | GB19: 支払手形 | GC19: 1 | HL19: 90 | HM19: 1 | HN19: 99 | HO19: 1 | HP19: ST005 | HQ19: 支払手形_一括決済 | IM19: 0 | IN19: 1 | IO19: 1 | IP19: 99
A20: 1 | C20: 0 | D20: 初期導入 | E20: 108400003 | H20: 10000000000007 | K20: 0 | L20: 0 | M20: 0 | N20: 0 | O20: 0 | P20: 0 | Q20: 0 | R20: 0 | S20: 全農 | U20: 全農 | V20: ｾﾞﾝｺｳ | BG20: 0 | BH20: 0 | BI20: 国内 | BJ20: 1 | BK20: 0 | BM20: 3 | BN20: 1 | BO20: 3 | BP20: － | BU20: 住商 一郎 | BV20: 2.0230713e+16 | BW20: 住商 一郎 | BX20: 2.0240415e+16 | CZ20: 0 | DA20: 0 | EZ20: 0 | FB20: 0 | FC20: 1 | FD20: 1 | FE20: 0 | FF20: 0
A21: 1 | C21: 0 | D21: 初期導入 | E21: 108400004 | H21: 10000000000008 | K21: 0 | L21: 0 | M21: 0 | N21: 0 | O21: 0 | P21: 0 | Q21: 0 | R21: 0 | S21: 青果市場 | U21: 青果市場 | V21: ｾｲｶ | BG21: 0 | BH21: 0 | BI21: 国内 | BJ21: 1 | BK21: 0 | BM21: 3 | BN21: 1 | BO21: 3 | BP21: － | BU21: 住商 一郎 | BV21: 2.0230713e+16 | BW21: 住商 一郎 | BX21: 2.0240415e+16 | CZ21: 0 | DA21: 0 | EZ21: 0 | FB21: 0 | FC21: 1 | FD21: 1 | FE21: 0 | FF21: 0
A22: 1 | C22: 0 | D22: 初期導入 | E22: 108400005 | H22: 10000000000009 | K22: 0 | L22: 0 | M22: 0 | N22: 0 | O22: 0 | P22: 0 | Q22: 0 | R22: 0 | S22: JAきたみらい | U22: JAきたみらい | V22: ja | BG22: 0 | BH22: 0 | BI22: 国内 | BJ22: 1 | BK22: 0 | BM22: 3 | BN22: 1 | BO22: 3 | BP22: － | BU22: 住商 一郎 | BV22: 2.0230713e+16 | BW22: 住商 一郎 | BX22: 2.0240415e+16 | CZ22: 0 | DA22: 0 | EZ22: 0 | FB22: 0 | FC22: 1 | FD22: 1 | FE22: 0 | FF22: 0
A23: 1 | C23: 0 | D23: 初期導入 | E23: 108400006 | K23: 0 | L23: 0 | M23: 0 | N23: 0 | O23: 0 | P23: 0 | Q23: 0 | R23: 0 | S23: 新函館農協 | U23: 新函館農協 | V23: ﾊｺﾀﾞﾃ | BG23: 0 | BH23: 0 | BI23: 国内 | BJ23: 1 | BK23: 0 | BM23: 3 | BN23: 1 | BO23: 3 | BP23: － | BU23: 住商 一郎 | BV23: 2.0230713e+16 | BW23: 住商 一郎 | BX23: 2.0230713e+16 | CZ23: 0 | DA23: 0 | EZ23: 0 | FB23: 0 | FC23: 1 | FD23: 1 | FE23: 0 | FF23: 0
A24: 1 | C24: 0 | D24: 初期導入 | E24: 108521001 | H24: TOU00000001 | K24: 0 | L24: 0 | M24: 0 | N24: 0 | O24: 0 | P24: 1 | Q24: 1 | R24: 0 | S24: ㈱ホクレン商事 | U24: ホクレン商事 | V24: ﾎｸﾚﾝ | AM24: 2 | AN24: グループ間取引 | BG24: 0 | BH24: 0 | BI24: 国内 | BJ24: 1 | BK24: 0 | BM24: 3 | BN24: 1 | BO24: 3 | BP24: － | BU24: 住商 二郎 | BV24: 2.023071e+16 | BW24: 住商 一郎 | BX24: 2.0240807e+16 | CZ24: 0 | DA24: 0 | EZ24: 0 | FB24: 0 | FC24: 1 | FD24: 0 | FE24: 0 | FF24: 0 | FG24: 送付後、1カ月以内にご連絡がない場合は内容を確認済みとさせていただきます。 | FH24: 1 | FI24: 1 | FJ24: 翌月末振込（経理課） | FK24: 翌月末振込（経理課） | FL24: 1 | FM24: 2 | FN24: 0 | FR24: 2 | FS24: 0 | FT24: 0 | FU24: 0 | FV24: 1 | GA24: S02 | GB24: 振込-ＦＢ | GC24: 1 | GZ24: 18 | HA24: 北洋銀行 | HB24: 28 | HC24: 本店 | HD24: 2 | HE24: 7 | HF24: ほくれん | HG24: ﾎｸﾚﾝ | HH24: 0 | IM24: 0 | IN24: 1 | IO24: 1 | IP24: 99
A25: 1 | C25: 0 | D25: 初期導入 | E25: 108521001 | H25: TOU00000001 | K25: 0 | L25: 0 | M25: 0 | N25: 0 | O25: 0 | P25: 1 | Q25: 1 | R25: 0 | S25: ㈱ホクレン商事 | U25: ホクレン商事 | V25: ﾎｸﾚﾝ | AM25: 2 | AN25: グループ間取引 | BG25: 0 | BH25: 0 | BI25: 国内 | BJ25: 1 | BK25: 0 | BM25: 3 | BN25: 1 | BO25: 3 | BP25: － | BU25: 住商 二郎 | BV25: 2.023071e+16 | BW25: 住商 一郎 | BX25: 2.0240807e+16 | CZ25: 0 | DA25: 0 | EZ25: 0 | FB25: 0 | FC25: 1 | FD25: 0 | FE25: 0 | FF25: 0 | FG25: 送付後、1カ月以内にご連絡がない場合は内容を確認済みとさせていただきます。 | FH25: 2 | FI25: 2 | FJ25: 翌月末振込（畜産生産部（飼料）） | FK25: 翌月末振込（飼料） | FL25: 1 | FM25: 2 | FN25: 0 | FR25: 2 | FS25: 0 | FT25: 0 | FU25: 0 | FV25: 1 | GA25: S02 | GB25: 振込-ＦＢ | GC25: 1 | GZ25: 18 | HA25: 北洋銀行 | HB25: 303 | HC25: 札幌南支店 | HD25: 1 | HE25: 9876543 | HF25: ホクレン商事 | HG25: ﾎｸﾚﾝｼﾖｳｼﾞ | HH25: 0 | IM25: 0 | IN25: 1 | IO25: 1 | IP25: 99
A26: 1 | C26: 0 | D26: 初期導入 | E26: 108521001 | H26: TOU00000001 | K26: 0 | L26: 0 | M26: 0 | N26: 0 | O26: 0 | P26: 1 | Q26: 1 | R26: 0 | S26: ㈱ホクレン商事 | U26: ホクレン商事 | V26: ﾎｸﾚﾝ | AM26: 2 | AN26: グループ間取引 | BG26: 0 | BH26: 0 | BI26: 国内 | BJ26: 1 | BK26: 0 | BM26: 3 | BN26: 1 | BO26: 3 | BP26: － | BU26: 住商 二郎 | BV26: 2.023071e+16 | BW26: 住商 一郎 | BX26: 2.0240807e+16 | CZ26: 0 | DA26: 0 | EZ26: 0 | FB26: 0 | FC26: 1 | FD26: 0 | FE26: 0 | FF26: 0 | FG26: 送付後、1カ月以内にご連絡がない場合は内容を確認済みとさせていただきます。 | FH26: 3 | FI26: 3 | FJ26: 翌月末振込（種苗課） | FK26: 翌月末振込（種苗課） | FL26: 1 | FM26: 2 | FN26: 0 | FR26: 2 | FS26: 0 | FT26: 0 | FU26: 0 | FV26: 1 | GA26: S02 | GB26: 振込-ＦＢ | GC26: 1 | GZ26: 18 | HA26: 北洋銀行 | HB26: 485 | HC26: 札幌市役所支店 | HD26: 1 | HE26: 8 | HF26: ホクレン商事 | HG26: ﾎｸﾚﾝ | HH26: 0 | IM26: 0 | IN26: 1 | IO26: 1 | IP26: 99
A27: 1 | C27: 0 | D27: 初期導入 | E27: 108521001 | H27: TOU00000001 | K27: 0 | L27: 0 | M27: 0 | N27: 0 | O27: 0 | P27: 1 | Q27: 1 | R27: 0 | S27: ㈱ホクレン商事 | U27: ホクレン商事 | V27: ﾎｸﾚﾝ | AM27: 2 | AN27: グループ間取引 | BG27: 0 | BH27: 0 | BI27: 国内 | BJ27: 1 | BK27: 0 | BM27: 3 | BN27: 1 | BO27: 3 | BP27: － | BU27: 住商 二郎 | BV27: 2.023071e+16 | BW27: 住商 一郎 | BX27: 2.0240807e+16 | CZ27: 0 | DA27: 0 | EZ27: 0 | FB27: 0 | FC27: 1 | FD27: 0 | FE27: 0 | FF27: 0 | FG27: 送付後、1カ月以内にご連絡がない場合は内容を確認済みとさせていただきます。 | FH27: 4 | FI27: 4 | FJ27: 翌月末振込（生産資材課（農薬）） | FK27: 翌月末振込（生資 | FL27: 1 | FM27: 2 | FN27: 0 | FR27: 2 | FS27: 0 | FT27: 0 | FU27: 0 | FV27: 1 | GA27: S02 | GB27: 振込-ＦＢ | GC27: 1 | GD27: 00200001 | GE27: 北信連本所 | GZ27: 20 | HA27: 北海道信金 | HB27: 1 | HC27: 本店 | HD27: 1 | HE27: 1112222 | HF27: ホクレン 生産資材課（農薬） | HG27: ﾎｸﾚﾝ | HH27: 0 | IM27: 0 | IN27: 1 | IO27: 1 | IP27: 99
A28: 1 | C28: 0 | D28: 初期導入 | E28: 108521001 | H28: TOU00000001 | K28: 0 | L28: 0 | M28: 0 | N28: 0 | O28: 0 | P28: 1 | Q28: 1 | R28: 0 | S28: ㈱ホクレン商事 | U28: ホクレン商事 | V28: ﾎｸﾚﾝ | AM28: 2 | AN28: グループ間取引 | BG28: 0 | BH28: 0 | BI28: 国内 | BJ28: 1 | BK28: 0 | BM28: 3 | BN28: 1 | BO28: 3 | BP28: － | BU28: 住商 二郎 | BV28: 2.023071e+16 | BW28: 住商 一郎 | BX28: 2.0240807e+16 | CZ28: 0 | DA28: 0 | EZ28: 0 | FB28: 0 | FC28: 1 | FD28: 0 | FE28: 0 | FF28: 0 | FG28: 送付後、1カ月以内にご連絡がない場合は内容を確認済みとさせていただきます。 | FH28: 5 | FI28: 5 | FJ28: 翌月末振込（酪農畜産課（生乳）） | FK28: 翌月末振込（酪畜） | FL28: 1 | FM28: 2 | FN28: 0 | FR28: 2 | FS28: 0 | FT28: 0 | FU28: 0 | FV28: 1 | GA28: S02 | GB28: 振込-ＦＢ | GC28: 1 | GD28: 00200002 | GE28: 北海道信金 山鼻中央 | GZ28: 20 | HA28: 北海道信金 | HB28: 5 | HC28: 山鼻中央支店 | HD28: 1 | HE28: 9995555 | HF28: ホクレン 北海道信金山鼻中央用 | HG28: ﾎｸﾚﾝ | HH28: 0 | IM28: 0 | IN28: 1 | IO28: 1 | IP28: 99
A29: 1 | C29: 0 | D29: 初期導入 | E29: 108521001 | H29: TOU00000001 | K29: 0 | L29: 0 | M29: 0 | N29: 0 | O29: 0 | P29: 1 | Q29: 1 | R29: 0 | S29: ㈱ホクレン商事 | U29: ホクレン商事 | V29: ﾎｸﾚﾝ | AM29: 2 | AN29: グループ間取引 | BG29: 0 | BH29: 0 | BI29: 国内 | BJ29: 1 | BK29: 0 | BM29: 3 | BN29: 1 | BO29: 3 | BP29: － | BU29: 住商 二郎 | BV29: 2.023071e+16 | BW29: 住商 一郎 | BX29: 2.0240807e+16 | CZ29: 0 | DA29: 0 | EZ29: 0 | FB29: 0 | FC29: 1 | FD29: 0 | FE29: 0 | FF29: 0 | FG29: 送付後、1カ月以内にご連絡がない場合は内容を確認済みとさせていただきます。 | FH29: 6 | FI29: 100 | FJ29: 随時支払 | FK29: 随時支払 | FL29: 1 | FM29: 2 | FN29: 0 | FR29: 1 | FS29: 0 | FT29: 0 | FU29: 0 | FV29: 1 | GA29: S02 | GB29: 振込-ＦＢ | GC29: 1 | GZ29: 3001 | HA29: 北海道信用農業協同組合連合会 | HB29: 820 | HC29: 本所 | HD29: 1 | HE29: 874 | HF29: ホクレン商事 | HG29: ﾎｸﾚﾝｼﾖｳｼﾞ | HH29: 0 | IM29: 0 | IN29: 1 | IO29: 0 | IP29: 1
A30: 1 | C30: 0 | D30: 初期導入 | E30: 108521001 | H30: TOU00000001 | K30: 0 | L30: 0 | M30: 0 | N30: 0 | O30: 0 | P30: 1 | Q30: 1 | R30: 0 | S30: ㈱ホクレン商事 | U30: ホクレン商事 | V30: ﾎｸﾚﾝ | AM30: 2 | AN30: グループ間取引 | BG30: 0 | BH30: 0 | BI30: 国内 | BJ30: 1 | BK30: 0 | BM30: 3 | BN30: 1 | BO30: 3 | BP30: － | BU30: 住商 二郎 | BV30: 2.023071e+16 | BW30: 住商 一郎 | BX30: 2.0240807e+16 | CZ30: 0 | DA30: 0 | EZ30: 0 | FB30: 0 | FC30: 1 | FD30: 0 | FE30: 0 | FF30: 0 | FG30: 送付後、1カ月以内にご連絡がない場合は内容を確認済みとさせていただきます。 | FH30: 7 | FI30: 6 | FJ30: 納付書支払 | FK30: 納付書支払 | FL30: 1 | FM30: 2 | FN30: 0 | FR30: 3 | FS30: 0 | FT30: 0 | FU30: 0 | FV30: 1 | GA30: S04 | GB30: 振込-総合 | GC30: 1 | GZ30: 19 | HA30: 北海道銀行 | HB30: 103 | HC30: 行啓通支店 | HD30: 1 | HE30: 8888884 | HF30: ホクレン商事 | HG30: ﾎｸﾚﾝｼﾖｳｼﾞ | HH30: 0 | IM30: 0 | IN30: 1 | IO30: 1 | IP30: 99
A31: 1 | C31: 0 | D31: 初期導入 | E31: 108521001 | H31: TOU00000001 | K31: 0 | L31: 0 | M31: 0 | N31: 0 | O31: 0 | P31: 1 | Q31: 1 | R31: 0 | S31: ㈱ホクレン商事 | U31: ホクレン商事 | V31: ﾎｸﾚﾝ | AM31: 2 | AN31: グループ間取引 | BG31: 0 | BH31: 0 | BI31: 国内 | BJ31: 1 | BK31: 0 | BM31: 3 | BN31: 1 | BO31: 3 | BP31: － | BU31: 住商 二郎 | BV31: 2.023071e+16 | BW31: 住商 一郎 | BX31: 2.0240807e+16 | CZ31: 0 | DA31: 0 | EZ31: 0 | FB31: 0 | FC31: 1 | FD31: 0 | FE31: 0 | FF31: 0 | FG31: 送付後、1カ月以内にご連絡がない場合は内容を確認済みとさせていただきます。 | FH31: 8 | FI31: 8 | FJ31: 一括決済_手形 | FK31: 一括決済_手形 | FL31: 1 | FM31: 2 | FN31: 0 | FR31: 1 | FS31: 0 | FT31: 0 | FU31: 0 | FV31: 1 | GA31: S07 | GB31: 支払手形 | GC31: 1 | HL31: 90 | HM31: 1 | HN31: 99 | HO31: 1 | HP31: ST005 | HQ31: 支払手形_一括決済 | IM31: 0 | IN31: 1 | IO31: 1 | IP31: 99
A32: 1 | C32: 0 | D32: 初期導入 | E32: 108521002 | H32: 10000000000010 | K32: 0 | L32: 0 | M32: 0 | N32: 0 | O32: 0 | P32: 0 | Q32: 0 | R32: 0 | S32: ㈱ホクレン商事 北見営業所 | U32: ホクレン 北見 | V32: ﾎｸﾚﾝ ｷﾀﾐ | BG32: 0 | BH32: 0 | BI32: 国内 | BJ32: 1 | BK32: 0 | BM32: 3 | BN32: 1 | BO32: 3 | BP32: － | BU32: 住商 二郎 | BV32: 2.023071e+16 | BW32: 住商 一郎 | BX32: 2.0240415e+16 | CZ32: 0 | DA32: 0 | EZ32: 0 | FB32: 0 | FC32: 1 | FD32: 1 | FE32: 0 | FF32: 0
