Workbook
Name 【債権】最新データ辞書: #REF!
Name oo: #REF!
Name 一般仕訳登録可否区分: #REF!
Name 科目タイプ: #REF!
Name 科目特性区分: #REF!
Name 科目分類: #REF!
Name 項科目摘要要否区分: #REF!
Name 項目辞書: #REF!
Name 項目辞書: #REF!
Name 債権債務対象区分: #REF!
Name 仕訳入力区分: #REF!
Name 所属: #REF!
Name 所属管理区分: #REF!
Name 消費税取引区分要否区分: #REF!
Name 節科目摘要要否区分: #REF!
Name 相手先要否区分: #REF!
Name 品目要否区分: #REF!
Name 目管理: #REF!

Sheet 表紙
F46: ProActive
B48: 変更履歴
B50: 項番 | C50: 変更発生日 | D50: 変更者 | E50: 変更箇所 | F50: 変更内容
B51: 1 | C51: 45898 | D51: SCSK位田 | F51: 新規作成
B52: 2
B53: 3
B54: 4
B55: 5
B56: 6
B57: 7
B58: 8
B59: 9
B60: 10
B61: 11
B62: 12
B63: 13
... B80: 30

Sheet 業務機能概要
A1: ドキュメント名 | L1: サブシステム | Q1: 業務機能名 | AJ1: 作成者 | AO1: =表紙!D51 -> SCSK位田 | AT1: 更新者
A2: 業務機能概要書 | G2: 業務機能概要 | L2: 業務共通 | Q2: 勘定科目・会計摘要マスタ自動取込 | AJ2: 作成日付 | AO2: =表紙!C51 -> 45898 | AT2: 更新日付
B4: 【目的・役割】
C5: ・ | D5: ホクレン様のシステムでは、伝票入力は部門システムやスクラッチ開発する機能で実施し、また、マスタ情報の管理も共通マスタや会計マスタのマスタ管理システムで実施する。
D6: このため、ProActiveC4では、仕訳、支払などの業務データや組織、勘定科目、取引先などのマスタ情報を外部のシステムから取込む必要がある。
D7: マスタデータは夜間処理にて、スクラッチ開発するマスタ（ProActiveC4外のシステム）の情報と同期をとる必要がある。
B10: 【利用者】
C11: ・ | D11: バッチ実行
B14: 【利用頻度】
C15: ・ | D15: 日次夜間（勘定科目マスタが変更、追加された場合のみ）
B18: 【対象要件定義書】
C19: ・ | D19: 要件定義書(他システムとのデータ連動)
B22: 【処理概要】
C23: １) | D23: ファイルによってデータ連動される勘定科目、会計摘要マスタの情報をProActiveC4標準の「勘定科目・補助科目取込」の処理を使用してProActiveC4に取込む。
D24: バッチファイルで定義された取込ディレクトリに配置されている連動データ（取込用のCSVファイル）の情報を取得する。
D25: ※ | E25: 会計摘要マスタの情報は、ProActiveC4の補助科目マスタに取込む
D26: ※ | E26: 勘定科目・補助科目取込では、取込項目のタイトルの行も必要となる
D27: ※ | E27: 勘定科目、補助科目はそれぞれ別の連動データとして別ファイルで作成される想定
F28: 勘定科目取込ファイル | O28: ： | P28: KANJOU_YYYYMMDDHHMMSSmmm.csv
F29: 会計摘要取込ファイル | O29: ： | P29: TEKIYOU_YYYYMMDDHHMMSSmmm.csv
C32: ２) | D32: 1)で取込データが取得できた場合は、登録済のマスタデータを全件削除する。（ただし、款科目より上位の統括科目は連動対象外のため、削除対象外とする）
D33: ※ | E33: 勘定科目情報、補助科目情報は常に最新情報を全件連動する想定とする
D34: ※ | E34: 勘定科目情報、補助科目情報の削除については、バッチファイルからSQLを実行して実現する
C37: ３) | D37: 1)で取得した取込ファイルをINPUTとして、勘定科目・補助科目取込をバッチ実行する。（オンライン機能「勘定科目・補助科目取込/出力」の取込動作を踏襲する。）
D38: ※ | E38: 標準の勘定科目・補助科目取込はオンライン処理可能なままとする
D40: 3-1. | F40: 勘定科目マスタ自動取込バッチ
F41: 標準機能の勘定科目・補助科目取込をバッチダイレクトで実行する。（※取込区分を「勘定科目・勘定科目属性」として実行する）
D43: 3-2. | F43: 会計摘要マスタ自動取込バッチ
F44: 標準機能の勘定科目・補助科目取込をバッチダイレクトで実行する。（※取込区分を「補助科目」として実行する）
C50: ４) | D50: バッチ実行される勘定科目・補助科目取込は、ProActiveC4外のタスク管理用のミドルウェア（以下、タスクスケジューラ）から実行する想定とする。
D51: 正常終了、対象データがない場合は、「異常なし」のステータスをタスクスケジューラに返却する。
D52: エラー終了の場合は、「エラーあり」のステータスをタスクスケジューラに返却する。
D54: [実行情報]
D55: No | F55: パラメータ | O55: 内容
D56: 1 | F56: ※イベント概要参照
D58: [終了情報]
D59: 戻り値 | F59: 内容 | O59: 内容
D60: 0 | F60: 正常終了
D61: 1 | F61: 異常終了 | O61: 業務エラー/システムエラー発生時
B64: 【共通要件】
...

Sheet 画面遷移図
A1: ドキュメント名 | L1: サブシステム | Q1: 業務機能名 | AJ1: 作成者 | AO1: =表紙!D51 -> SCSK位田 | AT1: 更新者 | AY1: SCSK相坂
A2: 業務機能概要書 | G2: 画面遷移図 | L2: =業務機能概要!L2 -> 業務共通 | Q2: =業務機能概要!Q2 -> 勘定科目・会計摘要マスタ自動取込 | AJ2: 作成日付 | AO2: =表紙!C51 -> 45898 | AT2: 更新日付 | AY2: 44103
B4: 【メニュー起動時の画面遷移】

Sheet 画面レイアウト
A1: ドキュメント名 | AH1: サブシステム | AX1: 業務機能名 | DF1: 作成者 | DV1: =表紙!D51 -> SCSK位田 | EL1: 更新者
A2: 業務機能概要書 | R2: 画面レイアウト | AH2: =業務機能概要!L2 -> 業務共通 | AX2: =業務機能概要!Q2 -> 勘定科目・会計摘要マスタ自動取込 | DF2: 作成日付 | DV2: =表紙!C51 -> 45898 | EL2: 更新日付
A3: 画面名 | FD3: 画面№ | FM3: ①
B4: 0 | H4: 40 | R4: 110 | AB4: 180 | AL4: 250 | AV4: 320 | BF4: 390 | BP4: 460 | BZ4: 530 | CJ4: 600 | CT4: 670 | DD4: 740 | DN4: 810 | DX4: 880 | EH4: 950 | EO4: 999 | ER4: ＜補足説明＞
A5: 0
A6: 5
A7: 20
A8: 35
A9: 50
A10: 65
A11: 80
A12: 95
A13: 110
A14: 125
A15: 140
A16: 155
... A47: 620
A57: 画面名 | J57: 自動消込確定情報登録画面 | FD57: 画面№ | FM57: ②
B58: 0 | H58: 40 | R58: 110 | AB58: 180 | AL58: 250 | AV58: 320 | BF58: 390 | BP58: 460 | BZ58: 530 | CJ58: 600 | CT58: 670 | DD58: 740 | DN58: 810 | DX58: 880 | EH58: 950 | EO58: 999 | ER58: ＜補足説明＞
A59: 0
A60: 5
A61: 20
A62: 35
A63: 50
A64: 65
A65: 80
A66: 95
A67: 110
A68: 125
A69: 140
A70: 155
... A101: 620
A111: 画面名 | FD111: 画面№ | FM111: ①
B112: 0 | H112: 40 | R112: 110 | AB112: 180 | AL112: 250 | AV112: 320 | BF112: 390 | BP112: 460 | BZ112: 530 | CJ112: 600 | CT112: 670 | DD112: 740 | DN112: 810 | DX112: 880 | EH112: 950 | EO112: 999 | ER112: ＜補足説明＞
A113: 0
A114: 5
A115: 20
A116: 35
A117: 50
A118: 65
...

Sheet 項目概要
A1: ドキュメント名 | L1: サブシステム | Q1: 業務機能名 | AJ1: 作成者 | AO1: =表紙!D51 -> SCSK位田 | AT1: 更新者 | BE1: ○ | BF1: IN | BG1: 文字列
A2: 業務機能概要書 | G2: 項目概要 | L2: =業務機能概要!L2 -> 業務共通 | Q2: =業務機能概要!Q2 -> 勘定科目・会計摘要マスタ自動取込 | AJ2: 作成日付 | AO2: =表紙!C51 -> 45898 | AT2: 更新日付 | BE2: － | BF2: OUT | BG2: 数値
BF3: IN/OUT | BG3: 半英数
A4: 【画面項目説明】 | BG4: 半カナ
BG5: コード
B6: [①自動消込確定情報登録画面] | AQ6: ※追加及び変更項目のみ記載 | BG6: 日付
B7: № | C7: ラベル | J7: 項目名 | Q7: I/O | S7: 必須 | U7: 型 | W7: 桁数 | Y7: ソート | AA7: 初期表示 | AE7: 備考 | BG7: －
B8: 【ヘッダ部】
B9: 1 | C9: 一覧を最大化 | J9: 一覧を最大化ボタン | Q9: IN | S9: － | U9: － | W9: － | Y9: ー | AA9: ー
B10: 2 | Q10: IN | S10: ○ | U10: 日付 | W10: 8 | Y10: ー | AA10: システム日付
B11: 3 | Q11: OUT | S11: － | U11: コード | W11: 12 | Y11: ー | AA11: ー
B12: 4 | Q12: IN | S12: ○ | U12: コード | W12: 10 | Y12: ー | AA12: ー
Q13: IN | S13: － | U13: － | W13: ー | Y13: ー | AA13: ー
Q14: OUT | S14: － | U14: 文字列 | W14: 20 | Y14: ー | AA14: ー
B15: 5 | Q15: IN | S15: ○ | U15: コード | W15: 15 | Y15: ー | AA15: ー
Q16: IN | S16: － | U16: － | W16: ー | Y16: ー | AA16: ー
Q17: OUT | S17: － | U17: 文字列 | W17: 20 | Y17: ー | AA17: ー
B18: 6 | Q18: IN | S18: ○ | U18: － | W18: ー | Y18: ー
B20: 7 | Q20: IN | S20: ○ | U20: 数値 | W20: 13 | Y20: ー | AA20: ー
B21: 【】
B22: 1
B25: 2
B28: 3
B30: 4
B31: 5
B32: 【】 | AE32: ※ソート順は画面レイアウトシートの補足説明欄参照。
B33: 1
B34: 2
B35: 2
B36: 3
B37: 2
B38: 3
B39: 4
B40: 5
B41: 6
B42: 7
B43: 8
B44: 9
... B52: 16
B53: 【フッタ部】
...

Sheet イベント概要
A1: ドキュメント名 | L1: サブシステム | Q1: 業務機能名 | AJ1: 作成者 | AO1: =表紙!D51 -> SCSK位田 | AT1: 更新者
A2: 業務機能概要書 | G2: イベント概要 | L2: =業務機能概要!L2 -> 業務共通 | Q2: =業務機能概要!Q2 -> 勘定科目・会計摘要マスタ自動取込 | AJ2: 作成日付 | AO2: =表紙!C51 -> 45898 | AT2: 更新日付
A4: 【画面イベント処理】
EV5: 注１）初期表示は全ての
B6: № | C6: イベント名 | J6: 処理説明 | EV6: データを処理対象とする
B7: =IF(C7="","",MAX(B$6:B6)+1) -> 1 | C7: 勘定科目マスタ自動取込バッチイベント | J7: 1. | K7: バッチファイルで定義されたディレクトリに配置された取込用のCSVファイルをINPUTとし、
B8: =IF(C8="","",MAX(B$6:B7)+1) | K8: ProActiveC4標準機能の勘定科目・補助科目取込を実行する。（※取込区分は「勘定科目」として実行する）
B9: =IF(C9="","",MAX(B$6:B8)+1) | K9: ＜パラメータ＞
B10: =IF(C10="","",MAX(B$6:B9)+1) | K10: ・ | L10: 会社コード | T10: ： | U10: バッチ実行用のxmlで指定された会社コード
B11: =IF(C11="","",MAX(B$6:B10)+1) | K11: ・ | L11: 取込CSVファイル | T11: ： | U11: バッチファイルのパラメータにて指定されたファイル
B12: =IF(C12="","",MAX(B$6:B10)+1)
B13: =IF(C13="","",MAX(B$6:B11)+1) | K13: 取込用のCSVファイルが取得できなかった場合は、処理を中断する。バッチ実行結果はエラーとする。
B14: =IF(C14="","",MAX(B$6:B13)+1) | K14: 取得できた場合は、後続の処理を継続する。
B15: =IF(C15="","",MAX(B$6:B14)+1) | K15: ※ | L15: 上記のファイル取得、エラーハンドリングはバッチファイルで実施する（アプリケーションでの考慮は不要）
B16: =IF(C16="","",MAX(B$6:B15)+1) | K16: ※ | L16: 取込用CSVのファイルサイズが0byteの場合は、正常として処理終了する。（バッチファイルにてファイルを正常処理フォルダへ移動する）
B18: =IF(C18="","",MAX(B$6:B16)+1)
B19: =IF(C19="","",MAX(B$6:B18)+1) | K19: 取込用のCSVファイルが取得できた場合、登録済の勘定科目マスタのデータを全件削除する。
B20: =IF(C20="","",MAX(B$6:B19)+1) | K20: ※ | L20: 削除用のSQLは別途作成してバッチファイルで実行する（アプリケーションでの考慮は不要）
B21: =IF(C21="","",MAX(B$6:B20)+1)
B22: =IF(C22="","",MAX(B$6:B21)+1) | J22: ２．実行結果をバッチジョブ情報に反映する。
B23: =IF(C23="","",MAX(B$6:B22)+1) | M23: 標準仕様に準じる
B24: =IF(C24="","",MAX(B$6:B23)+1)
B25: =IF(C25="","",MAX(B$6:B24)+1) | M25: ※ | N25: ProActiveC4標準の勘定科目・補助科目取込の仕様では、
B26: =IF(C26="","",MAX(B$6:B25)+1) | N26: 取込ファイルに取込項目のタイトル行しか存在しない場合はエラーとなるが、今回のデータ連動では
B27: =IF(C27="","",MAX(B$6:B26)+1) | N27: 連動対象データがない場合（連動ファイルが0byte）は、バッチファイルで処理終了のハンドリングを実施するため、
B28: =IF(C28="","",MAX(B$6:B27)+1) | N28: 取込処理は実行されない。
B29: =IF(C29="","",MAX(B$6:B28)+1)
B30: =IF(C30="","",MAX(B$6:B29)+1)
B31: =IF(C31="","",MAX(B$6:B30)+1) | J31: ３．バッチ実行結果の終了情報を返却する。
B32: =IF(C32="","",MAX(B$6:B31)+1) | K32: ■ | L32: 正常終了できた場合
B33: =IF(C33="","",MAX(B$6:B32)+1) | M33: 「0:正常終了」
B34: =IF(C34="","",MAX(B$6:B33)+1) | K34: ■ | L34: エラーが発生した場合（※ProActiveC4標準機能のデータ取込でエラーが発生した場合は当ケースに該当する）
B35: =IF(C35="","",MAX(B$6:B34)+1) | M35: 「1:異常終了」
B36: =IF(C36="","",MAX(B$6:B35)+1)
B37: =IF(C37="","",MAX(B$6:B36)+1) | J37: ４．取込処理後、取込用のCSVファイルは処理済用ファイルのディレクトリに移動する
B38: =IF(C38="","",MAX(B$6:B37)+1) | K38: ※ | L38: アプリケーションではなくバッチファイルでファイル移動する
B39: =IF(C39="","",MAX(B$6:B38)+1) | K39: ※ | L39: 正常用、エラー用のディレクトリを作成して処理結果によって移動先ディレクトリを分岐させる
B42: =IF(C42="","",MAX(B$6:B39)+1)
B43: =IF(C43="","",MAX(B$6:B42)+1)
B44: =IF(C44="","",MAX(B$6:B43)+1)
...

Sheet チェック仕様
A1: ドキュメント名 | L1: サブシステム | Q1: 業務機能名 | AJ1: 作成者 | AO1: =表紙!D51 -> SCSK位田 | AT1: 更新者
A2: 業務機能概要書 | G2: チェック仕様 | L2: =業務機能概要!L2 -> 業務共通 | Q2: =業務機能概要!Q2 -> 勘定科目・会計摘要マスタ自動取込 | AJ2: 作成日付 | AO2: =表紙!C51 -> 45898 | AT2: 更新日付
A4: 【チェック処理】
B6: １．初期処理時
B7: № | C7: 項目名 | L7: 条件必須 | O7: 存在 | R7: 範囲 | U7: 関連 | X7: その他 | AA7: 内容
B8: =IF(C8="","",MAX(B7:B$7)+1) -> 1 | C8: － | X8: ○
B9: =IF(C9="","",MAX(B$7:B8)+1)
B10: =IF(C10="","",MAX(B$7:B9)+1)
B11: =IF(C11="","",MAX(B$7:B10)+1)
B13: ２．検索ボタン押下時
B14: № | C14: 項目名 | L14: 条件必須 | O14: 存在 | R14: 範囲 | U14: 関連 | X14: その他 | AA14: 内容
B15: =IF(C15="","",MAX(B$14:B14)+1)
B16: =IF(C16="","",MAX(B$14:B15)+1)
B17: =IF(C17="","",MAX(B$14:B16)+1)
B18: =IF(C18="","",MAX(B$14:B17)+1)
B19: =IF(C19="","",MAX(B$14:B18)+1)
B20: =IF(C20="","",MAX(B$14:B19)+1)
B21: =IF(C21="","",MAX(B$14:B20)+1)
B22: =IF(C22="","",MAX(B$14:B21)+1)
B23: =IF(C23="","",MAX(B$14:B22)+1)
B24: =IF(C24="","",MAX(B$14:B23)+1)
B25: =IF(C25="","",MAX(B$14:B24)+1)
B26: =IF(C26="","",MAX(B$14:B25)+1)
... B31: =IF(C31="","",MAX(B$14:B30)+1)
B33: ３．データ取込ボタン
B34: № | C34: 項目名 | L34: 条件必須 | O34: 存在 | R34: 範囲 | U34: 関連 | X34: その他 | AA34: 内容
B35: =IF(C35="","",MAX(B$34:B34)+1)
B36: =IF(C36="","",MAX(B$34:B35)+1)
B37: =IF(C37="","",MAX(B$34:B36)+1)
B38: =IF(C38="","",MAX(B$34:B37)+1)
B39: =IF(C39="","",MAX(B$34:B38)+1)
B40: =IF(C40="","",MAX(B$34:B39)+1)
B41: =IF(C41="","",MAX(B$34:B40)+1)
B42: =IF(C42="","",MAX(B$34:B41)+1)
B43: =IF(C43="","",MAX(B$34:B42)+1)
B44: =IF(C44="","",MAX(B$34:B40)+1)
B45: =IF(C45="","",MAX(B$34:B44)+1)
B46: =IF(C46="","",MAX(B$34:B45)+1)
B47: 4
B48: =IF(C48="","",MAX(B$34:B47)+1)
...

Sheet 出力CSV定義
A1: ドキュメント名 | E1: サブシステム | G1: 業務機能名 | P1: 作成者 | R1: =表紙!D51 -> SCSK位田 | T1: 更新者
A2: 業務機能概要書 | C2: 出力CSV定義 | E2: =業務機能概要!L2 -> 業務共通 | G2: =業務機能概要!Q2 -> 勘定科目・会計摘要マスタ自動取込 | P2: 作成日 | R2: =表紙!C51 -> 45898 | T2: 更新日
A4: データ名 | I4: ヘッダ行 | K4: あり | M4: なし | N4: ダブルクォーテーション | Q4: あり | S4: なし | X4: 文字列
A5: ﾌｧｲﾙ形式・ﾚｺｰﾄﾞ長 | D5: 固定長（ | G5: Byte） | I5: 可変長（区切り文字［ ，(カンマ) ］） | M5: バイナリデータ | P5: その他（ ） | X5: 半英数
A6: 文字コード | D6: UNI（Win系） | F6: EBCDIC(K) | I6: その他（UTF-8） | M6: 改行コード | O6: LF(UNIX系) | Q6: CRLF(Win系) | T6: なし | X6: 半カナ
A7: 全角(2byte)文字項目 | D7: あり | F7: なし | M7: 数値編集 | O7: 左詰め | Q7: 右詰め［ゼロ埋め］ | T7: 右詰め［スペース埋め］ | X7: コード
A8: 特記事項 | C8: 出力順：起票日付、仕訳伝票番号、仕訳自動作成フラグ、仕訳伝票行番号 | J8: ※「"」が含まれる項目は「""」に変換する。 | X8: 数値
A9: No. | B9: 項目名 | E9: 必須 | F9: 型 | G9: 桁数 | H9: 開始位置 | I9: 備考 | X9: 日付
H10: /列 | X10: 時間
A11: 1 | F11: 日付 | G11: 8 | H11: A | X11: 年月
A12: 2 | F12: 半英数 | G12: 12 | H12: B | X12: 区分
A13: 3 | F13: コード | G13: 10 | H13: C | X13: フラグ
A14: 4 | F14: 文字列 | G14: 40 | H14: D | X14: -
A15: 5
A16: 6
A17: 7
A18: 8
A19: 9
A20: 10
A21: 11
A22: 12
A23: 13
A24: 14
A25: 15

Sheet 出力CSVサンプル

Sheet 取込フォーマット定義（勘定科目）
A1: ドキュメント名 | E1: サブシステム | G1: 業務機能名 | P1: 作成者 | R1: SCSK位田 | T1: 更新者
A2: 業務機能概要書 | C2: 取込フォーマット定義 | E2: 業務共通 | G2: 勘定科目・会計摘要マスタ自動取込 | P2: 作成日 | R2: =表紙!C51 -> 45898 | T2: 更新日
A4: データ名 | C4: 勘定科目マスタ自動取込 | I4: ヘッダ行 | K4: あり | M4: なし | N4: ダブルクォーテーション | Q4: あり | S4: なし | X4: 文字列
A5: ﾌｧｲﾙ形式・ﾚｺｰﾄﾞ長 | D5: 固定長（ | G5: Byte） | I5: 可変長（区切り文字［ ，(カンマ) ］） | M5: バイナリデータ | P5: その他（ ） | X5: 半英数
A6: 文字コード | D6: UNI（Win系） | F6: EBCDIC(K) | I6: その他（ UTF-8） | M6: 改行コード | O6: LF(UNIX系) | Q6: CRLF(Win系) | T6: なし | X6: 半カナ
A7: 全角(2byte)文字項目 | D7: あり | F7: なし | M7: 数値編集 | O7: 左詰め | Q7: 右詰め［ゼロ埋め］ | T7: 右詰め［スペース埋め］ | X7: コード
A8: 特記事項 | C8: 取込ファイルには、取込項目のタイトル行が必要となる | X8: 数値
A9: No. | B9: 項目名 | E9: 必須 | F9: 型 | G9: 桁数 | H9: 開始位置 | I9: 項目説明 | O9: 設定値 | X9: 日付
H10: /列 | X10: 時間
A11: =MAX($A$10:$A10)+1 -> 1 | B11: 編集区分 | E11: 〇 | F11: 区分 | G11: 1 | H11: =SUBSTITUTE(SUBSTITUTE(ADDRESS(1,A11),"$1",""),"$","") -> A | I11: 「1:新規」 固定 | K11: ※全件連動の前提 | O11: １（固定値） | X11: 年月
A12: =MAX($A$10:$A11)+1 -> 2 | B12: 勘定科目コード | E12: 〇 | F12: コード | G12: 8 | H12: =SUBSTITUTE(SUBSTITUTE(ADDRESS(1,A12),"$1",""),"$","") -> B | O12: 勘定科目マスタ.勘定科目コード + 目節科目マスタ.目節科目コード | X12: 区分
A13: =MAX($A$10:$A12)+1 -> 3 | B13: 勘定科目名 | E13: 〇 | F13: 文字列 | G13: 30 | H13: =SUBSTITUTE(SUBSTITUTE(ADDRESS(1,A13),"$1",""),"$","") -> C | O13: PA連動用名称 ※新規追加項目 | AB13: 桁数たりない？ 要相談
A14: =MAX($A$10:$A13)+1 -> 4 | B14: 勘定科目名（カナ） | E14: 〇 | F14: 文字列 | G14: 60 | H14: =SUBSTITUTE(SUBSTITUTE(ADDRESS(1,A14),"$1",""),"$","") -> D | O14: PA連動用カナ名称 ※新規追加項目 | AB14: 要ユーザヒアリング
A15: =MAX($A$10:$A14)+1 -> 5 | B15: 勘定科目名（略） | E15: 〇 | F15: 文字列 | G15: 20 | H15: =SUBSTITUTE(SUBSTITUTE(ADDRESS(1,A15),"$1",""),"$","") -> E | O15: PA連動用略称 ※新規追加項目 | AB15: 要ユーザヒアリング
A16: =MAX($A$10:$A15)+1 -> 6 | B16: B／S・P／L | E16: 〇 | F16: 文字列 | G16: 1 | H16: =SUBSTITUTE(SUBSTITUTE(ADDRESS(1,A16),"$1",""),"$","") -> F | I16: 1:B／S科目、2:P／L科目 | O16: 勘定科目マスタ.科目タイプから導出（資産・負債・純資産・費用・収益）
O17: 資産・負債・純資産⇒１、費用・収益→2
A18: =MAX($A$10:$A16)+1 -> 7 | B18: B／S・P／L名 | F18: 文字列 | G18: 30 | H18: =SUBSTITUTE(SUBSTITUTE(ADDRESS(1,A18),"$1",""),"$","") -> G | I18: 空白（設定不要） | O18: 設定なし
A19: =MAX($A$10:$A18)+1 -> 8 | B19: 属性 | E19: 〇 | F19: 文字列 | G19: 1 | H19: =SUBSTITUTE(SUBSTITUTE(ADDRESS(1,A19),"$1",""),"$","") -> H | I19: 1:資産、2:負債、3:純資産、4:収益、5:費用、6:利益 | O19: 勘定科目マスタ.科目タイプ（資産・負債・純資産・費用・収益）
A20: =MAX($A$10:$A19)+1 -> 9 | B20: 属性名 | F20: 文字列 | G20: 6 | H20: =SUBSTITUTE(SUBSTITUTE(ADDRESS(1,A20),"$1",""),"$","") -> I | I20: 空白（設定不要） | O20: 設定なし
A21: =MAX($A$10:$A20)+1 -> 10 | B21: 科目区分 | E21: 〇 | F21: 文字列 | G21: 1 | H21: =SUBSTITUTE(SUBSTITUTE(ADDRESS(1,A21),"$1",""),"$","") -> J | I21: 1:一般科目（伝票入力で使用する科目） 2:統括科目 | O21: 勘定科目マスタ（6桁コードで管理）の情報は、統括科目として6桁コードで連動する。 目節科目マスタの情報は、一般科目として8桁コードで連動する。 ※補足１シート参照 | AB21: 要ユーザヒアリング（スクラッチのマスタで一般科目／統括科目を意識してもらえる？）
A22: =MAX($A$10:$A21)+1 -> 11 | B22: 科目区分名 | F22: 文字列 | G22: 8 | H22: =SUBSTITUTE(SUBSTITUTE(ADDRESS(1,A22),"$1",""),"$","") -> K | I22: 空白（設定不要） | O22: 設定なし
A23: =MAX($A$10:$A22)+1 -> 12 | B23: 貸借 | E23: 〇 | F23: 文字列 | G23: 1 | H23: =SUBSTITUTE(SUBSTITUTE(ADDRESS(1,A23),"$1",""),"$","") -> L | I23: 1:借方、2:貸方 | O23: 勘定科目マスタ.貸借区分
A24: =MAX($A$10:$A23)+1 -> 13 | B24: 貸借名 | F24: 文字列 | G24: 4 | H24: =SUBSTITUTE(SUBSTITUTE(ADDRESS(1,A24),"$1",""),"$","") -> M | I24: 空白（設定不要） | O24: 設定なし
A25: =MAX($A$10:$A24)+1 -> 14 | B25: 補助科目別計上フラグ | E25: 〇 | F25: 数値 | G25: 1 | H25: =SUBSTITUTE(SUBSTITUTE(ADDRESS(1,A25),"$1",""),"$","") -> N | I25: 会計摘要を管理する科目の場合は「1:計上する」、 | O25: 目節科目マスタ.目節科目コードが00の場合、
I26: それ以外は「0：計上しない」 | O26: 勘定科目マスタ.項科目摘要要否区分が要の場合、1
O27: それ以外は2
O28: 目節科目マスタ.目節科目コードが00の以外の場合、
O29: 目節科目マスタ.目節科目摘要要否区分が要の場合、1
O30: それ以外は2
A31: =MAX($A$10:$A25)+1 -> 15 | B31: 通貨別計上フラグ | E31: 〇 | F31: 数値 | G31: 1 | H31: =SUBSTITUTE(SUBSTITUTE(ADDRESS(1,A31),"$1",""),"$","") -> O | I31: 「0:計上しない」 固定 | O31: ０（固定値）
A32: =MAX($A$10:$A31)+1 -> 16 | B32: 調整計上フラグ | E32: △ | F32: 数値 | G32: 1 | H32: =SUBSTITUTE(SUBSTITUTE(ADDRESS(1,A32),"$1",""),"$","") -> P | I32: 「0:計上しない」 固定 | O32: ０（固定値）
A33: =MAX($A$10:$A32)+1 -> 17 | B33: 評価替対象フラグ | E33: △ | F33: 数値 | G33: 1 | H33: =SUBSTITUTE(SUBSTITUTE(ADDRESS(1,A33),"$1",""),"$","") -> Q | I33: 空白（設定不要） | O33: 設定なし
A34: =MAX($A$10:$A33)+1 -> 18 | B34: 入力レート区分 | F34: 文字列 | G34: 1 | H34: =SUBSTITUTE(SUBSTITUTE(ADDRESS(1,A34),"$1",""),"$","") -> R | I34: 空白（設定不要） | O34: 設定なし
A35: =MAX($A$10:$A34)+1 -> 19 | B35: 入力レート区分名 | F35: 文字列 | G35: 3 | H35: =SUBSTITUTE(SUBSTITUTE(ADDRESS(1,A35),"$1",""),"$","") -> S | I35: 空白（設定不要） | O35: 設定なし
A36: =MAX($A$10:$A35)+1 -> 20 | B36: 評価替レート区分 | F36: 文字列 | G36: 1 | H36: =SUBSTITUTE(SUBSTITUTE(ADDRESS(1,A36),"$1",""),"$","") -> T | I36: 空白（設定不要） | O36: 設定なし
A37: =MAX($A$10:$A36)+1 -> 21 | B37: 評価替レート区分名 | F37: 文字列 | G37: 3 | H37: =SUBSTITUTE(SUBSTITUTE(ADDRESS(1,A37),"$1",""),"$","") -> U | I37: 空白（設定不要） | O37: 設定なし
A38: =MAX($A$10:$A37)+1 -> 22 | B38: 消費税区分 | E38: 〇 | F38: コード | G38: 2 | H38: =SUBSTITUTE(SUBSTITUTE(ADDRESS(1,A38),"$1",""),"$","") -> V | I38: ProActiveC4の消費税区分マスタ．消費税区分コードを設定。 | O38: 99 ：対象外（固定値）
A39: =MAX($A$10:$A38)+1 -> 23 | B39: 消費税区分名 | F39: 文字列 | G39: 30 | H39: =SUBSTITUTE(SUBSTITUTE(ADDRESS(1,A39),"$1",""),"$","") -> W | I39: 空白（設定不要） | O39: 設定なし
A40: =MAX($A$10:$A39)+1 -> 24 | B40: 消費税率 | F40: 数値 | G40: 4,2 | H40: =SUBSTITUTE(SUBSTITUTE(ADDRESS(1,A40),"$1",""),"$","") -> X | I40: 空白（設定不要） | O40: 設定なし
A41: =MAX($A$10:$A40)+1 -> 25 | B41: 消費税区分使用制限区分 | E41: 〇 | F41: 文字列 | G41: 1 | H41: =SUBSTITUTE(SUBSTITUTE(ADDRESS(1,A41),"$1",""),"$","") -> Y | I41: 「4:制限なし」 | O41: ４（固定値）
...

Sheet 取込フォーマット定義（補助科目）
A1: ドキュメント名 | E1: サブシステム | G1: 業務機能名 | P1: 作成者 | R1: SCSK位田 | T1: 更新者
A2: 業務機能概要書 | C2: 取込フォーマット定義 | E2: 業務共通 | G2: 勘定科目・会計摘要マスタ自動取込 | P2: 作成日 | R2: =表紙!C51 -> 45898 | T2: 更新日
A4: データ名 | C4: 補助科目マスタ自動取込 | I4: ヘッダ行 | K4: あり | M4: なし | N4: ダブルクォーテーション | Q4: あり | S4: なし | X4: 文字列
A5: ﾌｧｲﾙ形式・ﾚｺｰﾄﾞ長 | D5: 固定長（ | G5: Byte） | I5: 可変長（区切り文字［ ，(カンマ) ］） | M5: バイナリデータ | P5: その他（ ） | X5: 半英数
A6: 文字コード | D6: UNI（Win系） | F6: EBCDIC(K) | I6: その他（ UTF-8） | M6: 改行コード | O6: LF(UNIX系) | Q6: CRLF(Win系) | T6: なし | X6: 半カナ
A7: 全角(2byte)文字項目 | D7: あり | F7: なし | M7: 数値編集 | O7: 左詰め | Q7: 右詰め［ゼロ埋め］ | T7: 右詰め［スペース埋め］ | X7: コード
A8: 特記事項 | C8: 取込ファイルには、取込項目のタイトル行が必要となる | X8: 数値
A9: No. | B9: 項目名 | E9: 必須 | F9: 型 | G9: 桁数 | H9: 開始位置 | I9: 項目説明 | O9: 設定値 | X9: 日付
H10: /列 | X10: 時間
A11: =MAX($A$10:$A10)+1 -> 1 | B11: 編集区分 | E11: 〇 | F11: 区分 | G11: 1 | H11: =SUBSTITUTE(SUBSTITUTE(ADDRESS(1,A11),"$1",""),"$","") -> A | I11: 「1:新規」 | K11: ※全件連動の前提 | O11: １（固定値） | X11: 年月
A12: =MAX($A$10:$A11)+1 -> 2 | B12: 勘定科目コード | E12: 〇 | F12: コード | G12: 8 | H12: =SUBSTITUTE(SUBSTITUTE(ADDRESS(1,A12),"$1",""),"$","") -> B | I12: ProActiveC4勘定科目マスタに登録した8桁の勘定科目コード | O12: 科目摘要マスタ.勘定科目コード | X12: 区分
A13: =MAX($A$10:$A12)+1 -> 3 | B13: 勘定科目名（略） | F13: 文字列 | G13: 20 | H13: =SUBSTITUTE(SUBSTITUTE(ADDRESS(1,A13),"$1",""),"$","") -> C | I13: 設定不要 | O13: 設定なし | X13: フラグ
A14: =MAX($A$10:$A13)+1 -> 4 | B14: 補助科目コード | E14: △ | F14: コード | G14: 4 | H14: =SUBSTITUTE(SUBSTITUTE(ADDRESS(1,A14),"$1",""),"$","") -> D | I14: 科目摘要のコード | O14: 科目摘要マスタ.科目摘要コード | X14: -
A15: =MAX($A$10:$A14)+1 -> 5 | B15: 補助科目名 | E15: △ | F15: 文字列 | G15: 30 | H15: =SUBSTITUTE(SUBSTITUTE(ADDRESS(1,A15),"$1",""),"$","") -> E | I15: 科目摘要の名称 | O15: 科目摘要マスタ.科目摘要名 | R15: 36byteのうち、先頭30byteを設定する
A16: =MAX($A$10:$A15)+1 -> 6 | B16: 借方資金繰コード | F16: コード | G16: 5 | H16: =SUBSTITUTE(SUBSTITUTE(ADDRESS(1,A16),"$1",""),"$","") -> F | I16: 空白 | O16: 設定なし
A17: =MAX($A$10:$A16)+1 -> 7 | B17: 借方資金繰科目名 | F17: 文字列 | G17: 30 | H17: =SUBSTITUTE(SUBSTITUTE(ADDRESS(1,A17),"$1",""),"$","") -> G | I17: 空白 | O17: 設定なし
A18: =MAX($A$10:$A17)+1 -> 8 | B18: 貸方資金繰コード | F18: コード | G18: 5 | H18: =SUBSTITUTE(SUBSTITUTE(ADDRESS(1,A18),"$1",""),"$","") -> H | I18: 空白 | O18: 設定なし
A19: =MAX($A$10:$A18)+1 -> 9 | B19: 貸方資金繰科目名 | F19: 文字列 | G19: 30 | H19: =SUBSTITUTE(SUBSTITUTE(ADDRESS(1,A19),"$1",""),"$","") -> I | I19: 空白 | O19: 設定なし
A20: =MAX($A$10:$A19)+1 -> 10 | B20: 使用不可フラグ | E20: △ | F20: 数値 | G20: 1 | H20: =SUBSTITUTE(SUBSTITUTE(ADDRESS(1,A20),"$1",""),"$","") -> J | I20: 「0:使用可」 ※論理削除対象は「1：使用不可」とする | O20: ０（固定値）※論理削除済みデータは１
A21: =MAX($A$10:$A20)+1 -> 11 | B21: 登録者 | F21: コード | G21: 15 | H21: =SUBSTITUTE(SUBSTITUTE(ADDRESS(1,A21),"$1",""),"$","") -> K | I21: 空白（設定不要） | O21: 設定なし
A22: =MAX($A$10:$A21)+1 -> 12 | B22: 登録者名 | F22: 文字列 | G22: 22 | H22: =SUBSTITUTE(SUBSTITUTE(ADDRESS(1,A22),"$1",""),"$","") -> L | I22: 空白（設定不要） | O22: 設定なし
A23: =MAX($A$10:$A22)+1 -> 13 | B23: 登録日時 | F23: 数値 | G23: 17 | H23: =SUBSTITUTE(SUBSTITUTE(ADDRESS(1,A23),"$1",""),"$","") -> M | I23: 空白（設定不要） | O23: 設定なし
A24: =MAX($A$10:$A23)+1 -> 14 | B24: 更新者 | F24: コード | G24: 15 | H24: =SUBSTITUTE(SUBSTITUTE(ADDRESS(1,A24),"$1",""),"$","") -> N | I24: 空白（設定不要） | O24: 設定なし
A25: =MAX($A$10:$A24)+1 -> 15 | B25: 更新者名 | F25: 文字列 | G25: 22 | H25: =SUBSTITUTE(SUBSTITUTE(ADDRESS(1,A25),"$1",""),"$","") -> O | I25: 空白（設定不要） | O25: 設定なし
A26: =MAX($A$10:$A25)+1 -> 16 | B26: 更新日時 | F26: 数値 | G26: 17 | H26: =SUBSTITUTE(SUBSTITUTE(ADDRESS(1,A26),"$1",""),"$","") -> P | I26: 空白（設定不要） | O26: 設定なし

Sheet 取込フォーマット定義（勘定科目）bk
A1: ドキュメント名 | E1: サブシステム | G1: 業務機能名 | P1: 作成者 | R1: =表紙!D51 -> SCSK位田 | T1: 更新者
A2: 業務機能概要書 | C2: 取込フォーマット定義 | E2: =業務機能概要!L2 -> 業務共通 | G2: =業務機能概要!Q2 -> 勘定科目・会計摘要マスタ自動取込 | P2: 作成日 | R2: =表紙!C51 -> 45898 | T2: 更新日
A4: データ名 | C4: 勘定科目マスタ自動取込 | I4: ヘッダ行 | K4: あり | M4: なし | N4: ダブルクォーテーション | Q4: あり | S4: なし | X4: 文字列
A5: ﾌｧｲﾙ形式・ﾚｺｰﾄﾞ長 | D5: 固定長（ | G5: Byte） | I5: 可変長（区切り文字［ ，(カンマ) ］） | M5: バイナリデータ | P5: その他（ ） | X5: 半英数
A6: 文字コード | D6: UNI（Win系） | F6: EBCDIC(K) | I6: その他（ UTF-8） | M6: 改行コード | O6: LF(UNIX系) | Q6: CRLF(Win系) | T6: なし | X6: 半カナ
A7: 全角(2byte)文字項目 | D7: あり | F7: なし | M7: 数値編集 | O7: 左詰め | Q7: 右詰め［ゼロ埋め］ | T7: 右詰め［スペース埋め］ | X7: コード
A8: 特記事項 | C8: 取込ファイルには、取込項目のタイトル行が必要となる | X8: 数値
A9: No. | B9: 項目名 | E9: 必須 | F9: 型 | G9: 桁数 | H9: 開始位置 | I9: 備考 | X9: 日付
H10: /列 | X10: 時間
A11: =MAX($A$10:$A10)+1 -> 1 | B11: 編集区分 | E11: 〇 | F11: 区分 | G11: 1 | H11: =SUBSTITUTE(SUBSTITUTE(ADDRESS(1,A11),"$1",""),"$","") -> A | I11: 「1:新規」 固定 | K11: ※差分連動の前提 | X11: 年月
A12: =MAX($A$10:$A11)+1 -> 2 | B12: 勘定科目コード | E12: 〇 | F12: コード | G12: 8 | H12: =SUBSTITUTE(SUBSTITUTE(ADDRESS(1,A12),"$1",""),"$","") -> B | X12: 区分 | Y12: ★連動元のテーブル情報が決定後に設定値を設計する
A13: =MAX($A$10:$A12)+1 -> 3 | B13: 勘定科目名 | E13: 〇 | F13: 文字列 | G13: 30 | H13: =SUBSTITUTE(SUBSTITUTE(ADDRESS(1,A13),"$1",""),"$","") -> C | Y13: ★連動元のテーブル情報が決定後に設定値を設計する
A14: =MAX($A$10:$A13)+1 -> 4 | B14: 勘定科目名（カナ） | E14: 〇 | F14: 文字列 | G14: 60 | H14: =SUBSTITUTE(SUBSTITUTE(ADDRESS(1,A14),"$1",""),"$","") -> D | Y14: ★連動元のテーブル情報が決定後に設定値を設計する
A15: =MAX($A$10:$A14)+1 -> 5 | B15: 勘定科目名（略） | E15: 〇 | F15: 文字列 | G15: 20 | H15: =SUBSTITUTE(SUBSTITUTE(ADDRESS(1,A15),"$1",""),"$","") -> E | Y15: ★連動元のテーブル情報が決定後に設定値を設計する
A16: =MAX($A$10:$A15)+1 -> 6 | B16: B／S・P／L | E16: 〇 | F16: 文字列 | G16: 1 | H16: =SUBSTITUTE(SUBSTITUTE(ADDRESS(1,A16),"$1",""),"$","") -> F | Y16: ★連動元のテーブル情報が決定後に設定値を設計する
A17: =MAX($A$10:$A16)+1 -> 7 | B17: B／S・P／L名 | F17: 文字列 | G17: 30 | H17: =SUBSTITUTE(SUBSTITUTE(ADDRESS(1,A17),"$1",""),"$","") -> G | I17: 空白（設定不要） ProActiveC4へ取込時は使用しない項目。※ProActiveC4から勘定科目情報を出力する際も同じフォーマットを使用。出力の際に値が設定される。
A18: =MAX($A$10:$A17)+1 -> 8 | B18: 属性 | E18: 〇 | F18: 文字列 | G18: 1 | H18: =SUBSTITUTE(SUBSTITUTE(ADDRESS(1,A18),"$1",""),"$","") -> H | Y18: ★連動元のテーブル情報が決定後に設定値を設計する
A19: =MAX($A$10:$A18)+1 -> 9 | B19: 属性名 | F19: 文字列 | G19: 6 | H19: =SUBSTITUTE(SUBSTITUTE(ADDRESS(1,A19),"$1",""),"$","") -> I | I19: 空白（設定不要） ProActiveC4へ取込時は使用しない項目。※ProActiveC4から勘定科目情報を出力する際も同じフォーマットを使用。出力の際に値が設定される。
A20: =MAX($A$10:$A19)+1 -> 10 | B20: 科目区分 | E20: 〇 | F20: 文字列 | G20: 1 | H20: =SUBSTITUTE(SUBSTITUTE(ADDRESS(1,A20),"$1",""),"$","") -> J | Y20: ★連動元のテーブル情報が決定後に設定値を設計する
A21: =MAX($A$10:$A20)+1 -> 11 | B21: 科目区分名 | F21: 文字列 | G21: 8 | H21: =SUBSTITUTE(SUBSTITUTE(ADDRESS(1,A21),"$1",""),"$","") -> K | I21: 空白（設定不要） ProActiveC4へ取込時は使用しない項目。※ProActiveC4から勘定科目情報を出力する際も同じフォーマットを使用。出力の際に値が設定される。
A22: =MAX($A$10:$A21)+1 -> 12 | B22: 貸借 | E22: 〇 | F22: 文字列 | G22: 1 | H22: =SUBSTITUTE(SUBSTITUTE(ADDRESS(1,A22),"$1",""),"$","") -> L | I22: 1:借方、2:貸方 | Y22: ★連動元のテーブル情報が決定後に設定値を設計する
A23: =MAX($A$10:$A22)+1 -> 13 | B23: 貸借名 | F23: 文字列 | G23: 4 | H23: =SUBSTITUTE(SUBSTITUTE(ADDRESS(1,A23),"$1",""),"$","") -> M | I23: 空白（設定不要） ProActiveC4へ取込時は使用しない項目。※ProActiveC4から勘定科目情報を出力する際も同じフォーマットを使用。出力の際に値が設定される。
A24: =MAX($A$10:$A23)+1 -> 14 | B24: 補助科目別計上フラグ | E24: 〇 | F24: 数値 | G24: 1 | H24: =SUBSTITUTE(SUBSTITUTE(ADDRESS(1,A24),"$1",""),"$","") -> N | I24: 会計摘要を管理する科目の場合は「1:計上する」、それ以外は「0：計上しない」 | Y24: ★連動元のテーブル情報が決定後に設定値を設計する
A25: =MAX($A$10:$A24)+1 -> 15 | B25: 通貨別計上フラグ | E25: 〇 | F25: 数値 | G25: 1 | H25: =SUBSTITUTE(SUBSTITUTE(ADDRESS(1,A25),"$1",""),"$","") -> O | I25: 「0:計上しない」 固定
A26: =MAX($A$10:$A25)+1 -> 16 | B26: 調整計上フラグ | E26: △ | F26: 数値 | G26: 1 | H26: =SUBSTITUTE(SUBSTITUTE(ADDRESS(1,A26),"$1",""),"$","") -> P | I26: 「0:計上しない」 固定
A27: =MAX($A$10:$A26)+1 -> 17 | B27: 評価替対象フラグ | E27: △ | F27: 数値 | G27: 1 | H27: =SUBSTITUTE(SUBSTITUTE(ADDRESS(1,A27),"$1",""),"$","") -> Q | I27: 空白（設定不要） ProActiveC4へ取込時は使用しない項目。※ProActiveC4から勘定科目情報を出力する際も同じフォーマットを使用。出力の際に値が設定される。
A28: =MAX($A$10:$A27)+1 -> 18 | B28: 入力レート区分 | F28: 文字列 | G28: 1 | H28: =SUBSTITUTE(SUBSTITUTE(ADDRESS(1,A28),"$1",""),"$","") -> R | I28: 空白（設定不要） ProActiveC4へ取込時は使用しない項目。※ProActiveC4から勘定科目情報を出力する際も同じフォーマットを使用。出力の際に値が設定される。
A29: =MAX($A$10:$A28)+1 -> 19 | B29: 入力レート区分名 | F29: 文字列 | G29: 3 | H29: =SUBSTITUTE(SUBSTITUTE(ADDRESS(1,A29),"$1",""),"$","") -> S | I29: 空白（設定不要） ProActiveC4へ取込時は使用しない項目。※ProActiveC4から勘定科目情報を出力する際も同じフォーマットを使用。出力の際に値が設定される。
A30: =MAX($A$10:$A29)+1 -> 20 | B30: 評価替レート区分 | F30: 文字列 | G30: 1 | H30: =SUBSTITUTE(SUBSTITUTE(ADDRESS(1,A30),"$1",""),"$","") -> T | I30: 空白（設定不要） ProActiveC4へ取込時は使用しない項目。※ProActiveC4から勘定科目情報を出力する際も同じフォーマットを使用。出力の際に値が設定される。
A31: =MAX($A$10:$A30)+1 -> 21 | B31: 評価替レート区分名 | F31: 文字列 | G31: 3 | H31: =SUBSTITUTE(SUBSTITUTE(ADDRESS(1,A31),"$1",""),"$","") -> U | I31: 空白（設定不要） ProActiveC4へ取込時は使用しない項目。※ProActiveC4から勘定科目情報を出力する際も同じフォーマットを使用。出力の際に値が設定される。
A32: =MAX($A$10:$A31)+1 -> 22 | B32: 消費税区分 | E32: 〇 | F32: コード | G32: 2 | H32: =SUBSTITUTE(SUBSTITUTE(ADDRESS(1,A32),"$1",""),"$","") -> V | I32: ProActiveC4の消費税区分マスタ．消費税区分コードを設定。 | Y32: ★連動元のテーブル情報が決定後に設定値を設計する
A33: =MAX($A$10:$A32)+1 -> 23 | B33: 消費税区分名 | F33: 文字列 | G33: 30 | H33: =SUBSTITUTE(SUBSTITUTE(ADDRESS(1,A33),"$1",""),"$","") -> W | I33: 空白（設定不要） ProActiveC4へ取込時は使用しない項目。※ProActiveC4から勘定科目情報を出力する際も同じフォーマットを使用。出力の際に値が設定される。
A34: =MAX($A$10:$A33)+1 -> 24 | B34: 消費税率 | F34: 数値 | G34: 4,2 | H34: =SUBSTITUTE(SUBSTITUTE(ADDRESS(1,A34),"$1",""),"$","") -> X | I34: 空白（設定不要） ProActiveC4へ取込時は使用しない項目。※ProActiveC4から勘定科目情報を出力する際も同じフォーマットを使用。出力の際に値が設定される。
A35: =MAX($A$10:$A34)+1 -> 25 | B35: 消費税区分使用制限区分 | E35: 〇 | F35: 文字列 | G35: 1 | H35: =SUBSTITUTE(SUBSTITUTE(ADDRESS(1,A35),"$1",""),"$","") -> Y | I35: 「4:制限なし」
A36: =MAX($A$10:$A35)+1 -> 26 | B36: 消費税区分使用制限区分名 | F36: 文字列 | G36: 30 | H36: =SUBSTITUTE(SUBSTITUTE(ADDRESS(1,A36),"$1",""),"$","") -> Z | I36: 空白（設定不要） ProActiveC4へ取込時は使用しない項目。※ProActiveC4から勘定科目情報を出力する際も同じフォーマットを使用。出力の際に値が設定される。
A37: =MAX($A$10:$A36)+1 -> 27 | B37: 消費税計算区分 | E37: 〇 | F37: 文字列 | G37: 1 | H37: =SUBSTITUTE(SUBSTITUTE(ADDRESS(1,A37),"$1",""),"$","") -> AA | I37: 登録する勘定科目の消費税の計算方法に合わせて登録。1:税込入力、2:税抜入力、3:計算しない | Y37: ★連動元のテーブル情報が決定後に設定値を設計する
A38: =MAX($A$10:$A37)+1 -> 28 | B38: 消費税計算区分名 | F38: 文字列 | G38: 10 | H38: =SUBSTITUTE(SUBSTITUTE(ADDRESS(1,A38),"$1",""),"$","") -> AB | I38: 空白（設定不要） ProActiveC4へ取込時は使用しない項目。※ProActiveC4から勘定科目情報を出力する際も同じフォーマットを使用。出力の際に値が設定される。
A39: =MAX($A$10:$A38)+1 -> 29 | B39: 部門別計上区分 | E39: △ | F39: 文字列 | G39: 1 | H39: =SUBSTITUTE(SUBSTITUTE(ADDRESS(1,A39),"$1",""),"$","") -> AC | I39: 「1:全部門計上可」
A40: =MAX($A$10:$A39)+1 -> 30 | B40: 部門別計上区分名 | F40: 文字列 | G40: 10 | H40: =SUBSTITUTE(SUBSTITUTE(ADDRESS(1,A40),"$1",""),"$","") -> AD | I40: 空白（設定不要） ProActiveC4へ取込時は使用しない項目。※ProActiveC4から勘定科目情報を出力する際も同じフォーマットを使用。出力の際に値が設定される。
A41: =MAX($A$10:$A40)+1 -> 31 | B41: 計上部門コード | E41: △ | F41: コード | G41: 10 | H41: =SUBSTITUTE(SUBSTITUTE(ADDRESS(1,A41),"$1",""),"$","") -> AE | I41: 空白（設定不要） ProActiveC4へ取込時は使用しない項目。※ProActiveC4から勘定科目情報を出力する際も同じフォーマットを使用。出力の際に値が設定される。
...

Sheet 取込フォーマット定義（補助科目）bk
A1: ドキュメント名 | E1: サブシステム | G1: 業務機能名 | P1: 作成者 | R1: =表紙!D51 -> SCSK位田 | T1: 更新者
A2: 業務機能概要書 | C2: 取込フォーマット定義 | E2: =業務機能概要!L2 -> 業務共通 | G2: =業務機能概要!Q2 -> 勘定科目・会計摘要マスタ自動取込 | P2: 作成日 | R2: =表紙!C51 -> 45898 | T2: 更新日
A4: データ名 | C4: 補助科目マスタ自動取込 | I4: ヘッダ行 | K4: あり | M4: なし | N4: ダブルクォーテーション | Q4: あり | S4: なし | X4: 文字列
A5: ﾌｧｲﾙ形式・ﾚｺｰﾄﾞ長 | D5: 固定長（ | G5: Byte） | I5: 可変長（区切り文字［ ，(カンマ) ］） | M5: バイナリデータ | P5: その他（ ） | X5: 半英数
A6: 文字コード | D6: UNI（Win系） | F6: EBCDIC(K) | I6: その他（ UTF-8） | M6: 改行コード | O6: LF(UNIX系) | Q6: CRLF(Win系) | T6: なし | X6: 半カナ
A7: 全角(2byte)文字項目 | D7: あり | F7: なし | M7: 数値編集 | O7: 左詰め | Q7: 右詰め［ゼロ埋め］ | T7: 右詰め［スペース埋め］ | X7: コード
A8: 特記事項 | C8: 取込ファイルには、取込項目のタイトル行が必要となる | X8: 数値
A9: No. | B9: 項目名 | E9: 必須 | F9: 型 | G9: 桁数 | H9: 開始位置 | I9: 備考 | X9: 日付
H10: /列 | X10: 時間
A11: =MAX($A$10:$A10)+1 -> 1 | B11: 編集区分 | E11: 〇 | F11: 区分 | G11: 1 | H11: =SUBSTITUTE(SUBSTITUTE(ADDRESS(1,A11),"$1",""),"$","") -> A | I11: 「1:新規」 | K11: ※差分連動の前提 | X11: 年月
A12: =MAX($A$10:$A11)+1 -> 2 | B12: 勘定科目コード | E12: 〇 | F12: コード | G12: 8 | H12: =SUBSTITUTE(SUBSTITUTE(ADDRESS(1,A12),"$1",""),"$","") -> B | I12: ProActiveC4勘定科目マスタに登録した8桁の勘定科目コード | X12: 区分 | Y12: ★連動元のテーブル情報が決定後に設定値を設計する
A13: =MAX($A$10:$A12)+1 -> 3 | B13: 勘定科目名（略） | F13: 文字列 | G13: 20 | H13: =SUBSTITUTE(SUBSTITUTE(ADDRESS(1,A13),"$1",""),"$","") -> C | I13: 設定不要 | X13: フラグ
A14: =MAX($A$10:$A13)+1 -> 4 | B14: 補助科目コード | E14: △ | F14: コード | G14: 4 | H14: =SUBSTITUTE(SUBSTITUTE(ADDRESS(1,A14),"$1",""),"$","") -> D | I14: 科目摘要のコード | X14: - | Y14: ★連動元のテーブル情報が決定後に設定値を設計する
A15: =MAX($A$10:$A14)+1 -> 5 | B15: 補助科目名 | E15: △ | F15: 文字列 | G15: 30 | H15: =SUBSTITUTE(SUBSTITUTE(ADDRESS(1,A15),"$1",""),"$","") -> E | I15: 科目摘要の名称
A16: =MAX($A$10:$A15)+1 -> 6 | B16: 借方資金繰コード | F16: コード | G16: 5 | H16: =SUBSTITUTE(SUBSTITUTE(ADDRESS(1,A16),"$1",""),"$","") -> F | I16: 空白
A17: =MAX($A$10:$A16)+1 -> 7 | B17: 借方資金繰科目名 | F17: 文字列 | G17: 30 | H17: =SUBSTITUTE(SUBSTITUTE(ADDRESS(1,A17),"$1",""),"$","") -> G | I17: 空白
A18: =MAX($A$10:$A17)+1 -> 8 | B18: 貸方資金繰コード | F18: コード | G18: 5 | H18: =SUBSTITUTE(SUBSTITUTE(ADDRESS(1,A18),"$1",""),"$","") -> H | I18: 空白
A19: =MAX($A$10:$A18)+1 -> 9 | B19: 貸方資金繰科目名 | F19: 文字列 | G19: 30 | H19: =SUBSTITUTE(SUBSTITUTE(ADDRESS(1,A19),"$1",""),"$","") -> I | I19: 空白
A20: =MAX($A$10:$A19)+1 -> 10 | B20: 使用不可フラグ | E20: △ | F20: 数値 | G20: 1 | H20: =SUBSTITUTE(SUBSTITUTE(ADDRESS(1,A20),"$1",""),"$","") -> J | I20: 「0:使用可」 ※論理削除対象は「1：使用不可」とする
A21: =MAX($A$10:$A20)+1 -> 11 | B21: 登録者 | F21: コード | G21: 15 | H21: =SUBSTITUTE(SUBSTITUTE(ADDRESS(1,A21),"$1",""),"$","") -> K | I21: 空白（設定不要）
A22: =MAX($A$10:$A21)+1 -> 12 | B22: 登録者名 | F22: 文字列 | G22: 22 | H22: =SUBSTITUTE(SUBSTITUTE(ADDRESS(1,A22),"$1",""),"$","") -> L | I22: 空白（設定不要）
A23: =MAX($A$10:$A22)+1 -> 13 | B23: 登録日時 | F23: 数値 | G23: 17 | H23: =SUBSTITUTE(SUBSTITUTE(ADDRESS(1,A23),"$1",""),"$","") -> M | I23: 空白（設定不要）
A24: =MAX($A$10:$A23)+1 -> 14 | B24: 更新者 | F24: コード | G24: 15 | H24: =SUBSTITUTE(SUBSTITUTE(ADDRESS(1,A24),"$1",""),"$","") -> N | I24: 空白（設定不要）
A25: =MAX($A$10:$A24)+1 -> 15 | B25: 更新者名 | F25: 文字列 | G25: 22 | H25: =SUBSTITUTE(SUBSTITUTE(ADDRESS(1,A25),"$1",""),"$","") -> O | I25: 空白（設定不要）
A26: =MAX($A$10:$A25)+1 -> 16 | B26: 更新日時 | F26: 数値 | G26: 17 | H26: =SUBSTITUTE(SUBSTITUTE(ADDRESS(1,A26),"$1",""),"$","") -> P | I26: 空白（設定不要）
E27: 〇：必須 △：条件付き必須

Sheet ⇒

Sheet データアクセス要領
A1: ドキュメント名 | L1: サブシステム | Q1: 業務機能名 | AJ1: 作成者 | AO1: =表紙!D51 -> SCSK位田 | AT1: 更新者
A2: 業務機能概要書 | G2: データアクセス要領 | L2: =業務機能概要!L2 -> 業務共通 | Q2: =業務機能概要!Q2 -> 勘定科目・会計摘要マスタ自動取込 | AJ2: 作成日付 | AO2: =表紙!C51 -> 45898 | AT2: 更新日付
A4: 【編集要領】
B6: １. | C6: 登録済データの削除
C8: ① | D8: 勘定科目マスタ
D9: ・ | E9: 最新情報を取込む前に登録済データを全件削除する
E10: ただし、款科目より上位の統括科目（例．「流動資産」など）は連動対象外のため削除しない
D12: ■削除エンティティ
D13: № | E13: エンティティ名
D14: 1 | E14: 勘定科目
D15: 2 | E15: 勘定科目属性
D16: 3 | E16: Ｃ／Ｆ勘定科目設定
C18: ■削除条件
C19: № | D19: 取得条件 | AW19: 備考
C20: １ | F20: 勘定科目．会社コード | V20: ＝ | X20: 引数の会社コード
C21: ２ | F21: 勘定科目．勘定科目コード | V21: not like | Y21: 9%’
B24: ② | C24: 補助科目マスタ
C25: ・ | D25: 最新情報を取込む前に登録済データを全件削除する
C28: ■削除エンティティ
C29: № | D29: エンティティ名
C30: 1 | D30: 補助科目
C32: ■削除条件
C33: № | D33: 取得条件 | AW33: 備考
C34: １ | F34: 補助科目．会社コード | V34: ＝ | X34: 引数の会社コード
C35: ２
A39: ２. | B39: データの登録
C41: 標準の「勘定科目・補助科目取込」機能の実行時と同様。

Sheet 補足１
A1: ドキュメント名 | L1: サブシステム | Q1: 業務機能名 | AM1: 作成者 | AR1: =表紙!D51 -> SCSK位田 | AW1: 更新者
A2: 業務機能概要書 | G2: 補足説明 | L2: =業務機能概要!L2 -> 業務共通 | Q2: =業務機能概要!Q2 -> 勘定科目・会計摘要マスタ自動取込 | AM2: 作成日付 | AR2: =表紙!C51 -> 45898 | AW2: 更新日付
C4: スクラッチ機能からProActiveへ連動する勘定科目（一般科目／統括科目）のデータ
C6: 1 | D6: 連動仕様
E8: スクラッチ．勘定科目マスタ（6桁コードで管理）の情報は、統括科目として6桁コードで連動する。
E9: スクラッチ．目節科目マスタの情報は、一般科目として8桁コードで連動する。
C13: 2 | D13: 懸念
E15: 目節管理しない科目の場合、目節コードが00であるが、
E16: 目節管理する科目の場合も、目節コードが00のものがある。
E17: 両者が混在することで、ただしくデータ連動できるのか？
C20: 3 | D20: 整理
E22: 以下の3パターンがとりえるパターンのため、各パターンについて一般科目、統括科目の連動データを整理する。
E24: ケース１：目節管理なしの科目 | W24: → | X24: 目節マスタに8桁コード（6桁コード＋00）で管理される
E25: ケース２：目節管理ありでかつ目節コードが00の科目 | W25: → | X25: 目節マスタに8桁コードで管理される
E26: ケース３：目節管理ありでかつ目節コードが00以外の科目 | W26: → | X26: 目節マスタに8桁コードで管理される
E27: ケース４：6桁コードの下2桁が00のコード | W27: → | X27: 勘定科目マスタに6桁コードで管理される
E30: ケース１の具体列
E31: 11010100 現金 | O31: → | Q31: 一般科目として11010100（8桁）を連動、 | AH31: ※現行では、勘定科目コードは「1101010000」
Q32: 統括科目として110101（6桁）を連動
E34: ケース２の具体列
E35: 11020100 当座預金 | O35: → | Q35: 一般科目として11020100（8桁）を連動、 | AH35: ※現行では、勘定科目コードは「1102019800」
Q36: 統括科目として110201（6桁）を連動
E38: ケース３の具体列
E39: 11060101 販売共計支払金品代 | O39: → | Q39: 一般科目として11060101（8桁）を連動、 | AH39: ※現行では、勘定科目コードは「1106010100」
Q40: 統括科目として110601（6桁）を連動
E42: ケース４の具体例
E43: 110100 現金 | O43: → | Q43: 統括科目として110100（6桁）を連動

Sheet 補足２
A1: ドキュメント名 | L1: サブシステム | Q1: 業務機能名 | AM1: 作成者 | AR1: =表紙!D51 -> SCSK位田 | AW1: 更新者
A2: 業務機能概要書 | G2: 補足説明 | L2: =業務機能概要!L2 -> 業務共通 | Q2: =業務機能概要!Q2 -> 勘定科目・会計摘要マスタ自動取込 | AM2: 作成日付 | AR2: =表紙!C51 -> 45898 | AW2: 更新日付
B4: 当機能でのバッチファイル、xmlファイル、SQL実行の作成イメージ
C7: バッチファイル１ | P7: c4_import_kamoku.bat
D9: ①勘定科目取込 | AG9: SQL実行ファイル①（.sql）
E11: 取込ファイル探索 | J11: ※取込ファイルが0byteであった場合は正常として処理終了する | AH11: 勘定科目マスタを全件削除する | AR11: ※款科目より上位の統括科目は削除しない
E12: SQLの実行（既存データのバックアップ、削除）
E14: 取込実行バッチファイルの呼び出し | AG14: SQL実行ファイル②（.sql）
E16: 正常時 | AH16: 補助科目マスタを全件削除する
F17: 取込ファイルの退避（正常終了のファイル退避フォルダへ移動）
E18: エラー時
F19: 取込ファイルの退避（異常終了のファイル退避フォルダへ移動）
AG20: 入力データファイル（xml）
D21: ②補助科目取込
AH22: 会社コード
E23: 勘定科目取込と同様 | AH23: 取込区分 | AL23: を定義する
AH25: ※「cvo_sav_cd」は設定なしとして、取込ファイルはバッチファイルで定義する
C28: バッチファイル２ | I28: ※パタメータ定義用 | P28: param.bat
D30: 取込ファイルのフォルダパス、 | AG30: BRファイル（xml）
D31: SQLファイルのパスなどを定義する
AH32: バッチ処理の中で利用するビジネスリソースと、
AH33: J-SOXログ出力で利用するクライアント環境情報を定義
C37: バッチファイル３ | P37: Exec_kamokuImpBatch.bat
D39: 入力データファイル 読み込み
D41: BRファイル 読み込み
D43: バッチ実行
D44: 戻り値返却
C51: ディレクトリ構成
D54: ー | E54: ー | G54: c4_import_kamoku.bat | AD54: ・・・ | AF54: タスクスケジューラから起動されるbat
E55: ｜ | G55: param.bat | AD55: ・・・ | AF55: bat実行時に参照されるパラメータセットbat
E56: ｜
E57: ー | G57: CSV_DIR | AD57: ・・・ | AF57: 取込用のCSVファイルを配置するフォルダ
E58: ｜
E59: ー | G59: BATCH_SUB_DIR | Q59: ー | R59: c4_data_update_export.bat | AD59: ・・・ | AF59: SQLを実行するためのbat
E60: ｜ | R60: Exec_kamokuImpBatch.bat | AD60: ・・・ | AF60: 勘定科目取込を実行するためのbat
E61: ｜
E62: ー | G62: SQL_DIR | Q62: ー | R62: bk_zcmmhkanjoukamoku.sql | AD62: ・・・ | AF62: 勘定科目マスタ、属性の情報をバックアップテーブルにコピーしておく | AX62: ZCMMHKANJOUKAMOKU
E63: ｜ | R63: del_zcmmhkanjoukamoku.sql | AD63: ・・・ | AF63: 勘定科目マスタ、属性の情報を削除する | AX63: AGLMNKNKMKZOKUSEI
E64: ｜ | AX64: AGLMNCFKNKMKSET
E65: ｜
...
