Workbook
Name 【債権】最新データ辞書: #REF!
Name 項目辞書: #REF!
Name 項目辞書: #REF!

Sheet 表紙
F46: ProActive
B48: 変更履歴
B50: 項番 | C50: 変更発生日 | D50: 変更者 | E50: 変更箇所 | F50: 変更内容
B51: 1 | C51: 45898 | D51: SCSK大西 | F51: 新規作成
B52: 2
B53: 3
B54: 4
B55: 5
B56: 6
B57: 7
B58: 8
B59: 9
B60: 10
B61: 11
B62: 12
B63: 13
... B80: 30

Sheet 業務機能概要
A1: ドキュメント名 | L1: サブシステム | Q1: 業務機能名 | AJ1: 作成者 | AO1: =表紙!D51 -> SCSK大西 | AT1: 更新者
A2: 業務機能概要書 | G2: 業務機能概要 | L2: 財務会計 | Q2: 仕訳データ自動取込 | AJ2: 作成日付 | AO2: =表紙!C51 -> 45898 | AT2: 更新日付
B4: 【目的・役割】
C5: ・ | D5: ホクレン様の伝票入力は部門システムやスクラッチ開発機能で実施するため、ProActiveC4では、仕訳データを外部のシステムから取込する必要がある。
D6: 仕訳データの取込はバッチ処理で実行して、夜間処理後の翌営業日、または即時にProActiveC4で参照、更新するような状態となることが必要である。
B9: 【利用者】
C10: ・ | D10: バッチ実行
B13: 【利用頻度】
C14: ・ | D14: 随時
B17: 【対象要件定義書】
C18: ・ | D18: 要件定義書(他システムとのデータ連動)
B21: 【処理概要】
C22: １) | D22: ファイルによってデータ連動される仕訳データをProActiveC4標準の「仕訳外部データ取込」の処理を使用してProActiveC4に取込する。
D23: ※ | E23: ホクレン様の業務では1日あたりの仕訳データは最大で約200万件である。
E24: 取込処理のパフォーマンス向上のため、約8万件×25ファイル（＝200万件）に分割して連動された仕訳データファイルを並列で取込する。
D49: 当機能の責任範囲は以下となる。
D50: ※ | E50: スクラッチ開発機能から作成、連動される連動データ（CSVファイル）は、当機能の実行前に、ProActiveC4サーバ上から参照可能な取込ディレクトリに配置される想定とする。
D51: ※ | E51: 「仕訳外部データ取込バッチ」はProActiveC4外のタスク管理用ミドルウェア（以下、タスクスケジューラ）から実行する想定とする。
D52: ※ | E52: 「仕訳外部データ取込バッチ」は連動データ（CSVファイル）ごとに起動される想定とする。（処理結果も連動データごとにタスクスケジューラへ返却する）
AM55: ※ | AN55: 取込ディレクトリはProActiveC4の
AN56: バッチサーバ上から参照可能なディレクトリ
L60: 起動
AB62: ファイル参照
L63: 結果返却
Q69: 退避 | AK69: 登録
N83: ※削除処理は、当機能とは別にファイル削除処理を作成して、その処理で実施する
C94: ２) | D94: バッチ実行される「仕訳外部データ取込」について、以下の処理を実施する。
E96: ・ | F96: 取込ディレクトリに配置されている連動データ（取込用のCSVファイル）の情報を取得する。
F97: 取込データが取得できた場合は、取込ファイルをINPUTとして、「仕訳外部データ取込」をバッチ実行する。（オンライン機能「仕訳外部データ取込」の取込動作を踏襲する。）
F98: ※ | G98: 標準の「仕訳外部データ取込」はオンライン処理可能なままとする。
E100: ・ | F100: 「仕訳外部データ取込」のバッチ処理実行結果をバッチジョブ情報に登録する。（標準仕様に準じる）
E102: ・ | F102: 取込処理後、取込用のCSVファイルは処理済用ファイルのディレクトリに移動する。
F103: ※ | G103: アプリケーションではなく、バッチファイルで処理済ファイルを移動する。
F104: ※ | G104: 正常用、エラー用のディレクトリを作成して処理結果によって移動先ディレクトリを分岐させる。
E106: ・ | F106: バッチ処理実行結果の終了情報をタスクスケジューラに返却する。
F108: [実行情報]
F109: No | H109: パラメータ | Q109: 内容
F110: 1 | H110: ※イベント概要参照
F112: [終了情報]
F113: 戻り値 | H113: 内容 | Q113: 内容
...

Sheet 画面遷移図
A1: ドキュメント名 | L1: サブシステム | Q1: 業務機能名 | AJ1: 作成者 | AO1: =表紙!D51 -> SCSK大西 | AT1: 更新者 | AY1: SCSK相坂
A2: 業務機能概要書 | G2: 画面遷移図 | L2: =#REF! -> #REF! | Q2: =#REF! -> #REF! | AJ2: 作成日付 | AO2: =表紙!C51 -> 45898 | AT2: 更新日付 | AY2: 44103
B4: 【メニュー起動時の画面遷移】

Sheet 画面レイアウト
A1: ドキュメント名 | AH1: サブシステム | AX1: 業務機能名 | DF1: 作成者 | DV1: =表紙!D51 -> SCSK大西 | EL1: 更新者
A2: 業務機能概要書 | R2: 画面レイアウト | AH2: =#REF! -> #REF! | AX2: =#REF! -> #REF! | DF2: 作成日付 | DV2: =表紙!C51 -> 45898 | EL2: 更新日付
A3: 画面名 | FD3: 画面№ | FM3: ①
B4: 0 | H4: 40 | R4: 110 | AB4: 180 | AL4: 250 | AV4: 320 | BF4: 390 | BP4: 460 | BZ4: 530 | CJ4: 600 | CT4: 670 | DD4: 740 | DN4: 810 | DX4: 880 | EH4: 950 | EO4: 999 | ER4: ＜補足説明＞
A5: 0
A6: 5
A7: 20
A8: 35
A9: 50
A10: 65
A11: 80
A12: 95
A13: 110
A14: 125
A15: 140
A16: 155
... A47: 620
A57: 画面名 | J57: 自動消込確定情報登録画面 | FD57: 画面№ | FM57: ②
B58: 0 | H58: 40 | R58: 110 | AB58: 180 | AL58: 250 | AV58: 320 | BF58: 390 | BP58: 460 | BZ58: 530 | CJ58: 600 | CT58: 670 | DD58: 740 | DN58: 810 | DX58: 880 | EH58: 950 | EO58: 999 | ER58: ＜補足説明＞
A59: 0
A60: 5
A61: 20
A62: 35
A63: 50
A64: 65
A65: 80
A66: 95
A67: 110
A68: 125
A69: 140
A70: 155
... A101: 620
A111: 画面名 | FD111: 画面№ | FM111: ①
B112: 0 | H112: 40 | R112: 110 | AB112: 180 | AL112: 250 | AV112: 320 | BF112: 390 | BP112: 460 | BZ112: 530 | CJ112: 600 | CT112: 670 | DD112: 740 | DN112: 810 | DX112: 880 | EH112: 950 | EO112: 999 | ER112: ＜補足説明＞
A113: 0
A114: 5
A115: 20
A116: 35
A117: 50
A118: 65
...

Sheet 項目概要
A1: ドキュメント名 | L1: サブシステム | Q1: 業務機能名 | AJ1: 作成者 | AO1: =表紙!D51 -> SCSK大西 | AT1: 更新者 | BE1: ○ | BF1: IN | BG1: 文字列
A2: 業務機能概要書 | G2: 項目概要 | L2: =#REF! -> #REF! | Q2: =#REF! -> #REF! | AJ2: 作成日付 | AO2: =表紙!C51 -> 45898 | AT2: 更新日付 | BE2: － | BF2: OUT | BG2: 数値
BF3: IN/OUT | BG3: 半英数
A4: 【画面項目説明】 | BG4: 半カナ
BG5: コード
B6: [①自動消込確定情報登録画面] | AQ6: ※追加及び変更項目のみ記載 | BG6: 日付
B7: № | C7: ラベル | J7: 項目名 | Q7: I/O | S7: 必須 | U7: 型 | W7: 桁数 | Y7: ソート | AA7: 初期表示 | AE7: 備考 | BG7: －
B8: 【ヘッダ部】
B9: 1 | C9: 一覧を最大化 | J9: 一覧を最大化ボタン | Q9: IN | S9: － | U9: － | W9: － | Y9: ー | AA9: ー
B10: 2 | Q10: IN | S10: ○ | U10: 日付 | W10: 8 | Y10: ー | AA10: システム日付
B11: 3 | Q11: OUT | S11: － | U11: コード | W11: 12 | Y11: ー | AA11: ー
B12: 4 | Q12: IN | S12: ○ | U12: コード | W12: 10 | Y12: ー | AA12: ー
Q13: IN | S13: － | U13: － | W13: ー | Y13: ー | AA13: ー
Q14: OUT | S14: － | U14: 文字列 | W14: 20 | Y14: ー | AA14: ー
B15: 5 | Q15: IN | S15: ○ | U15: コード | W15: 15 | Y15: ー | AA15: ー
Q16: IN | S16: － | U16: － | W16: ー | Y16: ー | AA16: ー
Q17: OUT | S17: － | U17: 文字列 | W17: 20 | Y17: ー | AA17: ー
B18: 6 | Q18: IN | S18: ○ | U18: － | W18: ー | Y18: ー
B20: 7 | Q20: IN | S20: ○ | U20: 数値 | W20: 13 | Y20: ー | AA20: ー
B21: 【】
B22: 1
B25: 2
B28: 3
B30: 4
B31: 5
B32: 【】 | AE32: ※ソート順は画面レイアウトシートの補足説明欄参照。
B33: 1
B34: 2
B35: 2
B36: 3
B37: 2
B38: 3
B39: 4
B40: 5
B41: 6
B42: 7
B43: 8
B44: 9
... B52: 16
B53: 【フッタ部】
...

Sheet イベント概要
A1: ドキュメント名 | L1: サブシステム | Q1: 業務機能名 | AJ1: 作成者 | AO1: =表紙!D51 -> SCSK大西 | AT1: 更新者
A2: 業務機能概要書 | G2: イベント概要 | L2: =業務機能概要!L2 -> 財務会計 | Q2: =業務機能概要!Q2 -> 仕訳データ自動取込 | AJ2: 作成日付 | AO2: =表紙!C51 -> 45898 | AT2: 更新日付
A4: 【イベント処理】
B6: № | C6: イベント名 | J6: 処理説明
B7: =IF(C7="","",MAX(B$6:B6)+1) -> 1 | C7: 仕訳データ自動取込 | J7: １. | L7: 取込ディレクトリに配置された取込用のCSVファイルをINPUTとし、ProActiveC4標準機能の「仕訳外部データ取込」を実行する。
C8: バッチイベント | L8: ＜パラメータ＞
L9: ・ | M9: 会社コード | U9: ： | V9: バッチ実行用のxmlで指定された会社コード
L10: ・ | M10: 取込CSVファイル | U10: ： | V10: バッチ実行用のxmlで指定されたファイル
L12: 取込用のCSVファイルが取得できなかった場合は、取込処理は実行されない。
B13: =IF(C13="","",MAX(B$6:B6)+1) | L13: 取込用のCSVファイルが取得できた場合は、後続の処理を継続する。
B14: =IF(C14="","",MAX(B$6:B13)+1) | L14: ※ | M14: 上記のファイル取得、エラーハンドリングはバッチファイルで実施する（アプリケーションでの考慮は不要）
B15: =IF(C15="","",MAX(B$6:B14)+1) | L15: ※ | M15: 取込用CSVのファイルサイズが0byteの場合は、正常として処理終了する。（バッチファイルにてファイルを正常処理フォルダへ移動する）
B16: =IF(C16="","",MAX(B$6:B15)+1)
B17: =IF(C17="","",MAX(B$6:B16)+1) | J17: ２. | L17: 「仕訳外部データ取込」のバッチ処理実行結果をバッチジョブ情報に登録する。（標準仕様に準じる）
B18: =IF(C18="","",MAX(B$6:B13)+1)
B19: =IF(C19="","",MAX(B$6:B8)+1) | J19: ３. | L19: 取込処理後、取込用のCSVファイルは処理済用ファイルのディレクトリに移動する。
B20: =IF(C20="","",MAX(B$6:B19)+1) | L20: ※ | M20: 正常用、エラー用のディレクトリを作成して、処理結果によって移動先ディレクトリを分岐させる。
B21: =IF(C21="","",MAX(B$6:B20)+1)
B22: =IF(C22="","",MAX(B$6:B21)+1) | J22: ４. | L22: バッチ処理実行結果の終了情報をタスクスケジューラに返却する。
B23: =IF(C23="","",MAX(B$6:B22)+1) | L23: ■ | M23: 正常終了できた場合
N24: 「0:正常終了」
L25: ■ | M25: エラーが発生した場合（※ProActiveC4標準機能のデータ取込でエラーが発生した場合は当ケースに該当する）
N26: 「1:異常終了」
B27: =IF(C27="","",MAX(B$6:B26)+1)
B28: =IF(C28="","",MAX(B$6:B27)+1)
B30: =IF(C30="","",MAX(B$6:B29)+1)
B31: =IF(C31="","",MAX(B$6:B30)+1)
B32: =IF(C32="","",MAX(B$6:B31)+1)
B33: =IF(C33="","",MAX(B$6:B32)+1)
B40: =IF(C40="","",MAX(B$6:B39)+1)
B41: =IF(C41="","",MAX(B$6:B40)+1)
B42: =IF(C42="","",MAX(B$6:B41)+1)
B43: =IF(C43="","",MAX(B$6:B42)+1)
B44: =IF(C44="","",MAX(B$6:B43)+1)
B45: =IF(C45="","",MAX(B$6:B44)+1)

Sheet チェック仕様
A1: ドキュメント名 | L1: サブシステム | Q1: 業務機能名 | AJ1: 作成者 | AO1: =表紙!D51 -> SCSK大西 | AT1: 更新者
A2: 業務機能概要書 | G2: チェック仕様 | L2: =#REF! -> #REF! | Q2: =#REF! -> #REF! | AJ2: 作成日付 | AO2: =表紙!C51 -> 45898 | AT2: 更新日付
A4: 【チェック処理】
B6: １．初期処理時
B7: № | C7: 項目名 | L7: 条件必須 | O7: 存在 | R7: 範囲 | U7: 関連 | X7: その他 | AA7: 内容
B8: =IF(C8="","",MAX(B7:B$7)+1) -> 1 | C8: － | X8: ○
B9: =IF(C9="","",MAX(B$7:B8)+1)
B10: =IF(C10="","",MAX(B$7:B9)+1)
B11: =IF(C11="","",MAX(B$7:B10)+1)
B13: ２．検索ボタン押下時
B14: № | C14: 項目名 | L14: 条件必須 | O14: 存在 | R14: 範囲 | U14: 関連 | X14: その他 | AA14: 内容
B15: =IF(C15="","",MAX(B$14:B14)+1)
B16: =IF(C16="","",MAX(B$14:B15)+1)
B17: =IF(C17="","",MAX(B$14:B16)+1)
B18: =IF(C18="","",MAX(B$14:B17)+1)
B19: =IF(C19="","",MAX(B$14:B18)+1)
B20: =IF(C20="","",MAX(B$14:B19)+1)
B21: =IF(C21="","",MAX(B$14:B20)+1)
B22: =IF(C22="","",MAX(B$14:B21)+1)
B23: =IF(C23="","",MAX(B$14:B22)+1)
B24: =IF(C24="","",MAX(B$14:B23)+1)
B25: =IF(C25="","",MAX(B$14:B24)+1)
B26: =IF(C26="","",MAX(B$14:B25)+1)
... B31: =IF(C31="","",MAX(B$14:B30)+1)
B33: ３．データ取込ボタン
B34: № | C34: 項目名 | L34: 条件必須 | O34: 存在 | R34: 範囲 | U34: 関連 | X34: その他 | AA34: 内容
B35: =IF(C35="","",MAX(B$34:B34)+1)
B36: =IF(C36="","",MAX(B$34:B35)+1)
B37: =IF(C37="","",MAX(B$34:B36)+1)
B38: =IF(C38="","",MAX(B$34:B37)+1)
B39: =IF(C39="","",MAX(B$34:B38)+1)
B40: =IF(C40="","",MAX(B$34:B39)+1)
B41: =IF(C41="","",MAX(B$34:B40)+1)
B42: =IF(C42="","",MAX(B$34:B41)+1)
B43: =IF(C43="","",MAX(B$34:B42)+1)
B44: =IF(C44="","",MAX(B$34:B40)+1)
B45: =IF(C45="","",MAX(B$34:B44)+1)
B46: =IF(C46="","",MAX(B$34:B45)+1)
B47: 4
B48: =IF(C48="","",MAX(B$34:B47)+1)
...

Sheet 出力CSV定義
A1: ドキュメント名 | E1: サブシステム | G1: 業務機能名 | P1: 作成者 | R1: =表紙!D51 -> SCSK大西 | T1: 更新者
A2: 業務機能概要書 | C2: 出力CSV定義 | E2: =#REF! -> #REF! | G2: =#REF! -> #REF! | P2: 作成日 | R2: =表紙!C51 -> 45898 | T2: 更新日
A4: データ名 | I4: ヘッダ行 | K4: あり | M4: なし | N4: ダブルクォーテーション | Q4: あり | S4: なし | X4: 文字列
A5: ﾌｧｲﾙ形式・ﾚｺｰﾄﾞ長 | D5: 固定長（ | G5: Byte） | I5: 可変長（区切り文字［ ，(カンマ) ］） | M5: バイナリデータ | P5: その他（ ） | X5: 半英数
A6: 文字コード | D6: UNI（Win系） | F6: EBCDIC(K) | I6: その他（UTF-8） | M6: 改行コード | O6: LF(UNIX系) | Q6: CRLF(Win系) | T6: なし | X6: 半カナ
A7: 全角(2byte)文字項目 | D7: あり | F7: なし | M7: 数値編集 | O7: 左詰め | Q7: 右詰め［ゼロ埋め］ | T7: 右詰め［スペース埋め］ | X7: コード
A8: 特記事項 | C8: 出力順：起票日付、仕訳伝票番号、仕訳自動作成フラグ、仕訳伝票行番号 | J8: ※「"」が含まれる項目は「""」に変換する。 | X8: 数値
A9: No. | B9: 項目名 | E9: 必須 | F9: 型 | G9: 桁数 | H9: 開始位置 | I9: 備考 | X9: 日付
H10: /列 | X10: 時間
A11: 1 | F11: 日付 | G11: 8 | H11: A | X11: 年月
A12: 2 | F12: 半英数 | G12: 12 | H12: B | X12: 区分
A13: 3 | F13: コード | G13: 10 | H13: C | X13: フラグ
A14: 4 | F14: 文字列 | G14: 40 | H14: D | X14: -
A15: 5
A16: 6
A17: 7
A18: 8
A19: 9
A20: 10
A21: 11
A22: 12
A23: 13
A24: 14
A25: 15

Sheet 出力CSVサンプル

Sheet 取込フォーマット定義
A1: ドキュメント名 | E1: サブシステム | G1: 業務機能名 | P1: 作成者 | R1: SCSK大西 | T1: 更新者
A2: 業務機能概要書 | C2: 取込フォーマット定義 | E2: 財務会計 | G2: 仕訳データ自動取込 | P2: 作成日 | R2: =表紙!C51 -> 45898 | T2: 更新日
A4: データ名 | C4: 仕訳データ | I4: ヘッダ行 | K4: あり | M4: なし | N4: ダブルクォーテーション | Q4: あり | S4: なし | X4: 文字列
A5: ﾌｧｲﾙ形式・ﾚｺｰﾄﾞ長 | D5: 固定長（ | G5: Byte） | I5: 可変長（区切り文字［ ，(カンマ) ］） | M5: バイナリデータ | P5: その他（ ） | X5: 半英数
A6: 文字コード | D6: UNI（Win系） | F6: EBCDIC(K) | I6: その他（ UTF-8） | M6: 改行コード | O6: LF(UNIX系) | Q6: CRLF(Win系) | T6: なし | X6: 半カナ
A7: 全角(2byte)文字項目 | D7: あり | F7: なし | M7: 数値編集 | O7: 左詰め | Q7: 右詰め［ゼロ埋め］ | T7: 右詰め［スペース埋め］ | X7: コード
A8: 特記事項 | X8: 数値
A9: No. | B9: 項目名 | E9: 必須 | F9: 型 | G9: 桁数 | H9: 開始位置 | I9: 項目説明 | Q9: 設定値 | X9: 日付
H10: /列 | X10: 時間
A11: =MAX($A$10:$A10)+1 -> 1 | B11: 元帳領域コード | F11: コード | G11: 2 | H11: =SUBSTITUTE(SUBSTITUTE(ADDRESS(1,A11),"$1",""),"$","") -> A | I11: 仕訳の種類を判別するためのコード | Q11: 仕訳ヘッダ.仕訳種類コード | X11: 年月
I12: （01.一般仕訳、02.月次修正仕訳、03.管理会計仕訳、04.売上高・売上原価仕訳、05.組替仕訳）
A13: =MAX($A$10:$A11)+1 -> 2 | B13: 仕訳伝票番号 | E13: △ | F13: 文字列 | G13: 12 | H13: =SUBSTITUTE(SUBSTITUTE(ADDRESS(1,A13),"$1",""),"$","") -> B | I13: 仕訳伝票番号。ProActiveC4上一意の番号とする必要がある。 | Q13: 仕訳ヘッダ.仕訳番号 | X13: 区分
A14: =MAX($A$10:$A13)+1 -> 3 | B14: 仕訳伝票起票日付 | E14: 〇 | F14: 日付 | G14: 8 | H14: =SUBSTITUTE(SUBSTITUTE(ADDRESS(1,A14),"$1",""),"$","") -> C | I14: 経理日 | Q14: 仕訳ヘッダ.経理日
A15: =MAX($A$10:$A14)+1 -> 4 | B15: 起票部門表示コード | E15: 〇 | F15: コード | G15: 10 | H15: =SUBSTITUTE(SUBSTITUTE(ADDRESS(1,A15),"$1",""),"$","") -> D | I15: 伝票起票した部署のコード | Q15: 事業所コード＋ 所属に紐づく業種コードの一番若いコード ＋ 所属コード
A16: =MAX($A$10:$A15)+1 -> 5 | B16: 仕訳円貨区分 | E16: 〇 | F16: 区分 | G16: 1 | H16: =SUBSTITUTE(SUBSTITUTE(ADDRESS(1,A16),"$1",""),"$","") -> E | I16: 外貨建ての伝票か円貨の伝票かの区分（1.円貨、2.外貨） | Q16: 1（円貨）
A17: =MAX($A$10:$A16)+1 -> 6 | B17: 起票者コード | E17: 〇 | F17: コード | G17: 15 | H17: =SUBSTITUTE(SUBSTITUTE(ADDRESS(1,A17),"$1",""),"$","") -> F | I17: 仕訳伝票を起票したユーザーID | Q17: 999999999999999（ダミー）
A18: =MAX($A$10:$A17)+1 -> 7 | B18: 決算仕訳フラグ | E18: 〇 | F18: フラグ | G18: 1 | H18: =SUBSTITUTE(SUBSTITUTE(ADDRESS(1,A18),"$1",""),"$","") -> G | I18: 決算仕訳か否かのフラグ（0.通常仕訳、1.決算仕訳） | Q18: 0（通常仕訳）
A19: =MAX($A$10:$A18)+1 -> 8 | B19: 仕訳伝票摘要 | F19: 文字列 | G19: 80 | H19: =SUBSTITUTE(SUBSTITUTE(ADDRESS(1,A19),"$1",""),"$","") -> H | Q19: 仕訳ヘッダ.仕訳摘要
A20: =MAX($A$10:$A19)+1 -> 9 | B20: 洗替実施区分 | F20: 区分 | G20: 1 | H20: =SUBSTITUTE(SUBSTITUTE(ADDRESS(1,A20),"$1",""),"$","") -> I | I20: 9.不要 | Q20: 9（不要）
A21: =MAX($A$10:$A20)+1 -> 10 | B21: 洗替伝票起票日付 | E21: △ | F21: 日付 | G21: 8 | H21: =SUBSTITUTE(SUBSTITUTE(ADDRESS(1,A21),"$1",""),"$","") -> J | I21: 空白（設定不要） | Q21: 設定なし
A22: =MAX($A$10:$A21)+1 -> 11 | B22: 仕訳伝票行番号 | E22: 〇 | F22: 数値 | G22: 4 | H22: =SUBSTITUTE(SUBSTITUTE(ADDRESS(1,A22),"$1",""),"$","") -> K | I22: 仕訳伝票明細の行番号 | Q22: 連動時に仕訳伝票単位で採番
A23: =MAX($A$10:$A22)+1 -> 12 | B23: 仕訳伝票明細摘要 | F23: 文字列 | G23: 80 | H23: =SUBSTITUTE(SUBSTITUTE(ADDRESS(1,A23),"$1",""),"$","") -> L | Q23: 仕訳ヘッダ.仕訳摘要
A24: =MAX($A$10:$A23)+1 -> 13 | B24: 勘定科目コード（借方） | F24: コード | G24: 8 | H24: =SUBSTITUTE(SUBSTITUTE(ADDRESS(1,A24),"$1",""),"$","") -> M | Q24: 仕訳明細.勘定科目コード＋目節科目コード
A25: =MAX($A$10:$A24)+1 -> 14 | B25: 補助科目コード（借方） | E25: △ | F25: コード | G25: 4 | H25: =SUBSTITUTE(SUBSTITUTE(ADDRESS(1,A25),"$1",""),"$","") -> N | I25: 科目摘要を判別するコード | Q25: 仕訳明細.科目摘要コード
A26: =MAX($A$10:$A25)+1 -> 15 | B26: 計上部門表示コード（借方） | F26: コード | G26: 10 | H26: =SUBSTITUTE(SUBSTITUTE(ADDRESS(1,A26),"$1",""),"$","") -> O | I26: 借方科目残を計上する部署のコード | Q26: 仕訳明細.業種+予算組織コード
A27: =MAX($A$10:$A26)+1 -> 16 | B27: 取引先コード（借方） | E27: △ | F27: コード | G27: 15 | H27: =SUBSTITUTE(SUBSTITUTE(ADDRESS(1,A27),"$1",""),"$","") -> P | I27: ※借方科目を取引先計上する場合、必須 | Q27: 仕訳明細.取引先コード
A28: =MAX($A$10:$A27)+1 -> 17 | B28: 自社口座コード（借方） | E28: △ | F28: コード | G28: 8 | H28: =SUBSTITUTE(SUBSTITUTE(ADDRESS(1,A28),"$1",""),"$","") -> Q | I28: 出金を行う銀行口座のコード ※借方科目を口座別計上する場合、必須 | Q28: 仕訳明細.自社口座コード
A29: =MAX($A$10:$A28)+1 -> 18 | B29: プロジェクトコード（借方） | E29: △ | F29: コード | G29: 20 | H29: =SUBSTITUTE(SUBSTITUTE(ADDRESS(1,A29),"$1",""),"$","") -> R | I29: 業種を判別するコード ※借方科目を業種別計上する場合、必須 | Q29: 仕訳明細.業種コード
A30: =MAX($A$10:$A29)+1 -> 19 | B30: 担当者コード（借方） | E30: △ | F30: コード | G30: 15 | H30: =SUBSTITUTE(SUBSTITUTE(ADDRESS(1,A30),"$1",""),"$","") -> S | I30: 空白（設定不要） | Q30: 設定なし
A31: =MAX($A$10:$A30)+1 -> 20 | B31: セグメントコード（借方） | E31: △ | F31: コード | G31: 4 | H31: =SUBSTITUTE(SUBSTITUTE(ADDRESS(1,A31),"$1",""),"$","") -> T | I31: 会計品目を判別するコード ※借方科目を会計品目別計上する場合、必須 | Q31: 仕訳明細.会計情報品目コード
A32: =MAX($A$10:$A31)+1 -> 21 | B32: セグメントコード１（借方） | E32: △ | F32: コード | G32: 4 | H32: =SUBSTITUTE(SUBSTITUTE(ADDRESS(1,A32),"$1",""),"$","") -> U | I32: 空白（設定不要） | Q32: 設定なし
A33: =MAX($A$10:$A32)+1 -> 22 | B33: セグメントコード２（借方） | E33: △ | F33: コード | G33: 4 | H33: =SUBSTITUTE(SUBSTITUTE(ADDRESS(1,A33),"$1",""),"$","") -> V | I33: 空白（設定不要） | Q33: 設定なし
A34: =MAX($A$10:$A33)+1 -> 23 | B34: セグメントコード３（借方） | E34: △ | F34: コード | G34: 4 | H34: =SUBSTITUTE(SUBSTITUTE(ADDRESS(1,A34),"$1",""),"$","") -> W | I34: 空白（設定不要） | Q34: 設定なし
A35: =MAX($A$10:$A34)+1 -> 24 | B35: セグメントコード４（借方） | E35: △ | F35: コード | G35: 4 | H35: =SUBSTITUTE(SUBSTITUTE(ADDRESS(1,A35),"$1",""),"$","") -> X | I35: 空白（設定不要） | Q35: 設定なし
A36: =MAX($A$10:$A35)+1 -> 25 | B36: セグメントコード５（借方） | E36: △ | F36: コード | G36: 4 | H36: =SUBSTITUTE(SUBSTITUTE(ADDRESS(1,A36),"$1",""),"$","") -> Y | I36: 空白（設定不要） | Q36: 設定なし
A37: =MAX($A$10:$A36)+1 -> 26 | B37: 仕訳伝票明細金額（借方） | E37: 〇 | F37: 数値 | G37: 13 | H37: =SUBSTITUTE(SUBSTITUTE(ADDRESS(1,A37),"$1",""),"$","") -> Z | Q37: 仕訳明細.借方金額
A38: =MAX($A$10:$A37)+1 -> 27 | B38: 消費税額（借方） | F38: 数値 | G38: 13 | H38: =SUBSTITUTE(SUBSTITUTE(ADDRESS(1,A38),"$1",""),"$","") -> AA | Q38: （消費税発生元科目に一致する場合、消費税行の）仕訳明細.借方金額
A39: =MAX($A$10:$A38)+1 -> 28 | B39: 消費税区分（借方） | F39: 区分 | G39: 2 | H39: =SUBSTITUTE(SUBSTITUTE(ADDRESS(1,A39),"$1",""),"$","") -> AB | Q39: 仕訳明細.消費税取引区分（PA向けの変換処理あり）
A40: =MAX($A$10:$A39)+1 -> 29 | B40: 消費税計算区分（借方） | F40: 区分 | G40: 1 | H40: =SUBSTITUTE(SUBSTITUTE(ADDRESS(1,A40),"$1",""),"$","") -> AC | I40: 3.計算しない | Q40: 3（計算しない）
A41: =MAX($A$10:$A40)+1 -> 30 | B41: 調整計上フラグ | E41: △ | F41: フラグ | G41: 1 | H41: =SUBSTITUTE(SUBSTITUTE(ADDRESS(1,A41),"$1",""),"$","") -> AD | I41: 空白（設定不要） | Q41: 設定なし
...

Sheet 取込フォーマット定義 bk
A1: ドキュメント名 | E1: サブシステム | G1: 業務機能名 | P1: 作成者 | R1: =表紙!D51 -> SCSK大西 | T1: 更新者
A2: 業務機能概要書 | C2: 取込フォーマット定義 | E2: =業務機能概要!L2 -> 財務会計 | G2: =業務機能概要!Q2 -> 仕訳データ自動取込 | P2: 作成日 | R2: =表紙!C51 -> 45898 | T2: 更新日
A4: データ名 | C4: 仕訳データ | I4: ヘッダ行 | K4: あり | M4: なし | N4: ダブルクォーテーション | Q4: あり | S4: なし | X4: 文字列
A5: ﾌｧｲﾙ形式・ﾚｺｰﾄﾞ長 | D5: 固定長（ | G5: Byte） | I5: 可変長（区切り文字［ ，(カンマ) ］） | M5: バイナリデータ | P5: その他（ ） | X5: 半英数
A6: 文字コード | D6: UNI（Win系） | F6: EBCDIC(K) | I6: その他（ UTF-8） | M6: 改行コード | O6: LF(UNIX系) | Q6: CRLF(Win系) | T6: なし | X6: 半カナ
A7: 全角(2byte)文字項目 | D7: あり | F7: なし | M7: 数値編集 | O7: 左詰め | Q7: 右詰め［ゼロ埋め］ | T7: 右詰め［スペース埋め］ | X7: コード
A8: 特記事項 | X8: 数値
A9: No. | B9: 項目名 | E9: 必須 | F9: 型 | G9: 桁数 | H9: 開始位置 | I9: 備考 | X9: 日付
H10: /列 | X10: 時間
A11: =MAX($A$10:$A10)+1 -> 1 | B11: 元帳領域コード | F11: コード | G11: 2 | H11: =SUBSTITUTE(SUBSTITUTE(ADDRESS(1,A11),"$1",""),"$","") -> A | I11: 仕訳の種類を判別するためのコード（01.一般仕訳、02.月次修正仕訳、03.管理会計仕訳、04.売上高・売上原価仕訳、05.組替仕訳） | X11: 年月
A12: =MAX($A$10:$A11)+1 -> 2 | B12: 仕訳伝票番号 | E12: △ | F12: 文字列 | G12: 12 | H12: =SUBSTITUTE(SUBSTITUTE(ADDRESS(1,A12),"$1",""),"$","") -> B | I12: 仕訳伝票番号。ProActiveC4上一位の番号とする必要がある。 | X12: 区分
A13: =MAX($A$10:$A12)+1 -> 3 | B13: 仕訳伝票起票日付 | E13: 〇 | F13: 日付 | G13: 8 | H13: =SUBSTITUTE(SUBSTITUTE(ADDRESS(1,A13),"$1",""),"$","") -> C | I13: 経理日
A14: =MAX($A$10:$A13)+1 -> 4 | B14: 起票部門表示コード | E14: 〇 | F14: コード | G14: 10 | H14: =SUBSTITUTE(SUBSTITUTE(ADDRESS(1,A14),"$1",""),"$","") -> D | I14: 伝票起票した部署のコード（事業所コード＋業種コード（2桁）＋所属コード（3桁の場合は前0埋め）の8桁で指定する）
A15: =MAX($A$10:$A14)+1 -> 5 | B15: 仕訳円貨区分 | E15: 〇 | F15: 区分 | G15: 1 | H15: =SUBSTITUTE(SUBSTITUTE(ADDRESS(1,A15),"$1",""),"$","") -> E | I15: 外貨建ての伝票か円貨の伝票かの区分（1.円貨、2.外貨）
A16: =MAX($A$10:$A15)+1 -> 6 | B16: 起票者コード | E16: 〇 | F16: コード | G16: 15 | H16: =SUBSTITUTE(SUBSTITUTE(ADDRESS(1,A16),"$1",""),"$","") -> F | I16: 仕訳伝票を起票したユーザーID（固定値：999999999999999（ダミー））
A17: =MAX($A$10:$A16)+1 -> 7 | B17: 決算仕訳フラグ | E17: 〇 | F17: フラグ | G17: 1 | H17: =SUBSTITUTE(SUBSTITUTE(ADDRESS(1,A17),"$1",""),"$","") -> G | I17: 決算仕訳か否かのフラグ（0.通常仕訳、1.決算仕訳）
A18: =MAX($A$10:$A17)+1 -> 8 | B18: 仕訳伝票摘要 | F18: 文字列 | G18: 80 | H18: =SUBSTITUTE(SUBSTITUTE(ADDRESS(1,A18),"$1",""),"$","") -> H
A19: =MAX($A$10:$A18)+1 -> 9 | B19: 洗替実施区分 | F19: 区分 | G19: 1 | H19: =SUBSTITUTE(SUBSTITUTE(ADDRESS(1,A19),"$1",""),"$","") -> I | I19: 9.不要
A20: =MAX($A$10:$A19)+1 -> 10 | B20: 洗替伝票起票日付 | E20: △ | F20: 日付 | G20: 8 | H20: =SUBSTITUTE(SUBSTITUTE(ADDRESS(1,A20),"$1",""),"$","") -> J | I20: 空白（設定不要）
A21: =MAX($A$10:$A20)+1 -> 11 | B21: 仕訳伝票行番号 | E21: 〇 | F21: 数値 | G21: 4 | H21: =SUBSTITUTE(SUBSTITUTE(ADDRESS(1,A21),"$1",""),"$","") -> K | I21: 仕訳伝票明細の行番号
A22: =MAX($A$10:$A21)+1 -> 12 | B22: 仕訳伝票明細摘要 | F22: 文字列 | G22: 80 | H22: =SUBSTITUTE(SUBSTITUTE(ADDRESS(1,A22),"$1",""),"$","") -> L
A23: =MAX($A$10:$A22)+1 -> 13 | B23: 勘定科目コード（借方） | F23: コード | G23: 8 | H23: =SUBSTITUTE(SUBSTITUTE(ADDRESS(1,A23),"$1",""),"$","") -> M
A24: =MAX($A$10:$A23)+1 -> 14 | B24: 補助科目コード（借方） | E24: △ | F24: コード | G24: 4 | H24: =SUBSTITUTE(SUBSTITUTE(ADDRESS(1,A24),"$1",""),"$","") -> N | I24: 科目摘要を判別するコード
A25: =MAX($A$10:$A24)+1 -> 15 | B25: 計上部門表示コード（借方） | F25: コード | G25: 10 | H25: =SUBSTITUTE(SUBSTITUTE(ADDRESS(1,A25),"$1",""),"$","") -> O | I25: 借方科目残を計上する部署のコード（業種コード（2桁）＋所属コード（3桁の場合は前0埋め）の6桁で指定する） | Q25: ※費用科目の場合は費用管理組織。未収未払の場合は未収未払管理組織。
A26: =MAX($A$10:$A25)+1 -> 16 | B26: 取引先コード（借方） | E26: △ | F26: コード | G26: 15 | H26: =SUBSTITUTE(SUBSTITUTE(ADDRESS(1,A26),"$1",""),"$","") -> P | I26: ※借方科目を取引先計上する場合、必須
A27: =MAX($A$10:$A26)+1 -> 17 | B27: 自社口座コード（借方） | E27: △ | F27: コード | G27: 8 | H27: =SUBSTITUTE(SUBSTITUTE(ADDRESS(1,A27),"$1",""),"$","") -> Q | I27: 出金を行う銀行口座のコード ※借方科目を口座別計上する場合、必須
A28: =MAX($A$10:$A27)+1 -> 18 | B28: プロジェクトコード（借方） | E28: △ | F28: コード | G28: 20 | H28: =SUBSTITUTE(SUBSTITUTE(ADDRESS(1,A28),"$1",""),"$","") -> R | I28: 業種を判別するコード ※借方科目を業種別計上する場合、必須
A29: =MAX($A$10:$A28)+1 -> 19 | B29: 担当者コード（借方） | E29: △ | F29: コード | G29: 15 | H29: =SUBSTITUTE(SUBSTITUTE(ADDRESS(1,A29),"$1",""),"$","") -> S | I29: 空白（設定不要）
A30: =MAX($A$10:$A29)+1 -> 20 | B30: セグメントコード（借方） | E30: △ | F30: コード | G30: 4 | H30: =SUBSTITUTE(SUBSTITUTE(ADDRESS(1,A30),"$1",""),"$","") -> T | I30: 会計品目を判別するコード ※借方科目を会計品目別計上する場合、必須
A31: =MAX($A$10:$A30)+1 -> 21 | B31: セグメントコード１（借方） | E31: △ | F31: コード | G31: 4 | H31: =SUBSTITUTE(SUBSTITUTE(ADDRESS(1,A31),"$1",""),"$","") -> U | I31: 空白（設定不要）
A32: =MAX($A$10:$A31)+1 -> 22 | B32: セグメントコード２（借方） | E32: △ | F32: コード | G32: 4 | H32: =SUBSTITUTE(SUBSTITUTE(ADDRESS(1,A32),"$1",""),"$","") -> V | I32: 空白（設定不要）
A33: =MAX($A$10:$A32)+1 -> 23 | B33: セグメントコード３（借方） | E33: △ | F33: コード | G33: 4 | H33: =SUBSTITUTE(SUBSTITUTE(ADDRESS(1,A33),"$1",""),"$","") -> W | I33: 空白（設定不要）
A34: =MAX($A$10:$A33)+1 -> 24 | B34: セグメントコード４（借方） | E34: △ | F34: コード | G34: 4 | H34: =SUBSTITUTE(SUBSTITUTE(ADDRESS(1,A34),"$1",""),"$","") -> X | I34: 空白（設定不要）
A35: =MAX($A$10:$A34)+1 -> 25 | B35: セグメントコード５（借方） | E35: △ | F35: コード | G35: 4 | H35: =SUBSTITUTE(SUBSTITUTE(ADDRESS(1,A35),"$1",""),"$","") -> Y | I35: 空白（設定不要）
A36: =MAX($A$10:$A35)+1 -> 26 | B36: 仕訳伝票明細金額（借方） | E36: 〇 | F36: 数値 | G36: 13 | H36: =SUBSTITUTE(SUBSTITUTE(ADDRESS(1,A36),"$1",""),"$","") -> Z
A37: =MAX($A$10:$A36)+1 -> 27 | B37: 消費税額（借方） | F37: 数値 | G37: 13 | H37: =SUBSTITUTE(SUBSTITUTE(ADDRESS(1,A37),"$1",""),"$","") -> AA
A38: =MAX($A$10:$A37)+1 -> 28 | B38: 消費税区分（借方） | F38: 区分 | G38: 2 | H38: =SUBSTITUTE(SUBSTITUTE(ADDRESS(1,A38),"$1",""),"$","") -> AB
A39: =MAX($A$10:$A38)+1 -> 29 | B39: 消費税計算区分（借方） | F39: 区分 | G39: 1 | H39: =SUBSTITUTE(SUBSTITUTE(ADDRESS(1,A39),"$1",""),"$","") -> AC | I39: 3.計算しない
A40: =MAX($A$10:$A39)+1 -> 30 | B40: 調整計上フラグ | E40: △ | F40: フラグ | G40: 1 | H40: =SUBSTITUTE(SUBSTITUTE(ADDRESS(1,A40),"$1",""),"$","") -> AD | I40: 空白（設定不要）
A41: =MAX($A$10:$A40)+1 -> 31 | B41: 通貨コード | E41: △ | F41: コード | G41: 3 | H41: =SUBSTITUTE(SUBSTITUTE(ADDRESS(1,A41),"$1",""),"$","") -> AE | I41: 空白（設定不要）
...

Sheet ⇒

Sheet データアクセス要領
A1: ドキュメント名 | L1: サブシステム | Q1: 業務機能名 | AJ1: 作成者 | AO1: =表紙!D51 -> SCSK大西 | AT1: 更新者
A2: 業務機能概要書 | G2: データアクセス要領 | L2: =業務機能概要!L2 -> 財務会計 | Q2: =業務機能概要!Q2 -> 仕訳データ自動取込 | AJ2: 作成日付 | AO2: =表紙!C51 -> 45898 | AT2: 更新日付
A4: 【編集要領】
B6: データ登録の要領は、標準の「仕訳外部データ取込」機能の実行時と同様。

Sheet 補足
A1: ドキュメント名 | L1: サブシステム | Q1: 業務機能名 | AM1: 作成者 | AR1: =表紙!D51 -> SCSK大西 | AW1: 更新者
A2: 業務機能概要書 | G2: 補足説明 | L2: =業務機能概要!L2 -> 財務会計 | Q2: =業務機能概要!Q2 -> 仕訳データ自動取込 | AM2: 作成日付 | AR2: =表紙!C51 -> 45898 | AW2: 更新日付
C4: 当機能でのバッチファイル、xmlファイルの作成イメージ
C7: バッチファイル１ | P7: c4_import_shiwak.bat
D9: ①仕訳データ取込 | AG9: 入力データファイル（xml）
E11: 取込ファイル探索 | J11: ※取込ファイルが0byteであった場合は正常として処理終了する | AH11: 会社コードを定義する
AH12: ※ | AI12: 「cvo_sav_cd」は設定なしとして、取込ファイルは
AI13: バッチ実行定義ファイルで定義する
E14: 取込実行バッチファイルの呼び出し
E16: 正常時 | AG16: BRファイル（xml）
F17: 取込ファイルの退避（正常終了のファイル退避フォルダへ移動）
E18: エラー時 | AH18: バッチ処理の中で利用するビジネスリソース
F19: 取込ファイルの退避（異常終了のファイル退避フォルダへ移動） | AH19: J-SOXログ出力で利用するクライアント環境情報 | AW19: を定義する
C28: バッチファイル２ | I28: ※パタメータ定義用 | P28: param.bat
D30: 取込ファイルのフォルダパス、
D31: SQLファイルのパスなどを定義する
C37: バッチファイル３ | P37: Exec_ShiwkImpBatch.bat
D39: 入力データファイル 読み込み
D41: BRファイル 読み込み
D43: バッチ実行
D44: 戻り値返却
C49: ディレクトリ構成
D52: ー | E52: ー | G52: c4_import_shiwk.bat | AD52: ・・・ | AF52: タスクスケジューラから起動されるbat
E53: ｜ | G53: param.bat | AD53: ・・・ | AF53: bat実行時に参照されるパラメータセットbat
E54: ｜
E55: ー | G55: CSV_DIR | AD55: ・・・ | AF55: 取込用のCSVファイルを配置するフォルダ
E56: ｜
E57: ー | G57: BATCH_SUB_DIR | Q57: ー | R57: Exec_ShiwkImpBatch.bat | AD57: ・・・ | AF57: 仕訳データ取込を実行するためのbat
E58: ｜
E59: ｜
E60: ー | G60: SETTING_DIR | Q60: ー | R60: BR_GL.xml | AD60: ・・・ | AF60: BRファイル
E61: ｜ | R61: Input_ShiwkImpBatch.xml | AD61: ・・・ | AF61: 取込用のインプットファイル
E62: ｜
E63: ｜
E64: ー | G64: SUCCESS_DIR | AD64: ・・・ | AF64: 正常取込できた取込ファイルを退避するフォルダ
E65: ｜
E66: ー | G66: ERR_DIR | AD66: ・・・ | AF66: 取込エラーとなった取込ファイルを退避するフォルダ
AF67: エラー時のログを出力するフォルダ
C94: スクラッチ開発機能からProActiveC4に連動する仕訳、支払の業務データで必要となるマスタコード
C97: ① | D97: ユーザID（起票者） | V97: → | X97: 夜間連動時のユーザIDは連動用ユーザ固定とする。 即時連動のときは伝票入力ユーザとする
...
