Workbook
Name 【債権】最新データ辞書: [1]データ辞書!$H$331:$O$5000
Name 項目辞書: [2]項目辞書!$A$3:$G$1522

Sheet 表紙
F46: ProActive
B48: 変更履歴
B50: 項番 | C50: 変更発生日 | D50: 変更者 | E50: 変更箇所 | F50: 変更内容
B51: 1 | C51: 45898 | D51: SCSK井上 | F51: 新規作成
B52: 2
B53: 3
B54: 4
B55: 5
B56: 6
B57: 7
B58: 8
B59: 9
B60: 10
B61: 11
B62: 12
B63: 13
... B80: 30

Sheet 業務機能概要
A1: ドキュメント名 | L1: サブシステム | Q1: 業務機能名 | AJ1: 作成者 | AO1: =表紙!D51 -> SCSK井上 | AT1: 更新者
A2: 業務機能概要書 | G2: 業務機能概要 | L2: 財務会計 | Q2: 仕訳連動 | AJ2: 作成日付 | AO2: =表紙!C51 -> 45898 | AT2: 更新日付
B4: 【目的・役割】
C5: ・ | D5: ホクレン様の仕訳情報は、スクラッチ開発機能にて全量を持つ想定である。
D6: しかし、以下の仕訳データはProActiveC4にて作成する想定である。
D8: ① | E8: 支払決済時の仕訳 | L8: ・・・取引の支払を行った際の仕訳。ProActiveC4債務管理サブシステムにて支払決済確定処理を
M9: 実施したタイミングで自動的に起票される。
D10: ② | E10: 債務科目の振替仕訳 | L10: ・・・計上されている債務科目を別科目に振り替える仕訳。ProActiveC4債務管理サブシステムにて債務振替処理を
M11: 実施したタイミングで自動的に起票される。
D12: ③ | E12: 組替仕訳 | L12: ・・・決算時、帳簿上の勘定科目を財務諸表の表示科目に変換する仕訳。ProActiveC4財務会計サブシステムにて起票する。
M13: 翌期になったタイミングで洗替する。
D15: 上記①、②の仕訳はスクラッチ開発機能に連動する必要がある。
D16: 今回、ProActiveC4側で新規開発する仕訳連動機能にて、①、②の仕訳データをスクラッチ開発機能へ連動する。
B18: 【利用者】
C19: ・ | D19: バッチ
B22: 【利用頻度】
C23: ・ | D23: 日次
B26: 【対象要件定義書】
C27: ・ | D27: 要件定義書（仕訳連動）.xls
B30: 【処理概要】
C31: １) | D31: ProActiveC4で作成した仕訳情報を抽出する。
D33: ① | E33: 仕訳連動バッチ処理開始日時の取得
E35: 前回、仕訳連動バッチ処理を開始した日時以降かつ、今回仕訳連動バッチ処理を開始した日時までに作成された仕訳を抽出対象とする。
E36: そのため、仕訳連動バッチ処理を開始したタイミングで日時（YYYYMMDDHHMMSSmmm）を取得する。
E37: 日時は、ProActiveC4のシステム日時から取得する。
D39: ② | E39: 抽出条件
E41: 抽出対象となるデータの項目は、出力CSV定義シート参照。
E42: 以下の条件に合致するデータを抽出する。
F44: ・ProActiveC4で作成された仕訳（スクラッチ開発機能等から連動された仕訳は対象外）
F45: ・前回の仕訳連動バッチ処理の実行開始日時以降に作成された仕訳 | AC45: ※変数管理テーブルを作成し、仕訳連動バッチ処理実行開始日時の履歴情報を管理する。
F46: ・出力対象となる元帳領域を使用している仕訳 | AC46: ※変数管理テーブルを作成し、出力対象外の元帳領域コードを管理する。
D50: ③ | E50: 出力項目
E52: 出力CSV定義参照
D55: ④ | E55: コード変換
E57: 出力項目のうち、ProActiveC4固有のコードについて、スクラッチ開発機能に合わせたコード変換を実施する。
D60: ⑤ | E60: CSVファイル出力
E62: ③で出力対象データが1件以上取得できた場合、仕訳データをCSVファイル出力する。
F64: ・ | G64: ファイル名は「siwk_ 」に①で取得した仕訳連動バッチ処理開始日時を付加する。
G65: 例) | I65: ファイル名：siwk_YYYYMMDDHHMMSSmmm.csv
F67: ・ | G67: 変数管理テーブルから、ファイル出力先パスを取得する。 | AJ67: ※ | AK67: 変数管理テーブルを作成し、仕訳データ出力先の
...

Sheet イベント概要
A1: ドキュメント名 | L1: サブシステム | Q1: 業務機能名 | AJ1: 作成者 | AO1: =表紙!D51 -> SCSK井上 | AT1: 更新者
A2: 業務機能概要書 | G2: イベント概要 | L2: =業務機能概要!L2 -> 財務会計 | Q2: =業務機能概要!Q2 -> 仕訳連動 | AJ2: 作成日付 | AO2: =表紙!C51 -> 45898 | AT2: 更新日付
A4: 【イベント処理】
B5: № | C5: イベント名 | J5: 処理説明
B6: =IF(C6="","",MAX(B$5:B5)+1) -> 1 | C6: 仕訳連動 | J6: １． | L6: 仕訳連動バッチ処理開始日時（YYYYMMDDhhMMssmmm）を取得する。 | EV6: 注１）初期表示は全ての
C7: バッチイベント | EV7: データを処理対象とする
B8: =IF(C8="","",MAX(B$5:B7)+1) | J8: ２. | L8: 変数管理TBLから抽出条件（バッチ処理最終実行開始日時）を取得する。（データアクセス要領１．参照）
L9: <パラメータ>
L10: ・ | M10: 会社コード | Q10: ： | R10: バッチ実行用のxmlファイルで指定された会社コード
L11: ・ | M11: 変数ID | Q11: ： | R11: 変数管理テーブルで管理する「仕訳データ出力処理最終実行開始日時」の管理ID
B13: =IF(C13="","",MAX(B$5:B8)+1) | J13: ３. | L13: 変数管理TBLから抽出条件（出力対象外の元帳領域コード）を取得する。（データアクセス要領２．参照）
L14: <パラメータ>
L15: ・ | M15: 会社コード | Q15: ： | R15: バッチ実行用のxmlファイルで指定された会社コード
L16: ・ | M16: 変数ID | Q16: ： | R16: 変数管理テーブルで管理する「出力対象外の元帳領域コード」の管理ID
B17: =IF(C17="","",MAX(B$5:B9)+1)
J18: ４. | L18: 変数管理TBLから抽出条件（外部連動用ユーザID）を取得する。（データアクセス要領３．参照）
L19: <パラメータ>
L20: ・ | M20: 会社コード | Q20: ： | R20: バッチ実行用のxmlファイルで指定された会社コード
L21: ・ | M21: 変数ID | Q21: ： | R21: 変数管理テーブルで管理する「外部連動用ユーザID」の管理ID
J23: ５. | L23: 仕訳データを取得する。（データアクセス要領４．参照）
L24: <パラメータ>
L25: ・ | M25: 会社コード | Q25: ： | R25: バッチ実行用のxmlファイルで指定された会社コード
B26: =IF(C26="","",MAX(B$5:B25)+1) | L26: ・ | M26: 変数1 | Q26: ： | R26: ２．で取得した「仕訳データ出力処理最終実行開始日時」
L27: ・ | M27: 変数2 | Q27: ： | R27: ３．で取得した「出力対象外の元帳領域コードFROM」
L28: ・ | M28: 変数3 | Q28: ： | R28: ３．で取得した「出力対象外の元帳領域コードTO」
L29: ・ | M29: 変数4 | Q29: ： | R29: ４．で取得した「外部連動用ユーザID」
B30: =IF(C30="","",MAX(B$5:B26)+1)
B31: =IF(C31="","",MAX(B$5:B30)+1) | J31: ６. | L31: 仕訳データが1件以上取得できた場合、仕訳データをCSVファイルで出力する。（出力CSV定義参照）
L32: ※ | M32: 出力対象データがない場合、後続の処理に移行する。（当処理呼び出し用のbatファイルにて0byteファイルを作成する（ヘッダ行も作成しない））
L33: ・ | M33: ファイル名に１．で取得した仕訳連動バッチ処理実行開始日時を付加する。
L34: ・ | M34: 変数管理TBLからファイル出力先パスを取得する。（データアクセス要領５．参照）
M35: <パラメータ>
M36: ・ | N36: 会社コード | R36: ： | S36: バッチ実行用のxmlファイルで指定された会社コード
M37: ・ | N37: 変数1 | R37: ： | S37: 変数管理テーブルで管理する「仕訳データ出力先パス」の管理ID
J39: ７. | L39: 変数管理TBLのバッチ処理最終実行開始日時を更新する。（データアクセス要領６．参照）
L40: <パラメータ>
L41: ・ | M41: 会社コード | Q41: ： | R41: バッチ実行用のxmlファイルで指定された会社コード
L42: ・ | M42: 変数ID | Q42: ： | R42: 変数管理テーブルで管理する「仕訳データ出力処理最終実行開始日時」の管理ID
J44: ８. | L44: バッチ処理実行結果をバッチジョブ情報に登録する。
J46: ９. | L46: バッチ処理実行結果の終了情報をタスクスケジューラに返却する。

Sheet 出力CSV定義
A1: ドキュメント名 | E1: サブシステム | G1: 業務機能名 | P1: 作成者 | R1: =表紙!D51 -> SCSK井上 | T1: 更新者
A2: 業務機能概要書 | C2: 出力CSV定義 | E2: =業務機能概要!L2 -> 財務会計 | G2: =業務機能概要!Q2 -> 仕訳連動 | P2: 作成日 | R2: =表紙!C51 -> 45898 | T2: 更新日
A4: データ名 | C4: 仕訳データ | I4: ヘッダ行 | K4: あり | M4: なし | N4: ダブルクォーテーション | Q4: あり | S4: なし | AB4: 文字列
A5: ﾌｧｲﾙ形式・ﾚｺｰﾄﾞ長 | D5: 固定長（ | G5: Byte） | I5: 可変長（区切り文字［ ，(カンマ) ］） | M5: バイナリデータ | P5: その他（ ） | AB5: 半英数
A6: 文字コード | D6: UNI（Win系） | F6: EBCDIC(K) | I6: その他（UTF-8） | M6: 改行コード | O6: LF(UNIX系) | Q6: CRLF(Win系) | T6: なし | AB6: 半カナ
A7: 全角(2byte)文字項目 | D7: あり | F7: なし | M7: 数値編集 | O7: 左詰め | Q7: 右詰め［ゼロ埋め］ | T7: 右詰め［スペース埋め］ | AB7: コード
A8: 特記事項 | AB8: 数値
A9: No. | B9: 項目名 | E9: 必須 | F9: 型 | G9: 桁数 | H9: 開始位置 | I9: 項目説明 | S9: 設定値 | AB9: 日付
H10: /列 | AB10: 時間
A11: 1 | B11: 削除区分 | E11: 〇 | F11: 区分 | G11: 1 | H11: A | I11: 対象レコードの論理的な有効性を示す。0:有効、1:無効（論理削除状態） | S11: ０(固定値) | AB11: 年月
A12: 2 | B12: 排他カウンタ | E12: 〇 | F12: 数値 | G12: 1 | H12: B | I12: 排他制御に使用するカウンタ。 | S12: ０(固定値) | AB12: 区分
A13: 3 | B13: 作成日時 | E13: 〇 | F13: 時間 | H13: C | I13: 対象レコードが最初に作成された日時。 | S13: 空欄 | AB13: フラグ
A14: 4 | B14: 最終更新日時 | E14: 〇 | F14: 時間 | H14: D | I14: 対象レコードが最後に更新された日時。 | S14: 空欄 | AB14: -
A15: 5 | B15: 最終更新者ユーザーＩＤ | E15: 〇 | F15: 文字列 | G15: 8 | H15: E | I15: 対象レコードを最後に更新したユーザーのユーザーID。 | S15: CST変数管理．CST変数１
A16: 6 | B16: データ種別 | F16: 文字列 | G16: 2 | H16: F | I16: ＩＦ制御部、DEX登録申請で決定した種別。 | S16: 空欄
A17: 7 | B17: データ区分 | F17: 文字列 | G17: 1 | H17: G | I17: 連動データの登録、訂正、削除を表す区分。１：登録、２：訂正、３：削除。 | S17: １(固定値)
A18: 8 | B18: 経理日 | E18: 〇 | F18: 日付 | H18: H | I18: 会計帳簿上、取引が認識される日付 | S18: 仕訳伝票．仕訳伝票起票日付
A19: 9 | B19: 取引日 | F19: 日付 | H19: I | I19: 仕訳作成日付 | S19: 仕訳伝票．仕訳伝票起票日付
A20: 10 | B20: 連動元システム管理コード | F20: 文字列 | G20: 2 | H20: J | I20: 連動元のシステムを識別するためのコード。 | S20: CST変数管理．CST変数２
A21: 11 | B21: 発生元システム管理コード | F21: 文字列 | G21: 2 | H21: K | I21: 入力機能のシステム管理コード。 | S21: CST変数管理．CST変数３
A22: 12 | B22: 添付ファイル数 | F22: 数値 | G22: 1 | H22: L | I22: 添付ファイル数。 | S22: ０(固定値)
A23: 13 | B23: 仕訳種別コード | F23: 文字列 | G23: 2 | H23: M | I23: 仕訳伝票の発生元機能を識別する為のコード。 | S23: CST変数管理．CST変数４
A24: 14 | B24: 仕訳種類コード | F24: 文字列 | G24: 1 | H24: N | I24: 仕訳の種類を表すコード。 | S24: CST変数管理．CST変数５
A25: 15 | B25: 仕訳番号 | E25: 〇 | F25: 文字列 | G25: 11 | H25: O | I25: ホクレン財務会計システムで管理する仕訳番号。連動元システム管理コード[2桁]＋処理単位連番[2桁]＋連番[7桁]。 | S25: 空欄
A26: 16 | B26: 連動元仕訳番号 | F26: 文字列 | G26: 9 | H26: P | I26: 連動元システムで発番された発生元の仕訳番号 | S26: 仕訳伝票．仕訳伝票番号
A27: 17 | B27: 事業所コード | F27: 文字列 | G27: 2 | H27: Q | I27: ホクレンの事業所を分類するコード | S27: 組織体系．部門表示コードの先頭2桁
A28: 18 | B28: 業種コード | F28: 文字列 | G28: 2 | H28: R | I28: ホクレンの業種を分類するコード | S28: 組織体系．部門表示表示コードの3~4桁
A29: 19 | B29: 予算組織コード | F29: 文字列 | G29: 4 | H29: S | I29: ホクレンの組織コード | S29: 組織体系．部門表示表示コードの下4桁
A30: 20 | B30: 仕訳摘要 | F30: 文字列 | G30: 96 | H30: T | I30: 仕訳摘要 | S30: 仕訳伝票．仕訳伝票摘要
A31: 21 | B31: 出金時計上区分 | F31: 文字列 | G31: 1 | H31: U | I31: 支払時計上仕訳を起票をするか否かの区分。 | S31: 空欄
A32: 22 | B32: 発生元システム取引番号 | F32: 文字列 | G32: 24 | H32: V | I32: 各部門システムや経費システムで取引を照会するための番号 | S32: 仕訳伝票．仕訳伝票番号
A33: 23 | B33: 仕訳作成日時 | F33: 時間 | H33: W | I33: 仕訳の作成日時 | S33: 仕訳伝票．登録日時
A34: 24 | B34: 仕訳作成担当者 | F34: 文字列 | G34: 8 | H34: X | I34: 仕訳伝票の作成を行った職員の職員番号 | S34: 仕訳伝票．登録者
A35: 25 | B35: 仕訳作成担当者所属コード | F35: 文字列 | G35: 4 | H35: Y | I35: 仕訳伝票の作成を行った職員が所属する部署を示すコード | S35: 空欄（登録者のIDからスクラッチ側で取得）
A36: 26 | B36: 仕訳更新日時 | F36: 時間 | H36: Z | I36: 仕訳の更新日時（最後に行われた、一時保存、登録、承認依頼時の日時を保持） | S36: 仕訳伝票．更新日時
A37: 27 | B37: 仕訳更新担当者 | F37: 文字列 | G37: 8 | H37: AA | I37: 仕訳伝票の一時保存、登録、承認依頼を行った職員の職員番号 | S37: 仕訳伝票．更新者
A38: 28 | B38: 仕訳更新担当者所属コード | F38: 文字列 | G38: 4 | H38: AB | I38: 仕訳伝票の一時保存、登録、承認依頼を行った職員が所属する部署を示すコード | S38: 空欄（登録者のIDからスクラッチ側で取得）
A39: 29 | B39: 承認依頼日時 | F39: 時間 | H39: AC | I39: 仕訳伝票の承認依頼を行った際の日時 | S39: 仕訳伝票．更新日時
A40: 30 | B40: 承認依頼者 | F40: 文字列 | G40: 8 | H40: AD | I40: 承認依頼者の職員番号 | S40: 仕訳伝票．サブシステムID＝'AP'のとき、固定値。それ以外は仕訳伝票．更新者
A41: 31 | B41: 承認依頼者所属コード | F41: 文字列 | G41: 4 | H41: AE | I41: 承認依頼者が所属する部署を表すコード | S41: 空欄（更新者のIDからスクラッチ側で取得）
...

Sheet 出力CSVサンプル
A1: 削除区分 | B1: 排他カウンタ | C1: 作成日時 | D1: 最終更新日時 | E1: 最終更新者ユーザーID | F1: データ種別 | G1: データ区分 | H1: 経理日 | I1: 取引日 | J1: 連携元システム管理コード | K1: 発生元システム管理コード | L1: 添付ファイル数 | M1: 仕訳種別コード | N1: 仕訳種類コード | O1: 仕訳番号 | P1: 連動元仕訳番号 | Q1: 事業所コード | R1: 業種コード | S1: 予算組織コード | T1: 仕訳摘要 | U1: 出金時計上区分 | V1: 発生元システム取引番号 | W1: 仕訳作成日時 | X1: 仕訳作成担当者 | Y1: 仕訳作成担当者所属コード | Z1: 仕訳更新日時 | AA1: 仕訳更新担当者 | AB1: 仕訳更新担当者所属コード | AC1: 承認依頼日時 | AD1: 承認依頼者 | AE1: 承認依頼者所属コード | AF1: 承認差戻日時 | AG1: 承認差戻担当者 | AH1: 承認差戻担当者所属コード | AI1: 決済日時 | AJ1: 決裁者コード | AK1: 決裁所属コード | AL1: 取消訂正理由コード | AM1: 取消理由 | AN1: 元取引日 | AO1: 訂正元発生元システム取引番号 | AP1: 元伝エラー区分 | AQ1: りん議書URL | AR1: 伝票番号 | AS1: 共計区分 | AT1: 入出荷日 | AU1: 取扱区分 | AV1: PA集約先伝票番号 | AW1: 仕訳番号 | AX1: 仕訳明細番号 | AY1: 連動元仕訳番号 | AZ1: 連動元仕訳明細番号 | BA1: 業種コード | BB1: 予算組織コード | BC1: 管理会計事業所コード | BD1: 購買販売区分 | BE1: 勘定科目コード | BF1: 款科目コード | BG1: 分類口座コード | BH1: 管理項目コード | BI1: 目節科目コード | BJ1: 共計内訳コード | BK1: 消費税発生元勘定科目コード | BL1: 消費税発生元分類口座コード | BM1: 消費税発生元管理項目コード | BN1: 消費税発生元目節科目コード | BO1: 計上金額 | BP1: 借方金額 | BQ1: 借方消費税額 | BR1: 貸方金額 | BS1: 貸方消費税額 | BT1: 科目摘要コード | BU1: 科目摘要細目 | BV1: 消費税基準日 | BW1: 消費税取引区分 | BX1: 消費税率（連動） | BY1: 消費税コード | BZ1: 科目摘要補足 | CA1: 伝票番号 | CB1: 伝票明細番号 | CC1: 免税区分 | CD1: CF勘定科目内訳コード | CE1: 支払入金予定日 | CF1: 支払入金方法 | CG1: 入出金番号 | CH1: PA集約先伝票明細番号 | CI1: 相手先区分 | CJ1: 相手先コード | CK1: 諸口取引先カナ名称 | CL1: 会計情報品目コード | CM1: 出荷元コード | CN1: 添付ファイル名称１ | CO1: 添付ファイルパス１ | CP1: 添付ファイル名称２ | CQ1: 添付ファイルパス２ | CR1: 添付ファイル名称３ | CS1: 添付ファイルパス３ | CT1: 自社口座コード
A2: 0 | B2: 0 | E2: ダミーユーザID | G2: 1 | H2: 20150513 | I2: 20150513 | J2: DA1 | K2: DA2 | L2: 0 | M2: DA3 | N2: A | P2: K15050000009 | Q2: 01 | R2: 20 | S2: 1000 | T2: « NULL » | V2: K15050000009 | W2: 2.0250514e+16 | X2: 0002 | Z2: 2.0250514e+16 | AA2: 0002 | AC2: 2.0250514e+16 | AD2: jidou | AF2: 2.0250514e+16 | AG2: jidou | AI2: 2.0250514e+16 | AJ2: jidou | AV2: K15050000009 | AY2: K15050000009 | AZ2: 1 | BA2: 20 | BB2: 1000 | BE2: 110701 | BI2: 00 | BO2: 18518 | BP2: 18518 | BQ2: 1482 | BT2: « NULL » | BV2: 20150513 | BW2: « NULL » | BX2: 10 | BZ2: « NULL » | CC2: « NULL » | CD2: « NULL » | CI2: « NULL » | CJ2: « NULL » | CL2: 0002 | CT2: « NULL »
A3: 0 | B3: 0 | E3: ダミーユーザID | G3: 1 | H3: 20150513 | I3: 20150513 | J3: DA1 | K3: DA2 | L3: 0 | M3: DA3 | N3: A | P3: K15050000009 | Q3: 01 | R3: 20 | S3: 1000 | T3: « NULL » | V3: K15050000009 | W3: 2.0250514e+16 | X3: 0002 | Z3: 2.0250514e+16 | AA3: 0002 | AC3: 2.0250514e+16 | AD3: jidou | AF3: 2.0250514e+16 | AG3: jidou | AI3: 2.0250514e+16 | AJ3: jidou | AV3: K15050000009 | AY3: K15050000009 | AZ3: 1 | BA3: 20 | BB3: 1000 | BE3: 210401 | BI3: 00 | BO3: 20000 | BR3: 20000 | BS3: 0 | BT3: « NULL » | BV3: 20150513 | BW3: 0 | BX3: 0 | BZ3: « NULL » | CC3: 0 | CD3: « NULL » | CI3: 1 | CJ3: 1101 | CL3: 0002 | CT3: « NULL »
A4: 0 | B4: 0 | E4: ダミーユーザID | G4: 1 | H4: 20150602 | I4: 20150602 | J4: DA1 | K4: DA2 | L4: 0 | M4: DA3 | N4: A | P4: K15060000005 | Q4: 01 | R4: 20 | S4: 2000 | T4: « NULL » | V4: K15060000005 | W4: 2.0250602e+16 | X4: 0002 | Z4: 2.0250602e+16 | AA4: 0002 | AC4: 2.0250602e+16 | AD4: jidou | AF4: 2.0250602e+16 | AG4: jidou | AI4: 2.0250602e+16 | AJ4: jidou | AV4: K15060000005 | AY4: K15060000005 | AZ4: 1 | BA4: 20 | BB4: 2000 | BE4: 110901 | BI4: 10 | BO4: 9259 | BP4: 9259 | BQ4: 741 | BT4: 0 | BV4: 20150602 | BW4: « NULL » | BX4: 10 | BZ4: « NULL » | CC4: « NULL » | CD4: « NULL » | CI4: 1 | CJ4: 1101 | CL4: 0002 | CT4: « NULL »
A5: 0 | B5: 0 | E5: ダミーユーザID | G5: 1 | H5: 20150602 | I5: 20150602 | J5: DA1 | K5: DA2 | L5: 0 | M5: DA3 | N5: A | P5: K15060000005 | Q5: 01 | R5: 20 | S5: 2000 | T5: « NULL » | V5: K15060000005 | W5: 2.0250602e+16 | X5: 0002 | Z5: 2.0250602e+16 | AA5: 0002 | AC5: 2.0250602e+16 | AD5: jidou | AF5: 2.0250602e+16 | AG5: jidou | AI5: 2.0250602e+16 | AJ5: jidou | AV5: K15060000005 | AY5: K15060000005 | AZ5: 1 | BA5: 20 | BB5: 1000 | BE5: 210701 | BI5: 10 | BO5: 10000 | BR5: 10000 | BS5: 0 | BT5: 0 | BV5: 20150602 | BW5: 0 | BX5: 0 | BZ5: « NULL » | CC5: 0 | CD5: « NULL » | CI5: 1 | CJ5: 1101 | CL5: 0002 | CT5: « NULL »
A6: 0 | B6: 0 | E6: ダミーユーザID | G6: 1 | H6: 20150602 | I6: 20150602 | J6: DA1 | K6: DA2 | L6: 0 | M6: DA3 | N6: A | P6: K15060000006 | Q6: 01 | R6: 10 | S6: 1010 | T6: « NULL » | V6: K15060000006 | W6: 2.0250602e+16 | X6: 0002 | Z6: 2.0250602e+16 | AA6: 0002 | AC6: 2.0250602e+16 | AD6: jidou | AF6: 2.0250602e+16 | AG6: jidou | AI6: 2.0250602e+16 | AJ6: jidou | AV6: K15060000006 | AY6: K15060000006 | AZ6: 1 | BA6: 10 | BB6: 1010 | BE6: 110701 | BI6: 00 | BO6: 9259 | BP6: 9259 | BQ6: 741 | BT6: « NULL » | BV6: 20150602 | BW6: « NULL » | BX6: 10 | BZ6: « NULL » | CC6: « NULL » | CD6: « NULL » | CI6: « NULL » | CJ6: « NULL » | CL6: 0001 | CT6: « NULL »
A7: 0 | B7: 0 | E7: ダミーユーザID | G7: 1 | H7: 20150602 | I7: 20150602 | J7: DA1 | K7: DA2 | L7: 0 | M7: DA3 | N7: A | P7: K15060000006 | Q7: 01 | R7: 10 | S7: 1010 | T7: « NULL » | V7: K15060000006 | W7: 2.0250602e+16 | X7: 0002 | Z7: 2.0250602e+16 | AA7: 0002 | AC7: 2.0250602e+16 | AD7: jidou | AF7: 2.0250602e+16 | AG7: jidou | AI7: 2.0250602e+16 | AJ7: jidou | AV7: K15060000006 | AY7: K15060000006 | AZ7: 1 | BA7: 10 | BB7: 2000 | BE7: 210401 | BI7: 00 | BO7: 10000 | BR7: 10000 | BS7: 0 | BT7: « NULL » | BV7: 20150602 | BW7: 0 | BX7: 0 | BZ7: « NULL » | CC7: 0 | CD7: « NULL » | CI7: 1 | CJ7: 1101 | CL7: 1 | CT7: « NULL »
A8: 0 | B8: 0 | E8: ダミーユーザID | G8: 1 | H8: 20150715 | I8: 20150715 | J8: DA1 | K8: DA2 | L8: 0 | M8: DA3 | N8: A | P8: K15070000001 | Q8: 01 | R8: 20 | S8: 1000 | T8: 支払決済 支払決済番号[PK1507000001] | V8: K15070000001 | W8: 2.0250602e+16 | X8: 0002 | Z8: 2.0250602e+16 | AA8: 0002 | AC8: 2.0250602e+16 | AD8: jidou | AF8: 2.0250602e+16 | AG8: jidou | AI8: 2.0250602e+16 | AJ8: jidou | AV8: K15070000001 | AY8: K15070000001 | AZ8: 1 | BA8: 20 | BB8: 1000 | BE8: 210701 | BI8: 10 | BO8: 10000 | BP8: 10000 | BQ8: 0 | BT8: 0 | BV8: 20150715 | BW8: 0 | BX8: 0 | BZ8: 支払決済 支払決済番号[PK1507000001] | CC8: 0 | CD8: « NULL » | CI8: 1 | CJ8: 1101 | CL8: 0002 | CT8: « NULL »
A9: 0 | B9: 0 | E9: ダミーユーザID | G9: 1 | H9: 20150715 | I9: 20150715 | J9: DA1 | K9: DA2 | L9: 0 | M9: DA3 | N9: A | P9: K15070000001 | Q9: 01 | R9: 20 | S9: 1000 | T9: 支払決済 支払決済番号[PK1507000001] | V9: K15070000001 | W9: 2.0250602e+16 | X9: 0002 | Z9: 2.0250602e+16 | AA9: 0002 | AC9: 2.0250602e+16 | AD9: jidou | AF9: 2.0250602e+16 | AG9: jidou | AI9: 2.0250602e+16 | AJ9: jidou | AV9: K15070000001 | AY9: K15070000001 | AZ9: 1 | BA9: 20 | BB9: 2000 | BE9: 11120 | BI9: 20 | BO9: 10000 | BR9: 10000 | BS9: 0 | BT9: « NULL » | BV9: 20150715 | BW9: 0 | BX9: 0 | BZ9: 支払決済 支払決済番号[PK1507000001] | CC9: 0 | CD9: « NULL » | CI9: 1 | CJ9: 1101 | CL9: « NULL » | CT9: JISHA001
A10: 0 | B10: 0 | E10: ダミーユーザID | G10: 1 | H10: 20150715 | I10: 20150715 | J10: DA1 | K10: DA2 | L10: 0 | M10: DA3 | N10: A | P10: K15070000002 | Q10: 02 | R10: 10 | S10: 2000 | T10: 支払決済 支払決済番号[PK1507000002] | V10: K15070000002 | W10: 2.0250602e+16 | X10: 0002 | Z10: 2.0250602e+16 | AA10: 0002 | AC10: 2.0250602e+16 | AD10: jidou | AF10: 2.0250602e+16 | AG10: jidou | AI10: 2.0250602e+16 | AJ10: jidou | AV10: K15070000002 | AY10: K15070000002 | AZ10: 1 | BA10: 10 | BB10: 2000 | BE10: 210401 | BI10: 00 | BO10: 10000 | BP10: 10000 | BQ10: 0 | BT10: « NULL » | BV10: 20150715 | BW10: 0 | BX10: 0 | BZ10: 支払決済 支払決済番号[PK1507000002] | CC10: 0 | CD10: « NULL » | CI10: 1 | CJ10: 1101 | CL10: 0001 | CT10: « NULL »
A11: 0 | B11: 0 | E11: ダミーユーザID | G11: 1 | H11: 20150715 | I11: 20150715 | J11: DA1 | K11: DA2 | L11: 0 | M11: DA3 | N11: A | P11: K15070000002 | Q11: 02 | R11: 10 | S11: 2000 | T11: 支払決済 支払決済番号[PK1507000002] | V11: K15070000002 | W11: 2.0250602e+16 | X11: 0002 | Z11: 2.0250602e+16 | AA11: 0002 | AC11: 2.0250602e+16 | AD11: jidou | AF11: 2.0250602e+16 | AG11: jidou | AI11: 2.0250602e+16 | AJ11: jidou | AV11: K15070000002 | AY11: K15070000002 | AZ11: 1 | BA11: 20 | BB11: 2000 | BE11: 110202 | BI11: 00 | BO11: 10000 | BR11: 10000 | BS11: 0 | BT11: 0 | BV11: 20150715 | BW11: 0 | BX11: 0 | BZ11: 支払決済 支払決済番号[PK1507000002] | CC11: 0 | CD11: « NULL » | CI11: « NULL » | CJ11: « NULL » | CL11: « NULL » | CT11: JISHA001
A12: 0 | B12: 0 | E12: ダミーユーザID | G12: 1 | H12: 20150501 | I12: 20150501 | J12: DA1 | K12: DA2 | L12: 0 | M12: DA3 | N12: A | P12: S15050000002 | Q12: 01 | R12: 20 | S12: 1000 | T12: « NULL » | V12: S15050000002 | W12: 2.0250417e+16 | X12: 0002 | Z12: 2.0250507e+16 | AA12: 0002 | AC12: 2.0250507e+16 | AD12: 0002 | AF12: 2.0250507e+16 | AG12: 0002 | AI12: 2.0250507e+16 | AJ12: 0002 | AV12: S15050000002 | AY12: S15050000002 | AZ12: 1 | BA12: 20 | BB12: 1000 | BE12: 110701 | BI12: 00 | BO12: 1000 | BP12: 1000 | BQ12: 0 | BT12: « NULL » | BV12: 20150501 | BW12: 0 | BX12: 0 | BZ12: « NULL » | CC12: 0 | CD12: « NULL » | CI12: « NULL » | CJ12: « NULL » | CL12: 0001 | CT12: « NULL »
A13: 0 | B13: 0 | E13: ダミーユーザID | G13: 1 | H13: 20150501 | I13: 20150501 | J13: DA1 | K13: DA2 | L13: 0 | M13: DA3 | N13: A | P13: S15050000002 | Q13: 01 | R13: 20 | S13: 1000 | T13: « NULL » | V13: S15050000002 | W13: 2.0250417e+16 | X13: 0002 | Z13: 2.0250507e+16 | AA13: 0002 | AC13: 2.0250507e+16 | AD13: 0002 | AF13: 2.0250507e+16 | AG13: 0002 | AI13: 2.0250507e+16 | AJ13: 0002 | AV13: S15050000002 | AY13: S15050000002 | AZ13: 1 | BA13: 20 | BB13: 1000 | BE13: 210401 | BI13: 00 | BO13: 1000 | BR13: 1000 | BS13: 0 | BT13: « NULL » | BV13: 20150501 | BW13: 0 | BX13: 0 | BZ13: « NULL » | CC13: 0 | CD13: « NULL » | CI13: 1 | CJ13: 1101 | CL13: 0001 | CT13: « NULL »
A14: 0 | B14: 0 | E14: ダミーユーザID | G14: 1 | H14: 20150507 | I14: 20150507 | J14: DA1 | K14: DA2 | L14: 0 | M14: DA3 | N14: A | P14: S15050000003 | Q14: 01 | R14: 20 | S14: 1000 | T14: « NULL » | V14: S15050000003 | W14: 2.0250507e+16 | X14: 0002 | Z14: 2.0250507e+16 | AA14: 0002 | AC14: 2.0250507e+16 | AD14: 0002 | AF14: 2.0250507e+16 | AG14: 0002 | AI14: 2.0250507e+16 | AJ14: 0002 | AV14: S15050000003 | AY14: S15050000003 | AZ14: 1 | BA14: 20 | BB14: 1000 | BE14: 210502 | BI14: 10 | BO14: 5500 | BP14: 5500 | BQ14: 0 | BT14: « NULL » | BV14: 20150507 | BW14: 0 | BX14: 0 | BZ14: « NULL » | CC14: 0 | CD14: « NULL » | CI14: « NULL » | CJ14: « NULL » | CL14: 2 | CT14: « NULL »
A15: 0 | B15: 0 | E15: ダミーユーザID | G15: 1 | H15: 20150507 | I15: 20150507 | J15: DA1 | K15: DA2 | L15: 0 | M15: DA3 | N15: A | P15: S15050000003 | Q15: 01 | R15: 20 | S15: 1000 | T15: « NULL » | V15: S15050000003 | W15: 2.0250507e+16 | X15: 0002 | Z15: 2.0250507e+16 | AA15: 0002 | AC15: 2.0250507e+16 | AD15: 0002 | AF15: 2.0250507e+16 | AG15: 0002 | AI15: 2.0250507e+16 | AJ15: 0002 | AV15: S15050000003 | AY15: S15050000003 | AZ15: 1 | BA15: 20 | BB15: 1000 | BE15: 300104 | BI15: 43 | BO15: 5000 | BR15: 5000 | BS15: 500 | BT15: 0 | BV15: 20150507 | BW15: « NULL » | BX15: 10 | BZ15: « NULL » | CC15: « NULL » | CD15: « NULL » | CI15: « NULL » | CJ15: « NULL » | CL15: 0001 | CT15: « NULL »
A16: 0 | B16: 0 | E16: ダミーユーザID | G16: 1 | H16: 20150507 | I16: 20150507 | J16: DA1 | K16: DA2 | L16: 0 | M16: DA3 | N16: A | P16: S15050000003 | Q16: 01 | R16: 20 | S16: 1000 | T16: « NULL » | V16: S15050000003 | W16: 2.0250507e+16 | X16: 0002 | Z16: 2.0250507e+16 | AA16: 0002 | AC16: 2.0250507e+16 | AD16: 0002 | AF16: 2.0250507e+16 | AG16: 0002 | AI16: 2.0250507e+16 | AJ16: 0002 | AV16: S15050000003 | AY16: S15050000003 | AZ16: 1 | BA16: 20 | BB16: 1000 | BE16: 110902 | BI16: 20 | BO16: 500 | BR16: 500 | BS16: 0 | BT16: « NULL » | BV16: 20150507 | BW16: 0 | BX16: 0 | BZ16: « NULL » | CC16: 0 | CD16: « NULL » | CI16: « NULL » | CJ16: « NULL » | CL16: « NULL » | CT16: « NULL »
A17: 0 | B17: 0 | E17: ダミーユーザID | G17: 1 | H17: 20150507 | I17: 20150507 | J17: DA1 | K17: DA2 | L17: 0 | M17: DA3 | N17: A | P17: S15050000003 | Q17: 01 | R17: 20 | S17: 1000 | T17: « NULL » | V17: S15050000003 | W17: 2.0250507e+16 | X17: 0002 | Z17: 2.0250507e+16 | AA17: 0002 | AC17: 2.0250507e+16 | AD17: 0002 | AF17: 2.0250507e+16 | AG17: 0002 | AI17: 2.0250507e+16 | AJ17: 0002 | AV17: S15050000003 | AY17: S15050000003 | AZ17: 2 | BA17: 20 | BB17: 1000 | BE17: 110602 | BI17: 70 | BO17: 13200 | BP17: 13200 | BQ17: 0 | BT17: « NULL » | BV17: 20150507 | BW17: 0 | BX17: 0 | BZ17: « NULL » | CC17: 0 | CD17: « NULL » | CI17: « NULL » | CJ17: « NULL » | CL17: 1 | CT17: « NULL »
A18: 0 | B18: 0 | E18: ダミーユーザID | G18: 1 | H18: 20150507 | I18: 20150507 | J18: DA1 | K18: DA2 | L18: 0 | M18: DA3 | N18: A | P18: S15050000003 | Q18: 01 | R18: 20 | S18: 1000 | T18: « NULL » | V18: S15050000003 | W18: 2.0250507e+16 | X18: 0002 | Z18: 2.0250507e+16 | AA18: 0002 | AC18: 2.0250507e+16 | AD18: 0002 | AF18: 2.0250507e+16 | AG18: 0002 | AI18: 2.0250507e+16 | AJ18: 0002 | AV18: S15050000003 | AY18: S15050000003 | AZ18: 2 | BA18: 20 | BB18: 1000 | BE18: 300104 | BI18: 4D | BO18: 12000 | BR18: 12000 | BS18: 1200 | BT18: 0 | BV18: 20150507 | BW18: « NULL » | BX18: 10 | BZ18: « NULL » | CC18: « NULL » | CD18: « NULL » | CI18: « NULL » | CJ18: « NULL » | CL18: 0001 | CT18: « NULL »
A19: 0 | B19: 0 | E19: ダミーユーザID | G19: 1 | H19: 20150507 | I19: 20150507 | J19: DA1 | K19: DA2 | L19: 0 | M19: DA3 | N19: A | P19: S15050000003 | Q19: 01 | R19: 20 | S19: 1000 | T19: « NULL » | V19: S15050000003 | W19: 2.0250507e+16 | X19: 0002 | Z19: 2.0250507e+16 | AA19: 0002 | AC19: 2.0250507e+16 | AD19: 0002 | AF19: 2.0250507e+16 | AG19: 0002 | AI19: 2.0250507e+16 | AJ19: 0002 | AV19: S15050000003 | AY19: S15050000003 | AZ19: 2 | BA19: 20 | BB19: 1000 | BE19: 110902 | BI19: 20 | BO19: 1200 | BR19: 1200 | BS19: 0 | BT19: « NULL » | BV19: 20150507 | BW19: 0 | BX19: 0 | BZ19: « NULL » | CC19: 0 | CD19: « NULL » | CI19: « NULL » | CJ19: « NULL » | CL19: « NULL » | CT19: « NULL »
A20: 0 | B20: 0 | E20: ダミーユーザID | G20: 1 | H20: 20150507 | I20: 20150507 | J20: DA1 | K20: DA2 | L20: 0 | M20: DA3 | N20: A | P20: S15050000003 | Q20: 01 | R20: 20 | S20: 1000 | T20: « NULL » | V20: S15050000003 | W20: 2.0250507e+16 | X20: 0002 | Z20: 2.0250507e+16 | AA20: 0002 | AC20: 2.0250507e+16 | AD20: 0002 | AF20: 2.0250507e+16 | AG20: 0002 | AI20: 2.0250507e+16 | AJ20: 0002 | AV20: S15050000003 | AY20: S15050000003 | AZ20: 3 | BA20: 20 | BB20: 1000 | BE20: 300104 | BI20: 4F | BO20: 44000 | BP20: 44000 | BQ20: 4400 | BT20: 0 | BV20: 20150507 | BW20: « NULL » | BX20: 10 | BZ20: « NULL » | CC20: « NULL » | CD20: « NULL » | CI20: « NULL » | CJ20: « NULL » | CL20: 1 | CT20: « NULL »
A21: 0 | B21: 0 | E21: ダミーユーザID | G21: 1 | H21: 20150507 | I21: 20150507 | J21: DA1 | K21: DA2 | L21: 0 | M21: DA3 | N21: A | P21: S15050000003 | Q21: 01 | R21: 20 | S21: 1000 | T21: « NULL » | V21: S15050000003 | W21: 2.0250507e+16 | X21: 0002 | Z21: 2.0250507e+16 | AA21: 0002 | AC21: 2.0250507e+16 | AD21: 0002 | AF21: 2.0250507e+16 | AG21: 0002 | AI21: 2.0250507e+16 | AJ21: 0002 | AV21: S15050000003 | AY21: S15050000003 | AZ21: 3 | BA21: 20 | BB21: 1000 | BE21: 210502 | BI21: 80 | BO21: 48400 | BR21: 48400 | BS21: 0 | BT21: « NULL » | BV21: 20150507 | BW21: 0 | BX21: 0 | BZ21: « NULL » | CC21: 0 | CD21: « NULL » | CI21: « NULL » | CJ21: « NULL » | CL21: 0001 | CT21: « NULL »
A22: 0 | B22: 0 | E22: ダミーユーザID | G22: 1 | H22: 20150507 | I22: 20150507 | J22: DA1 | K22: DA2 | L22: 0 | M22: DA3 | N22: A | P22: S15050000003 | Q22: 01 | R22: 20 | S22: 1000 | T22: « NULL » | V22: S15050000003 | W22: 2.0250507e+16 | X22: 0002 | Z22: 2.0250507e+16 | AA22: 0002 | AC22: 2.0250507e+16 | AD22: 0002 | AF22: 2.0250507e+16 | AG22: 0002 | AI22: 2.0250507e+16 | AJ22: 0002 | AV22: S15050000003 | AY22: S15050000003 | AZ22: 3 | BA22: 20 | BB22: 1000 | BE22: 110902 | BI22: 20 | BO22: 4400 | BP22: 4400 | BQ22: 0 | BT22: « NULL » | BV22: 20150507 | BW22: 0 | BX22: 0 | BZ22: « NULL » | CC22: 0 | CD22: « NULL » | CI22: « NULL » | CJ22: « NULL » | CL22: « NULL » | CT22: « NULL »
A23: 0 | B23: 0 | E23: ダミーユーザID | G23: 1 | H23: 20150507 | I23: 20150507 | J23: DA1 | K23: DA2 | L23: 0 | M23: DA3 | N23: A | P23: S15050000004 | Q23: 01 | R23: 20 | S23: 1000 | T23: « NULL » | V23: S15050000004 | W23: 2.0250507e+16 | X23: 0002 | Z23: 2.0250507e+16 | AA23: 0002 | AC23: 2.0250507e+16 | AD23: 0002 | AF23: 2.0250507e+16 | AG23: 0002 | AI23: 2.0250507e+16 | AJ23: 0002 | AV23: S15050000004 | AY23: S15050000004 | AZ23: 1 | BA23: 20 | BB23: 1000 | BE23: 300107 | BI23: 51 | BO23: 57000 | BP23: 57000 | BQ23: 4560 | BT23: 0 | BV23: 20150507 | BW23: « NULL » | BX23: 10 | BZ23: « NULL » | CC23: « NULL » | CD23: « NULL » | CI23: « NULL » | CJ23: « NULL » | CL23: 1 | CT23: « NULL »
A24: 0 | B24: 0 | E24: ダミーユーザID | G24: 1 | H24: 20150507 | I24: 20150507 | J24: DA1 | K24: DA2 | L24: 0 | M24: DA3 | N24: A | P24: S15050000004 | Q24: 01 | R24: 20 | S24: 1000 | T24: « NULL » | V24: S15050000004 | W24: 2.0250507e+16 | X24: 0002 | Z24: 2.0250507e+16 | AA24: 0002 | AC24: 2.0250507e+16 | AD24: 0002 | AF24: 2.0250507e+16 | AG24: 0002 | AI24: 2.0250507e+16 | AJ24: 0002 | AV24: S15050000004 | AY24: S15050000004 | AZ24: 1 | BA24: 20 | BB24: 1000 | BE24: 300108 | BI24: 51 | BO24: 57000 | BR24: 57000 | BS24: 4560 | BT24: 0 | BV24: 20150507 | BW24: « NULL » | BX24: 10 | BZ24: « NULL » | CC24: « NULL » | CD24: « NULL » | CI24: « NULL » | CJ24: « NULL » | CL24: 1 | CT24: « NULL »
A25: 0 | B25: 0 | E25: ダミーユーザID | G25: 1 | H25: 20150507 | I25: 20150507 | J25: DA1 | K25: DA2 | L25: 0 | M25: DA3 | N25: A | P25: S15050000004 | Q25: 01 | R25: 20 | S25: 1000 | T25: « NULL » | V25: S15050000004 | W25: 2.0250507e+16 | X25: 0002 | Z25: 2.0250507e+16 | AA25: 0002 | AC25: 2.0250507e+16 | AD25: 0002 | AF25: 2.0250507e+16 | AG25: 0002 | AI25: 2.0250507e+16 | AJ25: 0002 | AV25: S15050000004 | AY25: S15050000004 | AZ25: 1 | BA25: 20 | BB25: 1000 | BE25: 110902 | BI25: 20 | BO25: 4560 | BP25: 4560 | BQ25: 0 | BT25: « NULL » | BV25: 20150507 | BW25: 0 | BX25: 0 | BZ25: « NULL » | CC25: 0 | CD25: « NULL » | CI25: « NULL » | CJ25: « NULL » | CL25: « NULL » | CT25: « NULL »
A26: 0 | B26: 0 | E26: ダミーユーザID | G26: 1 | H26: 20150507 | I26: 20150507 | J26: DA1 | K26: DA2 | L26: 0 | M26: DA3 | N26: A | P26: S15050000004 | Q26: 01 | R26: 20 | S26: 1000 | T26: « NULL » | V26: S15050000004 | W26: 2.0250507e+16 | X26: 0002 | Z26: 2.0250507e+16 | AA26: 0002 | AC26: 2.0250507e+16 | AD26: 0002 | AF26: 2.0250507e+16 | AG26: 0002 | AI26: 2.0250507e+16 | AJ26: 0002 | AV26: S15050000004 | AY26: S15050000004 | AZ26: 1 | BA26: 20 | BB26: 1000 | BE26: 110902 | BI26: 20 | BO26: 4560 | BR26: 4560 | BS26: 0 | BT26: « NULL » | BV26: 20150507 | BW26: 0 | BX26: 0 | BZ26: « NULL » | CC26: 0 | CD26: « NULL » | CI26: « NULL » | CJ26: « NULL » | CL26: « NULL » | CT26: « NULL »
A27: 0 | B27: 0 | E27: ダミーユーザID | G27: 1 | H27: 20150507 | I27: 20150507 | J27: DA1 | K27: DA2 | L27: 0 | M27: DA3 | N27: A | P27: S15050000004 | Q27: 01 | R27: 20 | S27: 1000 | T27: « NULL » | V27: S15050000004 | W27: 2.0250507e+16 | X27: 0002 | Z27: 2.0250507e+16 | AA27: 0002 | AC27: 2.0250507e+16 | AD27: 0002 | AF27: 2.0250507e+16 | AG27: 0002 | AI27: 2.0250507e+16 | AJ27: 0002 | AV27: S15050000004 | AY27: S15050000004 | AZ27: 2 | BA27: 20 | BB27: 1000 | BE27: 300107 | BI27: 5A | BO27: 10000 | BP27: 10000 | BQ27: 800 | BT27: 0 | BV27: 20150507 | BW27: « NULL » | BX27: 10 | BZ27: « NULL » | CC27: « NULL » | CD27: « NULL » | CI27: « NULL » | CJ27: « NULL » | CL27: 3 | CT27: « NULL »
A28: 0 | B28: 0 | E28: ダミーユーザID | G28: 1 | H28: 20150507 | I28: 20150507 | J28: DA1 | K28: DA2 | L28: 0 | M28: DA3 | N28: A | P28: S15050000004 | Q28: 01 | R28: 20 | S28: 1000 | T28: « NULL » | V28: S15050000004 | W28: 2.0250507e+16 | X28: 0002 | Z28: 2.0250507e+16 | AA28: 0002 | AC28: 2.0250507e+16 | AD28: 0002 | AF28: 2.0250507e+16 | AG28: 0002 | AI28: 2.0250507e+16 | AJ28: 0002 | AV28: S15050000004 | AY28: S15050000004 | AZ28: 2 | BA28: 20 | BB28: 1000 | BE28: 300108 | BI28: 5E | BO28: 10000 | BR28: 10000 | BS28: 800 | BT28: 0 | BV28: 20150507 | BW28: « NULL » | BX28: 10 | BZ28: « NULL » | CC28: « NULL » | CD28: « NULL » | CI28: « NULL » | CJ28: « NULL » | CL28: 3 | CT28: « NULL »
A29: 0 | B29: 0 | E29: ダミーユーザID | G29: 1 | H29: 20150507 | I29: 20150507 | J29: DA1 | K29: DA2 | L29: 0 | M29: DA3 | N29: A | P29: S15050000004 | Q29: 01 | R29: 20 | S29: 1000 | T29: « NULL » | V29: S15050000004 | W29: 2.0250507e+16 | X29: 0002 | Z29: 2.0250507e+16 | AA29: 0002 | AC29: 2.0250507e+16 | AD29: 0002 | AF29: 2.0250507e+16 | AG29: 0002 | AI29: 2.0250507e+16 | AJ29: 0002 | AV29: S15050000004 | AY29: S15050000004 | AZ29: 2 | BA29: 20 | BB29: 1000 | BE29: 110902 | BI29: 20 | BO29: 800 | BP29: 800 | BQ29: 0 | BT29: « NULL » | BV29: 20150507 | BW29: 0 | BX29: 0 | BZ29: « NULL » | CC29: 0 | CD29: « NULL » | CI29: « NULL » | CJ29: « NULL » | CL29: « NULL » | CT29: « NULL »
A30: 0 | B30: 0 | E30: ダミーユーザID | G30: 1 | H30: 20150507 | I30: 20150507 | J30: DA1 | K30: DA2 | L30: 0 | M30: DA3 | N30: A | P30: S15050000004 | Q30: 01 | R30: 20 | S30: 1000 | T30: « NULL » | V30: S15050000004 | W30: 2.0250507e+16 | X30: 0002 | Z30: 2.0250507e+16 | AA30: 0002 | AC30: 2.0250507e+16 | AD30: 0002 | AF30: 2.0250507e+16 | AG30: 0002 | AI30: 2.0250507e+16 | AJ30: 0002 | AV30: S15050000004 | AY30: S15050000004 | AZ30: 2 | BA30: 20 | BB30: 1000 | BE30: 110902 | BI30: 20 | BO30: 800 | BR30: 800 | BS30: 0 | BT30: « NULL » | BV30: 20150507 | BW30: 0 | BX30: 0 | BZ30: « NULL » | CC30: 0 | CD30: « NULL » | CI30: « NULL » | CJ30: « NULL » | CL30: « NULL » | CT30: « NULL »
A31: 0 | B31: 0 | E31: ダミーユーザID | G31: 1 | H31: 20150507 | I31: 20150507 | J31: DA1 | K31: DA2 | L31: 0 | M31: DA3 | N31: A | P31: S15050000004 | Q31: 01 | R31: 20 | S31: 1000 | T31: « NULL » | V31: S15050000004 | W31: 2.0250507e+16 | X31: 0002 | Z31: 2.0250507e+16 | AA31: 0002 | AC31: 2.0250507e+16 | AD31: 0002 | AF31: 2.0250507e+16 | AG31: 0002 | AI31: 2.0250507e+16 | AJ31: 0002 | AV31: S15050000004 | AY31: S15050000004 | AZ31: 3 | BA31: 20 | BB31: 1000 | BE31: 300108 | BI31: 57 | BO31: 23000 | BP31: 23000 | BQ31: 1840 | BT31: 0 | BV31: 20150507 | BW31: « NULL » | BX31: 10 | BZ31: « NULL » | CC31: « NULL » | CD31: « NULL » | CI31: « NULL » | CJ31: « NULL » | CL31: 1 | CT31: « NULL »
A32: 0 | B32: 0 | E32: ダミーユーザID | G32: 1 | H32: 20150507 | I32: 20150507 | J32: DA1 | K32: DA2 | L32: 0 | M32: DA3 | N32: A | P32: S15050000004 | Q32: 01 | R32: 20 | S32: 1000 | T32: « NULL » | V32: S15050000004 | W32: 2.0250507e+16 | X32: 0002 | Z32: 2.0250507e+16 | AA32: 0002 | AC32: 2.0250507e+16 | AD32: 0002 | AF32: 2.0250507e+16 | AG32: 0002 | AI32: 2.0250507e+16 | AJ32: 0002 | AV32: S15050000004 | AY32: S15050000004 | AZ32: 3 | BA32: 20 | BB32: 1000 | BE32: 300107 | BI32: 5L | BO32: 23000 | BR32: 23000 | BS32: 1840 | BT32: 0 | BV32: 20150507 | BW32: « NULL » | BX32: 10 | BZ32: « NULL » | CC32: « NULL » | CD32: « NULL » | CI32: « NULL » | CJ32: « NULL » | CL32: 1 | CT32: « NULL »
A33: 0 | B33: 0 | E33: ダミーユーザID | G33: 1 | H33: 20150507 | I33: 20150507 | J33: DA1 | K33: DA2 | L33: 0 | M33: DA3 | N33: A | P33: S15050000004 | Q33: 01 | R33: 20 | S33: 1000 | T33: « NULL » | V33: S15050000004 | W33: 2.0250507e+16 | X33: 0002 | Z33: 2.0250507e+16 | AA33: 0002 | AC33: 2.0250507e+16 | AD33: 0002 | AF33: 2.0250507e+16 | AG33: 0002 | AI33: 2.0250507e+16 | AJ33: 0002 | AV33: S15050000004 | AY33: S15050000004 | AZ33: 3 | BA33: 20 | BB33: 1000 | BE33: 110902 | BI33: 20 | BO33: 1840 | BP33: 1840 | BQ33: 0 | BT33: « NULL » | BV33: 20150507 | BW33: 0 | BX33: 0 | BZ33: « NULL » | CC33: 0 | CD33: « NULL » | CI33: « NULL » | CJ33: « NULL » | CL33: « NULL » | CT33: « NULL »
A34: 0 | B34: 0 | E34: ダミーユーザID | G34: 1 | H34: 20150507 | I34: 20150507 | J34: DA1 | K34: DA2 | L34: 0 | M34: DA3 | N34: A | P34: S15050000004 | Q34: 01 | R34: 20 | S34: 1000 | T34: « NULL » | V34: S15050000004 | W34: 2.0250507e+16 | X34: 0002 | Z34: 2.0250507e+16 | AA34: 0002 | AC34: 2.0250507e+16 | AD34: 0002 | AF34: 2.0250507e+16 | AG34: 0002 | AI34: 2.0250507e+16 | AJ34: 0002 | AV34: S15050000004 | AY34: S15050000004 | AZ34: 3 | BA34: 20 | BB34: 1000 | BE34: 110902 | BI34: 20 | BO34: 1840 | BR34: 1840 | BS34: 0 | BT34: « NULL » | BV34: 20150507 | BW34: 0 | BX34: 0 | BZ34: « NULL » | CC34: 0 | CD34: « NULL » | CI34: « NULL » | CJ34: « NULL » | CL34: « NULL » | CT34: « NULL »
A35: 0 | B35: 0 | E35: ダミーユーザID | G35: 1 | H35: 20150507 | I35: 20150507 | J35: DA1 | K35: DA2 | L35: 0 | M35: DA3 | N35: A | P35: S15050000005 | Q35: 01 | R35: 20 | S35: 1000 | T35: « NULL » | V35: S15050000005 | W35: 2.0250507e+16 | X35: 0002 | Z35: 2.0250507e+16 | AA35: 0002 | AC35: 2.0250507e+16 | AD35: 0002 | AF35: 2.0250507e+16 | AG35: 0002 | AI35: 2.0250507e+16 | AJ35: 0002 | AV35: S15050000005 | AY35: S15050000005 | AZ35: 1 | BA35: 20 | BB35: 1000 | BE35: 210502 | BI35: 10 | BO35: -5500 | BP35: -5500 | BQ35: 0 | BT35: « NULL » | BV35: 20150507 | BW35: 0 | BX35: 0 | BZ35: « NULL » | CC35: 0 | CD35: « NULL » | CI35: « NULL » | CJ35: « NULL » | CL35: 2 | CT35: « NULL »
A36: 0 | B36: 0 | E36: ダミーユーザID | G36: 1 | H36: 20150507 | I36: 20150507 | J36: DA1 | K36: DA2 | L36: 0 | M36: DA3 | N36: A | P36: S15050000005 | Q36: 01 | R36: 20 | S36: 1000 | T36: « NULL » | V36: S15050000005 | W36: 2.0250507e+16 | X36: 0002 | Z36: 2.0250507e+16 | AA36: 0002 | AC36: 2.0250507e+16 | AD36: 0002 | AF36: 2.0250507e+16 | AG36: 0002 | AI36: 2.0250507e+16 | AJ36: 0002 | AV36: S15050000005 | AY36: S15050000005 | AZ36: 1 | BA36: 20 | BB36: 1000 | BE36: 300104 | BI36: 43 | BO36: -5000 | BR36: -5000 | BS36: -500 | BT36: 0 | BV36: 20150507 | BW36: « NULL » | BX36: 10 | BZ36: « NULL » | CC36: « NULL » | CD36: « NULL » | CI36: « NULL » | CJ36: « NULL » | CL36: 0001 | CT36: « NULL »
A37: 0 | B37: 0 | E37: ダミーユーザID | G37: 1 | H37: 20150507 | I37: 20150507 | J37: DA1 | K37: DA2 | L37: 0 | M37: DA3 | N37: A | P37: S15050000005 | Q37: 01 | R37: 20 | S37: 1000 | T37: « NULL » | V37: S15050000005 | W37: 2.0250507e+16 | X37: 0002 | Z37: 2.0250507e+16 | AA37: 0002 | AC37: 2.0250507e+16 | AD37: 0002 | AF37: 2.0250507e+16 | AG37: 0002 | AI37: 2.0250507e+16 | AJ37: 0002 | AV37: S15050000005 | AY37: S15050000005 | AZ37: 1 | BA37: 20 | BB37: 1000 | BE37: 110902 | BI37: 20 | BO37: -500 | BR37: -500 | BS37: 0 | BT37: « NULL » | BV37: 20150507 | BW37: 0 | BX37: 0 | BZ37: « NULL » | CC37: 0 | CD37: « NULL » | CI37: « NULL » | CJ37: « NULL » | CL37: « NULL » | CT37: « NULL »
A38: 0 | B38: 0 | E38: ダミーユーザID | G38: 1 | H38: 20150507 | I38: 20150507 | J38: DA1 | K38: DA2 | L38: 0 | M38: DA3 | N38: A | P38: S15050000005 | Q38: 01 | R38: 20 | S38: 1000 | T38: « NULL » | V38: S15050000005 | W38: 2.0250507e+16 | X38: 0002 | Z38: 2.0250507e+16 | AA38: 0002 | AC38: 2.0250507e+16 | AD38: 0002 | AF38: 2.0250507e+16 | AG38: 0002 | AI38: 2.0250507e+16 | AJ38: 0002 | AV38: S15050000005 | AY38: S15050000005 | AZ38: 2 | BA38: 20 | BB38: 1000 | BE38: 110602 | BI38: 70 | BO38: -13200 | BP38: -13200 | BQ38: 0 | BT38: « NULL » | BV38: 20150507 | BW38: 0 | BX38: 0 | BZ38: « NULL » | CC38: 0 | CD38: « NULL » | CI38: « NULL » | CJ38: « NULL » | CL38: 1 | CT38: « NULL »
A39: 0 | B39: 0 | E39: ダミーユーザID | G39: 1 | H39: 20150507 | I39: 20150507 | J39: DA1 | K39: DA2 | L39: 0 | M39: DA3 | N39: A | P39: S15050000005 | Q39: 01 | R39: 20 | S39: 1000 | T39: « NULL » | V39: S15050000005 | W39: 2.0250507e+16 | X39: 0002 | Z39: 2.0250507e+16 | AA39: 0002 | AC39: 2.0250507e+16 | AD39: 0002 | AF39: 2.0250507e+16 | AG39: 0002 | AI39: 2.0250507e+16 | AJ39: 0002 | AV39: S15050000005 | AY39: S15050000005 | AZ39: 2 | BA39: 20 | BB39: 1000 | BE39: 300104 | BI39: 4D | BO39: -12000 | BR39: -12000 | BS39: -1200 | BT39: 0 | BV39: 20150507 | BW39: « NULL » | BX39: 10 | BZ39: « NULL » | CC39: « NULL » | CD39: « NULL » | CI39: « NULL » | CJ39: « NULL » | CL39: 0001 | CT39: « NULL »
A40: 0 | B40: 0 | E40: ダミーユーザID | G40: 1 | H40: 20150507 | I40: 20150507 | J40: DA1 | K40: DA2 | L40: 0 | M40: DA3 | N40: A | P40: S15050000005 | Q40: 01 | R40: 20 | S40: 1000 | T40: « NULL » | V40: S15050000005 | W40: 2.0250507e+16 | X40: 0002 | Z40: 2.0250507e+16 | AA40: 0002 | AC40: 2.0250507e+16 | AD40: 0002 | AF40: 2.0250507e+16 | AG40: 0002 | AI40: 2.0250507e+16 | AJ40: 0002 | AV40: S15050000005 | AY40: S15050000005 | AZ40: 2 | BA40: 20 | BB40: 1000 | BE40: 110902 | BI40: 20 | BO40: -1200 | BR40: -1200 | BS40: 0 | BT40: « NULL » | BV40: 20150507 | BW40: 0 | BX40: 0 | BZ40: « NULL » | CC40: 0 | CD40: « NULL » | CI40: « NULL » | CJ40: « NULL » | CL40: « NULL » | CT40: « NULL »
...

Sheet ⇒

Sheet データアクセス要領
A1: ドキュメント名 | L1: サブシステム | Q1: 業務機能名 | AJ1: 作成者 | AO1: =表紙!D51 -> SCSK井上 | AT1: 更新者
A2: 業務機能概要書 | G2: データアクセス要領 | L2: =業務機能概要!L2 -> 財務会計 | Q2: =業務機能概要!Q2 -> 仕訳連動 | AJ2: 作成日付 | AO2: =表紙!C51 -> 45898 | AT2: 更新日付
A4: 【編集要領】
B6: ※ | C6: 今回のProActiveC4環境では、AWSのRDSを使用するため、Java（APサーバ）でファイル書き出しを実施する。
C7: （DBサーバ上にファイル出力できないため、DBオブジェクトを使用してファイル出力することはできない。）
B9: １． | C9: 仕訳データ出力処理最終実行開始日時取得
D11: ■抽出エンティティ
D12: № | E12: エンティティ名
D13: 1 | E13: CST変数管理
D15: ■抽出項目
D16: № | E16: 項目名
D17: 1 | E17: CST変数1 AS 仕訳データ出力処理最終実行開始日時
D19: ■抽出条件
D20: № | E20: 取得条件 | AX20: 備考
D21: 1 | E21: 会社コード | Q21: = パラメータ．会社コード | AP21: AND
D22: ２ | E22: CST変数ID | Q22: = 変数名が「仕訳データ出力処理最終実行開始日時」の変数ID
B24: ２． | C24: 出力対象外の元帳領域コード取得
D26: ■抽出エンティティ
D27: № | E27: エンティティ名
D28: 1 | E28: CST変数管理
D30: ■抽出項目
D31: № | E31: 項目名
D32: 1 | E32: CST変数1 AS 出力対象外の元帳領域コードFROM 、 CST変数2 AS 出力対象外の元帳領域コードTO
D34: ■抽出条件
D35: № | E35: 取得条件 | AX35: 備考
D36: 1 | E36: 会社コード | Q36: = パラメータ．会社コード | AP36: AND
D37: ２ | E37: CST変数ID | Q37: = 変数名が「出力対象外の元帳領域コード」の変数ID
E40: ※出力対象外としたい元帳領域の元帳領域コードは連番となるように採番しておく。
B50: ３． | C50: 外部連動用ユーザIDの取得
D52: ■抽出エンティティ
D53: № | E53: エンティティ名
D54: 1 | E54: CST変数管理
D56: ■抽出項目
D57: № | E57: 項目名
D58: 1 | E58: CST変数1 AS 外部連動用ユーザID
D60: ■抽出条件
D61: № | E61: 取得条件 | AX61: 備考
D62: 1 | E62: 会社コード | Q62: = パラメータ．会社コード | AP62: AND
D63: ２ | E63: CST変数ID | Q63: = 変数名が「外部連動用ユーザID」の変数ID
B96: ４． | C96: 仕訳データ取得 （１）と（２）を内部結合する
...

Sheet 補足
A1: ドキュメント名 | L1: サブシステム | Q1: 業務機能名 | AM1: 作成者 | AR1: =表紙!D51 -> SCSK井上 | AW1: 更新者
A2: 業務機能概要書 | G2: 補足説明 | L2: =業務機能概要!L2 -> 財務会計 | Q2: =業務機能概要!Q2 -> 仕訳連動 | AM2: 作成日付 | AR2: =表紙!C51 -> 45898 | AW2: 更新日付
C4: １）データアクセス要領シート「２．仕訳データ取得」について
D6: ①仕訳の取得範囲について（いつ作成された仕訳を取得するか）
E8: 仕訳データを重複して取得しないよう、仕訳の作成日時を適切に範囲指定して仕訳データを取得する必要がある。
E10: データ取得までの流れの例
Y11: 変数管理テーブル | AS11: 仕訳テーブル
Y12: バッチ処理最終実行開始日時 | AH12: 2025/2/6 23:05:00:000 | AS12: 仕訳No | AV12: 登録日時
AS13: 001 | AV13: 2025/2/6 23:05:00:000
AS14: 002 | AV14: 2025/2/6 23:06:00:000
AS15: 003 | AV15: 2025/2/7 08:10:00:000
AS16: 004 | AV16: 2025/2/7 09:30:00:000
F17: １．今回の仕訳連動バッチ実行開始日時の取得 | AS17: 005 | AV17: 2025/2/7 23:00:00:000
AS18: 006 | AV18: 2025/2/7 23:01:00:000
H19: 2025/2/7 23:00:00:000 | AS19: 007 | AV19: 2025/2/7 23:30:00:000
F21: ２．仕訳データの取得
H23: 2025/2/6 23:05:00:000 < 仕訳テーブル.登録日時 ≦ 2025/2/7 23:00:00:000
I25: → | J25: 取得できるのは仕訳No.002,003,004,005 | Y25: ※仕訳データ取得するころには仕訳No.006が作成されているが、今回のバッチ実行時は取得しない。
F28: ３．バッチ処理最終実行開始日時を更新
H30: 2025/2/7 23:00:00:000
H34: ↓
G36: 次回は、「 2025/2/7 23:00:00:000 ＜ 仕訳テーブル.登録日時 ≦ 次回の仕訳連動バッチ実行開始日時」 の条件で仕訳を取得する。
G37: 仕訳No.006以降が取得できる。（取得できる仕訳データに重複や漏れはない）
D50: ②抽出対象の仕訳の種類について
E51: 以下の条件を満たす仕訳を抽出する。
F53: １． | G53: ProActiveC4上で承認済みの仕訳データ。
H54: 承認機能を使用しない場合、ProActiveC4では仕訳起票と同時に承認済みというステータスとなる。
F56: ２． | G56: ProActiveC4上で本登録されている仕訳データ。
H57: ProActiveC4では、仮登録というステータスで仕訳を起票することも可能。仮登録の伝票は帳票に出力できない。
F59: ３． | G59: 元帳領域コードが抽出対象となっている仕訳データ。
H60: ホクレン様は、元帳領域コードで仕訳の色分けを行う。仕訳の種類によっては抽出対象外となる可能性がある。
F62: ４． | G62: スクラッチ開発機能からProActiveC4へ連動された仕訳以外の仕訳データ
H63: 抽出対象は、ProActiveC4上で作成された仕訳データ。
E65: データアクセス要領シート「４．仕訳データ取得」の■抽出条件より
E66: 仕訳伝票．仕訳伝票承認申請状況区分 | Q66: = '1' | AN66: 条件１．に対応
E67: 仕訳伝票．仮伝票フラグ | Q67: = '0' | AN67: 条件２．に対応
E68: 仕訳伝票．元帳領域コード | Q68: NOT BETWEEN CST変数管理．出力対象外の元帳領域コードFROM AND | AN68: 条件３．に対応
V69: CST変数管理．出力対象外の元帳領域コードTO
E70: 仕訳伝票．登録者 | Q70: <> CST変数管理．外部連動用ユーザID | AN70: 条件４．に対応
F71: ※CST変数管理テーブルにて、抽出対象外の元帳領域コードを管理する。
...
