Workbook
Name 【債権】最新データ辞書: [1]データ辞書!$H$331:$O$5000
Name 項目辞書: [2]項目辞書!$A$3:$G$1522

Sheet 表紙
F46: ProActiveC4
B48: 変更履歴
B50: 項番 | C50: 変更発生日 | D50: 変更者 | E50: 変更箇所 | F50: 変更内容
B51: 1 | C51: 45898 | D51: SCSK井上 | F51: 新規作成
B52: 2
B53: 3
B54: 4
B55: 5
B56: 6
B57: 7
B58: 8
B59: 9
B60: 10
B61: 11
B62: 12
B63: 13
... B80: 30

Sheet 業務機能概要
A1: ドキュメント名 | L1: サブシステム | Q1: 業務機能名 | AJ1: 作成者 | AO1: =表紙!D51 -> SCSK井上 | AT1: 更新者
A2: 業務機能概要書 | G2: 業務機能概要 | L2: 業務共通 | Q2: 金融機関マスタ自動取込 | AJ2: 作成日付 | AO2: =表紙!C51 -> 45898 | AT2: 更新日付
B4: 【目的・役割】
C5: ・ | D5: ホクレン様が支払や入金に使用する銀行口座の金融機関をProActiveC4では金融機関マスタで管理する。
D6: 全銀協データを複数のシステムにそれぞれ取込を行う業務運用はしたくないため、今回ProActiveC4側で作成する金融機関マスタ自動取込機能を用いて
D7: 共通のマスタとして登録された金融機関マスタ情報を取込み、ProActiveC4の金融機関マスタに反映する。
B9: 【利用者】
C10: ・ | D10: バッチ
B13: 【利用頻度】
C14: ・ | D14: 日次夜間 | H14: ※ | I14: スクラッチで新規の金融機関マスタのデータが取り込まれた後、夜間処理にて実行
B17: 【対象要件定義書】
C18: ・ | D18: 要件定義書（他システムとのデータ連動）.xls
B21: 【処理概要】
C22: １) | D22: ファイルによってデータ連動される金融機関マスタの情報をProActiveC4標準の「金融機関外部データ取込」の処理を使用してProActiveC4に取込む。
D23: バッチファイルで定義された取込ディレクトリに配置されている連動データ（取込用のCSVファイル）の情報を取得する。
C25: ２) | D25: 1)で取得した取込ファイルをINPUTとして、金融機関外部データ取込をバッチ実行する。（オンライン機能「金融機関外部データ取込」の取込動作を踏襲する。）
D26: ※ | E26: 標準の金融機関外部データ取込はオンライン処理可能なままとする
C28: ３) | D28: バッチ実行される金融機関外部データ取込は、ProActiveC4外のタスク管理用のミドルウェア（以下、タスクスケジューラ）から実行する想定とする。
D29: 正常終了、対象データがない場合は、「異常なし」のステータスをタスクスケジューラに返却する。
D30: エラー終了の場合は、「エラーあり」のステータスをタスクスケジューラに返却する。
D32: [実行情報]
D33: No | F33: パラメータ | O33: 内容
D34: 1 | F34: ※イベント概要参照
D36: [終了情報]
D37: 戻り値 | F37: 内容 | O37: 内容
D38: 0 | F38: 正常終了
D39: 1 | F39: 異常終了 | O39: 業務エラー/システムエラー発生時
B42: 【共通要件】
D43: 共通要件内容 | J43: 対応内容（標準準拠の場合、記載省略）
D44: セキュリティ | J44: 部門制限、本人制限の機能性は実装しない。
D45: 承認WF | J45: 対応なし。承認WFの利用は不可とする。
D46: 組織変更 | J46: 対応なし。当機能は仕訳に関係しないため、組織変更を考慮しない。
B50: 【前提・制約事項】
C51: １) | D51: ProActiveC4の各データの取込機能では、固定の取込フォーマットがあるため、該当するフォーマットに合わせて連動データが作成される前提とする。
D52: （データ作成は、連動元システムまたは、連動処理（ProActiveC4外）で実施する）
C54: ２) | D54: ProActiveC4に連動されるデータ（CSVファイル）は、ProActiveC4のバッチサーバから参照可能な場所に配置されることを前提とする。
C56: ３) | D56: データ取込をバッチ実行した情報は、ProActiveC4標準の「バッチジョブ」として扱われ、「バッチジョブ状況一覧」機能で状況の確認が可能となる。
D57: 状況の確認は上記機能で実施する方針として、個別にエラーログ出力等の機能性は開発しない。
C59: ４) | D59: ProActiveC4標準の金融機関外部データ取込処理を改修せずバッチ実行する。
D60: 以下のようなケースでは、標準の取込処理にも改修が必要となるため、別途対応工数を見積もることとする。
...

Sheet イベント概要
A1: ドキュメント名 | L1: サブシステム | Q1: 業務機能名 | AJ1: 作成者 | AO1: =表紙!D51 -> SCSK井上 | AT1: 更新者
A2: 業務機能概要書 | G2: イベント概要 | L2: =業務機能概要!L2 -> 業務共通 | Q2: =業務機能概要!Q2 -> 金融機関マスタ自動取込 | AJ2: 作成日付 | AO2: =表紙!C51 -> 45898 | AT2: 更新日付
A4: 【イベント処理】
B6: [-] | EV6: 注１）初期表示は全ての
B7: № | C7: イベント名 | J7: 処理説明 | EV7: データを処理対象とする
B8: =IF(C8="","",MAX(B$7:B7)+1) -> 1 | C8: 金融機関マスタ | J8: 1. | K8: バッチファイルで定義されたディレクトリに配置された取込用のCSVファイルをINPUTとし、
B9: =IF(C9="","",MAX(B$7:B8)+1) | D9: 自動取込バッチ | K9: ProActiveC4標準機能の金融機関外部データ取込を実行する。
B10: =IF(C10="","",MAX(B$7:B9)+1) | K10: ＜パラメータ＞
B11: =IF(C11="","",MAX(B$7:B10)+1) | K11: ・ | L11: 会社コード | T11: ： | U11: バッチ実行用のxmlで指定された会社コード
K12: ・ | L12: 取込CSVファイル | T12: ： | U12: バッチファイルのパラメータにて指定されたファイル
B13: =IF(C13="","",MAX(B$7:B11)+1)
B14: =IF(C14="","",MAX(B$7:B12)+1) | K14: 取込用のCSVファイルが取得できなかった場合は、処理を中断する。バッチ実行結果はエラーとする。
B15: =IF(C15="","",MAX(B$7:B13)+1) | K15: 取得できた場合は、後続の処理を継続する。
B16: =IF(C16="","",MAX(B$7:B15)+1) | K16: ※ | L16: 上記のファイル取得、エラーハンドリングはバッチファイルで実施する（アプリケーションでの考慮は不要）
B17: =IF(C17="","",MAX(B$7:B16)+1) | K17: ※ | L17: 取込用CSVのファイルサイズが0byteの場合は、正常として処理終了する。（バッチファイルにてファイルを正常処理フォルダへ移動する）
B18: =IF(C18="","",MAX(B$7:B17)+1)
B19: =IF(C19="","",MAX(B$7:B18)+1) | J19: ２．実行結果をバッチジョブ情報に反映する。
B20: =IF(C20="","",MAX(B$7:B19)+1) | M20: 標準仕様に準じる
B21: =IF(C21="","",MAX(B$7:B20)+1)
B22: =IF(C22="","",MAX(B$7:B21)+1) | M22: ※ | N22: 連動対象データがある場合のみデータ連動を行う。
B23: =IF(C23="","",MAX(B$7:B22)+1) | N23: 連動対象データがない場合（連動ファイルが0byte）は、バッチファイルで処理終了のハンドリングを実施するため、
B24: =IF(C24="","",MAX(B$7:B23)+1) | N24: 取込処理は実行されない。
B25: =IF(C25="","",MAX(B$7:B24)+1)
B26: =IF(C26="","",MAX(B$7:B25)+1) | J26: ３．バッチ実行結果の終了情報を返却する。
B27: =IF(C27="","",MAX(B$7:B26)+1) | K27: ■ | L27: 正常終了できた場合
B28: =IF(C28="","",MAX(B$7:B27)+1) | M28: 「0:正常終了」
B29: =IF(C29="","",MAX(B$7:B28)+1) | K29: ■ | L29: エラーが発生した場合（※ProActiveC4標準機能のデータ取込でエラーが発生した場合は当ケースに該当する）
B30: =IF(C30="","",MAX(B$7:B29)+1) | M30: 「1:異常終了」
B31: =IF(C31="","",MAX(B$7:B30)+1)
B32: =IF(C32="","",MAX(B$7:B31)+1) | J32: ４．取込処理後、取込用のCSVファイルは処理済用ファイルのディレクトリに移動する
B33: =IF(C33="","",MAX(B$7:B32)+1) | K33: ※ | L33: アプリケーションではなくバッチファイルでファイル移動する
B34: =IF(C34="","",MAX(B$7:B33)+1) | K34: ※ | L34: 正常用、エラー用のディレクトリを作成して処理結果によって移動先ディレクトリを分岐させる
B35: =IF(C35="","",MAX(B$7:B34)+1)
B36: =IF(C36="","",MAX(B$7:B35)+1)
B37: =IF(C37="","",MAX(B$7:B36)+1)
B38: =IF(C38="","",MAX(B$7:B37)+1)
B39: =IF(C39="","",MAX(B$7:B38)+1)
B40: =IF(C40="","",MAX(B$7:B39)+1)
B41: =IF(C41="","",MAX(B$7:B40)+1)
B42: =IF(C42="","",MAX(B$7:B41)+1)
...

Sheet 取込フォーマット定義
A1: ドキュメント名 | E1: サブシステム | G1: 業務機能名 | P1: 作成者 | R1: =表紙!D51 -> SCSK井上 | T1: 更新者
A2: 業務機能概要書 | C2: 取込フォーマット定義 | E2: =業務機能概要!L2 -> 業務共通 | G2: =業務機能概要!Q2 -> 金融機関マスタ自動取込 | P2: 作成日 | R2: =表紙!C51 -> 45898 | T2: 更新日
A4: データ名 | I4: ヘッダ行 | K4: あり | M4: なし | N4: ダブルクォーテーション | Q4: あり | S4: なし | X4: 文字列
A5: ﾌｧｲﾙ形式・ﾚｺｰﾄﾞ長 | D5: 固定長（ | G5: Byte） | I5: 可変長（区切り文字［ ，(カンマ) ］） | M5: バイナリデータ | P5: その他（ ） | X5: 半英数
A6: 文字コード | D6: UNI（Win系） | F6: EBCDIC(K) | I6: その他（ UTF-8） | M6: 改行コード | O6: LF(UNIX系) | Q6: CRLF(Win系) | T6: なし | X6: 半カナ
A7: 全角(2byte)文字項目 | D7: あり | F7: なし | M7: 数値編集 | O7: 左詰め | Q7: 右詰め［ゼロ埋め］ | T7: 右詰め［スペース埋め］ | X7: コード
A8: 特記事項 | C8: ※初期データ設定時に全国銀行協会より販売されている金融機関・店舗情報データをもとにそのデータを取り込むことを想定する。 | X8: 数値
A9: No. | B9: 項目名 | E9: 必須 | F9: 型 | G9: 桁数 | H9: 開始位置 | I9: 備考 | O9: 設定値 | X9: 日付
H10: /列 | X10: 時間
A11: 1 | B11: 金融機関コード | E11: 〇 | F11: コード | G11: 4 | H11: =SUBSTITUTE(SUBSTITUTE(ADDRESS(1,A11),"$1",""),"$","") -> A | I11: 金融機関を識別するコード（全銀協コードを設定） | O11: 金融機関マスタ.金融機関コード | X11: 年月
A12: =MAX(A$11:A11)+1 -> 2 | B12: 店舗コード | E12: 〇 | F12: コード | G12: 3 | H12: =SUBSTITUTE(SUBSTITUTE(ADDRESS(1,A12),"$1",""),"$","") -> B | I12: 店舗を識別するコード（全銀協コードを設定） | O12: 金融機関マスタ.店舗コード | X12: 区分
A13: =MAX(A$11:A12)+1 -> 3 | B13: 金融機関名カナ | F13: 文字列 | G13: 25 | H13: =SUBSTITUTE(SUBSTITUTE(ADDRESS(1,A13),"$1",""),"$","") -> C | I13: 金融機関のカナ名称 | O13: 金融機関マスタ.金融機関名（カナ）※MAX15桁 | X13: -
A14: =MAX(A$11:A13)+1 -> 4 | B14: 金融機関名 | E14: 〇 | F14: 文字列 | G14: 50 | H14: =SUBSTITUTE(SUBSTITUTE(ADDRESS(1,A14),"$1",""),"$","") -> D | I14: 金融機関の名称 | O14: 金融機関マスタ.金融機関名（漢字）
A15: =MAX(A$11:A14)+1 -> 5 | B15: 店舗名カナ | F15: 文字列 | G15: 15 | H15: =SUBSTITUTE(SUBSTITUTE(ADDRESS(1,A15),"$1",""),"$","") -> E | I15: 店舗のカナ名称 | O15: 金融機関マスタ.店舗名（カナ）※MAX15桁
A16: =MAX(A$11:A15)+1 -> 6 | B16: 店舗名 | E16: 〇 | F16: 文字列 | G16: 30 | H16: =SUBSTITUTE(SUBSTITUTE(ADDRESS(1,A16),"$1",""),"$","") -> F | I16: 店舗の名称 | O16: 金融機関マスタ.店舗名（漢字）
A17: =MAX(A$11:A16)+1 -> 7 | B17: 店舗郵便番号 | F17: 文字列 | G17: 8 | H17: =SUBSTITUTE(SUBSTITUTE(ADDRESS(1,A17),"$1",""),"$","") -> G | I17: 店舗の郵便番号 | O17: 金融機関マスタ.郵便番号 ※8桁想定のため省略不要
A18: =MAX(A$11:A17)+1 -> 8 | B18: 店舗所在地 | F18: 文字列 | G18: - | H18: =SUBSTITUTE(SUBSTITUTE(ADDRESS(1,A18),"$1",""),"$","") -> H | I18: 店舗の所在を示す住所情報 | O18: 金融機関マスタ.店舗所在地（漢字）
A19: =MAX(A$11:A18)+1 -> 9 | B19: 店舗電話番号 | F19: 文字列 | G19: 17 | H19: =SUBSTITUTE(SUBSTITUTE(ADDRESS(1,A19),"$1",""),"$","") -> I | I19: 店舗の電話番号 | O19: 金融機関マスタ.電話番号
A20: =MAX(A$11:A19)+1 -> 10 | B20: 手形交換所番号 | F20: 文字列 | G20: 4 | H20: =SUBSTITUTE(SUBSTITUTE(ADDRESS(1,A20),"$1",""),"$","") -> J | I20: 店舗が参加している手形交換所番号 | O20: 金融機関マスタ.手形交換所番号
A21: =MAX(A$11:A20)+1 -> 11 | B21: 店舗並びコード | F21: 文字列 | G21: 1 | H21: =SUBSTITUTE(SUBSTITUTE(ADDRESS(1,A21),"$1",""),"$","") -> K | O21: 設定なし
E22: 〇：必須 △：条件付き必須

Sheet ⇒

Sheet 補足
A1: ドキュメント名 | L1: サブシステム | Q1: 業務機能名 | AM1: 作成者 | AR1: =表紙!D51 -> SCSK井上 | AW1: 更新者
A2: 業務機能概要書 | G2: 補足説明 | L2: =業務機能概要!L2 -> 業務共通 | Q2: =業務機能概要!Q2 -> 金融機関マスタ自動取込 | AM2: 作成日付 | AR2: =表紙!C51 -> 45898 | AW2: 更新日付
B4: ProActiveC4標準機能の金融機関外部データ取込の仕様
B6: １）新規金融機関のみの取込
D8: 金融機関マスタ | W8: 金融機関マスタ
P9: →
E10: 金融機関001 店舗011 | P10: 取込 | X10: 金融機関001 店舗011
E11: 金融機関001 店舗012 | X11: 金融機関001 店舗012
E12: 金融機関001 店舗013 | X12: 金融機関001 店舗013
E13: 金融機関002 店舗021 | N13: 取込データ | X13: 金融機関002 店舗021
E14: 金融機関002 店舗022 | X14: 金融機関002 店舗022
O15: 金融機関004 店舗001 | X15: 金融機関004 店舗001
B18: ２）既に登録されている金融機関で、店舗の変更がある場合
D20: 金融機関マスタ | W20: 金融機関マスタ
P21: →
E22: 金融機関001 店舗011 | P22: 取込 | X22: 金融機関001 店舗011
E23: 金融機関001 店舗012 | X23: 金融機関001 店舗012
E24: 金融機関001 店舗013 | X24: 金融機関001 店舗013
E25: 金融機関002 店舗021 | N25: 取込データ | X25: 金融機関002 店舗023
E26: 金融機関002 店舗022 | X26: 金融機関002 店舗024 | AH26: ←金融機関001の情報は取込データにないため、更新を行わない。（取込前と変更はない。）
O27: 金融機関002 店舗023 | AI27: 金融機関002の店舗情報は、取込データを正として全件洗替する仕様である。
O28: 金融機関002 店舗024
B31: ３）最新情報をすべて取り込む（金融機関マスタ自動取込機能を使用する場合はこのパターンで取込データを作成する想定とする。）
D33: 金融機関マスタ | W33: 金融機関マスタ
P34: →
E35: 金融機関001 店舗011 | P35: 取込 | X35: 金融機関001 店舗011
E36: 金融機関001 店舗012 | X36: 金融機関001 店舗013
E37: 金融機関001 店舗013 | X37: 金融機関002 店舗021
E38: 金融機関002 店舗021 | N38: 取込データ | X38: 金融機関002 店舗024
E39: 金融機関002 店舗022 | X39: 金融機関002 店舗025 | AH39: ←更新のない金融機関や店舗の情報も取込データに記載する。
O40: 金融機関001 店舗011
O41: 金融機関001 店舗013
O42: 金融機関002 店舗021
O43: 金融機関002 店舗024
O44: 金融機関002 店舗025
C50: 当機能でのバッチファイル、xmlファイルの作成イメージ
C53: バッチファイル１ | P53: c4_import_kinyk.bat
D55: ①仕訳データ取込 | AG55: 入力データファイル（xml）
E57: 取込ファイル探索 | J57: ※取込ファイルが0byteであった場合は正常として処理終了する | AH57: 会社コードを定義する
AH58: ※ | AI58: 「cvo_sav_cd」は設定なしとして、取込ファイルは
...
