Workbook
Name 【債権】最新データ辞書: [1]データ辞書!$H$331:$O$5000
Name 項目辞書: [2]項目辞書!$A$3:$G$1522

Sheet 表紙
F46: ProActive
B48: 変更履歴
B50: 項番 | C50: 変更発生日 | D50: 変更者 | E50: 変更箇所 | F50: 変更内容
B51: 1 | C51: 45898 | D51: SCSK井上 | E51: 新規作成
B52: 2
B53: 3
B54: 4
B55: 5
B56: 6
B57: 7
B58: 8
B59: 9
B60: 10
B61: 11
B62: 12
B63: 13
... B80: 30

Sheet 業務機能概要
A1: ドキュメント名 | L1: サブシステム | Q1: 業務機能名 | AJ1: 作成者 | AO1: =表紙!D51 -> SCSK井上 | AT1: 更新者
A2: 業務機能概要書 | G2: 業務機能概要 | L2: 業務共通 | Q2: バッチ処理実行日更新 | AJ2: 作成日付 | AO2: =表紙!C51 -> 45898 | AT2: 更新日付
B4: 【目的・役割】
C5: ・ | D5: ProActiveC4の夜間バッチ処理全般は、バッチ処理の基準日として「バッチ処理実行日」を使用する。 ※夜間バッチ処理は日付を跨いで実行されるため、システム日付を基準日として使用できない
D6: （例えば支払決済確定バッチでは、「バッチ処理実行日」の3営業日後が支払予定日となっている支払予定データの支払決済確定を行う。）
C7: ・ | D7: 「バッチ処理実行日」は変数管理テーブルで管理する。
C8: ・ | D8: 当日のバッチ処理ががすべて正常終了してから、本機能にて「バッチ処理実行日」を更新する。
B11: 【利用者】
C12: ・ | D12: バッチ
B15: 【利用頻度】
C16: ・ | D16: 日次
B19: 【対象要件定義書】
C20: ・ | D20: 要件定義書(支払決済確定自動化).xls
B23: 【処理概要】
C24: １) | D24: バッチ実行される「バッチ処理実行日更新」はProActiveC4外のタスク管理用のミドルウェア（以下、タスクスケジューラ）から実行する想定とする。
D25: 当日のProActiveC4のバッチがすべて正常終了したことを契機に、「バッチ処理実行日更新」を実行する。
C27: ２) | D27: 変数管理テーブルで、バッチ処理実行日を管理する。
D28: ProActiveC4の営業日マスタから翌営業日を取得し、翌営業日でバッチ処理実行日を更新する。
C30: 3) | D30: 正常終了の場合は、「異常なし」のステータスをタスクスケジューラに返却する。
D31: エラー終了の場合は、「エラーあり」のステータスをタスクスケジューラに返却する。
D33: [実行情報]
D34: No | F34: パラメータ | O34: 内容
D35: 1 | F35: ※イベント概要参照
D37: [終了情報]
D38: 戻り値 | F38: 内容 | O38: 内容
D39: 0 | F39: 正常終了
D40: 1 | F40: 異常終了 | O40: 業務エラー/システムエラー発生時
B50: 【共通要件】
D51: 共通要件内容 | J51: 対応内容（標準準拠の場合、記載省略）
D52: セキュリティ | J52: 部門制限、本人制限の機能性は実装しない。
D53: 承認WF | J53: 対応なし。承認WFの利用は不可とする。
D54: 組織変更 | J54: 対応なし。当機能は仕訳に関係しないため、組織変更を考慮しない。
B57: 【前提・制約事項】
C58: １) | D58: ホクレン様の休業日は、ProActiveC4の休日マスタに正しく登録される想定とする。
D59: （ProActiveC4では休日マスタの設定内容をもとに、営業日マスタにデータが作成される。）
C61: ２) | D61: 営業日マスタの情報をもとにバッチ処理実行日更新を行う。バッチ処理実行日をイレギュラーな日付に更新する場合、営業日マスタを変更する必要がある。
C63: ３) | D63: タスクスケジューラにてProActiveC4のバッチの終了状態を監視し、すべて正常終了した場合に「バッチ処理実行日更新」を実行するものとする。
B66: 【主な取り扱い情報】
C67: ①初期処理時
D68: № | E68: 取り扱う情報 | O68: I/O | Q68: 用途
...

Sheet イベント概要
A1: ドキュメント名 | L1: サブシステム | Q1: 業務機能名 | AJ1: 作成者 | AO1: =表紙!D51 -> SCSK井上 | AT1: 更新者
A2: 業務機能概要書 | G2: イベント概要 | L2: =業務機能概要!L2 -> 業務共通 | Q2: =業務機能概要!Q2 -> バッチ処理実行日更新 | AJ2: 作成日付 | AO2: =表紙!C51 -> 45898 | AT2: 更新日付
A4: 【イベント処理】
EV6: 注１）初期表示は全ての
B7: № | C7: イベント名 | J7: 処理説明 | EV7: データを処理対象とする
B8: =IF(C8="","",MAX(B$7:B7)+1) -> 1 | C8: バッチ処理実行日更新 | J8: １． | K8: 変数管理テーブルから「バッチ処理実行日」を取得する。（データアクセス要領１．参照）
B9: =IF(C9="","",MAX(B$7:B8)+1) | K9: <パラメータ>
B10: =IF(C10="","",MAX(B$7:B9)+1) | K10: ・ | L10: 会社コード | P10: ： | Q10: パラメータファイルで指定された会社コード
B11: =IF(C11="","",MAX(B$7:B10)+1) | K11: ・ | L11: 変数ID | P11: ： | Q11: 変数管理テーブルで管理する「バッチ処理実行日」の管理ID
B13: =IF(C13="","",MAX(B$7:B11)+1) | J13: ２． | K13: ProActiveC4の営業日マスタから翌営業日を取得する。（データアクセス要領２．参照）
B14: =IF(C14="","",MAX(B$7:B12)+1) | K14: <パラメータ>
B15: =IF(C15="","",MAX(B$7:B13)+1) | K15: ・ | L15: 会社コード | R15: ： | S15: パラメータファイルで指定された会社コード
B16: =IF(C16="","",MAX(B$7:B15)+1) | K16: ・ | L16: 休日パターンコード | R16: ： | S16: パラメータファイルで指定された休日パターンコード
B17: =IF(C17="","",MAX(B$7:B16)+1) | K17: ・ | L17: 休日区分 | R17: ： | S17: パラメータファイルで指定された休日区分
B18: =IF(C18="","",MAX(B$7:B17)+1) | K18: ・ | L18: 営業日付 | R18: ： | S18: １．で取得したバッチ処理実行日
J20: ３． | K20: 変数管理テーブルの「バッチ処理実行日」を更新する。（データアクセス要領３．参照）
K21: <パラメータ>
K22: ・ | L22: 会社コード | P22: ： | Q22: パラメータファイルで指定された会社コード
K23: ・ | L23: 変数ID | P23: ： | Q23: 変数管理テーブルで管理する「バッチ処理実行日」の管理ID
K24: ・ | L24: 変数１ | P24: ： | Q24: ２．で取得した翌営業日
J26: ４． | K26: バッチ実行結果の終了情報を返却する。
K27: ■ | L27: 正常終了できた場合
M28: 「0:正常終了」
K29: ■ | L29: エラーが発生した場合
M30: 「1:異常終了」 | T30: ※SQLファイルが存在しない、SQLの実行に失敗した場合などはエラーとする。

Sheet ⇒

Sheet データアクセス要領
A1: ドキュメント名 | L1: サブシステム | Q1: 業務機能名 | AJ1: 作成者 | AO1: =表紙!D51 -> SCSK井上 | AT1: 更新者
A2: 業務機能概要書 | G2: データアクセス要領 | L2: =業務機能概要!L2 -> 業務共通 | Q2: =業務機能概要!Q2 -> バッチ処理実行日更新 | AJ2: 作成日付 | AO2: =表紙!C51 -> 45898 | AT2: 更新日付
A4: 【編集要領】
B6: １. | C6: バッチ処理実行日取得
C8: ■抽出エンティティ
C9: № | D9: エンティティ名
C10: 1 | D10: CST変数管理
C12: ■抽出項目
C13: № | D13: 項目名
C14: 1 | D14: CST変数1
C16: ■抽出条件
C17: № | D17: 取得条件 | AW17: 備考
C18: 1 | D18: 会社コード | P18: = パラメータ．会社コード | AO18: AND
C19: ２ | D19: CST変数ID | P19: = 変数名が「バッチ処理実行日」の変数ID
B22: ２. | C22: 翌営業日取得
C24: ■抽出エンティティ
C25: № | D25: エンティティ名
C26: 1 | D26: 営業日
C28: ■抽出項目
C29: № | D29: 項目名
C30: 1 | D30: MIN(営業日付) AS 翌営業日
C32: ■抽出条件
C33: № | D33: 取得条件 | AW33: 備考
C34: 1 | D34: 会社コード | P34: = パラメータ．会社コード | AO34: AND
C35: ２ | D35: 休日パターンコード | P35: = パラメータ．休日パターンコード | AO35: AND
C36: ３ | D36: 休日区分 | P36: = パラメータ．休日区分 | AO36: AND
C37: ４ | D37: 営業日付 | P37: > CST変数管理．CST変数１ | AW37: １．参照
B51: ３. | C51: バッチ処理実行日更新
C53: ■更新エンティティ
C54: № | D54: エンティティ名
C55: 1 | D55: CST変数管理
C57: ■更新内容
C58: № | D58: 項目名 | T58: 編集内容 | AW58: 備考
C59: 1 | D59: CST変数１ | T59: 営業日．翌営業日 | AW59: ２．参照
C61: ■更新条件
C62: № | D62: 取得条件 | AW62: 備考
C63: １ | D63: 会社コード | P63: = パラメータ．会社コード | AO63: AND
C64: ２ | D64: CST変数ID | P64: = 変数名が「バッチ処理実行日」の変数ID

Sheet 補足
A1: ドキュメント名 | L1: サブシステム | Q1: 業務機能名 | AM1: 作成者 | AR1: =表紙!D51 -> SCSK井上 | AW1: 更新者
A2: 業務機能概要書 | G2: 補足説明 | L2: =業務機能概要!L2 -> 業務共通 | Q2: =業務機能概要!Q2 -> バッチ処理実行日更新 | AM2: 作成日付 | AR2: =表紙!C51 -> 45898 | AW2: 更新日付
C5: １．バッチ処理実行日の更新イメージ
D7: ※ProActiveC4に関する処理のみ記載
H8: 日時 | Q8: ProActiveC4のバッチの処理
D10: 2025/2/20 9:00:00:000 | N10: ・ | O10: 日中のバッチ処理開始 | AJ10: CST変数管理 | AU10: 営業日マスタ
P11: ・ | Q11: 仕訳データの自動取込バッチ | AU11: 20250217
P12: ・ | Q12: 支払依頼データの自動取込バッチ | AJ12: バッチ処理実行日 | AP12: 20250220 | AU12: 20250218
P13: ・ | Q13: 支払決済確定情報、支払予定修正情報出力バッチ | AU13: 20250219
AU14: 20250220
D15: 2025/2/20 18:00:00:000 | N15: ・ | O15: 日中のバッチ処理終了 | AU15: 20250221
AU16: 20250225
AU17: 20250226
D18: 2025/2/20 23:00:00:000 | N18: ・ | O18: 夜間バッチ処理開始 | AU18: 20250227
P19: ・ | Q19: ProActiveC4の各種マスタデータ自動取込バッチ | AU19: 20250228
P20: ・ | Q20: 仕訳データ、支払依頼データの自動取込バッチ | AU20: 20250303
P21: ・ | Q21: ProActiveC4の支払決済確定バッチ
Q23: １．バッチ処理実行日の取得
S24: → | T24: 20250220 を取得
Q26: ２．バッチ処理実行日+３営業日が支払予定日となっている
R27: 支払予定データの支払決済確定を実行する。
S28: → | T28: 20250226 が支払予定日となるデータが対象
P30: ・ | Q30: 仕訳データ出力バッチ
D32: 2025/2/21 4:50:00:000 | N32: ・ | O32: 夜間バッチ処理終了
N33: ・ | O33: ProActiveC4の当日の全バッチ処理が正常終了
D35: 2025/2/21 5:00:00:000 | N35: ・ | O35: バッチ処理実行日の更新処理開始 | AJ35: CST変数管理
P37: １．バッチ処理実行日の取得 | AJ37: バッチ処理実行日 | AP37: 20250221
R38: → | S38: 20250220 を取得
P40: ２．翌営業日の取得
R41: → | S41: 20250221 を取得
P43: ３．バッチ処理実行日の更新
R44: → | S44: 20250221 に更新
N46: ・ | O46: バッチ処理実行日の更新処理終了
B50: 当機能でのバッチファイル、SQL実行の作成イメージ
C53: バッチファイル | P53: c4_update_batStartDt.bat | AE53: SQL実行ファイル①（.sql）
D55: ・バッチ処理日更新 | AF55: バッチ処理実行日の取得
E57: SQL①の実行（バッチ処理実行日の取得）
E58: SQL②の実行（翌営業日の取得） | AE58: SQL実行ファイル②（.sql）
E59: SQL③の実行（バッチ処理実行日の更新）
AF60: 翌営業日の取得
...
