Workbook

Sheet 変更履歴
A1: Ｐｈａｓｅ 外部設計工程 | BJ1: HOKUREN INTERNAL USE ONLY
A2: 帳票DesignDoc_v3_v2 変更履歴 | AV2: 様式No. | AZ2: F4109-0 | BD2: PAGE
A3: システム名 | H3: 統合会計システム | AV3: 作成日 | AZ3: 2025/8/29
A4: サブシステム名 | H4: 部門提供 | AV4: 更新日
A6: 機能Ｎｏ． | H6: 8.6.2 | P6: 帳票名 | V6: 加工施設採算表（総括表）
A8: 管理番号 | I8: 案件名 / 障害・問合せ件名
B10: 24058 | I10: 基幹システム再構築 会計システム外部設計

Sheet 1.帳票レイアウト
A1: Ｐｈａｓｅ 外部設計工程 | EC1: HOKUREN INTERNAL USE ONLY
A2: 帳 票 レ イ ア ウ ト
A3: システム名 | L3: 統合会計システム | CR3: 様 式 № | DB3: F4109-1 | DK3: ＰＡＧＥ
A4: 業務名 | L4: 部門提供 | CR4: 作成日 | DB4: 45898 | DK4: 更新日
A6: 帳 票 名 | L6: 加工施設採算表（総括表）
A7: 0 | K7: 1 | U7: 2 | AE7: 3 | AO7: 4 | AY7: 5 | BI7: 6 | BS7: 7 | CC7: 8 | CM7: 9 | CW7: 0 | DG7: 1 | DQ7: 2 | EA7: 3
A8: 0 | B8: =(A8+1) -> 1 | C8: =(B8+1) -> 2 | D8: =(C8+1) -> 3 | E8: =(D8+1) -> 4 | F8: =(E8+1) -> 5 | G8: =(F8+1) -> 6 | H8: =(G8+1) -> 7 | I8: =(H8+1) -> 8 | J8: =(I8+1) -> 9 | K8: 0 | L8: =(K8+1) -> 1 | M8: =(L8+1) -> 2 | N8: =(M8+1) -> 3 | O8: =(N8+1) -> 4 | P8: =(O8+1) -> 5 | Q8: =(P8+1) -> 6 | R8: =(Q8+1) -> 7 | S8: =(R8+1) -> 8 | T8: =(S8+1) -> 9 | U8: 0 | V8: =(U8+1) -> 1 | W8: =(V8+1) -> 2 | X8: =(W8+1) -> 3 | Y8: =(X8+1) -> 4 | Z8: =(Y8+1) -> 5 | AA8: =(Z8+1) -> 6 | AB8: =(AA8+1) -> 7 | AC8: =(AB8+1) -> 8 | AD8: =(AC8+1) -> 9 | AE8: 0 | AF8: =(AE8+1) -> 1 | AG8: =(AF8+1) -> 2 | AH8: =(AG8+1) -> 3 | AI8: =(AH8+1) -> 4 | AJ8: =(AI8+1) -> 5 | AK8: =(AJ8+1) -> 6 | AL8: =(AK8+1) -> 7 | AM8: =(AL8+1) -> 8 | AN8: =(AM8+1) -> 9 | AO8: 0 | AP8: =(AO8+1) -> 1 | AQ8: =(AP8+1) -> 2 | AR8: =(AQ8+1) -> 3 | AS8: =(AR8+1) -> 4 | AT8: =(AS8+1) -> 5 | AU8: =(AT8+1) -> 6 | AV8: =(AU8+1) -> 7 | AW8: =(AV8+1) -> 8 | AX8: =(AW8+1) -> 9 | AY8: 0 | AZ8: =(AY8+1) -> 1 | BA8: =(AZ8+1) -> 2 | BB8: =(BA8+1) -> 3 | BC8: =(BB8+1) -> 4 | BD8: =(BC8+1) -> 5 | BE8: =(BD8+1) -> 6 | BF8: =(BE8+1) -> 7 | BG8: =(BF8+1) -> 8 | BH8: =(BG8+1) -> 9 | BI8: 0 | BJ8: =(BI8+1) -> 1 | BK8: =(BJ8+1) -> 2 | BL8: =(BK8+1) -> 3 | BM8: =(BL8+1) -> 4 | BN8: =(BM8+1) -> 5 | BO8: =(BN8+1) -> 6 | BP8: =(BO8+1) -> 7 | BQ8: =(BP8+1) -> 8 | BR8: =(BQ8+1) -> 9 | BS8: 0 | BT8: =(BS8+1) -> 1 | BU8: =(BT8+1) -> 2 | BV8: =(BU8+1) -> 3 | BW8: =(BV8+1) -> 4 | BX8: =(BW8+1) -> 5 | BY8: =(BX8+1) -> 6 | BZ8: =(BY8+1) -> 7 | CA8: =(BZ8+1) -> 8 | CB8: =(CA8+1) -> 9 | CC8: 0 | CD8: =(CC8+1) -> 1 | CE8: =(CD8+1) -> 2 | CF8: =(CE8+1) -> 3 | CG8: =(CF8+1) -> 4 | CH8: =(CG8+1) -> 5 | CI8: =(CH8+1) -> 6 | CJ8: =(CI8+1) -> 7 | CK8: =(CJ8+1) -> 8 | CL8: =(CK8+1) -> 9 | CM8: 0 | CN8: =(CM8+1) -> 1 | CO8: =(CN8+1) -> 2 | CP8: =(CO8+1) -> 3 | CQ8: =(CP8+1) -> 4 | CR8: =(CQ8+1) -> 5 | CS8: =(CR8+1) -> 6 | CT8: =(CS8+1) -> 7 | CU8: =(CT8+1) -> 8 | CV8: =(CU8+1) -> 9 | CW8: 0 | CX8: =(CW8+1) -> 1 | CY8: =(CX8+1) -> 2 | CZ8: =(CY8+1) -> 3 | DA8: =(CZ8+1) -> 4 | DB8: =(DA8+1) -> 5 | DC8: =(DB8+1) -> 6 | DD8: =(DC8+1) -> 7 | DE8: =(DD8+1) -> 8 | DF8: =(DE8+1) -> 9 | DG8: 0 | DH8: =(DG8+1) -> 1 | DI8: =(DH8+1) -> 2 | DJ8: =(DI8+1) -> 3 | DK8: =(DJ8+1) -> 4 | DL8: =(DK8+1) -> 5 | DM8: =(DL8+1) -> 6 | DN8: =(DM8+1) -> 7 | DO8: =(DN8+1) -> 8 | DP8: =(DO8+1) -> 9 | DQ8: 0 | DR8: =(DQ8+1) -> 1 | DS8: =(DR8+1) -> 2 | DT8: =(DS8+1) -> 3 | DU8: =(DT8+1) -> 4 | DV8: =(DU8+1) -> 5 | DW8: =(DV8+1) -> 6 | DX8: =(DW8+1) -> 7 | DY8: =(DX8+1) -> 8 | DZ8: =(DY8+1) -> 9 | EA8: 0 | EB8: =(EA8+1) -> 1 | EC8: =(EB8+1) -> 2
A9: =A8+1 -> 1 | D9: XXXXXX | AW9: ＸＸＸＸＸＸＸＸＸＸＸＸＸＸＸＸＸＸＸ | CV9: 9999/Z9/Z9 HH:MM:SS | DQ9: PAGE：Z,ZZ9
A10: =A9+1 -> 2
A11: =A10+1 -> 3
A12: =A11+1 -> 4 | F12: 施設 | N12: XXXX | S12: ＸＸＸＸＸＸＸＸＸＸＸＸＸＸＸＸＸＸＸＸＸＸＸＸＸ
A13: =A12+1 -> 5 | F13: 作成年月日 | N13: XXXX年 XX月 XX日
A14: =A13+1 -> 6 | C14: 費用 | BR14: 収益
A15: =A14+1 -> 7 | C15: 科目 | Y15: 実績 | BC15: 年間計画 | BR15: 科目 | CJ15: 実績 | DN15: 年間計画
A16: =A15+1 -> 8 | C16: ＸＸＸＸＸＸ | Y16: 月計 | AN16: 累計 | BR16: ＸＸＸＸＸＸ | CJ16: 月計 | CY16: 累計
A17: =A16+1 -> 9 | D17: ＸＸＸＸＸＸＸＸＸＸ | BS17: ＸＸＸＸＸＸＸＸＸＸ
A18: =A17+1 -> 10 | F18: ＸＸＸＸＸＸＸＸＸ | Y18: 999,999,999,999 | AN18: 999,999,999,999 | BC18: 999,999,999,999 | BU18: ＸＸＸＸＸＸＸＸＸ | CJ18: 999,999,999,999 | CY18: 999,999,999,999 | DN18: 999,999,999,999
A19: =A18+1 -> 11
A20: =A19+1 -> 12
A21: =A20+1 -> 13
A22: =A21+1 -> 14
A23: =A22+1 -> 15
A24: =A23+1 -> 16 | F24: ＸＸＸＸＸＸＸＸＸ | Y24: 999,999,999,999 | AN24: 999,999,999,999 | BC24: 999,999,999,999 | BU24: ＸＸＸＸＸＸＸＸＸ | CJ24: 999,999,999,999 | CY24: 999,999,999,999 | DN24: 999,999,999,999
A25: =A24+1 -> 17 | H25: 小計 | Y25: 999,999,999,999 | AN25: 999,999,999,999 | BC25: 999,999,999,999 | BS25: ＸＸＸＸＸＸＸＸＸＸ
A26: =A25+1 -> 18 | D26: ＸＸＸＸＸＸＸＸＸＸ | BU26: ＸＸＸＸＸＸＸＸＸ | CJ26: 999,999,999,999 | CY26: 999,999,999,999 | DN26: 999,999,999,999
A27: =A26+1 -> 19 | F27: ＸＸＸＸＸＸＸＸＸ | Y27: 999,999,999,999 | AN27: 999,999,999,999 | BC27: 999,999,999,999
A28: =A27+1 -> 20
A29: =A28+1 -> 21
A30: =A29+1 -> 22
A31: =A30+1 -> 23
A32: =A31+1 -> 24 | BU32: ＸＸＸＸＸＸＸＸＸ | CJ32: 999,999,999,999 | CY32: 999,999,999,999 | DN32: 999,999,999,999
A33: =A32+1 -> 25 | F33: ＸＸＸＸＸＸＸＸＸ | Y33: 999,999,999,999 | AN33: 999,999,999,999 | BC33: 999,999,999,999 | BS33: ＸＸＸＸＸＸＸＸＸＸ
A34: =A33+1 -> 26 | H34: 小計 | Y34: 999,999,999,999 | AN34: 999,999,999,999 | BC34: 999,999,999,999 | BU34: ＸＸＸＸＸＸＸＸＸ | CJ34: 999,999,999,999 | CY34: 999,999,999,999 | DN34: 999,999,999,999
A35: =A34+1 -> 27
A36: =A35+1 -> 28
A37: =A36+1 -> 29
A38: =A37+1 -> 30
A39: =A38+1 -> 31
A40: =A39+1 -> 32 | BU40: ＸＸＸＸＸＸＸＸＸ | CJ40: 999,999,999,999 | CY40: 999,999,999,999 | DN40: 999,999,999,999
A41: =A40+1 -> 33 | BS41: ＸＸＸＸＸＸＸＸＸＸ
...

Sheet 1.帳票イメージ
A1: Ｐｈａｓｅ 外部設計工程 | EC1: HOKUREN INTERNAL USE ONLY
A2: 帳 票 レ イ ア ウ ト
A3: システム名 | L3: 統合会計システム | CR3: 様 式 № | DB3: F4109-1 | DK3: ＰＡＧＥ
A4: 業務名 | L4: 部門提供 | CR4: 作成日 | DB4: 45898 | DK4: 更新日
A6: 帳 票 名 | L6: 加工施設採算表（総括表）
A7: 0 | K7: 1 | U7: 2 | AE7: 3 | AO7: 4 | AY7: 5 | BI7: 6 | BS7: 7 | CC7: 8 | CM7: 9 | CW7: 0 | DG7: 1 | DQ7: 2 | EA7: 3
A8: 0 | B8: =(A8+1) -> 1 | C8: =(B8+1) -> 2 | D8: =(C8+1) -> 3 | E8: =(D8+1) -> 4 | F8: =(E8+1) -> 5 | G8: =(F8+1) -> 6 | H8: =(G8+1) -> 7 | I8: =(H8+1) -> 8 | J8: =(I8+1) -> 9 | K8: 0 | L8: =(K8+1) -> 1 | M8: =(L8+1) -> 2 | N8: =(M8+1) -> 3 | O8: =(N8+1) -> 4 | P8: =(O8+1) -> 5 | Q8: =(P8+1) -> 6 | R8: =(Q8+1) -> 7 | S8: =(R8+1) -> 8 | T8: =(S8+1) -> 9 | U8: 0 | V8: =(U8+1) -> 1 | W8: =(V8+1) -> 2 | X8: =(W8+1) -> 3 | Y8: =(X8+1) -> 4 | Z8: =(Y8+1) -> 5 | AA8: =(Z8+1) -> 6 | AB8: =(AA8+1) -> 7 | AC8: =(AB8+1) -> 8 | AD8: =(AC8+1) -> 9 | AE8: 0 | AF8: =(AE8+1) -> 1 | AG8: =(AF8+1) -> 2 | AH8: =(AG8+1) -> 3 | AI8: =(AH8+1) -> 4 | AJ8: =(AI8+1) -> 5 | AK8: =(AJ8+1) -> 6 | AL8: =(AK8+1) -> 7 | AM8: =(AL8+1) -> 8 | AN8: =(AM8+1) -> 9 | AO8: 0 | AP8: =(AO8+1) -> 1 | AQ8: =(AP8+1) -> 2 | AR8: =(AQ8+1) -> 3 | AS8: =(AR8+1) -> 4 | AT8: =(AS8+1) -> 5 | AU8: =(AT8+1) -> 6 | AV8: =(AU8+1) -> 7 | AW8: =(AV8+1) -> 8 | AX8: =(AW8+1) -> 9 | AY8: 0 | AZ8: =(AY8+1) -> 1 | BA8: =(AZ8+1) -> 2 | BB8: =(BA8+1) -> 3 | BC8: =(BB8+1) -> 4 | BD8: =(BC8+1) -> 5 | BE8: =(BD8+1) -> 6 | BF8: =(BE8+1) -> 7 | BG8: =(BF8+1) -> 8 | BH8: =(BG8+1) -> 9 | BI8: 0 | BJ8: =(BI8+1) -> 1 | BK8: =(BJ8+1) -> 2 | BL8: =(BK8+1) -> 3 | BM8: =(BL8+1) -> 4 | BN8: =(BM8+1) -> 5 | BO8: =(BN8+1) -> 6 | BP8: =(BO8+1) -> 7 | BQ8: =(BP8+1) -> 8 | BR8: =(BQ8+1) -> 9 | BS8: 0 | BT8: =(BS8+1) -> 1 | BU8: =(BT8+1) -> 2 | BV8: =(BU8+1) -> 3 | BW8: =(BV8+1) -> 4 | BX8: =(BW8+1) -> 5 | BY8: =(BX8+1) -> 6 | BZ8: =(BY8+1) -> 7 | CA8: =(BZ8+1) -> 8 | CB8: =(CA8+1) -> 9 | CC8: 0 | CD8: =(CC8+1) -> 1 | CE8: =(CD8+1) -> 2 | CF8: =(CE8+1) -> 3 | CG8: =(CF8+1) -> 4 | CH8: =(CG8+1) -> 5 | CI8: =(CH8+1) -> 6 | CJ8: =(CI8+1) -> 7 | CK8: =(CJ8+1) -> 8 | CL8: =(CK8+1) -> 9 | CM8: 0 | CN8: =(CM8+1) -> 1 | CO8: =(CN8+1) -> 2 | CP8: =(CO8+1) -> 3 | CQ8: =(CP8+1) -> 4 | CR8: =(CQ8+1) -> 5 | CS8: =(CR8+1) -> 6 | CT8: =(CS8+1) -> 7 | CU8: =(CT8+1) -> 8 | CV8: =(CU8+1) -> 9 | CW8: 0 | CX8: =(CW8+1) -> 1 | CY8: =(CX8+1) -> 2 | CZ8: =(CY8+1) -> 3 | DA8: =(CZ8+1) -> 4 | DB8: =(DA8+1) -> 5 | DC8: =(DB8+1) -> 6 | DD8: =(DC8+1) -> 7 | DE8: =(DD8+1) -> 8 | DF8: =(DE8+1) -> 9 | DG8: 0 | DH8: =(DG8+1) -> 1 | DI8: =(DH8+1) -> 2 | DJ8: =(DI8+1) -> 3 | DK8: =(DJ8+1) -> 4 | DL8: =(DK8+1) -> 5 | DM8: =(DL8+1) -> 6 | DN8: =(DM8+1) -> 7 | DO8: =(DN8+1) -> 8 | DP8: =(DO8+1) -> 9 | DQ8: 0 | DR8: =(DQ8+1) -> 1 | DS8: =(DR8+1) -> 2 | DT8: =(DS8+1) -> 3 | DU8: =(DT8+1) -> 4 | DV8: =(DU8+1) -> 5 | DW8: =(DV8+1) -> 6 | DX8: =(DW8+1) -> 7 | DY8: =(DX8+1) -> 8 | DZ8: =(DY8+1) -> 9 | EA8: 0 | EB8: =(EA8+1) -> 1 | EC8: =(EB8+1) -> 2
A9: =A8+1 -> 1 | D9: XXXXXX | AW9: 加工施設採算表 | CV9: 2025/03/07 00:00:00 | DQ9: PAGE： 1
A10: =A9+1 -> 2
A11: =A10+1 -> 3
A12: =A11+1 -> 4 | F12: 施設 | S12: パールライス工場総括
A13: =A12+1 -> 5 | F13: 作成年月日 | N13: 2025年 03月 07日
A14: =A13+1 -> 6 | C14: 費用 | BR14: 収益
A15: =A14+1 -> 7 | C15: 科目 | Y15: 実績 | BC15: 年間計画 | BR15: 科目 | CJ15: 実績 | DN15: 年間計画
A16: =A15+1 -> 8 | C16: 加工費用 | Y16: 月計 | AN16: 累計 | BR16: 加工収入 | CJ16: 月計 | CY16: 累計
A17: =A16+1 -> 9 | D17: 加工原料費 | BS17: 加工収入
A18: =A17+1 -> 10 | F18: 加工原料費 | Y18: 82939097 | AN18: 10176246431 | BC18: 21182997000 | BU18: 加工料 | CJ18: 0 | CY18: 18867500 | DN18: 166450000
A19: =A18+1 -> 11 | F19: 期首仕掛品 | Y19: 0 | AN19: 10908694 | BC19: 0 | BU19: 学校給食 | CJ19: 0 | CY19: 2772982 | DN19: 0
A20: =A19+1 -> 12 | H20: 小計 | Y20: 82939097 | AN20: 10187155125 | BC20: 21182997000 | BU20: 米糠他 | CJ20: 202860 | CY20: 22222754 | DN20: 70710000
A21: =A20+1 -> 13 | D21: 加工材料費 | BU21: 酒米委託加工料 | CJ21: 0 | CY21: 2376735 | DN21: 0
A22: =A21+1 -> 14 | F22: 補助材料費 | Y22: 0 | AN22: 40046787 | BC22: 61700000 | BU22: 精米 | CJ22: 81901818 | CY22: 7978374575 | DN22: 23699089000
A23: =A22+1 -> 15 | F23: 包装材料費 | Y23: 0 | AN23: 204846371 | BC23: 495300000 | BU23: その他 | CJ23: 0 | CY23: 22175288 | DN23: 0
A24: =A23+1 -> 16 | F24: 消耗工具器具備品 | Y24: 0 | AN24: 113220 | BC24: 1750000 | BS24: 加工雑収入
A25: =A24+1 -> 17 | H25: 小計 | Y25: 0 | AN25: 245006378 | BC25: 558750000 | BU25: 学校給食 | CJ25: 0 | CY25: 3407956 | DN25: 0
A26: =A25+1 -> 18 | D26: 加工労務費 | BU26: 空容器 | CJ26: 0 | CY26: 12396 | DN26: 27000000
A27: =A26+1 -> 19 | F27: 給料手当 | Y27: 320586 | AN27: 1357070 | BC27: 2097000 | BU27: 酒米運賃 | CJ27: 0 | CY27: 411244 | DN27: 0
A28: =A27+1 -> 20 | F28: 福利厚生費 | Y28: 54513 | AN28: 253025 | BC28: 360000 | BU28: その他 | CJ28: 0 | CY28: 11469724 | DN28: 28545000
A29: =A28+1 -> 21 | H29: 小計 | Y29: 375099 | AN29: 1610095 | BC29: 2457000 | BS29: 合計 | CJ29: 82104678 | CY29: 8062092054 | DN29: 23991794000
A30: =A29+1 -> 22 | D30: 加工経費
A31: =A30+1 -> 23 | F31: 電力料 | Y31: 0 | AN31: 50498073 | BC31: 159500000 | BS31: 事業粗利益 | CJ31: -6543193 | CY31: -3002225355 | DN31: 3539000
A32: =A31+1 -> 24
A33: =A32+1 -> 25 | BS33: 取扱高控除額 | CJ33: 82939097 | CY33: 10176246431 | DN33: 0
A34: =A33+1 -> 26
A35: =A34+1 -> 27
A36: =A35+1 -> 28
A37: =A36+1 -> 29
A38: =A37+1 -> 30
A39: =A38+1 -> 31
A40: =A39+1 -> 32
A41: =A40+1 -> 33
...

Sheet 2.条件表
A1: Ｐｈａｓｅ 外部設計工程 | BJ1: HOKUREN INTERNAL USE ONLY
A2: 帳票説明書 （作成条件表） | AV2: 様式No. | AZ2: F4109-2 | BD2: PAGE
A3: システム名 | H3: 統合会計システム | AV3: 作成日 | AZ3: 2025/8/29
A4: 業務名 | H4: 部門提供 | AV4: 更新日 | AZ4: =IF(ISBLANK(変更履歴!AZ4),"",変更履歴!AZ4)
A6: 機能Ｎｏ． | H6: 8.6.2 | P6: 帳票名 | Y6: 加工施設採算表（総括表） | AV6: データストア№ | BD6: D08060201
A8: 【帳票 用途】
E9: １． | F9: 勘定科目の費用、収益、粗利益の実績を科目摘要単位で把握する為に作成する。
A12: 作成処理 概要 | G12: 入力ファイル ： | AE12: 対象とするデータの条件 ：
H13: D08070101 | AF13: 施設採算表出力画面で設定された条件に合致する
I14: 施設実績情報 | AF14: 施設実績情報を出力する。
G15: 留意事項：
H16: なし
A20: 帳票ＩＤ
A21: 印刷箇所 | H21: □ | J21: センター印刷（ 1 部） | AE21: 印刷装置 | AM21: ■ | AO21: レーザープリンター
H22: ■ | J22: オンライン印刷（ ） | AM22: □ | AO22: インパクトプリンター
H23: □ | J23: その他 | AM23: □ | AO23: その他
J24: （ | AB24: ） | AO24: （ | BI24: ）
A25: 印刷用紙 | H25: ■ | J25: Ａ４カット紙 | AE25: 作成サイクル | AM25: 随時 | AW25: 帳票管理ｓ 保管 | BC25: 世代数
H26: □ | J26: 連続用紙 | O26: （ | R26: ｲﾝﾁx | AC26: ｲﾝﾁ | AD26: ）
H27: □ | J27: 定型用紙 | O27: （ | AD27: ） | AE27: センター印刷時 配布箇所 | BC27: 期間日数 | BG27: 10年
H28: □ | J28: その他 | O28: （ | AD28: ）
A29: 印字サイズ | AE29: 処理タイプ | AM29: □ | AO29: バッチ | AS29: （ 日中 ・ 夜間 ）
H30: 132 | P30: 桁 | AM30: ■ | AO30: オンライン画面起動
H31: 66 | P31: 行 | AM31: □ | AO31: その他 | AS31: （ | BI31: ）
A34: ページ番号 採番条件 | H34: □ | J34: 一連番号で採番（１から連番） | AK34: □ | AM34: ページ番号印字なし
H35: ■ | J35: 1施設内で複数枚になる場合同一ページが連続する。
A38: 改ページ条件 | H38: １．施設コード
A42: １ページ 明細数 | G42: 27明細
A44: 入力ファイルソートキー （明細印字順） | G44: 1: | I44: 目科目コード | AH44: 昇順／降順 | AJ44: 10: | BI44: 昇順／降順
G45: 2: | I45: 節科目コード | AH45: 昇順／降順 | AJ45: 11: | BI45: 昇順／降順
G46: 3: | AH46: 昇順／降順 | AJ46: 12: | BI46: 昇順／降順
G47: 4: | AH47: 昇順／降順 | AJ47: 13: | BI47: 昇順／降順
G48: 5: | AH48: 昇順／降順 | AJ48: 14: | BI48: 昇順／降順
G49: 6: | AH49: 昇順／降順 | AJ49: 15: | BI49: 昇順／降順
G50: 7: | AH50: 昇順／降順 | AJ50: 16: | BI50: 昇順／降順
G51: 8: | AH51: 昇順／降順 | AJ51: 17: | BI51: 昇順／降順
G52: 9: | AH52: 昇順／降順 | AJ52: 18: | BI52: 昇順／降順
A54: 合計等 印字条件 明細行の合計計算、合計行の集計計算等について記載する。
H55: １．印字順（紙の並び順）は、施設コード順に印字する。
H56: ２．目科目コードが変わった場合、小計を印字する。
...

Sheet 3.項目説明
A1: Ｐｈａｓｅ 外部設計工程 | BJ1: HOKUREN INTERNAL USE ONLY
A2: 帳票説明書 （項目説明） | AV2: 様式No. | AZ2: F4109-3 | BD2: PAGE
A3: システム名 | H3: 統合会計システム | AV3: 作成日 | AZ3: 2025/8/29
A4: 業務名 | H4: 部門提供 | AV4: 更新日 | AZ4: =IF(ISBLANK(変更履歴!AZ4),"",変更履歴!AZ4)
A6: 機能Ｎｏ． | H6: ='2.条件表'!H6 -> 8.6.2 | P6: 帳票名 | Y6: ='2.条件表'!Y6 -> 加工施設採算表（総括表） | AV6: データストア№ | BD6: ='2.条件表'!BD6 -> D08060201
A8: № | D8: 項目名 | R8: 桁数 | U8: 編集パターン | AE8: 項目編集説明
D9: 【ヘッダ】
A10: 1 | D10: 帳票ID | R10: 6 | U10: XXXXXX | AE10: 帳票ID
A11: 2 | D11: タイトル | R11: 19 | U11: 全角19文字 | AE11: 「加工施設採算表」
A12: 3 | D12: 作成日 | R12: 10 | U12: 9999/Z9/Z9 | AE12: 作成年月日
A13: 4 | D13: 作成時刻 | R13: 8 | U13: HH:MM:SS | AE13: 作成時刻
A14: 5 | D14: ページ数 | R14: 5 | U14: Z,ZZ9 | AE14: 現ページ数
A15: 6 | D15: 施設コード | R15: 4 | U15: XXXX | AE15: "4"+課コード
A16: 7 | D16: 施設名称 | R16: 25 | U16: 全角25文字 | AE16: 総括名称
A17: 8 | D17: 作成年月日 | R17: 10 | U17: YYYY/MM/DD | AE17: 作成年月日
D18: 【明細-費用】
A19: 9 | D19: 項科目名称 | R19: 6 | U19: 全角6文字 | AE19: 費用に対する項科目の名称
A20: 10 | D20: 目科目名称 | R20: 10 | U20: 全角10文字 | AE20: 費用に対する目科目の名称
A21: 11 | D21: 節科目名称 | R21: 9 | U21: 全角9文字 | AE21: 費用に対する節科目の名称
A22: 12 | D22: 節科目月計 | R22: 15 | U22: 999,999,999,999 | AE22: 費用に対する節科目月計
A23: 13 | D23: 節科目累計 | R23: 15 | U23: 999,999,999,999 | AE23: 費用に対する節科目累計
A24: 14 | D24: 節科目年間計画 | R24: 15 | U24: 999,999,999,999 | AE24: 費用に対する節科目年間計画
A25: 15 | D25: 小計項目見出し | R25: 9 | U25: 全角9文字 | AE25: 「小計」
A26: 16 | D26: 小計月計 | R26: 15 | U26: 999,999,999,999 | AE26: 費用に対する目科目月計
A27: 17 | D27: 小計累計 | R27: 15 | U27: 999,999,999,999 | AE27: 費用に対する目科目累計
A28: 18 | D28: 小計年間計画 | R28: 15 | U28: 999,999,999,999 | AE28: 費用に対する目科目年間計画
A29: 19 | D29: 合計月計 | R29: 15 | U29: 999,999,999,999 | AE29: 費用の月計合計
A30: 20 | D30: 合計累計 | R30: 15 | U30: 999,999,999,999 | AE30: 費用の累計合計
A31: 21 | D31: 合計年間計画 | R31: 15 | U31: 999,999,999,999 | AE31: 費用の年間計画合計
D32: 【明細-収益】
A33: 22 | D33: 項科目名称 | R33: 6 | U33: 全角6文字 | AE33: 収益に対する項科目の名称
A34: 23 | D34: 目科目名称 | R34: 8 | U34: 全角8文字 | AE34: 収益に対する目科目の名称
A35: 24 | D35: 品目名称 | R35: 7 | U35: 全角7文字 | AE35: 収益に対する品目の名称
A36: 25 | D36: 品目別月計 | R36: 15 | U36: 999,999,999,999 | AE36: 収益に対する品目別月計
A37: 26 | D37: 品目別累計 | R37: 15 | U37: 999,999,999,999 | AE37: 収益に対する品目別累計
A38: 27 | D38: 品目別年間計画 | R38: 15 | U38: 999,999,999,999 | AE38: 収益に対する品目別年間計画
A39: 28 | D39: 合計月計 | R39: 15 | U39: 999,999,999,999 | AE39: 収益の月計合計
A40: 29 | D40: 合計累計 | R40: 15 | U40: 999,999,999,999 | AE40: 収益の累計合計
A41: 30 | D41: 合計年間計画 | R41: 15 | U41: 999,999,999,999 | AE41: 収益の年間計画合計
A42: 31 | D42: 事業粗利益月計 | R42: 15 | U42: 999,999,999,999 | AE42: 【明細-収益】合計月計 － 【明細-費用】合計月計
...
